
#######################################################################
# +-----------------------------------------------------------------+ #
# |                            BO4 object                           | #
# +-----------------------------------------------------------------+ #
#######################################################################

Author: NLBlackEagle

Description: No description given

SettingsMode: WriteDisable


#######################################################################
# +-----------------------------------------------------------------+ #
# |                          Main settings                          | #
# +-----------------------------------------------------------------+ #
#######################################################################

FixedRotation: 

Frequency: 0

SpawnHeight: highestBlock

UseCenterForHighestBlock: true

##############################
# Height Limits for the BO4. #
##############################

MinHeight: 0

MaxHeight: 255

InheritBO3: 

InheritBO3Rotation: NORTH

OverrideChildSettings: true

OverrideParentHeight: false

CanOverride: false

BranchFrequency: 0

BranchFrequencyGroup: 

MustBeBelowOther: false

MustBeInside: 

CannotBeInside: 

ReplacesBO3: 

MustBeInsideWorldBorders: false

CanSpawnOnWater: true

SpawnOnWaterOnly: false

SpawnUnderWater: false

SpawnAtWaterLevel: false

HeightOffset: 0

RemoveAir: true

ReplaceAbove: 

ReplaceBelow: 

ReplaceWithBiomeBlocks: true

ReplaceWithSurfaceBlock: GRASS

ReplaceWithGroundBlock: DIRT

ReplaceWithStoneBlock: STONE

SmoothRadius: 0

SmoothHeightOffset: 0

SmoothStartTop: false

SmoothStartWood: false

SmoothingSurfaceBlock: 

SmoothingGroundBlock: 

BO3Group: 

IsSpawnPoint: false

DoReplaceBlocks: true


#######################################################################
# +-----------------------------------------------------------------+ #
# |                              Blocks                             | #
# +-----------------------------------------------------------------+ #
#######################################################################

Block(-8,4,0,LEAVES:0)
Block(-8,4,1,LEAVES:0)
Block(-8,4,2,LEAVES:0)
Block(-8,5,0,LEAVES:0)
Block(-8,5,1,LOG:12)
Block(-8,5,2,LOG:12)
Block(-8,5,3,LOG:12)
Block(-8,5,4,LOG:12)
Block(-8,6,1,LEAVES:0)
Block(-8,6,2,LEAVES:0)
Block(-8,6,3,LOG:12)
Block(-8,6,4,LOG:12)
Block(-8,7,3,quark:leaf_carpet)
Block(-8,7,7,LOG:12)
Block(-8,7,8,LOG:12)
Block(-8,8,7,LOG:12)
Block(-8,8,8,LOG:12)
Block(-8,9,7,LOG:12)
Block(-8,9,8,LOG:12)
Block(-8,10,8,LOG:12)
Block(-8,19,8,WOOL:14)
Block(-8,20,8,WOOL:14)
RandomBlock(-8,21,0,minecraft:wool:0,10,quark:quilted_wool:0,100)
RandomBlock(-8,21,1,minecraft:wool:0,10,quark:quilted_wool:0,100)
RandomBlock(-8,21,2,minecraft:wool:0,10,quark:quilted_wool:0,100)
Block(-8,21,8,WOOL:14)
RandomBlock(-8,22,-1,minecraft:wool:0,10,quark:quilted_wool:0,100)
RandomBlock(-8,22,0,minecraft:wool:0,10,quark:quilted_wool:0,100)
RandomBlock(-8,22,1,minecraft:wool:0,10,quark:quilted_wool:0,100)
RandomBlock(-8,22,2,minecraft:wool:0,10,quark:quilted_wool:0,100)
RandomBlock(-8,22,3,minecraft:wool:0,10,quark:quilted_wool:0,100)
Block(-8,22,8,WOOL:14)
RandomBlock(-8,23,-2,minecraft:wool:0,10,quark:quilted_wool:0,100)
RandomBlock(-8,23,-1,minecraft:wool:0,10,quark:quilted_wool:0,100)
RandomBlock(-8,23,0,minecraft:wool:0,10,quark:quilted_wool:0,100)
RandomBlock(-8,23,1,minecraft:wool:0,10,quark:quilted_wool:0,100)
RandomBlock(-8,23,2,minecraft:wool:0,10,quark:quilted_wool:0,100)
RandomBlock(-8,23,3,minecraft:wool:0,10,quark:quilted_wool:0,100)
RandomBlock(-8,23,4,minecraft:wool:0,10,quark:quilted_wool:0,100)
Block(-8,23,8,WOOL:14)
RandomBlock(-8,24,-2,minecraft:wool:0,10,quark:quilted_wool:0,100)
RandomBlock(-8,24,-1,minecraft:wool:0,10,quark:quilted_wool:0,100)
RandomBlock(-8,24,0,minecraft:wool:0,10,quark:quilted_wool:0,100)
RandomBlock(-8,24,1,minecraft:wool:0,10,quark:quilted_wool:0,100)
RandomBlock(-8,24,2,minecraft:wool:0,10,quark:quilted_wool:0,100)
RandomBlock(-8,24,3,minecraft:wool:0,10,quark:quilted_wool:0,100)
RandomBlock(-8,24,4,minecraft:wool:0,10,quark:quilted_wool:0,100)
RandomBlock(-8,25,-3,minecraft:wool:0,10,quark:quilted_wool:0,100)
RandomBlock(-8,25,-2,minecraft:wool:0,10,quark:quilted_wool:0,100)
RandomBlock(-8,25,-1,minecraft:wool:0,10,quark:quilted_wool:0,100)
RandomBlock(-8,25,0,minecraft:wool:0,10,quark:quilted_wool:0,100)
RandomBlock(-8,25,1,minecraft:wool:0,10,quark:quilted_wool:0,100)
RandomBlock(-8,25,2,minecraft:wool:0,10,quark:quilted_wool:0,100)
RandomBlock(-8,25,3,minecraft:wool:0,10,quark:quilted_wool:0,100)
RandomBlock(-8,25,4,minecraft:wool:0,10,quark:quilted_wool:0,100)
RandomBlock(-8,25,5,minecraft:wool:0,10,quark:quilted_wool:0,100)
RandomBlock(-8,26,-3,minecraft:wool:0,10,quark:quilted_wool:0,100)
RandomBlock(-8,26,-2,minecraft:wool:0,10,quark:quilted_wool:0,100)
RandomBlock(-8,26,-1,minecraft:wool:0,10,quark:quilted_wool:0,100)
RandomBlock(-8,26,0,minecraft:wool:0,10,quark:quilted_wool:0,100)
RandomBlock(-8,26,1,minecraft:wool:0,10,quark:quilted_wool:0,100)
RandomBlock(-8,26,2,minecraft:wool:0,10,quark:quilted_wool:0,100)
RandomBlock(-8,26,3,minecraft:wool:0,10,quark:quilted_wool:0,100)
RandomBlock(-8,26,4,minecraft:wool:0,10,quark:quilted_wool:0,100)
RandomBlock(-8,26,5,minecraft:wool:0,10,quark:quilted_wool:0,100)
RandomBlock(-8,27,-3,minecraft:wool:0,10,quark:quilted_wool:0,100)
RandomBlock(-8,27,-2,minecraft:wool:0,10,quark:quilted_wool:0,100)
RandomBlock(-8,27,-1,minecraft:wool:0,10,quark:quilted_wool:0,100)
RandomBlock(-8,27,0,minecraft:wool:0,10,quark:quilted_wool:0,100)
RandomBlock(-8,27,1,minecraft:wool:0,10,quark:quilted_wool:0,100)
RandomBlock(-8,27,2,minecraft:wool:0,10,quark:quilted_wool:0,100)
RandomBlock(-8,27,3,minecraft:wool:0,10,quark:quilted_wool:0,100)
RandomBlock(-8,27,4,minecraft:wool:0,10,quark:quilted_wool:0,100)
RandomBlock(-8,27,5,minecraft:wool:0,10,quark:quilted_wool:0,100)
RandomBlock(-8,28,-3,minecraft:wool:0,10,quark:quilted_wool:0,100)
RandomBlock(-8,28,-2,minecraft:wool:0,10,quark:quilted_wool:0,100)
RandomBlock(-8,28,-1,minecraft:wool:0,10,quark:quilted_wool:0,100)
RandomBlock(-8,28,0,minecraft:wool:0,10,quark:quilted_wool:0,100)
RandomBlock(-8,28,1,minecraft:wool:0,10,quark:quilted_wool:0,100)
RandomBlock(-8,28,2,minecraft:wool:0,10,quark:quilted_wool:0,100)
RandomBlock(-8,28,3,minecraft:wool:0,10,quark:quilted_wool:0,100)
RandomBlock(-8,28,4,minecraft:wool:0,10,quark:quilted_wool:0,100)
RandomBlock(-8,28,5,minecraft:wool:0,10,quark:quilted_wool:0,100)
RandomBlock(-8,29,-3,minecraft:wool:0,10,quark:quilted_wool:0,100)
RandomBlock(-8,29,-2,minecraft:wool:0,10,quark:quilted_wool:0,100)
RandomBlock(-8,29,-1,minecraft:wool:0,10,quark:quilted_wool:0,100)
RandomBlock(-8,29,0,minecraft:wool:0,10,quark:quilted_wool:0,100)
RandomBlock(-8,29,1,minecraft:wool:0,10,quark:quilted_wool:0,100)
RandomBlock(-8,29,2,minecraft:wool:0,10,quark:quilted_wool:0,100)
RandomBlock(-8,29,3,minecraft:wool:0,10,quark:quilted_wool:0,100)
RandomBlock(-8,29,4,minecraft:wool:0,10,quark:quilted_wool:0,100)
RandomBlock(-8,29,5,minecraft:wool:0,10,quark:quilted_wool:0,100)
RandomBlock(-8,30,-2,minecraft:wool:0,10,quark:quilted_wool:0,100)
RandomBlock(-8,30,-1,minecraft:wool:0,10,quark:quilted_wool:0,100)
RandomBlock(-8,30,0,minecraft:wool:0,10,quark:quilted_wool:0,100)
RandomBlock(-8,30,1,minecraft:wool:0,10,quark:quilted_wool:0,100)
RandomBlock(-8,30,2,minecraft:wool:0,10,quark:quilted_wool:0,100)
RandomBlock(-8,30,3,minecraft:wool:0,10,quark:quilted_wool:0,100)
RandomBlock(-8,30,4,minecraft:wool:0,10,quark:quilted_wool:0,100)
RandomBlock(-8,31,-2,minecraft:wool:0,10,quark:quilted_wool:0,100)
RandomBlock(-8,31,-1,minecraft:wool:0,10,quark:quilted_wool:0,100)
RandomBlock(-8,31,0,minecraft:wool:0,10,quark:quilted_wool:0,100)
RandomBlock(-8,31,1,minecraft:wool:0,10,quark:quilted_wool:0,100)
RandomBlock(-8,31,2,minecraft:wool:0,10,quark:quilted_wool:0,100)
RandomBlock(-8,31,3,minecraft:wool:0,10,quark:quilted_wool:0,100)
RandomBlock(-8,31,4,minecraft:wool:0,10,quark:quilted_wool:0,100)
RandomBlock(-8,32,-1,minecraft:wool:0,10,quark:quilted_wool:0,100)
RandomBlock(-8,32,0,minecraft:wool:0,10,quark:quilted_wool:0,100)
RandomBlock(-8,32,1,minecraft:wool:0,10,quark:quilted_wool:0,100)
RandomBlock(-8,32,2,minecraft:wool:0,10,quark:quilted_wool:0,100)
RandomBlock(-8,32,3,minecraft:wool:0,10,quark:quilted_wool:0,100)
RandomBlock(-8,33,0,minecraft:wool:0,10,quark:quilted_wool:0,100)
RandomBlock(-8,33,1,minecraft:wool:0,10,quark:quilted_wool:0,100)
RandomBlock(-8,33,2,minecraft:wool:0,10,quark:quilted_wool:0,100)
Block(-8,67,7,LEAVES:0)
Block(-8,67,8,LEAVES:0)
Block(-8,68,6,LEAVES:0)
Block(-8,68,7,LEAVES:0)
Block(-8,68,8,LEAVES:0)
Block(-8,69,6,LEAVES:0)
Block(-8,69,7,LEAVES:0)
Block(-8,69,8,LEAVES:0)
Block(-8,70,7,LEAVES:0)
Block(-8,70,8,LEAVES:0)
Block(-8,71,7,LEAVES:0)
Block(-8,71,8,LEAVES:0)
Block(-8,72,8,LEAVES:0)
Block(-8,74,8,LEAVES:0)
Block(-8,75,8,LEAVES:0)
RandomBlock(-8,83,7,minecraft:wool:0,10,quark:quilted_wool:0,100)
RandomBlock(-8,83,8,minecraft:wool:0,10,quark:quilted_wool:0,100)
RandomBlock(-8,84,7,minecraft:wool:0,10,quark:quilted_wool:0,100)
RandomBlock(-8,84,8,minecraft:wool:0,10,quark:quilted_wool:0,100)
RandomBlock(-8,85,7,minecraft:wool:0,10,quark:quilted_wool:0,100)
RandomBlock(-8,85,8,minecraft:wool:0,10,quark:quilted_wool:0,100)
RandomBlock(-8,86,7,minecraft:wool:0,10,quark:quilted_wool:0,100)
RandomBlock(-8,86,8,minecraft:wool:0,10,quark:quilted_wool:0,100)
RandomBlock(-8,87,7,minecraft:wool:0,10,quark:quilted_wool:0,100)
RandomBlock(-8,87,8,minecraft:wool:0,10,quark:quilted_wool:0,100)
RandomBlock(-8,97,8,minecraft:wool:0,10,quark:quilted_wool:0,100)
RandomBlock(-8,98,8,minecraft:wool:0,10,quark:quilted_wool:0,100)
RandomBlock(-8,99,7,minecraft:wool:0,10,quark:quilted_wool:0,100)
RandomBlock(-8,99,8,minecraft:wool:0,10,quark:quilted_wool:0,100)
RandomBlock(-8,100,7,minecraft:wool:0,10,quark:quilted_wool:0,100)
RandomBlock(-8,100,8,minecraft:wool:0,10,quark:quilted_wool:0,100)
RandomBlock(-8,101,7,minecraft:wool:0,10,quark:quilted_wool:0,100)
RandomBlock(-8,101,8,minecraft:wool:0,10,quark:quilted_wool:0,100)
RandomBlock(-8,102,7,minecraft:wool:0,10,quark:quilted_wool:0,100)
RandomBlock(-8,102,8,minecraft:wool:0,10,quark:quilted_wool:0,100)
RandomBlock(-8,103,7,minecraft:wool:0,10,quark:quilted_wool:0,100)
RandomBlock(-8,103,8,minecraft:wool:0,10,quark:quilted_wool:0,100)
RandomBlock(-8,104,7,minecraft:wool:0,10,quark:quilted_wool:0,100)
RandomBlock(-8,104,8,minecraft:wool:0,10,quark:quilted_wool:0,100)
RandomBlock(-8,105,7,minecraft:wool:0,10,quark:quilted_wool:0,100)
RandomBlock(-8,105,8,minecraft:wool:0,10,quark:quilted_wool:0,100)
RandomBlock(-8,106,8,minecraft:wool:0,10,quark:quilted_wool:0,100)
RandomBlock(-8,107,8,minecraft:wool:0,10,quark:quilted_wool:0,100)
Block(-7,3,0,LEAVES:0)
Block(-7,4,-1,LEAVES:0)
Block(-7,4,0,LOG:12)
Block(-7,4,1,LOG:12)
Block(-7,5,0,LEAVES:0)
Block(-7,5,1,LOG:12)
Block(-7,5,2,LOG:12)
Block(-7,6,1,inspirations:rope:1)
Block(-7,6,2,quark:leaf_carpet)
Block(-7,7,1,inspirations:rope:1)
Block(-7,7,8,LOG:12)
Block(-7,8,1,inspirations:rope:1)
Block(-7,8,7,LOG:12)
Block(-7,8,8,LOG:12)
Block(-7,9,1,inspirations:rope:1)
Block(-7,9,8,LOG:12)
Block(-7,10,1,inspirations:rope:1)
Block(-7,11,1,inspirations:rope:1)
Block(-7,12,1,inspirations:rope:1)
Block(-7,13,1,inspirations:rope:1)
Block(-7,14,1,inspirations:rope:1)
Block(-7,15,1,inspirations:rope:1)
Block(-7,16,1,inspirations:rope:1)
Block(-7,17,1,inspirations:rope:1)
Block(-7,18,1,inspirations:rope:1)
Block(-7,18,8,WOOL:14)
Block(-7,19,1,inspirations:rope:1)
Block(-7,19,8,WOOL:14)
Block(-7,20,1,inspirations:rope:1)
Block(-7,20,7,WOOL:14)
Block(-7,20,8,WOOL:14)
RandomBlock(-7,21,0,minecraft:wool:0,10,quark:quilted_wool:0,100)
RandomBlock(-7,21,1,minecraft:wool:0,10,quark:quilted_wool:0,100)
RandomBlock(-7,21,2,minecraft:wool:0,10,quark:quilted_wool:0,100)
Block(-7,21,7,WOOL:14)
Block(-7,21,8,WOOL:14)
RandomBlock(-7,22,-1,minecraft:wool:0,10,quark:quilted_wool:0,100)
RandomBlock(-7,22,0,minecraft:wool:0,10,quark:quilted_wool:0,100)
RandomBlock(-7,22,1,minecraft:wool:0,10,quark:quilted_wool:0,100)
RandomBlock(-7,22,2,minecraft:wool:0,10,quark:quilted_wool:0,100)
RandomBlock(-7,22,3,minecraft:wool:0,10,quark:quilted_wool:0,100)
Block(-7,22,7,WOOL:14)
Block(-7,22,8,WOOL:14)
RandomBlock(-7,23,-2,minecraft:wool:0,10,quark:quilted_wool:0,100)
RandomBlock(-7,23,-1,minecraft:wool:0,10,quark:quilted_wool:0,100)
RandomBlock(-7,23,0,minecraft:wool:0,10,quark:quilted_wool:0,100)
RandomBlock(-7,23,1,minecraft:wool:0,10,quark:quilted_wool:0,100)
RandomBlock(-7,23,2,minecraft:wool:0,10,quark:quilted_wool:0,100)
RandomBlock(-7,23,3,minecraft:wool:0,10,quark:quilted_wool:0,100)
RandomBlock(-7,23,4,minecraft:wool:0,10,quark:quilted_wool:0,100)
Block(-7,23,8,WOOL:14)
RandomBlock(-7,24,-2,minecraft:wool:0,10,quark:quilted_wool:0,100)
RandomBlock(-7,24,-1,minecraft:wool:0,10,quark:quilted_wool:0,100)
RandomBlock(-7,24,0,minecraft:wool:0,10,quark:quilted_wool:0,100)
RandomBlock(-7,24,1,minecraft:wool:0,10,quark:quilted_wool:0,100)
RandomBlock(-7,24,2,minecraft:wool:0,10,quark:quilted_wool:0,100)
RandomBlock(-7,24,3,minecraft:wool:0,10,quark:quilted_wool:0,100)
RandomBlock(-7,24,4,minecraft:wool:0,10,quark:quilted_wool:0,100)
Block(-7,24,8,WOOL:14)
RandomBlock(-7,25,-3,minecraft:wool:0,10,quark:quilted_wool:0,100)
RandomBlock(-7,25,-2,minecraft:wool:0,10,quark:quilted_wool:0,100)
RandomBlock(-7,25,-1,minecraft:wool:0,10,quark:quilted_wool:0,100)
RandomBlock(-7,25,0,minecraft:wool:0,10,quark:quilted_wool:0,100)
RandomBlock(-7,25,1,minecraft:wool:0,10,quark:quilted_wool:0,100)
RandomBlock(-7,25,2,minecraft:wool:0,10,quark:quilted_wool:0,100)
RandomBlock(-7,25,3,minecraft:wool:0,10,quark:quilted_wool:0,100)
RandomBlock(-7,25,4,minecraft:wool:0,10,quark:quilted_wool:0,100)
RandomBlock(-7,25,5,minecraft:wool:0,10,quark:quilted_wool:0,100)
RandomBlock(-7,26,-3,minecraft:wool:0,10,quark:quilted_wool:0,100)
RandomBlock(-7,26,-2,minecraft:wool:0,10,quark:quilted_wool:0,100)
RandomBlock(-7,26,-1,minecraft:wool:0,10,quark:quilted_wool:0,100)
RandomBlock(-7,26,0,minecraft:wool:0,10,quark:quilted_wool:0,100)
RandomBlock(-7,26,1,minecraft:wool:0,10,quark:quilted_wool:0,100)
RandomBlock(-7,26,2,minecraft:wool:0,10,quark:quilted_wool:0,100)
RandomBlock(-7,26,3,minecraft:wool:0,10,quark:quilted_wool:0,100)
RandomBlock(-7,26,4,minecraft:wool:0,10,quark:quilted_wool:0,100)
RandomBlock(-7,26,5,minecraft:wool:0,10,quark:quilted_wool:0,100)
RandomBlock(-7,27,-3,minecraft:wool:0,10,quark:quilted_wool:0,100)
RandomBlock(-7,27,-2,minecraft:wool:0,10,quark:quilted_wool:0,100)
RandomBlock(-7,27,-1,minecraft:wool:0,10,quark:quilted_wool:0,100)
RandomBlock(-7,27,0,minecraft:wool:0,10,quark:quilted_wool:0,100)
RandomBlock(-7,27,1,minecraft:wool:0,10,quark:quilted_wool:0,100)
RandomBlock(-7,27,2,minecraft:wool:0,10,quark:quilted_wool:0,100)
RandomBlock(-7,27,3,minecraft:wool:0,10,quark:quilted_wool:0,100)
RandomBlock(-7,27,4,minecraft:wool:0,10,quark:quilted_wool:0,100)
RandomBlock(-7,27,5,minecraft:wool:0,10,quark:quilted_wool:0,100)
RandomBlock(-7,28,-3,minecraft:wool:0,10,quark:quilted_wool:0,100)
RandomBlock(-7,28,-2,minecraft:wool:0,10,quark:quilted_wool:0,100)
RandomBlock(-7,28,-1,minecraft:wool:0,10,quark:quilted_wool:0,100)
RandomBlock(-7,28,0,minecraft:wool:0,10,quark:quilted_wool:0,100)
RandomBlock(-7,28,1,minecraft:wool:0,10,quark:quilted_wool:0,100)
RandomBlock(-7,28,2,minecraft:wool:0,10,quark:quilted_wool:0,100)
RandomBlock(-7,28,3,minecraft:wool:0,10,quark:quilted_wool:0,100)
RandomBlock(-7,28,4,minecraft:wool:0,10,quark:quilted_wool:0,100)
RandomBlock(-7,28,5,minecraft:wool:0,10,quark:quilted_wool:0,100)
RandomBlock(-7,29,-3,minecraft:wool:0,10,quark:quilted_wool:0,100)
RandomBlock(-7,29,-2,minecraft:wool:0,10,quark:quilted_wool:0,100)
RandomBlock(-7,29,-1,minecraft:wool:0,10,quark:quilted_wool:0,100)
RandomBlock(-7,29,0,minecraft:wool:0,10,quark:quilted_wool:0,100)
RandomBlock(-7,29,1,minecraft:wool:0,10,quark:quilted_wool:0,100)
RandomBlock(-7,29,2,minecraft:wool:0,10,quark:quilted_wool:0,100)
RandomBlock(-7,29,3,minecraft:wool:0,10,quark:quilted_wool:0,100)
RandomBlock(-7,29,4,minecraft:wool:0,10,quark:quilted_wool:0,100)
RandomBlock(-7,29,5,minecraft:wool:0,10,quark:quilted_wool:0,100)
RandomBlock(-7,30,-2,minecraft:wool:0,10,quark:quilted_wool:0,100)
RandomBlock(-7,30,-1,minecraft:wool:0,10,quark:quilted_wool:0,100)
RandomBlock(-7,30,0,minecraft:wool:0,10,quark:quilted_wool:0,100)
RandomBlock(-7,30,1,minecraft:wool:0,10,quark:quilted_wool:0,100)
RandomBlock(-7,30,2,minecraft:wool:0,10,quark:quilted_wool:0,100)
RandomBlock(-7,30,3,minecraft:wool:0,10,quark:quilted_wool:0,100)
RandomBlock(-7,30,4,minecraft:wool:0,10,quark:quilted_wool:0,100)
RandomBlock(-7,31,-2,minecraft:wool:0,10,quark:quilted_wool:0,100)
RandomBlock(-7,31,-1,minecraft:wool:0,10,quark:quilted_wool:0,100)
RandomBlock(-7,31,0,minecraft:wool:0,10,quark:quilted_wool:0,100)
RandomBlock(-7,31,1,minecraft:wool:0,10,quark:quilted_wool:0,100)
RandomBlock(-7,31,2,minecraft:wool:0,10,quark:quilted_wool:0,100)
RandomBlock(-7,31,3,minecraft:wool:0,10,quark:quilted_wool:0,100)
RandomBlock(-7,31,4,minecraft:wool:0,10,quark:quilted_wool:0,100)
RandomBlock(-7,32,-1,minecraft:wool:0,10,quark:quilted_wool:0,100)
RandomBlock(-7,32,0,minecraft:wool:0,10,quark:quilted_wool:0,100)
RandomBlock(-7,32,1,minecraft:wool:0,10,quark:quilted_wool:0,100)
RandomBlock(-7,32,2,minecraft:wool:0,10,quark:quilted_wool:0,100)
RandomBlock(-7,32,3,minecraft:wool:0,10,quark:quilted_wool:0,100)
RandomBlock(-7,33,0,minecraft:wool:0,10,quark:quilted_wool:0,100)
RandomBlock(-7,33,1,minecraft:wool:0,10,quark:quilted_wool:0,100)
RandomBlock(-7,33,2,minecraft:wool:0,10,quark:quilted_wool:0,100)
Block(-7,39,8,VINE:1)
Block(-7,40,8,VINE:1)
Block(-7,41,8,VINE:1)
Block(-7,42,8,VINE:1)
Block(-7,43,8,VINE:1)
Block(-7,44,8,VINE:1)
Block(-7,45,8,VINE:1)
Block(-7,46,8,VINE:1)
Block(-7,47,8,VINE:1)
Block(-7,48,8,VINE:1)
Block(-7,49,8,VINE:1)
Block(-7,50,8,VINE:1)
Block(-7,51,8,VINE:1)
Block(-7,52,8,VINE:1)
Block(-7,53,8,VINE:1)
Block(-7,54,8,VINE:1)
Block(-7,55,8,VINE:1)
Block(-7,56,8,VINE:1)
Block(-7,57,8,VINE:1)
Block(-7,58,8,VINE:1)
Block(-7,59,8,VINE:1)
Block(-7,60,8,VINE:1)
Block(-7,61,8,VINE:1)
Block(-7,62,8,VINE:1)
Block(-7,63,8,VINE:1)
Block(-7,64,8,VINE:1)
Block(-7,65,8,VINE:1)
Block(-7,66,8,VINE:1)
Block(-7,67,7,LEAVES:0)
Block(-7,67,8,LEAVES:0)
Block(-7,68,7,LEAVES:0)
Block(-7,68,8,LEAVES:0)
Block(-7,69,8,LEAVES:0)
Block(-7,70,8,LEAVES:0)
Block(-7,71,7,LEAVES:0)
Block(-7,71,8,LEAVES:0)
RandomBlock(-7,80,8,minecraft:wool:0,10,quark:quilted_wool:0,100)
RandomBlock(-7,81,7,minecraft:wool:0,10,quark:quilted_wool:0,100)
RandomBlock(-7,81,8,minecraft:wool:0,10,quark:quilted_wool:0,100)
RandomBlock(-7,82,6,minecraft:wool:0,10,quark:quilted_wool:0,100)
RandomBlock(-7,82,7,minecraft:wool:0,10,quark:quilted_wool:0,100)
RandomBlock(-7,82,8,minecraft:wool:0,10,quark:quilted_wool:0,100)
RandomBlock(-7,83,5,minecraft:wool:0,10,quark:quilted_wool:0,100)
RandomBlock(-7,83,6,minecraft:wool:0,10,quark:quilted_wool:0,100)
RandomBlock(-7,83,7,minecraft:wool:0,10,quark:quilted_wool:0,100)
RandomBlock(-7,83,8,minecraft:wool:0,10,quark:quilted_wool:0,100)
RandomBlock(-7,84,5,minecraft:wool:0,10,quark:quilted_wool:0,100)
RandomBlock(-7,84,6,minecraft:wool:0,10,quark:quilted_wool:0,100)
RandomBlock(-7,84,7,minecraft:wool:0,10,quark:quilted_wool:0,100)
RandomBlock(-7,84,8,minecraft:wool:0,10,quark:quilted_wool:0,100)
RandomBlock(-7,85,5,minecraft:wool:0,10,quark:quilted_wool:0,100)
RandomBlock(-7,85,6,minecraft:wool:0,10,quark:quilted_wool:0,100)
RandomBlock(-7,85,7,minecraft:wool:0,10,quark:quilted_wool:0,100)
RandomBlock(-7,85,8,minecraft:wool:0,10,quark:quilted_wool:0,100)
RandomBlock(-7,86,5,minecraft:wool:0,10,quark:quilted_wool:0,100)
RandomBlock(-7,86,6,minecraft:wool:0,10,quark:quilted_wool:0,100)
RandomBlock(-7,86,7,minecraft:wool:0,10,quark:quilted_wool:0,100)
RandomBlock(-7,86,8,minecraft:wool:0,10,quark:quilted_wool:0,100)
RandomBlock(-7,87,5,minecraft:wool:0,10,quark:quilted_wool:0,100)
RandomBlock(-7,87,6,minecraft:wool:0,10,quark:quilted_wool:0,100)
RandomBlock(-7,87,7,minecraft:wool:0,10,quark:quilted_wool:0,100)
RandomBlock(-7,87,8,minecraft:wool:0,10,quark:quilted_wool:0,100)
RandomBlock(-7,88,6,minecraft:wool:0,10,quark:quilted_wool:0,100)
RandomBlock(-7,88,7,minecraft:wool:0,10,quark:quilted_wool:0,100)
RandomBlock(-7,88,8,minecraft:wool:0,10,quark:quilted_wool:0,100)
RandomBlock(-7,89,7,minecraft:wool:0,10,quark:quilted_wool:0,100)
RandomBlock(-7,89,8,minecraft:wool:0,10,quark:quilted_wool:0,100)
RandomBlock(-7,90,8,minecraft:wool:0,10,quark:quilted_wool:0,100)
RandomBlock(-7,97,8,minecraft:wool:0,10,quark:quilted_wool:0,100)
RandomBlock(-7,98,8,minecraft:wool:0,10,quark:quilted_wool:0,100)
RandomBlock(-7,99,8,minecraft:wool:0,10,quark:quilted_wool:0,100)
RandomBlock(-7,100,7,minecraft:wool:0,10,quark:quilted_wool:0,100)
RandomBlock(-7,100,8,minecraft:wool:0,10,quark:quilted_wool:0,100)
RandomBlock(-7,101,7,minecraft:wool:0,10,quark:quilted_wool:0,100)
RandomBlock(-7,101,8,minecraft:wool:0,10,quark:quilted_wool:0,100)
RandomBlock(-7,102,7,minecraft:wool:0,10,quark:quilted_wool:0,100)
RandomBlock(-7,102,8,minecraft:wool:0,10,quark:quilted_wool:0,100)
RandomBlock(-7,103,7,minecraft:wool:0,10,quark:quilted_wool:0,100)
RandomBlock(-7,103,8,minecraft:wool:0,10,quark:quilted_wool:0,100)
RandomBlock(-7,104,7,minecraft:wool:0,10,quark:quilted_wool:0,100)
RandomBlock(-7,104,8,minecraft:wool:0,10,quark:quilted_wool:0,100)
RandomBlock(-7,105,8,minecraft:wool:0,10,quark:quilted_wool:0,100)
RandomBlock(-7,106,8,minecraft:wool:0,10,quark:quilted_wool:0,100)
RandomBlock(-7,107,8,minecraft:wool:0,10,quark:quilted_wool:0,100)
Block(-6,3,-1,LOG:12)
Block(-6,3,0,LOG:12)
Block(-6,4,-1,quark:leaf_carpet)
Block(-6,4,0,LOG:12)
Block(-6,4,1,LOG:12)
Block(-6,5,0,LEAVES:0)
Block(-6,5,1,quark:leaf_carpet)
Block(-6,8,8,LOG:12)
Block(-6,18,8,WOOL:14)
Block(-6,19,7,WOOL:14)
Block(-6,19,8,WOOL:14)
Block(-6,20,7,WOOL:14)
Block(-6,20,8,WOOL:14)
RandomBlock(-6,21,0,minecraft:wool:0,10,quark:quilted_wool:0,100)
RandomBlock(-6,21,1,minecraft:wool:0,10,quark:quilted_wool:0,100)
RandomBlock(-6,21,2,minecraft:wool:0,10,quark:quilted_wool:0,100)
Block(-6,21,7,WOOL:14)
Block(-6,21,8,WOOL:14)
RandomBlock(-6,22,-1,minecraft:wool:0,10,quark:quilted_wool:0,100)
RandomBlock(-6,22,0,minecraft:wool:0,10,quark:quilted_wool:0,100)
RandomBlock(-6,22,1,minecraft:wool:0,10,quark:quilted_wool:0,100)
RandomBlock(-6,22,2,minecraft:wool:0,10,quark:quilted_wool:0,100)
RandomBlock(-6,22,3,minecraft:wool:0,10,quark:quilted_wool:0,100)
Block(-6,22,7,WOOL:14)
Block(-6,22,8,WOOL:14)
RandomBlock(-6,23,-2,minecraft:wool:0,10,quark:quilted_wool:0,100)
RandomBlock(-6,23,-1,minecraft:wool:0,10,quark:quilted_wool:0,100)
RandomBlock(-6,23,0,minecraft:wool:0,10,quark:quilted_wool:0,100)
RandomBlock(-6,23,1,minecraft:wool:0,10,quark:quilted_wool:0,100)
RandomBlock(-6,23,2,minecraft:wool:0,10,quark:quilted_wool:0,100)
RandomBlock(-6,23,3,minecraft:wool:0,10,quark:quilted_wool:0,100)
RandomBlock(-6,23,4,minecraft:wool:0,10,quark:quilted_wool:0,100)
Block(-6,23,7,WOOL:14)
Block(-6,23,8,WOOL:14)
RandomBlock(-6,24,-2,minecraft:wool:0,10,quark:quilted_wool:0,100)
RandomBlock(-6,24,-1,minecraft:wool:0,10,quark:quilted_wool:0,100)
RandomBlock(-6,24,0,minecraft:wool:0,10,quark:quilted_wool:0,100)
RandomBlock(-6,24,1,minecraft:wool:0,10,quark:quilted_wool:0,100)
RandomBlock(-6,24,2,minecraft:wool:0,10,quark:quilted_wool:0,100)
RandomBlock(-6,24,3,minecraft:wool:0,10,quark:quilted_wool:0,100)
RandomBlock(-6,24,4,minecraft:wool:0,10,quark:quilted_wool:0,100)
Block(-6,24,8,WOOL:14)
RandomBlock(-6,25,-3,minecraft:wool:0,10,quark:quilted_wool:0,100)
RandomBlock(-6,25,-2,minecraft:wool:0,10,quark:quilted_wool:0,100)
RandomBlock(-6,25,-1,minecraft:wool:0,10,quark:quilted_wool:0,100)
RandomBlock(-6,25,0,minecraft:wool:0,10,quark:quilted_wool:0,100)
RandomBlock(-6,25,1,minecraft:wool:0,10,quark:quilted_wool:0,100)
RandomBlock(-6,25,2,minecraft:wool:0,10,quark:quilted_wool:0,100)
RandomBlock(-6,25,3,minecraft:wool:0,10,quark:quilted_wool:0,100)
RandomBlock(-6,25,4,minecraft:wool:0,10,quark:quilted_wool:0,100)
RandomBlock(-6,25,5,minecraft:wool:0,10,quark:quilted_wool:0,100)
RandomBlock(-6,26,-3,minecraft:wool:0,10,quark:quilted_wool:0,100)
RandomBlock(-6,26,-2,minecraft:wool:0,10,quark:quilted_wool:0,100)
RandomBlock(-6,26,-1,minecraft:wool:0,10,quark:quilted_wool:0,100)
RandomBlock(-6,26,0,minecraft:wool:0,10,quark:quilted_wool:0,100)
RandomBlock(-6,26,1,minecraft:wool:0,10,quark:quilted_wool:0,100)
RandomBlock(-6,26,2,minecraft:wool:0,10,quark:quilted_wool:0,100)
RandomBlock(-6,26,3,minecraft:wool:0,10,quark:quilted_wool:0,100)
RandomBlock(-6,26,4,minecraft:wool:0,10,quark:quilted_wool:0,100)
RandomBlock(-6,26,5,minecraft:wool:0,10,quark:quilted_wool:0,100)
RandomBlock(-6,27,-3,minecraft:wool:0,10,quark:quilted_wool:0,100)
RandomBlock(-6,27,-2,minecraft:wool:0,10,quark:quilted_wool:0,100)
RandomBlock(-6,27,-1,minecraft:wool:0,10,quark:quilted_wool:0,100)
RandomBlock(-6,27,0,minecraft:wool:0,10,quark:quilted_wool:0,100)
RandomBlock(-6,27,1,minecraft:wool:0,10,quark:quilted_wool:0,100)
RandomBlock(-6,27,2,minecraft:wool:0,10,quark:quilted_wool:0,100)
RandomBlock(-6,27,3,minecraft:wool:0,10,quark:quilted_wool:0,100)
RandomBlock(-6,27,4,minecraft:wool:0,10,quark:quilted_wool:0,100)
RandomBlock(-6,27,5,minecraft:wool:0,10,quark:quilted_wool:0,100)
RandomBlock(-6,28,-3,minecraft:wool:0,10,quark:quilted_wool:0,100)
RandomBlock(-6,28,-2,minecraft:wool:0,10,quark:quilted_wool:0,100)
RandomBlock(-6,28,-1,minecraft:wool:0,10,quark:quilted_wool:0,100)
RandomBlock(-6,28,0,minecraft:wool:0,10,quark:quilted_wool:0,100)
RandomBlock(-6,28,1,minecraft:wool:0,10,quark:quilted_wool:0,100)
RandomBlock(-6,28,2,minecraft:wool:0,10,quark:quilted_wool:0,100)
RandomBlock(-6,28,3,minecraft:wool:0,10,quark:quilted_wool:0,100)
RandomBlock(-6,28,4,minecraft:wool:0,10,quark:quilted_wool:0,100)
RandomBlock(-6,28,5,minecraft:wool:0,10,quark:quilted_wool:0,100)
RandomBlock(-6,29,-3,minecraft:wool:0,10,quark:quilted_wool:0,100)
RandomBlock(-6,29,-2,minecraft:wool:0,10,quark:quilted_wool:0,100)
RandomBlock(-6,29,-1,minecraft:wool:0,10,quark:quilted_wool:0,100)
RandomBlock(-6,29,0,minecraft:wool:0,10,quark:quilted_wool:0,100)
RandomBlock(-6,29,1,minecraft:wool:0,10,quark:quilted_wool:0,100)
RandomBlock(-6,29,2,minecraft:wool:0,10,quark:quilted_wool:0,100)
RandomBlock(-6,29,3,minecraft:wool:0,10,quark:quilted_wool:0,100)
RandomBlock(-6,29,4,minecraft:wool:0,10,quark:quilted_wool:0,100)
RandomBlock(-6,29,5,minecraft:wool:0,10,quark:quilted_wool:0,100)
RandomBlock(-6,30,-2,minecraft:wool:0,10,quark:quilted_wool:0,100)
RandomBlock(-6,30,-1,minecraft:wool:0,10,quark:quilted_wool:0,100)
RandomBlock(-6,30,0,minecraft:wool:0,10,quark:quilted_wool:0,100)
RandomBlock(-6,30,1,minecraft:wool:0,10,quark:quilted_wool:0,100)
RandomBlock(-6,30,2,minecraft:wool:0,10,quark:quilted_wool:0,100)
RandomBlock(-6,30,3,minecraft:wool:0,10,quark:quilted_wool:0,100)
RandomBlock(-6,30,4,minecraft:wool:0,10,quark:quilted_wool:0,100)
RandomBlock(-6,31,-2,minecraft:wool:0,10,quark:quilted_wool:0,100)
RandomBlock(-6,31,-1,minecraft:wool:0,10,quark:quilted_wool:0,100)
RandomBlock(-6,31,0,minecraft:wool:0,10,quark:quilted_wool:0,100)
RandomBlock(-6,31,1,minecraft:wool:0,10,quark:quilted_wool:0,100)
RandomBlock(-6,31,2,minecraft:wool:0,10,quark:quilted_wool:0,100)
RandomBlock(-6,31,3,minecraft:wool:0,10,quark:quilted_wool:0,100)
RandomBlock(-6,31,4,minecraft:wool:0,10,quark:quilted_wool:0,100)
RandomBlock(-6,32,-1,minecraft:wool:0,10,quark:quilted_wool:0,100)
RandomBlock(-6,32,0,minecraft:wool:0,10,quark:quilted_wool:0,100)
RandomBlock(-6,32,1,minecraft:wool:0,10,quark:quilted_wool:0,100)
RandomBlock(-6,32,2,minecraft:wool:0,10,quark:quilted_wool:0,100)
RandomBlock(-6,32,3,minecraft:wool:0,10,quark:quilted_wool:0,100)
RandomBlock(-6,33,0,minecraft:wool:0,10,quark:quilted_wool:0,100)
RandomBlock(-6,33,1,minecraft:wool:0,10,quark:quilted_wool:0,100)
RandomBlock(-6,33,2,minecraft:wool:0,10,quark:quilted_wool:0,100)
Block(-6,67,7,LEAVES:0)
Block(-6,67,8,LEAVES:0)
Block(-6,68,7,LEAVES:0)
Block(-6,68,8,LEAVES:0)
Block(-6,70,8,LEAVES:0)
Block(-6,71,8,LEAVES:0)
RandomBlock(-6,79,8,minecraft:wool:0,10,quark:quilted_wool:0,100)
RandomBlock(-6,80,6,minecraft:wool:0,10,quark:quilted_wool:0,100)
RandomBlock(-6,80,7,minecraft:wool:0,10,quark:quilted_wool:0,100)
RandomBlock(-6,80,8,minecraft:wool:0,10,quark:quilted_wool:0,100)
RandomBlock(-6,81,5,minecraft:wool:0,10,quark:quilted_wool:0,100)
RandomBlock(-6,81,6,minecraft:wool:0,10,quark:quilted_wool:0,100)
RandomBlock(-6,81,7,minecraft:wool:0,10,quark:quilted_wool:0,100)
RandomBlock(-6,81,8,minecraft:wool:0,10,quark:quilted_wool:0,100)
RandomBlock(-6,82,5,minecraft:wool:0,10,quark:quilted_wool:0,100)
RandomBlock(-6,82,6,minecraft:wool:0,10,quark:quilted_wool:0,100)
RandomBlock(-6,82,7,minecraft:wool:0,10,quark:quilted_wool:0,100)
RandomBlock(-6,82,8,minecraft:wool:0,10,quark:quilted_wool:0,100)
RandomBlock(-6,83,4,minecraft:wool:0,10,quark:quilted_wool:0,100)
RandomBlock(-6,83,5,minecraft:wool:0,10,quark:quilted_wool:0,100)
RandomBlock(-6,83,6,minecraft:wool:0,10,quark:quilted_wool:0,100)
RandomBlock(-6,83,7,minecraft:wool:0,10,quark:quilted_wool:0,100)
RandomBlock(-6,83,8,minecraft:wool:0,10,quark:quilted_wool:0,100)
RandomBlock(-6,84,4,minecraft:wool:0,10,quark:quilted_wool:0,100)
RandomBlock(-6,84,5,minecraft:wool:0,10,quark:quilted_wool:0,100)
RandomBlock(-6,84,6,minecraft:wool:0,10,quark:quilted_wool:0,100)
RandomBlock(-6,84,7,minecraft:wool:0,10,quark:quilted_wool:0,100)
RandomBlock(-6,84,8,minecraft:wool:0,10,quark:quilted_wool:0,100)
RandomBlock(-6,85,4,minecraft:wool:0,10,quark:quilted_wool:0,100)
RandomBlock(-6,85,5,minecraft:wool:0,10,quark:quilted_wool:0,100)
RandomBlock(-6,85,6,minecraft:wool:0,10,quark:quilted_wool:0,100)
RandomBlock(-6,85,7,minecraft:wool:0,10,quark:quilted_wool:0,100)
RandomBlock(-6,85,8,minecraft:wool:0,10,quark:quilted_wool:0,100)
RandomBlock(-6,86,4,minecraft:wool:0,10,quark:quilted_wool:0,100)
RandomBlock(-6,86,5,minecraft:wool:0,10,quark:quilted_wool:0,100)
RandomBlock(-6,86,6,minecraft:wool:0,10,quark:quilted_wool:0,100)
RandomBlock(-6,86,7,minecraft:wool:0,10,quark:quilted_wool:0,100)
RandomBlock(-6,86,8,minecraft:wool:0,10,quark:quilted_wool:0,100)
RandomBlock(-6,87,4,minecraft:wool:0,10,quark:quilted_wool:0,100)
RandomBlock(-6,87,5,minecraft:wool:0,10,quark:quilted_wool:0,100)
RandomBlock(-6,87,6,minecraft:wool:0,10,quark:quilted_wool:0,100)
RandomBlock(-6,87,7,minecraft:wool:0,10,quark:quilted_wool:0,100)
RandomBlock(-6,87,8,minecraft:wool:0,10,quark:quilted_wool:0,100)
RandomBlock(-6,88,5,minecraft:wool:0,10,quark:quilted_wool:0,100)
RandomBlock(-6,88,6,minecraft:wool:0,10,quark:quilted_wool:0,100)
RandomBlock(-6,88,7,minecraft:wool:0,10,quark:quilted_wool:0,100)
RandomBlock(-6,88,8,minecraft:wool:0,10,quark:quilted_wool:0,100)
RandomBlock(-6,89,5,minecraft:wool:0,10,quark:quilted_wool:0,100)
RandomBlock(-6,89,6,minecraft:wool:0,10,quark:quilted_wool:0,100)
RandomBlock(-6,89,7,minecraft:wool:0,10,quark:quilted_wool:0,100)
RandomBlock(-6,89,8,minecraft:wool:0,10,quark:quilted_wool:0,100)
RandomBlock(-6,90,6,minecraft:wool:0,10,quark:quilted_wool:0,100)
RandomBlock(-6,90,7,minecraft:wool:0,10,quark:quilted_wool:0,100)
RandomBlock(-6,90,8,minecraft:wool:0,10,quark:quilted_wool:0,100)
RandomBlock(-6,91,8,minecraft:wool:0,10,quark:quilted_wool:0,100)
RandomBlock(-6,98,8,minecraft:wool:0,10,quark:quilted_wool:0,100)
RandomBlock(-6,99,8,minecraft:wool:0,10,quark:quilted_wool:0,100)
RandomBlock(-6,100,8,minecraft:wool:0,10,quark:quilted_wool:0,100)
RandomBlock(-6,101,7,minecraft:wool:0,10,quark:quilted_wool:0,100)
RandomBlock(-6,101,8,minecraft:wool:0,10,quark:quilted_wool:0,100)
RandomBlock(-6,102,7,minecraft:wool:0,10,quark:quilted_wool:0,100)
RandomBlock(-6,102,8,minecraft:wool:0,10,quark:quilted_wool:0,100)
RandomBlock(-6,103,7,minecraft:wool:0,10,quark:quilted_wool:0,100)
RandomBlock(-6,103,8,minecraft:wool:0,10,quark:quilted_wool:0,100)
RandomBlock(-6,104,8,minecraft:wool:0,10,quark:quilted_wool:0,100)
RandomBlock(-6,105,8,minecraft:wool:0,10,quark:quilted_wool:0,100)
RandomBlock(-6,106,8,minecraft:wool:0,10,quark:quilted_wool:0,100)
Block(-5,3,-1,LOG:12)
Block(-5,4,0,LEAVES:0)
Block(-5,18,8,WOOL:14)
Block(-5,19,8,WOOL:14)
Block(-5,20,7,WOOL:14)
Block(-5,20,8,WOOL:14)
Block(-5,21,7,WOOL:14)
Block(-5,21,8,WOOL:14)
RandomBlock(-5,22,-1,minecraft:wool:0,10,quark:quilted_wool:0,100)
RandomBlock(-5,22,0,minecraft:wool:0,10,quark:quilted_wool:0,100)
RandomBlock(-5,22,1,minecraft:wool:0,10,quark:quilted_wool:0,100)
RandomBlock(-5,22,2,minecraft:wool:0,10,quark:quilted_wool:0,100)
RandomBlock(-5,22,3,minecraft:wool:0,10,quark:quilted_wool:0,100)
Block(-5,22,7,WOOL:14)
Block(-5,22,8,WOOL:14)
RandomBlock(-5,23,-1,minecraft:wool:0,10,quark:quilted_wool:0,100)
RandomBlock(-5,23,0,minecraft:wool:0,10,quark:quilted_wool:0,100)
RandomBlock(-5,23,1,minecraft:wool:0,10,quark:quilted_wool:0,100)
RandomBlock(-5,23,2,minecraft:wool:0,10,quark:quilted_wool:0,100)
RandomBlock(-5,23,3,minecraft:wool:0,10,quark:quilted_wool:0,100)
Block(-5,23,8,WOOL:14)
RandomBlock(-5,24,-2,minecraft:wool:0,10,quark:quilted_wool:0,100)
RandomBlock(-5,24,-1,minecraft:wool:0,10,quark:quilted_wool:0,100)
RandomBlock(-5,24,0,minecraft:wool:0,10,quark:quilted_wool:0,100)
RandomBlock(-5,24,1,minecraft:wool:0,10,quark:quilted_wool:0,100)
RandomBlock(-5,24,2,minecraft:wool:0,10,quark:quilted_wool:0,100)
RandomBlock(-5,24,3,minecraft:wool:0,10,quark:quilted_wool:0,100)
RandomBlock(-5,24,4,minecraft:wool:0,10,quark:quilted_wool:0,100)
Block(-5,24,8,WOOL:14)
RandomBlock(-5,25,-2,minecraft:wool:0,10,quark:quilted_wool:0,100)
RandomBlock(-5,25,-1,minecraft:wool:0,10,quark:quilted_wool:0,100)
RandomBlock(-5,25,0,minecraft:wool:0,10,quark:quilted_wool:0,100)
RandomBlock(-5,25,1,minecraft:wool:0,10,quark:quilted_wool:0,100)
RandomBlock(-5,25,2,minecraft:wool:0,10,quark:quilted_wool:0,100)
RandomBlock(-5,25,3,minecraft:wool:0,10,quark:quilted_wool:0,100)
RandomBlock(-5,25,4,minecraft:wool:0,10,quark:quilted_wool:0,100)
RandomBlock(-5,26,-2,minecraft:wool:0,10,quark:quilted_wool:0,100)
RandomBlock(-5,26,-1,minecraft:wool:0,10,quark:quilted_wool:0,100)
RandomBlock(-5,26,0,minecraft:wool:0,10,quark:quilted_wool:0,100)
RandomBlock(-5,26,1,minecraft:wool:0,10,quark:quilted_wool:0,100)
RandomBlock(-5,26,2,minecraft:wool:0,10,quark:quilted_wool:0,100)
RandomBlock(-5,26,3,minecraft:wool:0,10,quark:quilted_wool:0,100)
RandomBlock(-5,26,4,minecraft:wool:0,10,quark:quilted_wool:0,100)
RandomBlock(-5,27,-3,minecraft:wool:0,10,quark:quilted_wool:0,100)
RandomBlock(-5,27,-2,minecraft:wool:0,10,quark:quilted_wool:0,100)
RandomBlock(-5,27,-1,minecraft:wool:0,10,quark:quilted_wool:0,100)
RandomBlock(-5,27,0,minecraft:wool:0,10,quark:quilted_wool:0,100)
RandomBlock(-5,27,1,minecraft:wool:0,10,quark:quilted_wool:0,100)
RandomBlock(-5,27,2,minecraft:wool:0,10,quark:quilted_wool:0,100)
RandomBlock(-5,27,3,minecraft:wool:0,10,quark:quilted_wool:0,100)
RandomBlock(-5,27,4,minecraft:wool:0,10,quark:quilted_wool:0,100)
RandomBlock(-5,27,5,minecraft:wool:0,10,quark:quilted_wool:0,100)
RandomBlock(-5,28,-2,minecraft:wool:0,10,quark:quilted_wool:0,100)
RandomBlock(-5,28,-1,minecraft:wool:0,10,quark:quilted_wool:0,100)
RandomBlock(-5,28,0,minecraft:wool:0,10,quark:quilted_wool:0,100)
RandomBlock(-5,28,1,minecraft:wool:0,10,quark:quilted_wool:0,100)
RandomBlock(-5,28,2,minecraft:wool:0,10,quark:quilted_wool:0,100)
RandomBlock(-5,28,3,minecraft:wool:0,10,quark:quilted_wool:0,100)
RandomBlock(-5,28,4,minecraft:wool:0,10,quark:quilted_wool:0,100)
RandomBlock(-5,29,-2,minecraft:wool:0,10,quark:quilted_wool:0,100)
RandomBlock(-5,29,-1,minecraft:wool:0,10,quark:quilted_wool:0,100)
RandomBlock(-5,29,0,minecraft:wool:0,10,quark:quilted_wool:0,100)
RandomBlock(-5,29,1,minecraft:wool:0,10,quark:quilted_wool:0,100)
RandomBlock(-5,29,2,minecraft:wool:0,10,quark:quilted_wool:0,100)
RandomBlock(-5,29,3,minecraft:wool:0,10,quark:quilted_wool:0,100)
RandomBlock(-5,29,4,minecraft:wool:0,10,quark:quilted_wool:0,100)
RandomBlock(-5,30,-2,minecraft:wool:0,10,quark:quilted_wool:0,100)
RandomBlock(-5,30,-1,minecraft:wool:0,10,quark:quilted_wool:0,100)
RandomBlock(-5,30,0,minecraft:wool:0,10,quark:quilted_wool:0,100)
RandomBlock(-5,30,1,minecraft:wool:0,10,quark:quilted_wool:0,100)
RandomBlock(-5,30,2,minecraft:wool:0,10,quark:quilted_wool:0,100)
RandomBlock(-5,30,3,minecraft:wool:0,10,quark:quilted_wool:0,100)
RandomBlock(-5,30,4,minecraft:wool:0,10,quark:quilted_wool:0,100)
RandomBlock(-5,31,-1,minecraft:wool:0,10,quark:quilted_wool:0,100)
RandomBlock(-5,31,0,minecraft:wool:0,10,quark:quilted_wool:0,100)
RandomBlock(-5,31,1,minecraft:wool:0,10,quark:quilted_wool:0,100)
RandomBlock(-5,31,2,minecraft:wool:0,10,quark:quilted_wool:0,100)
RandomBlock(-5,31,3,minecraft:wool:0,10,quark:quilted_wool:0,100)
RandomBlock(-5,32,-1,minecraft:wool:0,10,quark:quilted_wool:0,100)
RandomBlock(-5,32,0,minecraft:wool:0,10,quark:quilted_wool:0,100)
RandomBlock(-5,32,1,minecraft:wool:0,10,quark:quilted_wool:0,100)
RandomBlock(-5,32,2,minecraft:wool:0,10,quark:quilted_wool:0,100)
RandomBlock(-5,32,3,minecraft:wool:0,10,quark:quilted_wool:0,100)
Block(-5,67,8,LEAVES:0)
Block(-5,68,7,LEAVES:0)
Block(-5,68,8,LEAVES:0)
Block(-5,70,8,LEAVES:0)
Block(-5,71,8,LEAVES:0)
RandomBlock(-5,79,6,minecraft:wool:0,10,quark:quilted_wool:0,100)
RandomBlock(-5,79,7,minecraft:wool:0,10,quark:quilted_wool:0,100)
RandomBlock(-5,79,8,minecraft:wool:0,10,quark:quilted_wool:0,100)
RandomBlock(-5,80,5,minecraft:wool:0,10,quark:quilted_wool:0,100)
RandomBlock(-5,80,6,minecraft:wool:0,10,quark:quilted_wool:0,100)
RandomBlock(-5,80,7,minecraft:wool:0,10,quark:quilted_wool:0,100)
RandomBlock(-5,80,8,minecraft:wool:0,10,quark:quilted_wool:0,100)
RandomBlock(-5,81,5,minecraft:wool:0,10,quark:quilted_wool:0,100)
RandomBlock(-5,81,6,minecraft:wool:0,10,quark:quilted_wool:0,100)
RandomBlock(-5,81,7,minecraft:wool:0,10,quark:quilted_wool:0,100)
RandomBlock(-5,81,8,minecraft:wool:0,10,quark:quilted_wool:0,100)
RandomBlock(-5,82,4,minecraft:wool:0,10,quark:quilted_wool:0,100)
RandomBlock(-5,82,5,minecraft:wool:0,10,quark:quilted_wool:0,100)
RandomBlock(-5,82,6,minecraft:wool:0,10,quark:quilted_wool:0,100)
RandomBlock(-5,82,7,minecraft:wool:0,10,quark:quilted_wool:0,100)
RandomBlock(-5,82,8,minecraft:wool:0,10,quark:quilted_wool:0,100)
RandomBlock(-5,83,4,minecraft:wool:0,10,quark:quilted_wool:0,100)
RandomBlock(-5,83,5,minecraft:wool:0,10,quark:quilted_wool:0,100)
RandomBlock(-5,83,6,minecraft:wool:0,10,quark:quilted_wool:0,100)
RandomBlock(-5,83,7,minecraft:wool:0,10,quark:quilted_wool:0,100)
RandomBlock(-5,83,8,minecraft:wool:0,10,quark:quilted_wool:0,100)
RandomBlock(-5,84,4,minecraft:wool:0,10,quark:quilted_wool:0,100)
RandomBlock(-5,84,5,minecraft:wool:0,10,quark:quilted_wool:0,100)
RandomBlock(-5,84,6,minecraft:wool:0,10,quark:quilted_wool:0,100)
RandomBlock(-5,84,7,minecraft:wool:0,10,quark:quilted_wool:0,100)
RandomBlock(-5,84,8,minecraft:wool:0,10,quark:quilted_wool:0,100)
RandomBlock(-5,85,3,minecraft:wool:0,10,quark:quilted_wool:0,100)
RandomBlock(-5,85,4,minecraft:wool:0,10,quark:quilted_wool:0,100)
RandomBlock(-5,85,5,minecraft:wool:0,10,quark:quilted_wool:0,100)
RandomBlock(-5,85,6,minecraft:wool:0,10,quark:quilted_wool:0,100)
RandomBlock(-5,85,7,minecraft:wool:0,10,quark:quilted_wool:0,100)
RandomBlock(-5,85,8,minecraft:wool:0,10,quark:quilted_wool:0,100)
RandomBlock(-5,86,4,minecraft:wool:0,10,quark:quilted_wool:0,100)
RandomBlock(-5,86,5,minecraft:wool:0,10,quark:quilted_wool:0,100)
RandomBlock(-5,86,6,minecraft:wool:0,10,quark:quilted_wool:0,100)
RandomBlock(-5,86,7,minecraft:wool:0,10,quark:quilted_wool:0,100)
RandomBlock(-5,86,8,minecraft:wool:0,10,quark:quilted_wool:0,100)
RandomBlock(-5,87,4,minecraft:wool:0,10,quark:quilted_wool:0,100)
RandomBlock(-5,87,5,minecraft:wool:0,10,quark:quilted_wool:0,100)
RandomBlock(-5,87,6,minecraft:wool:0,10,quark:quilted_wool:0,100)
RandomBlock(-5,87,7,minecraft:wool:0,10,quark:quilted_wool:0,100)
RandomBlock(-5,87,8,minecraft:wool:0,10,quark:quilted_wool:0,100)
RandomBlock(-5,88,4,minecraft:wool:0,10,quark:quilted_wool:0,100)
RandomBlock(-5,88,5,minecraft:wool:0,10,quark:quilted_wool:0,100)
RandomBlock(-5,88,6,minecraft:wool:0,10,quark:quilted_wool:0,100)
RandomBlock(-5,88,7,minecraft:wool:0,10,quark:quilted_wool:0,100)
RandomBlock(-5,88,8,minecraft:wool:0,10,quark:quilted_wool:0,100)
RandomBlock(-5,89,5,minecraft:wool:0,10,quark:quilted_wool:0,100)
RandomBlock(-5,89,6,minecraft:wool:0,10,quark:quilted_wool:0,100)
RandomBlock(-5,89,7,minecraft:wool:0,10,quark:quilted_wool:0,100)
RandomBlock(-5,89,8,minecraft:wool:0,10,quark:quilted_wool:0,100)
RandomBlock(-5,90,5,minecraft:wool:0,10,quark:quilted_wool:0,100)
RandomBlock(-5,90,6,minecraft:wool:0,10,quark:quilted_wool:0,100)
RandomBlock(-5,90,7,minecraft:wool:0,10,quark:quilted_wool:0,100)
RandomBlock(-5,90,8,minecraft:wool:0,10,quark:quilted_wool:0,100)
RandomBlock(-5,91,6,minecraft:wool:0,10,quark:quilted_wool:0,100)
RandomBlock(-5,91,7,minecraft:wool:0,10,quark:quilted_wool:0,100)
RandomBlock(-5,91,8,minecraft:wool:0,10,quark:quilted_wool:0,100)
RandomBlock(-5,99,8,minecraft:wool:0,10,quark:quilted_wool:0,100)
RandomBlock(-5,100,8,minecraft:wool:0,10,quark:quilted_wool:0,100)
RandomBlock(-5,101,8,minecraft:wool:0,10,quark:quilted_wool:0,100)
RandomBlock(-5,102,8,minecraft:wool:0,10,quark:quilted_wool:0,100)
RandomBlock(-5,103,8,minecraft:wool:0,10,quark:quilted_wool:0,100)
RandomBlock(-5,104,8,minecraft:wool:0,10,quark:quilted_wool:0,100)
RandomBlock(-5,105,8,minecraft:wool:0,10,quark:quilted_wool:0,100)
Block(-4,19,8,WOOL:14)
Block(-4,20,8,WOOL:14)
Block(-4,21,8,WOOL:14)
Block(-4,22,8,WOOL:14)
RandomBlock(-4,23,0,minecraft:wool:0,10,quark:quilted_wool:0,100)
RandomBlock(-4,23,1,minecraft:wool:0,10,quark:quilted_wool:0,100)
RandomBlock(-4,23,2,minecraft:wool:0,10,quark:quilted_wool:0,100)
Block(-4,23,8,WOOL:14)
RandomBlock(-4,24,-1,minecraft:wool:0,10,quark:quilted_wool:0,100)
RandomBlock(-4,24,0,minecraft:wool:0,10,quark:quilted_wool:0,100)
RandomBlock(-4,24,1,minecraft:wool:0,10,quark:quilted_wool:0,100)
RandomBlock(-4,24,2,minecraft:wool:0,10,quark:quilted_wool:0,100)
RandomBlock(-4,24,3,minecraft:wool:0,10,quark:quilted_wool:0,100)
RandomBlock(-4,25,-2,minecraft:wool:0,10,quark:quilted_wool:0,100)
RandomBlock(-4,25,-1,minecraft:wool:0,10,quark:quilted_wool:0,100)
RandomBlock(-4,25,0,minecraft:wool:0,10,quark:quilted_wool:0,100)
RandomBlock(-4,25,1,minecraft:wool:0,10,quark:quilted_wool:0,100)
RandomBlock(-4,25,2,minecraft:wool:0,10,quark:quilted_wool:0,100)
RandomBlock(-4,25,3,minecraft:wool:0,10,quark:quilted_wool:0,100)
RandomBlock(-4,25,4,minecraft:wool:0,10,quark:quilted_wool:0,100)
RandomBlock(-4,26,-2,minecraft:wool:0,10,quark:quilted_wool:0,100)
RandomBlock(-4,26,-1,minecraft:wool:0,10,quark:quilted_wool:0,100)
RandomBlock(-4,26,0,minecraft:wool:0,10,quark:quilted_wool:0,100)
RandomBlock(-4,26,1,minecraft:wool:0,10,quark:quilted_wool:0,100)
RandomBlock(-4,26,2,minecraft:wool:0,10,quark:quilted_wool:0,100)
RandomBlock(-4,26,3,minecraft:wool:0,10,quark:quilted_wool:0,100)
RandomBlock(-4,26,4,minecraft:wool:0,10,quark:quilted_wool:0,100)
RandomBlock(-4,27,-2,minecraft:wool:0,10,quark:quilted_wool:0,100)
RandomBlock(-4,27,-1,minecraft:wool:0,10,quark:quilted_wool:0,100)
RandomBlock(-4,27,0,minecraft:wool:0,10,quark:quilted_wool:0,100)
RandomBlock(-4,27,1,minecraft:wool:0,10,quark:quilted_wool:0,100)
RandomBlock(-4,27,2,minecraft:wool:0,10,quark:quilted_wool:0,100)
RandomBlock(-4,27,3,minecraft:wool:0,10,quark:quilted_wool:0,100)
RandomBlock(-4,27,4,minecraft:wool:0,10,quark:quilted_wool:0,100)
RandomBlock(-4,28,-2,minecraft:wool:0,10,quark:quilted_wool:0,100)
RandomBlock(-4,28,-1,minecraft:wool:0,10,quark:quilted_wool:0,100)
RandomBlock(-4,28,0,minecraft:wool:0,10,quark:quilted_wool:0,100)
RandomBlock(-4,28,1,minecraft:wool:0,10,quark:quilted_wool:0,100)
RandomBlock(-4,28,2,minecraft:wool:0,10,quark:quilted_wool:0,100)
RandomBlock(-4,28,3,minecraft:wool:0,10,quark:quilted_wool:0,100)
RandomBlock(-4,28,4,minecraft:wool:0,10,quark:quilted_wool:0,100)
RandomBlock(-4,29,-2,minecraft:wool:0,10,quark:quilted_wool:0,100)
RandomBlock(-4,29,-1,minecraft:wool:0,10,quark:quilted_wool:0,100)
RandomBlock(-4,29,0,minecraft:wool:0,10,quark:quilted_wool:0,100)
RandomBlock(-4,29,1,minecraft:wool:0,10,quark:quilted_wool:0,100)
RandomBlock(-4,29,2,minecraft:wool:0,10,quark:quilted_wool:0,100)
RandomBlock(-4,29,3,minecraft:wool:0,10,quark:quilted_wool:0,100)
RandomBlock(-4,29,4,minecraft:wool:0,10,quark:quilted_wool:0,100)
RandomBlock(-4,30,-1,minecraft:wool:0,10,quark:quilted_wool:0,100)
RandomBlock(-4,30,0,minecraft:wool:0,10,quark:quilted_wool:0,100)
RandomBlock(-4,30,1,minecraft:wool:0,10,quark:quilted_wool:0,100)
RandomBlock(-4,30,2,minecraft:wool:0,10,quark:quilted_wool:0,100)
RandomBlock(-4,30,3,minecraft:wool:0,10,quark:quilted_wool:0,100)
RandomBlock(-4,31,0,minecraft:wool:0,10,quark:quilted_wool:0,100)
RandomBlock(-4,31,1,minecraft:wool:0,10,quark:quilted_wool:0,100)
RandomBlock(-4,31,2,minecraft:wool:0,10,quark:quilted_wool:0,100)
Block(-4,70,8,LEAVES:0)
Block(-4,71,8,LEAVES:0)
RandomBlock(-4,78,7,minecraft:wool:0,10,quark:quilted_wool:0,100)
RandomBlock(-4,78,8,minecraft:wool:0,10,quark:quilted_wool:0,100)
RandomBlock(-4,79,6,minecraft:wool:0,10,quark:quilted_wool:0,100)
RandomBlock(-4,79,7,minecraft:wool:0,10,quark:quilted_wool:0,100)
RandomBlock(-4,79,8,minecraft:wool:0,10,quark:quilted_wool:0,100)
RandomBlock(-4,80,5,minecraft:wool:0,10,quark:quilted_wool:0,100)
RandomBlock(-4,80,6,minecraft:wool:0,10,quark:quilted_wool:0,100)
RandomBlock(-4,80,7,minecraft:wool:0,10,quark:quilted_wool:0,100)
RandomBlock(-4,80,8,minecraft:wool:0,10,quark:quilted_wool:0,100)
RandomBlock(-4,81,4,minecraft:wool:0,10,quark:quilted_wool:0,100)
RandomBlock(-4,81,5,minecraft:wool:0,10,quark:quilted_wool:0,100)
RandomBlock(-4,81,6,minecraft:wool:0,10,quark:quilted_wool:0,100)
RandomBlock(-4,81,7,minecraft:wool:0,10,quark:quilted_wool:0,100)
RandomBlock(-4,81,8,minecraft:wool:0,10,quark:quilted_wool:0,100)
RandomBlock(-4,82,4,minecraft:wool:0,10,quark:quilted_wool:0,100)
RandomBlock(-4,82,5,minecraft:wool:0,10,quark:quilted_wool:0,100)
RandomBlock(-4,82,6,minecraft:wool:0,10,quark:quilted_wool:0,100)
RandomBlock(-4,82,7,minecraft:wool:0,10,quark:quilted_wool:0,100)
RandomBlock(-4,82,8,minecraft:wool:0,10,quark:quilted_wool:0,100)
RandomBlock(-4,83,3,minecraft:wool:0,10,quark:quilted_wool:0,100)
RandomBlock(-4,83,4,minecraft:wool:0,10,quark:quilted_wool:0,100)
RandomBlock(-4,83,5,minecraft:wool:0,10,quark:quilted_wool:0,100)
RandomBlock(-4,83,6,minecraft:wool:0,10,quark:quilted_wool:0,100)
RandomBlock(-4,83,7,minecraft:wool:0,10,quark:quilted_wool:0,100)
RandomBlock(-4,83,8,minecraft:wool:0,10,quark:quilted_wool:0,100)
RandomBlock(-4,84,3,minecraft:wool:0,10,quark:quilted_wool:0,100)
RandomBlock(-4,84,4,minecraft:wool:0,10,quark:quilted_wool:0,100)
RandomBlock(-4,84,5,minecraft:wool:0,10,quark:quilted_wool:0,100)
RandomBlock(-4,84,6,minecraft:wool:0,10,quark:quilted_wool:0,100)
RandomBlock(-4,84,7,minecraft:wool:0,10,quark:quilted_wool:0,100)
RandomBlock(-4,84,8,minecraft:wool:0,10,quark:quilted_wool:0,100)
RandomBlock(-4,85,3,minecraft:wool:0,10,quark:quilted_wool:0,100)
RandomBlock(-4,85,4,minecraft:wool:0,10,quark:quilted_wool:0,100)
RandomBlock(-4,85,5,minecraft:wool:0,10,quark:quilted_wool:0,100)
RandomBlock(-4,85,6,minecraft:wool:0,10,quark:quilted_wool:0,100)
RandomBlock(-4,85,7,minecraft:wool:0,10,quark:quilted_wool:0,100)
RandomBlock(-4,85,8,minecraft:wool:0,10,quark:quilted_wool:0,100)
RandomBlock(-4,86,3,minecraft:wool:0,10,quark:quilted_wool:0,100)
RandomBlock(-4,86,4,minecraft:wool:0,10,quark:quilted_wool:0,100)
RandomBlock(-4,86,5,minecraft:wool:0,10,quark:quilted_wool:0,100)
RandomBlock(-4,86,6,minecraft:wool:0,10,quark:quilted_wool:0,100)
RandomBlock(-4,86,7,minecraft:wool:0,10,quark:quilted_wool:0,100)
RandomBlock(-4,86,8,minecraft:wool:0,10,quark:quilted_wool:0,100)
RandomBlock(-4,87,3,minecraft:wool:0,10,quark:quilted_wool:0,100)
RandomBlock(-4,87,4,minecraft:wool:0,10,quark:quilted_wool:0,100)
RandomBlock(-4,87,5,minecraft:wool:0,10,quark:quilted_wool:0,100)
RandomBlock(-4,87,6,minecraft:wool:0,10,quark:quilted_wool:0,100)
RandomBlock(-4,87,7,minecraft:wool:0,10,quark:quilted_wool:0,100)
RandomBlock(-4,87,8,minecraft:wool:0,10,quark:quilted_wool:0,100)
RandomBlock(-4,88,4,minecraft:wool:0,10,quark:quilted_wool:0,100)
RandomBlock(-4,88,5,minecraft:wool:0,10,quark:quilted_wool:0,100)
RandomBlock(-4,88,6,minecraft:wool:0,10,quark:quilted_wool:0,100)
RandomBlock(-4,88,7,minecraft:wool:0,10,quark:quilted_wool:0,100)
RandomBlock(-4,88,8,minecraft:wool:0,10,quark:quilted_wool:0,100)
RandomBlock(-4,89,4,minecraft:wool:0,10,quark:quilted_wool:0,100)
RandomBlock(-4,89,5,minecraft:wool:0,10,quark:quilted_wool:0,100)
RandomBlock(-4,89,6,minecraft:wool:0,10,quark:quilted_wool:0,100)
RandomBlock(-4,89,7,minecraft:wool:0,10,quark:quilted_wool:0,100)
RandomBlock(-4,89,8,minecraft:wool:0,10,quark:quilted_wool:0,100)
RandomBlock(-4,90,5,minecraft:wool:0,10,quark:quilted_wool:0,100)
RandomBlock(-4,90,6,minecraft:wool:0,10,quark:quilted_wool:0,100)
RandomBlock(-4,90,7,minecraft:wool:0,10,quark:quilted_wool:0,100)
RandomBlock(-4,90,8,minecraft:wool:0,10,quark:quilted_wool:0,100)
RandomBlock(-4,91,6,minecraft:wool:0,10,quark:quilted_wool:0,100)
RandomBlock(-4,91,7,minecraft:wool:0,10,quark:quilted_wool:0,100)
RandomBlock(-4,91,8,minecraft:wool:0,10,quark:quilted_wool:0,100)
RandomBlock(-4,92,7,minecraft:wool:0,10,quark:quilted_wool:0,100)
RandomBlock(-4,92,8,minecraft:wool:0,10,quark:quilted_wool:0,100)
RandomBlock(-4,101,8,minecraft:wool:0,10,quark:quilted_wool:0,100)
RandomBlock(-4,102,8,minecraft:wool:0,10,quark:quilted_wool:0,100)
RandomBlock(-4,103,8,minecraft:wool:0,10,quark:quilted_wool:0,100)
RandomBlock(-3,25,0,minecraft:wool:0,10,quark:quilted_wool:0,100)
RandomBlock(-3,25,1,minecraft:wool:0,10,quark:quilted_wool:0,100)
RandomBlock(-3,25,2,minecraft:wool:0,10,quark:quilted_wool:0,100)
RandomBlock(-3,26,0,minecraft:wool:0,10,quark:quilted_wool:0,100)
RandomBlock(-3,26,1,minecraft:wool:0,10,quark:quilted_wool:0,100)
RandomBlock(-3,26,2,minecraft:wool:0,10,quark:quilted_wool:0,100)
RandomBlock(-3,27,-1,minecraft:wool:0,10,quark:quilted_wool:0,100)
RandomBlock(-3,27,0,minecraft:wool:0,10,quark:quilted_wool:0,100)
RandomBlock(-3,27,1,minecraft:wool:0,10,quark:quilted_wool:0,100)
RandomBlock(-3,27,2,minecraft:wool:0,10,quark:quilted_wool:0,100)
RandomBlock(-3,27,3,minecraft:wool:0,10,quark:quilted_wool:0,100)
RandomBlock(-3,28,0,minecraft:wool:0,10,quark:quilted_wool:0,100)
RandomBlock(-3,28,1,minecraft:wool:0,10,quark:quilted_wool:0,100)
RandomBlock(-3,28,2,minecraft:wool:0,10,quark:quilted_wool:0,100)
RandomBlock(-3,29,0,minecraft:wool:0,10,quark:quilted_wool:0,100)
RandomBlock(-3,29,1,minecraft:wool:0,10,quark:quilted_wool:0,100)
RandomBlock(-3,29,2,minecraft:wool:0,10,quark:quilted_wool:0,100)
Block(-3,70,8,LEAVES:0)
RandomBlock(-3,78,7,minecraft:wool:0,10,quark:quilted_wool:0,100)
RandomBlock(-3,78,8,minecraft:wool:0,10,quark:quilted_wool:0,100)
RandomBlock(-3,79,6,minecraft:wool:0,10,quark:quilted_wool:0,100)
RandomBlock(-3,79,7,minecraft:wool:0,10,quark:quilted_wool:0,100)
RandomBlock(-3,79,8,minecraft:wool:0,10,quark:quilted_wool:0,100)
RandomBlock(-3,80,5,minecraft:wool:0,10,quark:quilted_wool:0,100)
RandomBlock(-3,80,6,minecraft:wool:0,10,quark:quilted_wool:0,100)
RandomBlock(-3,80,7,minecraft:wool:0,10,quark:quilted_wool:0,100)
RandomBlock(-3,80,8,minecraft:wool:0,10,quark:quilted_wool:0,100)
RandomBlock(-3,81,4,minecraft:wool:0,10,quark:quilted_wool:0,100)
RandomBlock(-3,81,5,minecraft:wool:0,10,quark:quilted_wool:0,100)
RandomBlock(-3,81,6,minecraft:wool:0,10,quark:quilted_wool:0,100)
RandomBlock(-3,81,7,minecraft:wool:0,10,quark:quilted_wool:0,100)
RandomBlock(-3,81,8,minecraft:wool:0,10,quark:quilted_wool:0,100)
RandomBlock(-3,82,4,minecraft:wool:0,10,quark:quilted_wool:0,100)
RandomBlock(-3,82,5,minecraft:wool:0,10,quark:quilted_wool:0,100)
RandomBlock(-3,82,6,minecraft:wool:0,10,quark:quilted_wool:0,100)
RandomBlock(-3,82,7,minecraft:wool:0,10,quark:quilted_wool:0,100)
RandomBlock(-3,82,8,minecraft:wool:0,10,quark:quilted_wool:0,100)
RandomBlock(-3,83,3,minecraft:wool:0,10,quark:quilted_wool:0,100)
RandomBlock(-3,83,4,minecraft:wool:0,10,quark:quilted_wool:0,100)
RandomBlock(-3,83,5,minecraft:wool:0,10,quark:quilted_wool:0,100)
RandomBlock(-3,83,6,minecraft:wool:0,10,quark:quilted_wool:0,100)
RandomBlock(-3,83,7,minecraft:wool:0,10,quark:quilted_wool:0,100)
RandomBlock(-3,83,8,minecraft:wool:0,10,quark:quilted_wool:0,100)
RandomBlock(-3,84,3,minecraft:wool:0,10,quark:quilted_wool:0,100)
RandomBlock(-3,84,4,minecraft:wool:0,10,quark:quilted_wool:0,100)
RandomBlock(-3,84,5,minecraft:wool:0,10,quark:quilted_wool:0,100)
RandomBlock(-3,84,6,minecraft:wool:0,10,quark:quilted_wool:0,100)
RandomBlock(-3,84,7,minecraft:wool:0,10,quark:quilted_wool:0,100)
RandomBlock(-3,84,8,minecraft:wool:0,10,quark:quilted_wool:0,100)
RandomBlock(-3,85,3,minecraft:wool:0,10,quark:quilted_wool:0,100)
RandomBlock(-3,85,4,minecraft:wool:0,10,quark:quilted_wool:0,100)
RandomBlock(-3,85,5,minecraft:wool:0,10,quark:quilted_wool:0,100)
RandomBlock(-3,85,6,minecraft:wool:0,10,quark:quilted_wool:0,100)
RandomBlock(-3,85,7,minecraft:wool:0,10,quark:quilted_wool:0,100)
RandomBlock(-3,85,8,minecraft:wool:0,10,quark:quilted_wool:0,100)
RandomBlock(-3,86,3,minecraft:wool:0,10,quark:quilted_wool:0,100)
RandomBlock(-3,86,4,minecraft:wool:0,10,quark:quilted_wool:0,100)
RandomBlock(-3,86,5,minecraft:wool:0,10,quark:quilted_wool:0,100)
RandomBlock(-3,86,6,minecraft:wool:0,10,quark:quilted_wool:0,100)
RandomBlock(-3,86,7,minecraft:wool:0,10,quark:quilted_wool:0,100)
RandomBlock(-3,86,8,minecraft:wool:0,10,quark:quilted_wool:0,100)
RandomBlock(-3,87,3,minecraft:wool:0,10,quark:quilted_wool:0,100)
RandomBlock(-3,87,4,minecraft:wool:0,10,quark:quilted_wool:0,100)
RandomBlock(-3,87,5,minecraft:wool:0,10,quark:quilted_wool:0,100)
RandomBlock(-3,87,6,minecraft:wool:0,10,quark:quilted_wool:0,100)
RandomBlock(-3,87,7,minecraft:wool:0,10,quark:quilted_wool:0,100)
RandomBlock(-3,87,8,minecraft:wool:0,10,quark:quilted_wool:0,100)
RandomBlock(-3,88,4,minecraft:wool:0,10,quark:quilted_wool:0,100)
RandomBlock(-3,88,5,minecraft:wool:0,10,quark:quilted_wool:0,100)
RandomBlock(-3,88,6,minecraft:wool:0,10,quark:quilted_wool:0,100)
RandomBlock(-3,88,7,minecraft:wool:0,10,quark:quilted_wool:0,100)
RandomBlock(-3,88,8,minecraft:wool:0,10,quark:quilted_wool:0,100)
RandomBlock(-3,89,4,minecraft:wool:0,10,quark:quilted_wool:0,100)
RandomBlock(-3,89,5,minecraft:wool:0,10,quark:quilted_wool:0,100)
RandomBlock(-3,89,6,minecraft:wool:0,10,quark:quilted_wool:0,100)
RandomBlock(-3,89,7,minecraft:wool:0,10,quark:quilted_wool:0,100)
RandomBlock(-3,89,8,minecraft:wool:0,10,quark:quilted_wool:0,100)
RandomBlock(-3,90,5,minecraft:wool:0,10,quark:quilted_wool:0,100)
RandomBlock(-3,90,6,minecraft:wool:0,10,quark:quilted_wool:0,100)
RandomBlock(-3,90,7,minecraft:wool:0,10,quark:quilted_wool:0,100)
RandomBlock(-3,90,8,minecraft:wool:0,10,quark:quilted_wool:0,100)
RandomBlock(-3,91,6,minecraft:wool:0,10,quark:quilted_wool:0,100)
RandomBlock(-3,91,7,minecraft:wool:0,10,quark:quilted_wool:0,100)
RandomBlock(-3,91,8,minecraft:wool:0,10,quark:quilted_wool:0,100)
RandomBlock(-3,92,7,minecraft:wool:0,10,quark:quilted_wool:0,100)
RandomBlock(-3,92,8,minecraft:wool:0,10,quark:quilted_wool:0,100)
RandomBlock(-2,78,7,minecraft:wool:0,10,quark:quilted_wool:0,100)
RandomBlock(-2,78,8,minecraft:wool:0,10,quark:quilted_wool:0,100)
RandomBlock(-2,79,6,minecraft:wool:0,10,quark:quilted_wool:0,100)
RandomBlock(-2,79,7,minecraft:wool:0,10,quark:quilted_wool:0,100)
RandomBlock(-2,79,8,minecraft:wool:0,10,quark:quilted_wool:0,100)
RandomBlock(-2,80,5,minecraft:wool:0,10,quark:quilted_wool:0,100)
RandomBlock(-2,80,6,minecraft:wool:0,10,quark:quilted_wool:0,100)
RandomBlock(-2,80,7,minecraft:wool:0,10,quark:quilted_wool:0,100)
RandomBlock(-2,80,8,minecraft:wool:0,10,quark:quilted_wool:0,100)
RandomBlock(-2,81,4,minecraft:wool:0,10,quark:quilted_wool:0,100)
RandomBlock(-2,81,5,minecraft:wool:0,10,quark:quilted_wool:0,100)
RandomBlock(-2,81,6,minecraft:wool:0,10,quark:quilted_wool:0,100)
RandomBlock(-2,81,7,minecraft:wool:0,10,quark:quilted_wool:0,100)
RandomBlock(-2,81,8,minecraft:wool:0,10,quark:quilted_wool:0,100)
RandomBlock(-2,82,4,minecraft:wool:0,10,quark:quilted_wool:0,100)
RandomBlock(-2,82,5,minecraft:wool:0,10,quark:quilted_wool:0,100)
RandomBlock(-2,82,6,minecraft:wool:0,10,quark:quilted_wool:0,100)
RandomBlock(-2,82,7,minecraft:wool:0,10,quark:quilted_wool:0,100)
RandomBlock(-2,82,8,minecraft:wool:0,10,quark:quilted_wool:0,100)
RandomBlock(-2,83,3,minecraft:wool:0,10,quark:quilted_wool:0,100)
RandomBlock(-2,83,4,minecraft:wool:0,10,quark:quilted_wool:0,100)
RandomBlock(-2,83,5,minecraft:wool:0,10,quark:quilted_wool:0,100)
RandomBlock(-2,83,6,minecraft:wool:0,10,quark:quilted_wool:0,100)
RandomBlock(-2,83,7,minecraft:wool:0,10,quark:quilted_wool:0,100)
RandomBlock(-2,83,8,minecraft:wool:0,10,quark:quilted_wool:0,100)
RandomBlock(-2,84,3,minecraft:wool:0,10,quark:quilted_wool:0,100)
RandomBlock(-2,84,4,minecraft:wool:0,10,quark:quilted_wool:0,100)
RandomBlock(-2,84,5,minecraft:wool:0,10,quark:quilted_wool:0,100)
RandomBlock(-2,84,6,minecraft:wool:0,10,quark:quilted_wool:0,100)
RandomBlock(-2,84,7,minecraft:wool:0,10,quark:quilted_wool:0,100)
RandomBlock(-2,84,8,minecraft:wool:0,10,quark:quilted_wool:0,100)
RandomBlock(-2,85,3,minecraft:wool:0,10,quark:quilted_wool:0,100)
RandomBlock(-2,85,4,minecraft:wool:0,10,quark:quilted_wool:0,100)
RandomBlock(-2,85,5,minecraft:wool:0,10,quark:quilted_wool:0,100)
RandomBlock(-2,85,6,minecraft:wool:0,10,quark:quilted_wool:0,100)
RandomBlock(-2,85,7,minecraft:wool:0,10,quark:quilted_wool:0,100)
RandomBlock(-2,85,8,minecraft:wool:0,10,quark:quilted_wool:0,100)
RandomBlock(-2,86,3,minecraft:wool:0,10,quark:quilted_wool:0,100)
RandomBlock(-2,86,4,minecraft:wool:0,10,quark:quilted_wool:0,100)
RandomBlock(-2,86,5,minecraft:wool:0,10,quark:quilted_wool:0,100)
RandomBlock(-2,86,6,minecraft:wool:0,10,quark:quilted_wool:0,100)
RandomBlock(-2,86,7,minecraft:wool:0,10,quark:quilted_wool:0,100)
RandomBlock(-2,86,8,minecraft:wool:0,10,quark:quilted_wool:0,100)
RandomBlock(-2,87,3,minecraft:wool:0,10,quark:quilted_wool:0,100)
RandomBlock(-2,87,4,minecraft:wool:0,10,quark:quilted_wool:0,100)
RandomBlock(-2,87,5,minecraft:wool:0,10,quark:quilted_wool:0,100)
RandomBlock(-2,87,6,minecraft:wool:0,10,quark:quilted_wool:0,100)
RandomBlock(-2,87,7,minecraft:wool:0,10,quark:quilted_wool:0,100)
RandomBlock(-2,87,8,minecraft:wool:0,10,quark:quilted_wool:0,100)
RandomBlock(-2,88,4,minecraft:wool:0,10,quark:quilted_wool:0,100)
RandomBlock(-2,88,5,minecraft:wool:0,10,quark:quilted_wool:0,100)
RandomBlock(-2,88,6,minecraft:wool:0,10,quark:quilted_wool:0,100)
RandomBlock(-2,88,7,minecraft:wool:0,10,quark:quilted_wool:0,100)
RandomBlock(-2,88,8,minecraft:wool:0,10,quark:quilted_wool:0,100)
RandomBlock(-2,89,4,minecraft:wool:0,10,quark:quilted_wool:0,100)
RandomBlock(-2,89,5,minecraft:wool:0,10,quark:quilted_wool:0,100)
RandomBlock(-2,89,6,minecraft:wool:0,10,quark:quilted_wool:0,100)
RandomBlock(-2,89,7,minecraft:wool:0,10,quark:quilted_wool:0,100)
RandomBlock(-2,89,8,minecraft:wool:0,10,quark:quilted_wool:0,100)
RandomBlock(-2,90,5,minecraft:wool:0,10,quark:quilted_wool:0,100)
RandomBlock(-2,90,6,minecraft:wool:0,10,quark:quilted_wool:0,100)
RandomBlock(-2,90,7,minecraft:wool:0,10,quark:quilted_wool:0,100)
RandomBlock(-2,90,8,minecraft:wool:0,10,quark:quilted_wool:0,100)
RandomBlock(-2,91,6,minecraft:wool:0,10,quark:quilted_wool:0,100)
RandomBlock(-2,91,7,minecraft:wool:0,10,quark:quilted_wool:0,100)
RandomBlock(-2,91,8,minecraft:wool:0,10,quark:quilted_wool:0,100)
RandomBlock(-2,92,7,minecraft:wool:0,10,quark:quilted_wool:0,100)
RandomBlock(-2,92,8,minecraft:wool:0,10,quark:quilted_wool:0,100)
RandomBlock(-1,79,6,minecraft:wool:0,10,quark:quilted_wool:0,100)
RandomBlock(-1,79,7,minecraft:wool:0,10,quark:quilted_wool:0,100)
RandomBlock(-1,79,8,minecraft:wool:0,10,quark:quilted_wool:0,100)
RandomBlock(-1,80,5,minecraft:wool:0,10,quark:quilted_wool:0,100)
RandomBlock(-1,80,6,minecraft:wool:0,10,quark:quilted_wool:0,100)
RandomBlock(-1,80,7,minecraft:wool:0,10,quark:quilted_wool:0,100)
RandomBlock(-1,80,8,minecraft:wool:0,10,quark:quilted_wool:0,100)
RandomBlock(-1,81,5,minecraft:wool:0,10,quark:quilted_wool:0,100)
RandomBlock(-1,81,6,minecraft:wool:0,10,quark:quilted_wool:0,100)
RandomBlock(-1,81,7,minecraft:wool:0,10,quark:quilted_wool:0,100)
RandomBlock(-1,81,8,minecraft:wool:0,10,quark:quilted_wool:0,100)
RandomBlock(-1,82,4,minecraft:wool:0,10,quark:quilted_wool:0,100)
RandomBlock(-1,82,5,minecraft:wool:0,10,quark:quilted_wool:0,100)
RandomBlock(-1,82,6,minecraft:wool:0,10,quark:quilted_wool:0,100)
RandomBlock(-1,82,7,minecraft:wool:0,10,quark:quilted_wool:0,100)
RandomBlock(-1,82,8,minecraft:wool:0,10,quark:quilted_wool:0,100)
RandomBlock(-1,83,4,minecraft:wool:0,10,quark:quilted_wool:0,100)
RandomBlock(-1,83,5,minecraft:wool:0,10,quark:quilted_wool:0,100)
RandomBlock(-1,83,6,minecraft:wool:0,10,quark:quilted_wool:0,100)
RandomBlock(-1,83,7,minecraft:wool:0,10,quark:quilted_wool:0,100)
RandomBlock(-1,83,8,minecraft:wool:0,10,quark:quilted_wool:0,100)
RandomBlock(-1,84,4,minecraft:wool:0,10,quark:quilted_wool:0,100)
RandomBlock(-1,84,5,minecraft:wool:0,10,quark:quilted_wool:0,100)
RandomBlock(-1,84,6,minecraft:wool:0,10,quark:quilted_wool:0,100)
RandomBlock(-1,84,7,minecraft:wool:0,10,quark:quilted_wool:0,100)
RandomBlock(-1,84,8,minecraft:wool:0,10,quark:quilted_wool:0,100)
RandomBlock(-1,85,3,minecraft:wool:0,10,quark:quilted_wool:0,100)
RandomBlock(-1,85,4,minecraft:wool:0,10,quark:quilted_wool:0,100)
RandomBlock(-1,85,5,minecraft:wool:0,10,quark:quilted_wool:0,100)
RandomBlock(-1,85,6,minecraft:wool:0,10,quark:quilted_wool:0,100)
RandomBlock(-1,85,7,minecraft:wool:0,10,quark:quilted_wool:0,100)
RandomBlock(-1,85,8,minecraft:wool:0,10,quark:quilted_wool:0,100)
RandomBlock(-1,86,4,minecraft:wool:0,10,quark:quilted_wool:0,100)
RandomBlock(-1,86,5,minecraft:wool:0,10,quark:quilted_wool:0,100)
RandomBlock(-1,86,6,minecraft:wool:0,10,quark:quilted_wool:0,100)
RandomBlock(-1,86,7,minecraft:wool:0,10,quark:quilted_wool:0,100)
RandomBlock(-1,86,8,minecraft:wool:0,10,quark:quilted_wool:0,100)
RandomBlock(-1,87,4,minecraft:wool:0,10,quark:quilted_wool:0,100)
RandomBlock(-1,87,5,minecraft:wool:0,10,quark:quilted_wool:0,100)
RandomBlock(-1,87,6,minecraft:wool:0,10,quark:quilted_wool:0,100)
RandomBlock(-1,87,7,minecraft:wool:0,10,quark:quilted_wool:0,100)
RandomBlock(-1,87,8,minecraft:wool:0,10,quark:quilted_wool:0,100)
RandomBlock(-1,88,4,minecraft:wool:0,10,quark:quilted_wool:0,100)
RandomBlock(-1,88,5,minecraft:wool:0,10,quark:quilted_wool:0,100)
RandomBlock(-1,88,6,minecraft:wool:0,10,quark:quilted_wool:0,100)
RandomBlock(-1,88,7,minecraft:wool:0,10,quark:quilted_wool:0,100)
RandomBlock(-1,88,8,minecraft:wool:0,10,quark:quilted_wool:0,100)
RandomBlock(-1,89,5,minecraft:wool:0,10,quark:quilted_wool:0,100)
RandomBlock(-1,89,6,minecraft:wool:0,10,quark:quilted_wool:0,100)
RandomBlock(-1,89,7,minecraft:wool:0,10,quark:quilted_wool:0,100)
RandomBlock(-1,89,8,minecraft:wool:0,10,quark:quilted_wool:0,100)
RandomBlock(-1,90,5,minecraft:wool:0,10,quark:quilted_wool:0,100)
RandomBlock(-1,90,6,minecraft:wool:0,10,quark:quilted_wool:0,100)
RandomBlock(-1,90,7,minecraft:wool:0,10,quark:quilted_wool:0,100)
RandomBlock(-1,90,8,minecraft:wool:0,10,quark:quilted_wool:0,100)
RandomBlock(-1,91,6,minecraft:wool:0,10,quark:quilted_wool:0,100)
RandomBlock(-1,91,7,minecraft:wool:0,10,quark:quilted_wool:0,100)
RandomBlock(-1,91,8,minecraft:wool:0,10,quark:quilted_wool:0,100)
RandomBlock(0,79,8,minecraft:wool:0,10,quark:quilted_wool:0,100)
RandomBlock(0,80,6,minecraft:wool:0,10,quark:quilted_wool:0,100)
RandomBlock(0,80,7,minecraft:wool:0,10,quark:quilted_wool:0,100)
RandomBlock(0,80,8,minecraft:wool:0,10,quark:quilted_wool:0,100)
RandomBlock(0,81,5,minecraft:wool:0,10,quark:quilted_wool:0,100)
RandomBlock(0,81,6,minecraft:wool:0,10,quark:quilted_wool:0,100)
RandomBlock(0,81,7,minecraft:wool:0,10,quark:quilted_wool:0,100)
RandomBlock(0,81,8,minecraft:wool:0,10,quark:quilted_wool:0,100)
RandomBlock(0,82,5,minecraft:wool:0,10,quark:quilted_wool:0,100)
RandomBlock(0,82,6,minecraft:wool:0,10,quark:quilted_wool:0,100)
RandomBlock(0,82,7,minecraft:wool:0,10,quark:quilted_wool:0,100)
RandomBlock(0,82,8,minecraft:wool:0,10,quark:quilted_wool:0,100)
RandomBlock(0,83,4,minecraft:wool:0,10,quark:quilted_wool:0,100)
RandomBlock(0,83,5,minecraft:wool:0,10,quark:quilted_wool:0,100)
RandomBlock(0,83,6,minecraft:wool:0,10,quark:quilted_wool:0,100)
RandomBlock(0,83,7,minecraft:wool:0,10,quark:quilted_wool:0,100)
RandomBlock(0,83,8,minecraft:wool:0,10,quark:quilted_wool:0,100)
RandomBlock(0,84,4,minecraft:wool:0,10,quark:quilted_wool:0,100)
RandomBlock(0,84,5,minecraft:wool:0,10,quark:quilted_wool:0,100)
RandomBlock(0,84,6,minecraft:wool:0,10,quark:quilted_wool:0,100)
RandomBlock(0,84,7,minecraft:wool:0,10,quark:quilted_wool:0,100)
RandomBlock(0,84,8,minecraft:wool:0,10,quark:quilted_wool:0,100)
RandomBlock(0,85,4,minecraft:wool:0,10,quark:quilted_wool:0,100)
RandomBlock(0,85,5,minecraft:wool:0,10,quark:quilted_wool:0,100)
RandomBlock(0,85,6,minecraft:wool:0,10,quark:quilted_wool:0,100)
RandomBlock(0,85,7,minecraft:wool:0,10,quark:quilted_wool:0,100)
RandomBlock(0,85,8,minecraft:wool:0,10,quark:quilted_wool:0,100)
RandomBlock(0,86,4,minecraft:wool:0,10,quark:quilted_wool:0,100)
RandomBlock(0,86,5,minecraft:wool:0,10,quark:quilted_wool:0,100)
RandomBlock(0,86,6,minecraft:wool:0,10,quark:quilted_wool:0,100)
RandomBlock(0,86,7,minecraft:wool:0,10,quark:quilted_wool:0,100)
RandomBlock(0,86,8,minecraft:wool:0,10,quark:quilted_wool:0,100)
RandomBlock(0,87,4,minecraft:wool:0,10,quark:quilted_wool:0,100)
RandomBlock(0,87,5,minecraft:wool:0,10,quark:quilted_wool:0,100)
RandomBlock(0,87,6,minecraft:wool:0,10,quark:quilted_wool:0,100)
RandomBlock(0,87,7,minecraft:wool:0,10,quark:quilted_wool:0,100)
RandomBlock(0,87,8,minecraft:wool:0,10,quark:quilted_wool:0,100)
RandomBlock(0,88,5,minecraft:wool:0,10,quark:quilted_wool:0,100)
RandomBlock(0,88,6,minecraft:wool:0,10,quark:quilted_wool:0,100)
RandomBlock(0,88,7,minecraft:wool:0,10,quark:quilted_wool:0,100)
RandomBlock(0,88,8,minecraft:wool:0,10,quark:quilted_wool:0,100)
RandomBlock(0,89,5,minecraft:wool:0,10,quark:quilted_wool:0,100)
RandomBlock(0,89,6,minecraft:wool:0,10,quark:quilted_wool:0,100)
RandomBlock(0,89,7,minecraft:wool:0,10,quark:quilted_wool:0,100)
RandomBlock(0,89,8,minecraft:wool:0,10,quark:quilted_wool:0,100)
RandomBlock(0,90,6,minecraft:wool:0,10,quark:quilted_wool:0,100)
RandomBlock(0,90,7,minecraft:wool:0,10,quark:quilted_wool:0,100)
RandomBlock(0,90,8,minecraft:wool:0,10,quark:quilted_wool:0,100)
RandomBlock(0,91,8,minecraft:wool:0,10,quark:quilted_wool:0,100)
RandomBlock(1,80,8,minecraft:wool:0,10,quark:quilted_wool:0,100)
RandomBlock(1,81,7,minecraft:wool:0,10,quark:quilted_wool:0,100)
RandomBlock(1,81,8,minecraft:wool:0,10,quark:quilted_wool:0,100)
RandomBlock(1,82,6,minecraft:wool:0,10,quark:quilted_wool:0,100)
RandomBlock(1,82,7,minecraft:wool:0,10,quark:quilted_wool:0,100)
RandomBlock(1,82,8,minecraft:wool:0,10,quark:quilted_wool:0,100)
RandomBlock(1,83,5,minecraft:wool:0,10,quark:quilted_wool:0,100)
RandomBlock(1,83,6,minecraft:wool:0,10,quark:quilted_wool:0,100)
RandomBlock(1,83,7,minecraft:wool:0,10,quark:quilted_wool:0,100)
RandomBlock(1,83,8,minecraft:wool:0,10,quark:quilted_wool:0,100)
RandomBlock(1,84,5,minecraft:wool:0,10,quark:quilted_wool:0,100)
RandomBlock(1,84,6,minecraft:wool:0,10,quark:quilted_wool:0,100)
RandomBlock(1,84,7,minecraft:wool:0,10,quark:quilted_wool:0,100)
RandomBlock(1,84,8,minecraft:wool:0,10,quark:quilted_wool:0,100)
RandomBlock(1,85,5,minecraft:wool:0,10,quark:quilted_wool:0,100)
RandomBlock(1,85,6,minecraft:wool:0,10,quark:quilted_wool:0,100)
RandomBlock(1,85,7,minecraft:wool:0,10,quark:quilted_wool:0,100)
RandomBlock(1,85,8,minecraft:wool:0,10,quark:quilted_wool:0,100)
RandomBlock(1,86,5,minecraft:wool:0,10,quark:quilted_wool:0,100)
RandomBlock(1,86,6,minecraft:wool:0,10,quark:quilted_wool:0,100)
RandomBlock(1,86,7,minecraft:wool:0,10,quark:quilted_wool:0,100)
RandomBlock(1,86,8,minecraft:wool:0,10,quark:quilted_wool:0,100)
RandomBlock(1,87,5,minecraft:wool:0,10,quark:quilted_wool:0,100)
RandomBlock(1,87,6,minecraft:wool:0,10,quark:quilted_wool:0,100)
RandomBlock(1,87,7,minecraft:wool:0,10,quark:quilted_wool:0,100)
RandomBlock(1,87,8,minecraft:wool:0,10,quark:quilted_wool:0,100)
RandomBlock(1,88,6,minecraft:wool:0,10,quark:quilted_wool:0,100)
RandomBlock(1,88,7,minecraft:wool:0,10,quark:quilted_wool:0,100)
RandomBlock(1,88,8,minecraft:wool:0,10,quark:quilted_wool:0,100)
RandomBlock(1,89,7,minecraft:wool:0,10,quark:quilted_wool:0,100)
RandomBlock(1,89,8,minecraft:wool:0,10,quark:quilted_wool:0,100)
RandomBlock(1,90,8,minecraft:wool:0,10,quark:quilted_wool:0,100)
RandomBlock(2,83,7,minecraft:wool:0,10,quark:quilted_wool:0,100)
RandomBlock(2,83,8,minecraft:wool:0,10,quark:quilted_wool:0,100)
RandomBlock(2,84,7,minecraft:wool:0,10,quark:quilted_wool:0,100)
RandomBlock(2,84,8,minecraft:wool:0,10,quark:quilted_wool:0,100)
RandomBlock(2,85,7,minecraft:wool:0,10,quark:quilted_wool:0,100)
RandomBlock(2,85,8,minecraft:wool:0,10,quark:quilted_wool:0,100)
RandomBlock(2,86,7,minecraft:wool:0,10,quark:quilted_wool:0,100)
RandomBlock(2,86,8,minecraft:wool:0,10,quark:quilted_wool:0,100)
RandomBlock(2,87,7,minecraft:wool:0,10,quark:quilted_wool:0,100)
RandomBlock(2,87,8,minecraft:wool:0,10,quark:quilted_wool:0,100)

#######################################################################
# +-----------------------------------------------------------------+ #
# |                             Branches                            | #
# +-----------------------------------------------------------------+ #
#######################################################################

Branch(0,0,16,true,TreeTestC2R1,NORTH,100.0,0)

#######################################################################
# +-----------------------------------------------------------------+ #
# |                             Entities                            | #
# +-----------------------------------------------------------------+ #
#######################################################################


#######################################################################
# +-----------------------------------------------------------------+ #
# |                            Particles                            | #
# +-----------------------------------------------------------------+ #
#######################################################################


#######################################################################
# +-----------------------------------------------------------------+ #
# |                             Spawners                            | #
# +-----------------------------------------------------------------+ #
#######################################################################


#######################################################################
# +-----------------------------------------------------------------+ #
# |                             ModData                             | #
# +-----------------------------------------------------------------+ #
#######################################################################

