
#######################################################################
# +-----------------------------------------------------------------+ #
# |                            BO4 object                           | #
# +-----------------------------------------------------------------+ #
#######################################################################

Author: NLBlackEagle

Description: No description given

SettingsMode: WriteDisable


#######################################################################
# +-----------------------------------------------------------------+ #
# |                          Main settings                          | #
# +-----------------------------------------------------------------+ #
#######################################################################

FixedRotation: 

Frequency: 0

SpawnHeight: highestBlock

UseCenterForHighestBlock: true

##############################
# Height Limits for the BO4. #
##############################

MinHeight: 0

MaxHeight: 255

InheritBO3: 

InheritBO3Rotation: NORTH

OverrideChildSettings: true

OverrideParentHeight: false

CanOverride: false

BranchFrequency: 0

BranchFrequencyGroup: 

MustBeBelowOther: false

MustBeInside: 

CannotBeInside: 

ReplacesBO3: 

MustBeInsideWorldBorders: false

CanSpawnOnWater: true

SpawnOnWaterOnly: false

SpawnUnderWater: false

SpawnAtWaterLevel: false

HeightOffset: 0

RemoveAir: true

ReplaceAbove: 

ReplaceBelow: 

ReplaceWithBiomeBlocks: true

ReplaceWithSurfaceBlock: GRASS

ReplaceWithGroundBlock: DIRT

ReplaceWithStoneBlock: STONE

SmoothRadius: 0

SmoothHeightOffset: 0

SmoothStartTop: false

SmoothStartWood: false

SmoothingSurfaceBlock: 

SmoothingGroundBlock: 

BO3Group: 

IsSpawnPoint: false

DoReplaceBlocks: true


#######################################################################
# +-----------------------------------------------------------------+ #
# |                              Blocks                             | #
# +-----------------------------------------------------------------+ #
#######################################################################

Block(-8,6,3,LOG:12)
Block(-8,6,4,LOG:12)
Block(-8,6,5,LOG:12)
Block(-8,7,3,LOG:12)
Block(-8,7,4,LOG:12)
Block(-8,7,5,LOG:12)
Block(-8,8,3,LOG:12)
Block(-8,8,4,LOG:12)
Block(-8,8,5,LOG:12)
Block(-8,9,2,LOG:12)
Block(-8,9,3,LOG:12)
Block(-8,9,4,LOG:12)
Block(-8,9,5,LOG:12)
Block(-8,10,2,LOG:12)
Block(-8,10,3,LOG:12)
Block(-8,10,4,LOG:12)
Block(-8,10,5,LOG:12)
Block(-8,11,2,LOG:12)
Block(-8,11,3,LOG:12)
Block(-8,11,4,LOG:12)
Block(-8,11,5,LOG:12)
Block(-8,12,2,LOG:12)
Block(-8,12,3,LOG:12)
Block(-8,12,4,LOG:12)
Block(-8,13,2,quark:leaf_carpet)
Block(-8,13,3,LOG:12)
Block(-8,13,4,LOG:12)
Block(-8,13,5,LOG:12)
Block(-8,14,3,quark:leaf_carpet)
Block(-8,14,4,LOG:12)
Block(-8,14,5,LOG:12)
Block(-8,14,6,LOG:12)
Block(-8,15,4,LOG:12)
Block(-8,15,5,LOG:12)
Block(-8,15,6,LOG:12)
Block(-8,15,7,LOG:12)
Block(-8,16,4,LOG:12)
Block(-8,16,5,LOG:12)
Block(-8,16,6,LOG:12)
Block(-8,16,7,LOG:12)
Block(-8,17,4,quark:leaf_carpet)
Block(-8,17,5,LOG:12)
Block(-8,17,6,LOG:12)
Block(-8,17,7,LOG:12)
Block(-8,18,6,LOG:12)
Block(-8,19,6,quark:leaf_carpet)
Block(-8,30,4,WOOL:14)
Block(-8,30,5,WOOL:14)
Block(-8,30,6,WOOL:14)
Block(-8,31,3,WOOL:14)
Block(-8,31,4,WOOL:14)
Block(-8,31,5,WOOL:14)
Block(-8,31,6,WOOL:14)
Block(-8,31,7,WOOL:14)
Block(-8,32,2,WOOL:14)
Block(-8,32,3,WOOL:14)
Block(-8,32,4,WOOL:14)
Block(-8,32,5,WOOL:14)
Block(-8,32,6,WOOL:14)
Block(-8,32,7,WOOL:14)
Block(-8,32,8,WOOL:14)
Block(-8,33,2,WOOL:14)
Block(-8,33,3,WOOL:14)
Block(-8,33,4,WOOL:14)
Block(-8,33,5,WOOL:14)
Block(-8,33,6,WOOL:14)
Block(-8,33,7,WOOL:14)
Block(-8,33,8,WOOL:14)
Block(-8,34,2,WOOL:14)
Block(-8,34,3,WOOL:14)
Block(-8,34,4,WOOL:14)
Block(-8,34,5,WOOL:14)
Block(-8,34,6,WOOL:14)
Block(-8,34,7,WOOL:14)
Block(-8,34,8,WOOL:14)
Block(-8,35,2,WOOL:14)
Block(-8,35,3,WOOL:14)
Block(-8,35,4,WOOL:14)
Block(-8,35,5,WOOL:14)
Block(-8,35,6,WOOL:14)
Block(-8,35,7,WOOL:14)
Block(-8,35,8,WOOL:14)
Block(-8,36,2,WOOL:14)
Block(-8,36,3,WOOL:14)
Block(-8,36,4,WOOL:14)
Block(-8,36,5,WOOL:14)
Block(-8,36,6,WOOL:14)
Block(-8,36,7,WOOL:14)
Block(-8,36,8,WOOL:14)
Block(-8,37,3,WOOL:14)
Block(-8,37,4,WOOL:14)
Block(-8,37,5,WOOL:14)
Block(-8,37,6,WOOL:14)
Block(-8,37,7,WOOL:14)
Block(-8,38,4,WOOL:14)
Block(-8,38,5,WOOL:14)
Block(-8,38,6,WOOL:14)
Block(-8,65,5,LEAVES:0)
Block(-8,65,6,LEAVES:0)
Block(-8,65,7,LEAVES:0)
Block(-8,65,8,LEAVES:0)
Block(-8,66,5,LEAVES:0)
Block(-8,66,6,LEAVES:0)
Block(-8,66,7,LEAVES:0)
Block(-8,66,8,LEAVES:0)
Block(-8,67,8,LEAVES:0)
Block(-8,68,8,LEAVES:0)
Block(-8,73,8,LEAVES:0)
Block(-8,74,8,LEAVES:0)
Block(-8,75,8,LEAVES:0)
Block(-8,76,8,LEAVES:0)
Block(-8,77,8,LEAVES:0)
RandomBlock(-8,89,-1,minecraft:wool:7,10,quark:quilted_wool:7,100)
RandomBlock(-8,89,0,minecraft:wool:7,10,quark:quilted_wool:7,100)
RandomBlock(-8,89,1,minecraft:wool:7,10,quark:quilted_wool:7,100)
RandomBlock(-8,89,2,minecraft:wool:7,10,quark:quilted_wool:7,100)
RandomBlock(-8,89,3,minecraft:wool:7,10,quark:quilted_wool:7,100)
RandomBlock(-8,90,-2,minecraft:wool:7,10,quark:quilted_wool:7,100)
RandomBlock(-8,90,-1,minecraft:wool:7,10,quark:quilted_wool:7,100)
RandomBlock(-8,90,0,minecraft:wool:7,10,quark:quilted_wool:7,100)
RandomBlock(-8,90,1,minecraft:wool:7,10,quark:quilted_wool:7,100)
RandomBlock(-8,90,2,minecraft:wool:7,10,quark:quilted_wool:7,100)
RandomBlock(-8,90,3,minecraft:wool:7,10,quark:quilted_wool:7,100)
RandomBlock(-8,90,4,minecraft:wool:7,10,quark:quilted_wool:7,100)
RandomBlock(-8,91,-3,minecraft:wool:7,10,quark:quilted_wool:7,100)
RandomBlock(-8,91,-2,minecraft:wool:7,10,quark:quilted_wool:7,100)
RandomBlock(-8,91,-1,minecraft:wool:7,10,quark:quilted_wool:7,100)
RandomBlock(-8,91,0,minecraft:wool:7,10,quark:quilted_wool:7,100)
RandomBlock(-8,91,1,minecraft:wool:7,10,quark:quilted_wool:7,100)
RandomBlock(-8,91,2,minecraft:wool:7,10,quark:quilted_wool:7,100)
RandomBlock(-8,91,3,minecraft:wool:7,10,quark:quilted_wool:7,100)
RandomBlock(-8,91,4,minecraft:wool:7,10,quark:quilted_wool:7,100)
RandomBlock(-8,91,5,minecraft:wool:7,10,quark:quilted_wool:7,100)
RandomBlock(-8,92,-3,minecraft:wool:7,10,quark:quilted_wool:7,100)
RandomBlock(-8,92,-2,minecraft:wool:7,10,quark:quilted_wool:7,100)
RandomBlock(-8,92,-1,minecraft:wool:7,10,quark:quilted_wool:7,100)
RandomBlock(-8,92,0,minecraft:wool:7,10,quark:quilted_wool:7,100)
RandomBlock(-8,92,1,minecraft:wool:7,10,quark:quilted_wool:7,100)
RandomBlock(-8,92,2,minecraft:wool:7,10,quark:quilted_wool:7,100)
RandomBlock(-8,92,3,minecraft:wool:7,10,quark:quilted_wool:7,100)
RandomBlock(-8,92,4,minecraft:wool:7,10,quark:quilted_wool:7,100)
RandomBlock(-8,92,5,minecraft:wool:7,10,quark:quilted_wool:7,100)
RandomBlock(-8,93,-3,minecraft:wool:7,10,quark:quilted_wool:7,100)
RandomBlock(-8,93,-2,minecraft:wool:7,10,quark:quilted_wool:7,100)
RandomBlock(-8,93,-1,minecraft:wool:7,10,quark:quilted_wool:7,100)
RandomBlock(-8,93,0,minecraft:wool:7,10,quark:quilted_wool:7,100)
RandomBlock(-8,93,1,minecraft:wool:7,10,quark:quilted_wool:7,100)
RandomBlock(-8,93,2,minecraft:wool:7,10,quark:quilted_wool:7,100)
RandomBlock(-8,93,3,minecraft:wool:7,10,quark:quilted_wool:7,100)
RandomBlock(-8,93,4,minecraft:wool:7,10,quark:quilted_wool:7,100)
RandomBlock(-8,93,5,minecraft:wool:7,10,quark:quilted_wool:7,100)
RandomBlock(-8,94,-3,minecraft:wool:7,10,quark:quilted_wool:7,100)
RandomBlock(-8,94,-2,minecraft:wool:7,10,quark:quilted_wool:7,100)
RandomBlock(-8,94,-1,minecraft:wool:7,10,quark:quilted_wool:7,100)
RandomBlock(-8,94,0,minecraft:wool:7,10,quark:quilted_wool:7,100)
RandomBlock(-8,94,1,minecraft:wool:7,10,quark:quilted_wool:7,100)
RandomBlock(-8,94,2,minecraft:wool:7,10,quark:quilted_wool:7,100)
RandomBlock(-8,94,3,minecraft:wool:7,10,quark:quilted_wool:7,100)
RandomBlock(-8,94,4,minecraft:wool:7,10,quark:quilted_wool:7,100)
RandomBlock(-8,94,5,minecraft:wool:7,10,quark:quilted_wool:7,100)
RandomBlock(-8,95,-3,minecraft:wool:7,10,quark:quilted_wool:7,100)
RandomBlock(-8,95,-2,minecraft:wool:7,10,quark:quilted_wool:7,100)
RandomBlock(-8,95,-1,minecraft:wool:7,10,quark:quilted_wool:7,100)
RandomBlock(-8,95,0,minecraft:wool:7,10,quark:quilted_wool:7,100)
RandomBlock(-8,95,1,minecraft:wool:7,10,quark:quilted_wool:7,100)
RandomBlock(-8,95,2,minecraft:wool:7,10,quark:quilted_wool:7,100)
RandomBlock(-8,95,3,minecraft:wool:7,10,quark:quilted_wool:7,100)
RandomBlock(-8,95,4,minecraft:wool:7,10,quark:quilted_wool:7,100)
RandomBlock(-8,95,5,minecraft:wool:7,10,quark:quilted_wool:7,100)
RandomBlock(-8,96,-3,minecraft:wool:7,10,quark:quilted_wool:7,100)
RandomBlock(-8,96,-2,minecraft:wool:7,10,quark:quilted_wool:7,100)
RandomBlock(-8,96,-1,minecraft:wool:7,10,quark:quilted_wool:7,100)
RandomBlock(-8,96,0,minecraft:wool:7,10,quark:quilted_wool:7,100)
RandomBlock(-8,96,1,minecraft:wool:7,10,quark:quilted_wool:7,100)
RandomBlock(-8,96,2,minecraft:wool:7,10,quark:quilted_wool:7,100)
RandomBlock(-8,96,3,minecraft:wool:7,10,quark:quilted_wool:7,100)
RandomBlock(-8,96,4,minecraft:wool:7,10,quark:quilted_wool:7,100)
RandomBlock(-8,96,5,minecraft:wool:7,10,quark:quilted_wool:7,100)
RandomBlock(-8,97,-3,minecraft:wool:7,10,quark:quilted_wool:7,100)
RandomBlock(-8,97,-2,minecraft:wool:7,10,quark:quilted_wool:7,100)
RandomBlock(-8,97,-1,minecraft:wool:7,10,quark:quilted_wool:7,100)
RandomBlock(-8,97,0,minecraft:wool:7,10,quark:quilted_wool:7,100)
RandomBlock(-8,97,1,minecraft:wool:7,10,quark:quilted_wool:7,100)
RandomBlock(-8,97,2,minecraft:wool:7,10,quark:quilted_wool:7,100)
RandomBlock(-8,97,3,minecraft:wool:7,10,quark:quilted_wool:7,100)
RandomBlock(-8,97,4,minecraft:wool:7,10,quark:quilted_wool:7,100)
RandomBlock(-8,97,5,minecraft:wool:7,10,quark:quilted_wool:7,100)
RandomBlock(-8,98,-2,minecraft:wool:7,10,quark:quilted_wool:7,100)
RandomBlock(-8,98,-1,minecraft:wool:7,10,quark:quilted_wool:7,100)
RandomBlock(-8,98,0,minecraft:wool:7,10,quark:quilted_wool:7,100)
RandomBlock(-8,98,1,minecraft:wool:7,10,quark:quilted_wool:7,100)
RandomBlock(-8,98,2,minecraft:wool:7,10,quark:quilted_wool:7,100)
RandomBlock(-8,98,3,minecraft:wool:7,10,quark:quilted_wool:7,100)
RandomBlock(-8,98,4,minecraft:wool:7,10,quark:quilted_wool:7,100)
RandomBlock(-8,99,-1,minecraft:wool:7,10,quark:quilted_wool:7,100)
RandomBlock(-8,99,0,minecraft:wool:7,10,quark:quilted_wool:7,100)
RandomBlock(-8,99,1,minecraft:wool:7,10,quark:quilted_wool:7,100)
RandomBlock(-8,99,2,minecraft:wool:7,10,quark:quilted_wool:7,100)
RandomBlock(-8,99,3,minecraft:wool:7,10,quark:quilted_wool:7,100)
Block(-7,6,4,LOG:12)
Block(-7,6,5,LOG:12)
Block(-7,6,6,LOG:12)
Block(-7,7,4,LOG:12)
Block(-7,7,5,LOG:12)
Block(-7,7,6,quark:leaf_carpet)
Block(-7,8,4,LOG:12)
Block(-7,8,5,LOG:12)
Block(-7,9,3,LOG:12)
Block(-7,9,4,LOG:12)
Block(-7,9,5,LOG:12)
Block(-7,10,3,LOG:12)
Block(-7,10,4,LOG:12)
Block(-7,10,5,quark:leaf_carpet)
Block(-7,11,2,LOG:12)
Block(-7,11,3,LOG:12)
Block(-7,11,4,LOG:12)
Block(-7,12,2,quark:leaf_carpet)
Block(-7,12,3,LOG:12)
Block(-7,12,4,quark:leaf_carpet)
Block(-7,14,5,LOG:12)
Block(-7,15,4,LOG:12)
Block(-7,15,5,LOG:12)
Block(-7,15,6,LOG:12)
Block(-7,16,5,LOG:12)
Block(-7,16,6,LOG:12)
Block(-7,16,7,LOG:12)
Block(-7,17,5,LOG:12)
Block(-7,17,6,LOG:12)
Block(-7,17,7,LOG:12)
Block(-7,18,5,LOG:12)
Block(-7,18,6,LOG:12)
Block(-7,18,7,LOG:12)
Block(-7,19,5,quark:leaf_carpet)
Block(-7,19,6,LOG:12)
Block(-7,20,6,quark:leaf_carpet)
Block(-7,29,3,WOOL:14)
Block(-7,29,4,WOOL:14)
Block(-7,29,5,WOOL:14)
Block(-7,29,6,WOOL:14)
Block(-7,29,7,WOOL:14)
Block(-7,30,3,WOOL:14)
Block(-7,30,4,WOOL:14)
Block(-7,30,5,WOOL:14)
Block(-7,30,6,WOOL:14)
Block(-7,30,7,WOOL:14)
Block(-7,31,2,WOOL:14)
Block(-7,31,3,WOOL:14)
Block(-7,31,4,WOOL:14)
Block(-7,31,5,WOOL:14)
Block(-7,31,6,WOOL:14)
Block(-7,31,7,WOOL:14)
Block(-7,31,8,WOOL:14)
Block(-7,32,2,WOOL:14)
Block(-7,32,3,WOOL:14)
Block(-7,32,4,WOOL:14)
Block(-7,32,5,WOOL:14)
Block(-7,32,6,WOOL:14)
Block(-7,32,7,WOOL:14)
Block(-7,32,8,WOOL:14)
Block(-7,33,2,WOOL:14)
Block(-7,33,3,WOOL:14)
Block(-7,33,4,WOOL:14)
Block(-7,33,5,WOOL:14)
Block(-7,33,6,WOOL:14)
Block(-7,33,7,WOOL:14)
Block(-7,33,8,WOOL:14)
Block(-7,34,1,WOOL:14)
Block(-7,34,2,WOOL:14)
Block(-7,34,3,WOOL:14)
Block(-7,34,4,WOOL:14)
Block(-7,34,5,WOOL:14)
Block(-7,34,6,WOOL:14)
Block(-7,34,7,WOOL:14)
Block(-7,34,8,WOOL:14)
Block(-7,35,2,WOOL:14)
Block(-7,35,3,WOOL:14)
Block(-7,35,4,WOOL:14)
Block(-7,35,5,WOOL:14)
Block(-7,35,6,WOOL:14)
Block(-7,35,7,WOOL:14)
Block(-7,35,8,WOOL:14)
Block(-7,36,2,WOOL:14)
Block(-7,36,3,WOOL:14)
Block(-7,36,4,WOOL:14)
Block(-7,36,5,WOOL:14)
Block(-7,36,6,WOOL:14)
Block(-7,36,7,WOOL:14)
Block(-7,36,8,WOOL:14)
Block(-7,37,2,WOOL:14)
Block(-7,37,3,WOOL:14)
Block(-7,37,4,WOOL:14)
Block(-7,37,5,WOOL:14)
Block(-7,37,6,WOOL:14)
Block(-7,37,7,WOOL:14)
Block(-7,37,8,WOOL:14)
Block(-7,38,3,WOOL:14)
Block(-7,38,4,WOOL:14)
Block(-7,38,5,WOOL:14)
Block(-7,38,6,WOOL:14)
Block(-7,38,7,WOOL:14)
Block(-7,39,3,WOOL:14)
Block(-7,39,4,WOOL:14)
Block(-7,39,5,WOOL:14)
Block(-7,39,6,WOOL:14)
Block(-7,39,7,WOOL:14)
Block(-7,65,5,LEAVES:0)
Block(-7,65,6,LEAVES:0)
Block(-7,65,7,LEAVES:0)
Block(-7,65,8,LEAVES:0)
Block(-7,66,5,LEAVES:0)
Block(-7,66,6,LEAVES:0)
Block(-7,66,7,LEAVES:0)
Block(-7,66,8,LEAVES:0)
Block(-7,67,7,LEAVES:0)
Block(-7,67,8,LEAVES:0)
Block(-7,68,7,LEAVES:0)
Block(-7,68,8,LEAVES:0)
Block(-7,73,8,LEAVES:0)
Block(-7,74,8,LEAVES:0)
Block(-7,75,8,LEAVES:0)
Block(-7,76,8,LEAVES:0)
RandomBlock(-7,87,-1,minecraft:wool:7,10,quark:quilted_wool:7,100)
RandomBlock(-7,87,0,minecraft:wool:7,10,quark:quilted_wool:7,100)
RandomBlock(-7,87,1,minecraft:wool:7,10,quark:quilted_wool:7,100)
RandomBlock(-7,87,2,minecraft:wool:7,10,quark:quilted_wool:7,100)
RandomBlock(-7,87,3,minecraft:wool:7,10,quark:quilted_wool:7,100)
RandomBlock(-7,88,-2,minecraft:wool:7,10,quark:quilted_wool:7,100)
RandomBlock(-7,88,-1,minecraft:wool:7,10,quark:quilted_wool:7,100)
RandomBlock(-7,88,0,minecraft:wool:7,10,quark:quilted_wool:7,100)
RandomBlock(-7,88,1,minecraft:wool:7,10,quark:quilted_wool:7,100)
RandomBlock(-7,88,2,minecraft:wool:7,10,quark:quilted_wool:7,100)
RandomBlock(-7,88,3,minecraft:wool:7,10,quark:quilted_wool:7,100)
RandomBlock(-7,88,4,minecraft:wool:7,10,quark:quilted_wool:7,100)
RandomBlock(-7,89,-3,minecraft:wool:7,10,quark:quilted_wool:7,100)
RandomBlock(-7,89,-2,minecraft:wool:7,10,quark:quilted_wool:7,100)
RandomBlock(-7,89,-1,minecraft:wool:7,10,quark:quilted_wool:7,100)
RandomBlock(-7,89,0,minecraft:wool:7,10,quark:quilted_wool:7,100)
RandomBlock(-7,89,1,minecraft:wool:7,10,quark:quilted_wool:7,100)
RandomBlock(-7,89,2,minecraft:wool:7,10,quark:quilted_wool:7,100)
RandomBlock(-7,89,3,minecraft:wool:7,10,quark:quilted_wool:7,100)
RandomBlock(-7,89,4,minecraft:wool:7,10,quark:quilted_wool:7,100)
RandomBlock(-7,89,5,minecraft:wool:7,10,quark:quilted_wool:7,100)
RandomBlock(-7,90,-4,minecraft:wool:7,10,quark:quilted_wool:7,100)
RandomBlock(-7,90,-3,minecraft:wool:7,10,quark:quilted_wool:7,100)
RandomBlock(-7,90,-2,minecraft:wool:7,10,quark:quilted_wool:7,100)
RandomBlock(-7,90,-1,minecraft:wool:7,10,quark:quilted_wool:7,100)
RandomBlock(-7,90,0,minecraft:wool:7,10,quark:quilted_wool:7,100)
RandomBlock(-7,90,1,minecraft:wool:7,10,quark:quilted_wool:7,100)
RandomBlock(-7,90,2,minecraft:wool:7,10,quark:quilted_wool:7,100)
RandomBlock(-7,90,3,minecraft:wool:7,10,quark:quilted_wool:7,100)
RandomBlock(-7,90,4,minecraft:wool:7,10,quark:quilted_wool:7,100)
RandomBlock(-7,90,5,minecraft:wool:7,10,quark:quilted_wool:7,100)
RandomBlock(-7,90,6,minecraft:wool:7,10,quark:quilted_wool:7,100)
RandomBlock(-7,91,-4,minecraft:wool:7,10,quark:quilted_wool:7,100)
RandomBlock(-7,91,-3,minecraft:wool:7,10,quark:quilted_wool:7,100)
RandomBlock(-7,91,-2,minecraft:wool:7,10,quark:quilted_wool:7,100)
RandomBlock(-7,91,-1,minecraft:wool:7,10,quark:quilted_wool:7,100)
RandomBlock(-7,91,0,minecraft:wool:7,10,quark:quilted_wool:7,100)
RandomBlock(-7,91,1,minecraft:wool:7,10,quark:quilted_wool:7,100)
RandomBlock(-7,91,2,minecraft:wool:7,10,quark:quilted_wool:7,100)
RandomBlock(-7,91,3,minecraft:wool:7,10,quark:quilted_wool:7,100)
RandomBlock(-7,91,4,minecraft:wool:7,10,quark:quilted_wool:7,100)
RandomBlock(-7,91,5,minecraft:wool:7,10,quark:quilted_wool:7,100)
RandomBlock(-7,91,6,minecraft:wool:7,10,quark:quilted_wool:7,100)
RandomBlock(-7,92,-4,minecraft:wool:7,10,quark:quilted_wool:7,100)
RandomBlock(-7,92,-3,minecraft:wool:7,10,quark:quilted_wool:7,100)
RandomBlock(-7,92,-2,minecraft:wool:7,10,quark:quilted_wool:7,100)
RandomBlock(-7,92,-1,minecraft:wool:7,10,quark:quilted_wool:7,100)
RandomBlock(-7,92,0,minecraft:wool:7,10,quark:quilted_wool:7,100)
RandomBlock(-7,92,1,minecraft:wool:7,10,quark:quilted_wool:7,100)
RandomBlock(-7,92,2,minecraft:wool:7,10,quark:quilted_wool:7,100)
RandomBlock(-7,92,3,minecraft:wool:7,10,quark:quilted_wool:7,100)
RandomBlock(-7,92,4,minecraft:wool:7,10,quark:quilted_wool:7,100)
RandomBlock(-7,92,5,minecraft:wool:7,10,quark:quilted_wool:7,100)
RandomBlock(-7,92,6,minecraft:wool:7,10,quark:quilted_wool:7,100)
RandomBlock(-7,93,-4,minecraft:wool:7,10,quark:quilted_wool:7,100)
RandomBlock(-7,93,-3,minecraft:wool:7,10,quark:quilted_wool:7,100)
RandomBlock(-7,93,-2,minecraft:wool:7,10,quark:quilted_wool:7,100)
RandomBlock(-7,93,-1,minecraft:wool:7,10,quark:quilted_wool:7,100)
RandomBlock(-7,93,0,minecraft:wool:7,10,quark:quilted_wool:7,100)
RandomBlock(-7,93,1,minecraft:wool:7,10,quark:quilted_wool:7,100)
RandomBlock(-7,93,2,minecraft:wool:7,10,quark:quilted_wool:7,100)
RandomBlock(-7,93,3,minecraft:wool:7,10,quark:quilted_wool:7,100)
RandomBlock(-7,93,4,minecraft:wool:7,10,quark:quilted_wool:7,100)
RandomBlock(-7,93,5,minecraft:wool:7,10,quark:quilted_wool:7,100)
RandomBlock(-7,93,6,minecraft:wool:7,10,quark:quilted_wool:7,100)
RandomBlock(-7,94,-5,minecraft:wool:7,10,quark:quilted_wool:7,100)
RandomBlock(-7,94,-4,minecraft:wool:7,10,quark:quilted_wool:7,100)
RandomBlock(-7,94,-3,minecraft:wool:7,10,quark:quilted_wool:7,100)
RandomBlock(-7,94,-2,minecraft:wool:7,10,quark:quilted_wool:7,100)
RandomBlock(-7,94,-1,minecraft:wool:7,10,quark:quilted_wool:7,100)
RandomBlock(-7,94,0,minecraft:wool:7,10,quark:quilted_wool:7,100)
RandomBlock(-7,94,1,minecraft:wool:7,10,quark:quilted_wool:7,100)
RandomBlock(-7,94,2,minecraft:wool:7,10,quark:quilted_wool:7,100)
RandomBlock(-7,94,3,minecraft:wool:7,10,quark:quilted_wool:7,100)
RandomBlock(-7,94,4,minecraft:wool:7,10,quark:quilted_wool:7,100)
RandomBlock(-7,94,5,minecraft:wool:7,10,quark:quilted_wool:7,100)
RandomBlock(-7,94,6,minecraft:wool:7,10,quark:quilted_wool:7,100)
RandomBlock(-7,94,7,minecraft:wool:7,10,quark:quilted_wool:7,100)
RandomBlock(-7,95,-4,minecraft:wool:7,10,quark:quilted_wool:7,100)
RandomBlock(-7,95,-3,minecraft:wool:7,10,quark:quilted_wool:7,100)
RandomBlock(-7,95,-2,minecraft:wool:7,10,quark:quilted_wool:7,100)
RandomBlock(-7,95,-1,minecraft:wool:7,10,quark:quilted_wool:7,100)
RandomBlock(-7,95,0,minecraft:wool:7,10,quark:quilted_wool:7,100)
RandomBlock(-7,95,1,minecraft:wool:7,10,quark:quilted_wool:7,100)
RandomBlock(-7,95,2,minecraft:wool:7,10,quark:quilted_wool:7,100)
RandomBlock(-7,95,3,minecraft:wool:7,10,quark:quilted_wool:7,100)
RandomBlock(-7,95,4,minecraft:wool:7,10,quark:quilted_wool:7,100)
RandomBlock(-7,95,5,minecraft:wool:7,10,quark:quilted_wool:7,100)
RandomBlock(-7,95,6,minecraft:wool:7,10,quark:quilted_wool:7,100)
RandomBlock(-7,96,-4,minecraft:wool:7,10,quark:quilted_wool:7,100)
RandomBlock(-7,96,-3,minecraft:wool:7,10,quark:quilted_wool:7,100)
RandomBlock(-7,96,-2,minecraft:wool:7,10,quark:quilted_wool:7,100)
RandomBlock(-7,96,-1,minecraft:wool:7,10,quark:quilted_wool:7,100)
RandomBlock(-7,96,0,minecraft:wool:7,10,quark:quilted_wool:7,100)
RandomBlock(-7,96,1,minecraft:wool:7,10,quark:quilted_wool:7,100)
RandomBlock(-7,96,2,minecraft:wool:7,10,quark:quilted_wool:7,100)
RandomBlock(-7,96,3,minecraft:wool:7,10,quark:quilted_wool:7,100)
RandomBlock(-7,96,4,minecraft:wool:7,10,quark:quilted_wool:7,100)
RandomBlock(-7,96,5,minecraft:wool:7,10,quark:quilted_wool:7,100)
RandomBlock(-7,96,6,minecraft:wool:7,10,quark:quilted_wool:7,100)
RandomBlock(-7,97,-4,minecraft:wool:7,10,quark:quilted_wool:7,100)
RandomBlock(-7,97,-3,minecraft:wool:7,10,quark:quilted_wool:7,100)
RandomBlock(-7,97,-2,minecraft:wool:7,10,quark:quilted_wool:7,100)
RandomBlock(-7,97,-1,minecraft:wool:7,10,quark:quilted_wool:7,100)
RandomBlock(-7,97,0,minecraft:wool:7,10,quark:quilted_wool:7,100)
RandomBlock(-7,97,1,minecraft:wool:7,10,quark:quilted_wool:7,100)
RandomBlock(-7,97,2,minecraft:wool:7,10,quark:quilted_wool:7,100)
RandomBlock(-7,97,3,minecraft:wool:7,10,quark:quilted_wool:7,100)
RandomBlock(-7,97,4,minecraft:wool:7,10,quark:quilted_wool:7,100)
RandomBlock(-7,97,5,minecraft:wool:7,10,quark:quilted_wool:7,100)
RandomBlock(-7,97,6,minecraft:wool:7,10,quark:quilted_wool:7,100)
RandomBlock(-7,98,-4,minecraft:wool:7,10,quark:quilted_wool:7,100)
RandomBlock(-7,98,-3,minecraft:wool:7,10,quark:quilted_wool:7,100)
RandomBlock(-7,98,-2,minecraft:wool:7,10,quark:quilted_wool:7,100)
RandomBlock(-7,98,-1,minecraft:wool:7,10,quark:quilted_wool:7,100)
RandomBlock(-7,98,0,minecraft:wool:7,10,quark:quilted_wool:7,100)
RandomBlock(-7,98,1,minecraft:wool:7,10,quark:quilted_wool:7,100)
RandomBlock(-7,98,2,minecraft:wool:7,10,quark:quilted_wool:7,100)
RandomBlock(-7,98,3,minecraft:wool:7,10,quark:quilted_wool:7,100)
RandomBlock(-7,98,4,minecraft:wool:7,10,quark:quilted_wool:7,100)
RandomBlock(-7,98,5,minecraft:wool:7,10,quark:quilted_wool:7,100)
RandomBlock(-7,98,6,minecraft:wool:7,10,quark:quilted_wool:7,100)
RandomBlock(-7,99,-3,minecraft:wool:7,10,quark:quilted_wool:7,100)
RandomBlock(-7,99,-2,minecraft:wool:7,10,quark:quilted_wool:7,100)
RandomBlock(-7,99,-1,minecraft:wool:7,10,quark:quilted_wool:7,100)
RandomBlock(-7,99,0,minecraft:wool:7,10,quark:quilted_wool:7,100)
RandomBlock(-7,99,1,minecraft:wool:7,10,quark:quilted_wool:7,100)
RandomBlock(-7,99,2,minecraft:wool:7,10,quark:quilted_wool:7,100)
RandomBlock(-7,99,3,minecraft:wool:7,10,quark:quilted_wool:7,100)
RandomBlock(-7,99,4,minecraft:wool:7,10,quark:quilted_wool:7,100)
RandomBlock(-7,99,5,minecraft:wool:7,10,quark:quilted_wool:7,100)
RandomBlock(-7,100,-2,minecraft:wool:7,10,quark:quilted_wool:7,100)
RandomBlock(-7,100,-1,minecraft:wool:7,10,quark:quilted_wool:7,100)
RandomBlock(-7,100,0,minecraft:wool:7,10,quark:quilted_wool:7,100)
RandomBlock(-7,100,1,minecraft:wool:7,10,quark:quilted_wool:7,100)
RandomBlock(-7,100,2,minecraft:wool:7,10,quark:quilted_wool:7,100)
RandomBlock(-7,100,3,minecraft:wool:7,10,quark:quilted_wool:7,100)
RandomBlock(-7,100,4,minecraft:wool:7,10,quark:quilted_wool:7,100)
RandomBlock(-7,101,-1,minecraft:wool:7,10,quark:quilted_wool:7,100)
RandomBlock(-7,101,0,minecraft:wool:7,10,quark:quilted_wool:7,100)
RandomBlock(-7,101,1,minecraft:wool:7,10,quark:quilted_wool:7,100)
RandomBlock(-7,101,2,minecraft:wool:7,10,quark:quilted_wool:7,100)
RandomBlock(-7,101,3,minecraft:wool:7,10,quark:quilted_wool:7,100)
Block(-6,5,5,LOG:12)
Block(-6,5,6,LOG:12)
Block(-6,6,5,LOG:12)
Block(-6,6,6,LOG:12)
Block(-6,7,5,LOG:12)
Block(-6,8,5,quark:leaf_carpet)
Block(-6,16,6,LOG:12)
Block(-6,17,5,LOG:12)
Block(-6,17,6,LOG:12)
Block(-6,17,7,LOG:12)
Block(-6,18,5,LOG:12)
Block(-6,18,6,LOG:12)
Block(-6,18,7,LOG:12)
Block(-6,19,5,LOG:12)
Block(-6,19,6,LOG:12)
Block(-6,19,7,LOG:12)
Block(-6,20,6,LOG:12)
Block(-6,28,4,WOOL:14)
Block(-6,28,5,WOOL:14)
Block(-6,28,6,WOOL:14)
Block(-6,29,3,WOOL:14)
Block(-6,29,4,WOOL:14)
Block(-6,29,5,WOOL:14)
Block(-6,29,6,WOOL:14)
Block(-6,29,7,WOOL:14)
Block(-6,30,2,WOOL:14)
Block(-6,30,3,WOOL:14)
Block(-6,30,4,WOOL:14)
Block(-6,30,5,WOOL:14)
Block(-6,30,6,WOOL:14)
Block(-6,30,7,WOOL:14)
Block(-6,30,8,WOOL:14)
Block(-6,31,2,WOOL:14)
Block(-6,31,3,WOOL:14)
Block(-6,31,4,WOOL:14)
Block(-6,31,5,WOOL:14)
Block(-6,31,6,WOOL:14)
Block(-6,31,7,WOOL:14)
Block(-6,31,8,WOOL:14)
Block(-6,32,1,WOOL:14)
Block(-6,32,2,WOOL:14)
Block(-6,32,3,WOOL:14)
Block(-6,32,4,WOOL:14)
Block(-6,32,5,WOOL:14)
Block(-6,32,6,WOOL:14)
Block(-6,32,7,WOOL:14)
Block(-6,32,8,WOOL:14)
Block(-6,33,1,WOOL:14)
Block(-6,33,2,WOOL:14)
Block(-6,33,3,WOOL:14)
Block(-6,33,4,WOOL:14)
Block(-6,33,5,WOOL:14)
Block(-6,33,6,WOOL:14)
Block(-6,33,7,WOOL:14)
Block(-6,33,8,WOOL:14)
Block(-6,34,1,WOOL:14)
Block(-6,34,2,WOOL:14)
Block(-6,34,3,WOOL:14)
Block(-6,34,4,WOOL:14)
Block(-6,34,5,WOOL:14)
Block(-6,34,6,WOOL:14)
Block(-6,34,7,WOOL:14)
Block(-6,34,8,WOOL:14)
Block(-6,35,1,WOOL:14)
Block(-6,35,2,WOOL:14)
Block(-6,35,3,WOOL:14)
Block(-6,35,4,WOOL:14)
Block(-6,35,5,WOOL:14)
Block(-6,35,6,WOOL:14)
Block(-6,35,7,WOOL:14)
Block(-6,35,8,WOOL:14)
Block(-6,36,1,WOOL:14)
Block(-6,36,2,WOOL:14)
Block(-6,36,3,WOOL:14)
Block(-6,36,4,WOOL:14)
Block(-6,36,5,WOOL:14)
Block(-6,36,6,WOOL:14)
Block(-6,36,7,WOOL:14)
Block(-6,36,8,WOOL:14)
Block(-6,37,2,WOOL:14)
Block(-6,37,3,WOOL:14)
Block(-6,37,4,WOOL:14)
Block(-6,37,5,WOOL:14)
Block(-6,37,6,WOOL:14)
Block(-6,37,7,WOOL:14)
Block(-6,37,8,WOOL:14)
Block(-6,38,2,WOOL:14)
Block(-6,38,3,WOOL:14)
Block(-6,38,4,WOOL:14)
Block(-6,38,5,WOOL:14)
Block(-6,38,6,WOOL:14)
Block(-6,38,7,WOOL:14)
Block(-6,38,8,WOOL:14)
Block(-6,39,3,WOOL:14)
Block(-6,39,4,WOOL:14)
Block(-6,39,5,WOOL:14)
Block(-6,39,6,WOOL:14)
Block(-6,39,7,WOOL:14)
Block(-6,40,4,WOOL:14)
Block(-6,40,5,WOOL:14)
Block(-6,40,6,WOOL:14)
Block(-6,59,7,rustic:iron_lantern:0)
Block(-6,61,7,LOG:12)
Block(-6,61,8,LOG:12)
Block(-6,62,7,LOG:12)
Block(-6,63,7,LOG:12)
Block(-6,64,7,LOG:12)
Block(-6,65,5,LEAVES:0)
Block(-6,65,6,LEAVES:0)
Block(-6,65,7,LOG:12)
Block(-6,65,8,LEAVES:0)
Block(-6,66,5,LEAVES:0)
Block(-6,66,6,LEAVES:0)
Block(-6,66,7,LOG:12)
Block(-6,66,8,LEAVES:0)
Block(-6,67,6,LEAVES:0)
Block(-6,67,7,LOG:12)
Block(-6,67,8,LEAVES:0)
Block(-6,68,6,LEAVES:0)
Block(-6,68,7,LEAVES:0)
Block(-6,68,8,LEAVES:0)
Block(-6,70,7,LEAVES:0)
Block(-6,70,8,LEAVES:0)
Block(-6,71,6,LEAVES:0)
Block(-6,71,7,LEAVES:0)
Block(-6,71,8,LEAVES:0)
Block(-6,72,5,LEAVES:0)
Block(-6,72,6,LEAVES:0)
Block(-6,72,7,LEAVES:0)
Block(-6,72,8,LEAVES:0)
Block(-6,73,8,LEAVES:0)
Block(-6,74,8,LEAVES:0)
Block(-6,75,8,LEAVES:0)
Block(-6,76,5,LEAVES:0)
Block(-6,76,6,LEAVES:0)
Block(-6,76,7,LEAVES:0)
Block(-6,76,8,LEAVES:0)
Block(-6,77,5,LEAVES:0)
Block(-6,77,6,LEAVES:0)
Block(-6,77,7,LEAVES:0)
Block(-6,79,6,LEAVES:0)
Block(-6,79,7,LEAVES:0)
Block(-6,79,8,LEAVES:0)
Block(-6,80,7,LEAVES:0)
Block(-6,80,8,LEAVES:0)
RandomBlock(-6,86,-1,minecraft:wool:7,10,quark:quilted_wool:7,100)
RandomBlock(-6,86,0,minecraft:wool:7,10,quark:quilted_wool:7,100)
RandomBlock(-6,86,1,minecraft:wool:7,10,quark:quilted_wool:7,100)
RandomBlock(-6,86,2,minecraft:wool:7,10,quark:quilted_wool:7,100)
RandomBlock(-6,86,3,minecraft:wool:7,10,quark:quilted_wool:7,100)
RandomBlock(-6,87,-2,minecraft:wool:7,10,quark:quilted_wool:7,100)
RandomBlock(-6,87,-1,minecraft:wool:7,10,quark:quilted_wool:7,100)
RandomBlock(-6,87,0,minecraft:wool:7,10,quark:quilted_wool:7,100)
RandomBlock(-6,87,1,minecraft:wool:7,10,quark:quilted_wool:7,100)
RandomBlock(-6,87,2,minecraft:wool:7,10,quark:quilted_wool:7,100)
RandomBlock(-6,87,3,minecraft:wool:7,10,quark:quilted_wool:7,100)
RandomBlock(-6,87,4,minecraft:wool:7,10,quark:quilted_wool:7,100)
RandomBlock(-6,88,-3,minecraft:wool:7,10,quark:quilted_wool:7,100)
RandomBlock(-6,88,-2,minecraft:wool:7,10,quark:quilted_wool:7,100)
RandomBlock(-6,88,-1,minecraft:wool:7,10,quark:quilted_wool:7,100)
RandomBlock(-6,88,0,minecraft:wool:7,10,quark:quilted_wool:7,100)
RandomBlock(-6,88,1,minecraft:wool:7,10,quark:quilted_wool:7,100)
RandomBlock(-6,88,2,minecraft:wool:7,10,quark:quilted_wool:7,100)
RandomBlock(-6,88,3,minecraft:wool:7,10,quark:quilted_wool:7,100)
RandomBlock(-6,88,4,minecraft:wool:7,10,quark:quilted_wool:7,100)
RandomBlock(-6,88,5,minecraft:wool:7,10,quark:quilted_wool:7,100)
RandomBlock(-6,89,-4,minecraft:wool:7,10,quark:quilted_wool:7,100)
RandomBlock(-6,89,-3,minecraft:wool:7,10,quark:quilted_wool:7,100)
RandomBlock(-6,89,-2,minecraft:wool:7,10,quark:quilted_wool:7,100)
RandomBlock(-6,89,-1,minecraft:wool:7,10,quark:quilted_wool:7,100)
RandomBlock(-6,89,0,minecraft:wool:7,10,quark:quilted_wool:7,100)
RandomBlock(-6,89,1,minecraft:wool:7,10,quark:quilted_wool:7,100)
RandomBlock(-6,89,2,minecraft:wool:7,10,quark:quilted_wool:7,100)
RandomBlock(-6,89,3,minecraft:wool:7,10,quark:quilted_wool:7,100)
RandomBlock(-6,89,4,minecraft:wool:7,10,quark:quilted_wool:7,100)
RandomBlock(-6,89,5,minecraft:wool:7,10,quark:quilted_wool:7,100)
RandomBlock(-6,89,6,minecraft:wool:7,10,quark:quilted_wool:7,100)
RandomBlock(-6,90,-5,minecraft:wool:7,10,quark:quilted_wool:7,100)
RandomBlock(-6,90,-4,minecraft:wool:7,10,quark:quilted_wool:7,100)
RandomBlock(-6,90,-3,minecraft:wool:7,10,quark:quilted_wool:7,100)
RandomBlock(-6,90,-2,minecraft:wool:7,10,quark:quilted_wool:7,100)
RandomBlock(-6,90,-1,minecraft:wool:7,10,quark:quilted_wool:7,100)
RandomBlock(-6,90,0,minecraft:wool:7,10,quark:quilted_wool:7,100)
RandomBlock(-6,90,1,minecraft:wool:7,10,quark:quilted_wool:7,100)
RandomBlock(-6,90,2,minecraft:wool:7,10,quark:quilted_wool:7,100)
RandomBlock(-6,90,3,minecraft:wool:7,10,quark:quilted_wool:7,100)
RandomBlock(-6,90,4,minecraft:wool:7,10,quark:quilted_wool:7,100)
RandomBlock(-6,90,5,minecraft:wool:7,10,quark:quilted_wool:7,100)
RandomBlock(-6,90,6,minecraft:wool:7,10,quark:quilted_wool:7,100)
RandomBlock(-6,90,7,minecraft:wool:7,10,quark:quilted_wool:7,100)
RandomBlock(-6,91,-5,minecraft:wool:7,10,quark:quilted_wool:7,100)
RandomBlock(-6,91,-4,minecraft:wool:7,10,quark:quilted_wool:7,100)
RandomBlock(-6,91,-3,minecraft:wool:7,10,quark:quilted_wool:7,100)
RandomBlock(-6,91,-2,minecraft:wool:7,10,quark:quilted_wool:7,100)
RandomBlock(-6,91,-1,minecraft:wool:7,10,quark:quilted_wool:7,100)
RandomBlock(-6,91,0,minecraft:wool:7,10,quark:quilted_wool:7,100)
RandomBlock(-6,91,1,minecraft:wool:7,10,quark:quilted_wool:7,100)
RandomBlock(-6,91,2,minecraft:wool:7,10,quark:quilted_wool:7,100)
RandomBlock(-6,91,3,minecraft:wool:7,10,quark:quilted_wool:7,100)
RandomBlock(-6,91,4,minecraft:wool:7,10,quark:quilted_wool:7,100)
RandomBlock(-6,91,5,minecraft:wool:7,10,quark:quilted_wool:7,100)
RandomBlock(-6,91,6,minecraft:wool:7,10,quark:quilted_wool:7,100)
RandomBlock(-6,91,7,minecraft:wool:7,10,quark:quilted_wool:7,100)
RandomBlock(-6,92,-5,minecraft:wool:7,10,quark:quilted_wool:7,100)
RandomBlock(-6,92,-4,minecraft:wool:7,10,quark:quilted_wool:7,100)
RandomBlock(-6,92,-3,minecraft:wool:7,10,quark:quilted_wool:7,100)
RandomBlock(-6,92,-2,minecraft:wool:7,10,quark:quilted_wool:7,100)
RandomBlock(-6,92,-1,minecraft:wool:7,10,quark:quilted_wool:7,100)
RandomBlock(-6,92,0,minecraft:wool:7,10,quark:quilted_wool:7,100)
RandomBlock(-6,92,1,minecraft:wool:7,10,quark:quilted_wool:7,100)
RandomBlock(-6,92,2,minecraft:wool:7,10,quark:quilted_wool:7,100)
RandomBlock(-6,92,3,minecraft:wool:7,10,quark:quilted_wool:7,100)
RandomBlock(-6,92,4,minecraft:wool:7,10,quark:quilted_wool:7,100)
RandomBlock(-6,92,5,minecraft:wool:7,10,quark:quilted_wool:7,100)
RandomBlock(-6,92,6,minecraft:wool:7,10,quark:quilted_wool:7,100)
RandomBlock(-6,92,7,minecraft:wool:7,10,quark:quilted_wool:7,100)
RandomBlock(-6,93,-5,minecraft:wool:7,10,quark:quilted_wool:7,100)
RandomBlock(-6,93,-4,minecraft:wool:7,10,quark:quilted_wool:7,100)
RandomBlock(-6,93,-3,minecraft:wool:7,10,quark:quilted_wool:7,100)
RandomBlock(-6,93,-2,minecraft:wool:7,10,quark:quilted_wool:7,100)
RandomBlock(-6,93,-1,minecraft:wool:7,10,quark:quilted_wool:7,100)
RandomBlock(-6,93,0,minecraft:wool:7,10,quark:quilted_wool:7,100)
RandomBlock(-6,93,1,minecraft:wool:7,10,quark:quilted_wool:7,100)
RandomBlock(-6,93,2,minecraft:wool:7,10,quark:quilted_wool:7,100)
RandomBlock(-6,93,3,minecraft:wool:7,10,quark:quilted_wool:7,100)
RandomBlock(-6,93,4,minecraft:wool:7,10,quark:quilted_wool:7,100)
RandomBlock(-6,93,5,minecraft:wool:7,10,quark:quilted_wool:7,100)
RandomBlock(-6,93,6,minecraft:wool:7,10,quark:quilted_wool:7,100)
RandomBlock(-6,93,7,minecraft:wool:7,10,quark:quilted_wool:7,100)
RandomBlock(-6,94,-5,minecraft:wool:7,10,quark:quilted_wool:7,100)
RandomBlock(-6,94,-4,minecraft:wool:7,10,quark:quilted_wool:7,100)
RandomBlock(-6,94,-3,minecraft:wool:7,10,quark:quilted_wool:7,100)
RandomBlock(-6,94,-2,minecraft:wool:7,10,quark:quilted_wool:7,100)
RandomBlock(-6,94,-1,minecraft:wool:7,10,quark:quilted_wool:7,100)
RandomBlock(-6,94,0,minecraft:wool:7,10,quark:quilted_wool:7,100)
RandomBlock(-6,94,1,minecraft:wool:7,10,quark:quilted_wool:7,100)
RandomBlock(-6,94,2,minecraft:wool:7,10,quark:quilted_wool:7,100)
RandomBlock(-6,94,3,minecraft:wool:7,10,quark:quilted_wool:7,100)
RandomBlock(-6,94,4,minecraft:wool:7,10,quark:quilted_wool:7,100)
RandomBlock(-6,94,5,minecraft:wool:7,10,quark:quilted_wool:7,100)
RandomBlock(-6,94,6,minecraft:wool:7,10,quark:quilted_wool:7,100)
RandomBlock(-6,94,7,minecraft:wool:7,10,quark:quilted_wool:7,100)
RandomBlock(-6,95,-5,minecraft:wool:7,10,quark:quilted_wool:7,100)
RandomBlock(-6,95,-4,minecraft:wool:7,10,quark:quilted_wool:7,100)
RandomBlock(-6,95,-3,minecraft:wool:7,10,quark:quilted_wool:7,100)
RandomBlock(-6,95,-2,minecraft:wool:7,10,quark:quilted_wool:7,100)
RandomBlock(-6,95,-1,minecraft:wool:7,10,quark:quilted_wool:7,100)
RandomBlock(-6,95,0,minecraft:wool:7,10,quark:quilted_wool:7,100)
RandomBlock(-6,95,1,minecraft:wool:7,10,quark:quilted_wool:7,100)
RandomBlock(-6,95,2,minecraft:wool:7,10,quark:quilted_wool:7,100)
RandomBlock(-6,95,3,minecraft:wool:7,10,quark:quilted_wool:7,100)
RandomBlock(-6,95,4,minecraft:wool:7,10,quark:quilted_wool:7,100)
RandomBlock(-6,95,5,minecraft:wool:7,10,quark:quilted_wool:7,100)
RandomBlock(-6,95,6,minecraft:wool:7,10,quark:quilted_wool:7,100)
RandomBlock(-6,95,7,minecraft:wool:7,10,quark:quilted_wool:7,100)
RandomBlock(-6,96,-5,minecraft:wool:7,10,quark:quilted_wool:7,100)
RandomBlock(-6,96,-4,minecraft:wool:7,10,quark:quilted_wool:7,100)
RandomBlock(-6,96,-3,minecraft:wool:7,10,quark:quilted_wool:7,100)
RandomBlock(-6,96,-2,minecraft:wool:7,10,quark:quilted_wool:7,100)
RandomBlock(-6,96,-1,minecraft:wool:7,10,quark:quilted_wool:7,100)
RandomBlock(-6,96,0,minecraft:wool:7,10,quark:quilted_wool:7,100)
RandomBlock(-6,96,1,minecraft:wool:7,10,quark:quilted_wool:7,100)
RandomBlock(-6,96,2,minecraft:wool:7,10,quark:quilted_wool:7,100)
RandomBlock(-6,96,3,minecraft:wool:7,10,quark:quilted_wool:7,100)
RandomBlock(-6,96,4,minecraft:wool:7,10,quark:quilted_wool:7,100)
RandomBlock(-6,96,5,minecraft:wool:7,10,quark:quilted_wool:7,100)
RandomBlock(-6,96,6,minecraft:wool:7,10,quark:quilted_wool:7,100)
RandomBlock(-6,96,7,minecraft:wool:7,10,quark:quilted_wool:7,100)
RandomBlock(-6,97,-5,minecraft:wool:7,10,quark:quilted_wool:7,100)
RandomBlock(-6,97,-4,minecraft:wool:7,10,quark:quilted_wool:7,100)
RandomBlock(-6,97,-3,minecraft:wool:7,10,quark:quilted_wool:7,100)
RandomBlock(-6,97,-2,minecraft:wool:7,10,quark:quilted_wool:7,100)
RandomBlock(-6,97,-1,minecraft:wool:7,10,quark:quilted_wool:7,100)
RandomBlock(-6,97,0,minecraft:wool:7,10,quark:quilted_wool:7,100)
RandomBlock(-6,97,1,minecraft:wool:7,10,quark:quilted_wool:7,100)
RandomBlock(-6,97,2,minecraft:wool:7,10,quark:quilted_wool:7,100)
RandomBlock(-6,97,3,minecraft:wool:7,10,quark:quilted_wool:7,100)
RandomBlock(-6,97,4,minecraft:wool:7,10,quark:quilted_wool:7,100)
RandomBlock(-6,97,5,minecraft:wool:7,10,quark:quilted_wool:7,100)
RandomBlock(-6,97,6,minecraft:wool:7,10,quark:quilted_wool:7,100)
RandomBlock(-6,97,7,minecraft:wool:7,10,quark:quilted_wool:7,100)
RandomBlock(-6,98,-5,minecraft:wool:7,10,quark:quilted_wool:7,100)
RandomBlock(-6,98,-4,minecraft:wool:7,10,quark:quilted_wool:7,100)
RandomBlock(-6,98,-3,minecraft:wool:7,10,quark:quilted_wool:7,100)
RandomBlock(-6,98,-2,minecraft:wool:7,10,quark:quilted_wool:7,100)
RandomBlock(-6,98,-1,minecraft:wool:7,10,quark:quilted_wool:7,100)
RandomBlock(-6,98,0,minecraft:wool:7,10,quark:quilted_wool:7,100)
RandomBlock(-6,98,1,minecraft:wool:7,10,quark:quilted_wool:7,100)
RandomBlock(-6,98,2,minecraft:wool:7,10,quark:quilted_wool:7,100)
RandomBlock(-6,98,3,minecraft:wool:7,10,quark:quilted_wool:7,100)
RandomBlock(-6,98,4,minecraft:wool:7,10,quark:quilted_wool:7,100)
RandomBlock(-6,98,5,minecraft:wool:7,10,quark:quilted_wool:7,100)
RandomBlock(-6,98,6,minecraft:wool:7,10,quark:quilted_wool:7,100)
RandomBlock(-6,98,7,minecraft:wool:7,10,quark:quilted_wool:7,100)
RandomBlock(-6,99,-4,minecraft:wool:7,10,quark:quilted_wool:7,100)
RandomBlock(-6,99,-3,minecraft:wool:7,10,quark:quilted_wool:7,100)
RandomBlock(-6,99,-2,minecraft:wool:7,10,quark:quilted_wool:7,100)
RandomBlock(-6,99,-1,minecraft:wool:7,10,quark:quilted_wool:7,100)
RandomBlock(-6,99,0,minecraft:wool:7,10,quark:quilted_wool:7,100)
RandomBlock(-6,99,1,minecraft:wool:7,10,quark:quilted_wool:7,100)
RandomBlock(-6,99,2,minecraft:wool:7,10,quark:quilted_wool:7,100)
RandomBlock(-6,99,3,minecraft:wool:7,10,quark:quilted_wool:7,100)
RandomBlock(-6,99,4,minecraft:wool:7,10,quark:quilted_wool:7,100)
RandomBlock(-6,99,5,minecraft:wool:7,10,quark:quilted_wool:7,100)
RandomBlock(-6,99,6,minecraft:wool:7,10,quark:quilted_wool:7,100)
RandomBlock(-6,100,-3,minecraft:wool:7,10,quark:quilted_wool:7,100)
RandomBlock(-6,100,-2,minecraft:wool:7,10,quark:quilted_wool:7,100)
RandomBlock(-6,100,-1,minecraft:wool:7,10,quark:quilted_wool:7,100)
RandomBlock(-6,100,0,minecraft:wool:7,10,quark:quilted_wool:7,100)
RandomBlock(-6,100,1,minecraft:wool:7,10,quark:quilted_wool:7,100)
RandomBlock(-6,100,2,minecraft:wool:7,10,quark:quilted_wool:7,100)
RandomBlock(-6,100,3,minecraft:wool:7,10,quark:quilted_wool:7,100)
RandomBlock(-6,100,4,minecraft:wool:7,10,quark:quilted_wool:7,100)
RandomBlock(-6,100,5,minecraft:wool:7,10,quark:quilted_wool:7,100)
RandomBlock(-6,101,-2,minecraft:wool:7,10,quark:quilted_wool:7,100)
RandomBlock(-6,101,-1,minecraft:wool:7,10,quark:quilted_wool:7,100)
RandomBlock(-6,101,0,minecraft:wool:7,10,quark:quilted_wool:7,100)
RandomBlock(-6,101,1,minecraft:wool:7,10,quark:quilted_wool:7,100)
RandomBlock(-6,101,2,minecraft:wool:7,10,quark:quilted_wool:7,100)
RandomBlock(-6,101,3,minecraft:wool:7,10,quark:quilted_wool:7,100)
RandomBlock(-6,101,4,minecraft:wool:7,10,quark:quilted_wool:7,100)
RandomBlock(-6,102,-1,minecraft:wool:7,10,quark:quilted_wool:7,100)
RandomBlock(-6,102,0,minecraft:wool:7,10,quark:quilted_wool:7,100)
RandomBlock(-6,102,1,minecraft:wool:7,10,quark:quilted_wool:7,100)
RandomBlock(-6,102,2,minecraft:wool:7,10,quark:quilted_wool:7,100)
RandomBlock(-6,102,3,minecraft:wool:7,10,quark:quilted_wool:7,100)
Block(-5,4,7,LOG:12)
Block(-5,5,6,LOG:12)
Block(-5,5,7,LOG:12)
Block(-5,6,7,quark:leaf_carpet)
Block(-5,17,6,LOG:12)
Block(-5,18,5,LOG:12)
Block(-5,18,6,LOG:12)
Block(-5,18,7,LOG:12)
Block(-5,19,5,LOG:12)
Block(-5,19,6,LOG:12)
Block(-5,19,7,LOG:12)
Block(-5,19,8,LOG:12)
Block(-5,20,5,LOG:12)
Block(-5,20,6,LOG:12)
Block(-5,20,7,LOG:12)
Block(-5,21,5,inspirations:rope:1)
Block(-5,21,6,quark:leaf_carpet)
Block(-5,22,5,inspirations:rope:1)
Block(-5,23,5,inspirations:rope:1)
Block(-5,24,5,inspirations:rope:1)
Block(-5,25,5,inspirations:rope:1)
Block(-5,26,5,inspirations:rope:1)
Block(-5,27,5,inspirations:rope:1)
Block(-5,28,4,WOOL:14)
Block(-5,28,5,WOOL:14)
Block(-5,28,6,WOOL:14)
Block(-5,29,3,WOOL:14)
Block(-5,29,4,WOOL:14)
Block(-5,29,5,WOOL:14)
Block(-5,29,6,WOOL:14)
Block(-5,29,7,WOOL:14)
Block(-5,30,2,WOOL:14)
Block(-5,30,3,WOOL:14)
Block(-5,30,4,WOOL:14)
Block(-5,30,5,WOOL:14)
Block(-5,30,6,WOOL:14)
Block(-5,30,7,WOOL:14)
Block(-5,30,8,WOOL:14)
Block(-5,31,2,WOOL:14)
Block(-5,31,3,WOOL:14)
Block(-5,31,4,WOOL:14)
Block(-5,31,5,WOOL:14)
Block(-5,31,6,WOOL:14)
Block(-5,31,7,WOOL:14)
Block(-5,31,8,WOOL:14)
Block(-5,32,1,WOOL:14)
Block(-5,32,2,WOOL:14)
Block(-5,32,3,WOOL:14)
Block(-5,32,4,WOOL:14)
Block(-5,32,5,WOOL:14)
Block(-5,32,6,WOOL:14)
Block(-5,32,7,WOOL:14)
Block(-5,32,8,WOOL:14)
Block(-5,33,1,WOOL:14)
Block(-5,33,2,WOOL:14)
Block(-5,33,3,WOOL:14)
Block(-5,33,4,WOOL:14)
Block(-5,33,5,WOOL:14)
Block(-5,33,6,WOOL:14)
Block(-5,33,7,WOOL:14)
Block(-5,33,8,WOOL:14)
Block(-5,34,1,WOOL:14)
Block(-5,34,2,WOOL:14)
Block(-5,34,3,WOOL:14)
Block(-5,34,4,WOOL:14)
Block(-5,34,5,WOOL:14)
Block(-5,34,6,WOOL:14)
Block(-5,34,7,WOOL:14)
Block(-5,34,8,WOOL:14)
Block(-5,35,1,WOOL:14)
Block(-5,35,2,WOOL:14)
Block(-5,35,3,WOOL:14)
Block(-5,35,4,WOOL:14)
Block(-5,35,5,WOOL:14)
Block(-5,35,6,WOOL:14)
Block(-5,35,7,WOOL:14)
Block(-5,35,8,WOOL:14)
Block(-5,36,1,WOOL:14)
Block(-5,36,2,WOOL:14)
Block(-5,36,3,WOOL:14)
Block(-5,36,4,WOOL:14)
Block(-5,36,5,WOOL:14)
Block(-5,36,6,WOOL:14)
Block(-5,36,7,WOOL:14)
Block(-5,36,8,WOOL:14)
Block(-5,37,2,WOOL:14)
Block(-5,37,3,WOOL:14)
Block(-5,37,4,WOOL:14)
Block(-5,37,5,WOOL:14)
Block(-5,37,6,WOOL:14)
Block(-5,37,7,WOOL:14)
Block(-5,37,8,WOOL:14)
Block(-5,38,2,WOOL:14)
Block(-5,38,3,WOOL:14)
Block(-5,38,4,WOOL:14)
Block(-5,38,5,WOOL:14)
Block(-5,38,6,WOOL:14)
Block(-5,38,7,WOOL:14)
Block(-5,38,8,WOOL:14)
Block(-5,39,3,WOOL:14)
Block(-5,39,4,WOOL:14)
Block(-5,39,5,WOOL:14)
Block(-5,39,6,WOOL:14)
Block(-5,39,7,WOOL:14)
Block(-5,40,4,WOOL:14)
Block(-5,40,5,WOOL:14)
Block(-5,40,6,WOOL:14)
Block(-5,65,5,LEAVES:0)
Block(-5,65,6,LEAVES:0)
Block(-5,65,7,LEAVES:0)
Block(-5,65,8,LEAVES:0)
Block(-5,66,5,LEAVES:0)
Block(-5,66,6,LEAVES:0)
Block(-5,66,7,LEAVES:0)
Block(-5,66,8,LEAVES:0)
Block(-5,67,6,LEAVES:0)
Block(-5,67,7,LEAVES:0)
Block(-5,68,6,VINE:9)
Block(-5,68,7,LEAVES:0)
Block(-5,69,6,VINE:8)
Block(-5,70,5,LEAVES:0)
Block(-5,70,6,LEAVES:0)
Block(-5,70,7,LEAVES:0)
Block(-5,70,8,LEAVES:0)
Block(-5,71,5,LEAVES:0)
Block(-5,71,6,LEAVES:0)
Block(-5,71,7,LEAVES:0)
Block(-5,71,8,LEAVES:0)
Block(-5,72,5,LEAVES:0)
Block(-5,72,6,LEAVES:0)
Block(-5,72,7,LEAVES:0)
Block(-5,72,8,LEAVES:0)
Block(-5,73,6,LEAVES:0)
Block(-5,73,7,LEAVES:0)
Block(-5,73,8,LEAVES:0)
Block(-5,74,6,LEAVES:0)
Block(-5,74,7,LEAVES:0)
Block(-5,74,8,LEAVES:0)
Block(-5,75,6,LEAVES:0)
Block(-5,75,7,LEAVES:0)
Block(-5,75,8,LEAVES:0)
Block(-5,76,4,LEAVES:0)
Block(-5,76,5,LEAVES:0)
Block(-5,76,6,LEAVES:0)
Block(-5,76,7,LEAVES:0)
Block(-5,76,8,LEAVES:0)
Block(-5,77,4,LEAVES:0)
Block(-5,77,5,LEAVES:0)
Block(-5,77,6,LEAVES:0)
Block(-5,77,7,LEAVES:0)
Block(-5,77,8,LEAVES:0)
Block(-5,78,4,LEAVES:0)
Block(-5,78,5,LEAVES:0)
Block(-5,78,6,LEAVES:0)
Block(-5,78,7,LEAVES:0)
Block(-5,78,8,LEAVES:0)
Block(-5,79,5,LEAVES:0)
Block(-5,79,6,LEAVES:0)
Block(-5,79,7,LEAVES:0)
Block(-5,79,8,LEAVES:0)
Block(-5,80,6,LEAVES:0)
Block(-5,80,7,LEAVES:0)
Block(-5,80,8,LEAVES:0)
Block(-5,81,7,LEAVES:0)
Block(-5,81,8,LEAVES:0)
RandomBlock(-5,85,0,minecraft:wool:7,10,quark:quilted_wool:7,100)
RandomBlock(-5,85,1,minecraft:wool:7,10,quark:quilted_wool:7,100)
RandomBlock(-5,85,2,minecraft:wool:7,10,quark:quilted_wool:7,100)
RandomBlock(-5,86,-2,minecraft:wool:7,10,quark:quilted_wool:7,100)
RandomBlock(-5,86,-1,minecraft:wool:7,10,quark:quilted_wool:7,100)
RandomBlock(-5,86,0,minecraft:wool:7,10,quark:quilted_wool:7,100)
RandomBlock(-5,86,1,minecraft:wool:7,10,quark:quilted_wool:7,100)
RandomBlock(-5,86,2,minecraft:wool:7,10,quark:quilted_wool:7,100)
RandomBlock(-5,86,3,minecraft:wool:7,10,quark:quilted_wool:7,100)
RandomBlock(-5,86,4,minecraft:wool:7,10,quark:quilted_wool:7,100)
RandomBlock(-5,87,-3,minecraft:wool:7,10,quark:quilted_wool:7,100)
RandomBlock(-5,87,-2,minecraft:wool:7,10,quark:quilted_wool:7,100)
RandomBlock(-5,87,-1,minecraft:wool:7,10,quark:quilted_wool:7,100)
RandomBlock(-5,87,0,minecraft:wool:7,10,quark:quilted_wool:7,100)
RandomBlock(-5,87,1,minecraft:wool:7,10,quark:quilted_wool:7,100)
RandomBlock(-5,87,2,minecraft:wool:7,10,quark:quilted_wool:7,100)
RandomBlock(-5,87,3,minecraft:wool:7,10,quark:quilted_wool:7,100)
RandomBlock(-5,87,4,minecraft:wool:7,10,quark:quilted_wool:7,100)
RandomBlock(-5,87,5,minecraft:wool:7,10,quark:quilted_wool:7,100)
RandomBlock(-5,88,-4,minecraft:wool:7,10,quark:quilted_wool:7,100)
RandomBlock(-5,88,-3,minecraft:wool:7,10,quark:quilted_wool:7,100)
RandomBlock(-5,88,-2,minecraft:wool:7,10,quark:quilted_wool:7,100)
RandomBlock(-5,88,-1,minecraft:wool:7,10,quark:quilted_wool:7,100)
RandomBlock(-5,88,0,minecraft:wool:7,10,quark:quilted_wool:7,100)
RandomBlock(-5,88,1,minecraft:wool:7,10,quark:quilted_wool:7,100)
RandomBlock(-5,88,2,minecraft:wool:7,10,quark:quilted_wool:7,100)
RandomBlock(-5,88,3,minecraft:wool:7,10,quark:quilted_wool:7,100)
RandomBlock(-5,88,4,minecraft:wool:7,10,quark:quilted_wool:7,100)
RandomBlock(-5,88,5,minecraft:wool:7,10,quark:quilted_wool:7,100)
RandomBlock(-5,88,6,minecraft:wool:7,10,quark:quilted_wool:7,100)
RandomBlock(-5,89,-5,minecraft:wool:7,10,quark:quilted_wool:7,100)
RandomBlock(-5,89,-4,minecraft:wool:7,10,quark:quilted_wool:7,100)
RandomBlock(-5,89,-3,minecraft:wool:7,10,quark:quilted_wool:7,100)
RandomBlock(-5,89,-2,minecraft:wool:7,10,quark:quilted_wool:7,100)
RandomBlock(-5,89,-1,minecraft:wool:7,10,quark:quilted_wool:7,100)
RandomBlock(-5,89,0,minecraft:wool:7,10,quark:quilted_wool:7,100)
RandomBlock(-5,89,1,minecraft:wool:7,10,quark:quilted_wool:7,100)
RandomBlock(-5,89,2,minecraft:wool:7,10,quark:quilted_wool:7,100)
RandomBlock(-5,89,3,minecraft:wool:7,10,quark:quilted_wool:7,100)
RandomBlock(-5,89,4,minecraft:wool:7,10,quark:quilted_wool:7,100)
RandomBlock(-5,89,5,minecraft:wool:7,10,quark:quilted_wool:7,100)
RandomBlock(-5,89,6,minecraft:wool:7,10,quark:quilted_wool:7,100)
RandomBlock(-5,89,7,minecraft:wool:7,10,quark:quilted_wool:7,100)
RandomBlock(-5,90,-5,minecraft:wool:7,10,quark:quilted_wool:7,100)
RandomBlock(-5,90,-4,minecraft:wool:7,10,quark:quilted_wool:7,100)
RandomBlock(-5,90,-3,minecraft:wool:7,10,quark:quilted_wool:7,100)
RandomBlock(-5,90,-2,minecraft:wool:7,10,quark:quilted_wool:7,100)
RandomBlock(-5,90,-1,minecraft:wool:7,10,quark:quilted_wool:7,100)
RandomBlock(-5,90,0,minecraft:wool:7,10,quark:quilted_wool:7,100)
RandomBlock(-5,90,1,minecraft:wool:7,10,quark:quilted_wool:7,100)
RandomBlock(-5,90,2,minecraft:wool:7,10,quark:quilted_wool:7,100)
RandomBlock(-5,90,3,minecraft:wool:7,10,quark:quilted_wool:7,100)
RandomBlock(-5,90,4,minecraft:wool:7,10,quark:quilted_wool:7,100)
RandomBlock(-5,90,5,minecraft:wool:7,10,quark:quilted_wool:7,100)
RandomBlock(-5,90,6,minecraft:wool:7,10,quark:quilted_wool:7,100)
RandomBlock(-5,90,7,minecraft:wool:7,10,quark:quilted_wool:7,100)
RandomBlock(-5,91,-6,minecraft:wool:7,10,quark:quilted_wool:7,100)
RandomBlock(-5,91,-5,minecraft:wool:7,10,quark:quilted_wool:7,100)
RandomBlock(-5,91,-4,minecraft:wool:7,10,quark:quilted_wool:7,100)
RandomBlock(-5,91,-3,minecraft:wool:7,10,quark:quilted_wool:7,100)
RandomBlock(-5,91,-2,minecraft:wool:7,10,quark:quilted_wool:7,100)
RandomBlock(-5,91,-1,minecraft:wool:7,10,quark:quilted_wool:7,100)
RandomBlock(-5,91,0,minecraft:wool:7,10,quark:quilted_wool:7,100)
RandomBlock(-5,91,1,minecraft:wool:7,10,quark:quilted_wool:7,100)
RandomBlock(-5,91,2,minecraft:wool:7,10,quark:quilted_wool:7,100)
RandomBlock(-5,91,3,minecraft:wool:7,10,quark:quilted_wool:7,100)
RandomBlock(-5,91,4,minecraft:wool:7,10,quark:quilted_wool:7,100)
RandomBlock(-5,91,5,minecraft:wool:7,10,quark:quilted_wool:7,100)
RandomBlock(-5,91,6,minecraft:wool:7,10,quark:quilted_wool:7,100)
RandomBlock(-5,91,7,minecraft:wool:7,10,quark:quilted_wool:7,100)
RandomBlock(-5,91,8,minecraft:wool:7,10,quark:quilted_wool:7,100)
RandomBlock(-5,92,-6,minecraft:wool:7,10,quark:quilted_wool:7,100)
RandomBlock(-5,92,-5,minecraft:wool:7,10,quark:quilted_wool:7,100)
RandomBlock(-5,92,-4,minecraft:wool:7,10,quark:quilted_wool:7,100)
RandomBlock(-5,92,-3,minecraft:wool:7,10,quark:quilted_wool:7,100)
RandomBlock(-5,92,-2,minecraft:wool:7,10,quark:quilted_wool:7,100)
RandomBlock(-5,92,-1,minecraft:wool:7,10,quark:quilted_wool:7,100)
RandomBlock(-5,92,0,minecraft:wool:7,10,quark:quilted_wool:7,100)
RandomBlock(-5,92,1,minecraft:wool:7,10,quark:quilted_wool:7,100)
RandomBlock(-5,92,2,minecraft:wool:7,10,quark:quilted_wool:7,100)
RandomBlock(-5,92,3,minecraft:wool:7,10,quark:quilted_wool:7,100)
RandomBlock(-5,92,4,minecraft:wool:7,10,quark:quilted_wool:7,100)
RandomBlock(-5,92,5,minecraft:wool:7,10,quark:quilted_wool:7,100)
RandomBlock(-5,92,6,minecraft:wool:7,10,quark:quilted_wool:7,100)
RandomBlock(-5,92,7,minecraft:wool:7,10,quark:quilted_wool:7,100)
RandomBlock(-5,92,8,minecraft:wool:7,10,quark:quilted_wool:7,100)
RandomBlock(-5,93,-6,minecraft:wool:7,10,quark:quilted_wool:7,100)
RandomBlock(-5,93,-5,minecraft:wool:7,10,quark:quilted_wool:7,100)
RandomBlock(-5,93,-4,minecraft:wool:7,10,quark:quilted_wool:7,100)
RandomBlock(-5,93,-3,minecraft:wool:7,10,quark:quilted_wool:7,100)
RandomBlock(-5,93,-2,minecraft:wool:7,10,quark:quilted_wool:7,100)
RandomBlock(-5,93,-1,minecraft:wool:7,10,quark:quilted_wool:7,100)
RandomBlock(-5,93,0,minecraft:wool:7,10,quark:quilted_wool:7,100)
RandomBlock(-5,93,1,minecraft:wool:7,10,quark:quilted_wool:7,100)
RandomBlock(-5,93,2,minecraft:wool:7,10,quark:quilted_wool:7,100)
RandomBlock(-5,93,3,minecraft:wool:7,10,quark:quilted_wool:7,100)
RandomBlock(-5,93,4,minecraft:wool:7,10,quark:quilted_wool:7,100)
RandomBlock(-5,93,5,minecraft:wool:7,10,quark:quilted_wool:7,100)
RandomBlock(-5,93,6,minecraft:wool:7,10,quark:quilted_wool:7,100)
RandomBlock(-5,93,7,minecraft:wool:7,10,quark:quilted_wool:7,100)
RandomBlock(-5,93,8,minecraft:wool:7,10,quark:quilted_wool:7,100)
RandomBlock(-5,94,-6,minecraft:wool:7,10,quark:quilted_wool:7,100)
RandomBlock(-5,94,-5,minecraft:wool:7,10,quark:quilted_wool:7,100)
RandomBlock(-5,94,-4,minecraft:wool:7,10,quark:quilted_wool:7,100)
RandomBlock(-5,94,-3,minecraft:wool:7,10,quark:quilted_wool:7,100)
RandomBlock(-5,94,-2,minecraft:wool:7,10,quark:quilted_wool:7,100)
RandomBlock(-5,94,-1,minecraft:wool:7,10,quark:quilted_wool:7,100)
RandomBlock(-5,94,0,minecraft:wool:7,10,quark:quilted_wool:7,100)
RandomBlock(-5,94,1,minecraft:wool:7,10,quark:quilted_wool:7,100)
RandomBlock(-5,94,2,minecraft:wool:7,10,quark:quilted_wool:7,100)
RandomBlock(-5,94,3,minecraft:wool:7,10,quark:quilted_wool:7,100)
RandomBlock(-5,94,4,minecraft:wool:7,10,quark:quilted_wool:7,100)
RandomBlock(-5,94,5,minecraft:wool:7,10,quark:quilted_wool:7,100)
RandomBlock(-5,94,6,minecraft:wool:7,10,quark:quilted_wool:7,100)
RandomBlock(-5,94,7,minecraft:wool:7,10,quark:quilted_wool:7,100)
RandomBlock(-5,94,8,minecraft:wool:7,10,quark:quilted_wool:7,100)
RandomBlock(-5,95,-6,minecraft:wool:7,10,quark:quilted_wool:7,100)
RandomBlock(-5,95,-5,minecraft:wool:7,10,quark:quilted_wool:7,100)
RandomBlock(-5,95,-4,minecraft:wool:7,10,quark:quilted_wool:7,100)
RandomBlock(-5,95,-3,minecraft:wool:7,10,quark:quilted_wool:7,100)
RandomBlock(-5,95,-2,minecraft:wool:7,10,quark:quilted_wool:7,100)
RandomBlock(-5,95,-1,minecraft:wool:7,10,quark:quilted_wool:7,100)
RandomBlock(-5,95,0,minecraft:wool:7,10,quark:quilted_wool:7,100)
RandomBlock(-5,95,1,minecraft:wool:7,10,quark:quilted_wool:7,100)
RandomBlock(-5,95,2,minecraft:wool:7,10,quark:quilted_wool:7,100)
RandomBlock(-5,95,3,minecraft:wool:7,10,quark:quilted_wool:7,100)
RandomBlock(-5,95,4,minecraft:wool:7,10,quark:quilted_wool:7,100)
RandomBlock(-5,95,5,minecraft:wool:7,10,quark:quilted_wool:7,100)
RandomBlock(-5,95,6,minecraft:wool:7,10,quark:quilted_wool:7,100)
RandomBlock(-5,95,7,minecraft:wool:7,10,quark:quilted_wool:7,100)
RandomBlock(-5,95,8,minecraft:wool:7,10,quark:quilted_wool:7,100)
RandomBlock(-5,96,-6,minecraft:wool:7,10,quark:quilted_wool:7,100)
RandomBlock(-5,96,-5,minecraft:wool:7,10,quark:quilted_wool:7,100)
RandomBlock(-5,96,-4,minecraft:wool:7,10,quark:quilted_wool:7,100)
RandomBlock(-5,96,-3,minecraft:wool:7,10,quark:quilted_wool:7,100)
RandomBlock(-5,96,-2,minecraft:wool:7,10,quark:quilted_wool:7,100)
RandomBlock(-5,96,-1,minecraft:wool:7,10,quark:quilted_wool:7,100)
RandomBlock(-5,96,0,minecraft:wool:7,10,quark:quilted_wool:7,100)
RandomBlock(-5,96,1,minecraft:wool:7,10,quark:quilted_wool:7,100)
RandomBlock(-5,96,2,minecraft:wool:7,10,quark:quilted_wool:7,100)
RandomBlock(-5,96,3,minecraft:wool:7,10,quark:quilted_wool:7,100)
RandomBlock(-5,96,4,minecraft:wool:7,10,quark:quilted_wool:7,100)
RandomBlock(-5,96,5,minecraft:wool:7,10,quark:quilted_wool:7,100)
RandomBlock(-5,96,6,minecraft:wool:7,10,quark:quilted_wool:7,100)
RandomBlock(-5,96,7,minecraft:wool:7,10,quark:quilted_wool:7,100)
RandomBlock(-5,96,8,minecraft:wool:7,10,quark:quilted_wool:7,100)
RandomBlock(-5,97,-6,minecraft:wool:7,10,quark:quilted_wool:7,100)
RandomBlock(-5,97,-5,minecraft:wool:7,10,quark:quilted_wool:7,100)
RandomBlock(-5,97,-4,minecraft:wool:7,10,quark:quilted_wool:7,100)
RandomBlock(-5,97,-3,minecraft:wool:7,10,quark:quilted_wool:7,100)
RandomBlock(-5,97,-2,minecraft:wool:7,10,quark:quilted_wool:7,100)
RandomBlock(-5,97,-1,minecraft:wool:7,10,quark:quilted_wool:7,100)
RandomBlock(-5,97,0,minecraft:wool:7,10,quark:quilted_wool:7,100)
RandomBlock(-5,97,1,minecraft:wool:7,10,quark:quilted_wool:7,100)
RandomBlock(-5,97,2,minecraft:wool:7,10,quark:quilted_wool:7,100)
RandomBlock(-5,97,3,minecraft:wool:7,10,quark:quilted_wool:7,100)
RandomBlock(-5,97,4,minecraft:wool:7,10,quark:quilted_wool:7,100)
RandomBlock(-5,97,5,minecraft:wool:7,10,quark:quilted_wool:7,100)
RandomBlock(-5,97,6,minecraft:wool:7,10,quark:quilted_wool:7,100)
RandomBlock(-5,97,7,minecraft:wool:7,10,quark:quilted_wool:7,100)
RandomBlock(-5,97,8,minecraft:wool:7,10,quark:quilted_wool:7,100)
RandomBlock(-5,98,-5,minecraft:wool:7,10,quark:quilted_wool:7,100)
RandomBlock(-5,98,-4,minecraft:wool:7,10,quark:quilted_wool:7,100)
RandomBlock(-5,98,-3,minecraft:wool:7,10,quark:quilted_wool:7,100)
RandomBlock(-5,98,-2,minecraft:wool:7,10,quark:quilted_wool:7,100)
RandomBlock(-5,98,-1,minecraft:wool:7,10,quark:quilted_wool:7,100)
RandomBlock(-5,98,0,minecraft:wool:7,10,quark:quilted_wool:7,100)
RandomBlock(-5,98,1,minecraft:wool:7,10,quark:quilted_wool:7,100)
RandomBlock(-5,98,2,minecraft:wool:7,10,quark:quilted_wool:7,100)
RandomBlock(-5,98,3,minecraft:wool:7,10,quark:quilted_wool:7,100)
RandomBlock(-5,98,4,minecraft:wool:7,10,quark:quilted_wool:7,100)
RandomBlock(-5,98,5,minecraft:wool:7,10,quark:quilted_wool:7,100)
RandomBlock(-5,98,6,minecraft:wool:7,10,quark:quilted_wool:7,100)
RandomBlock(-5,98,7,minecraft:wool:7,10,quark:quilted_wool:7,100)
RandomBlock(-5,99,-5,minecraft:wool:7,10,quark:quilted_wool:7,100)
RandomBlock(-5,99,-4,minecraft:wool:7,10,quark:quilted_wool:7,100)
RandomBlock(-5,99,-3,minecraft:wool:7,10,quark:quilted_wool:7,100)
RandomBlock(-5,99,-2,minecraft:wool:7,10,quark:quilted_wool:7,100)
RandomBlock(-5,99,-1,minecraft:wool:7,10,quark:quilted_wool:7,100)
RandomBlock(-5,99,0,minecraft:wool:7,10,quark:quilted_wool:7,100)
RandomBlock(-5,99,1,minecraft:wool:7,10,quark:quilted_wool:7,100)
RandomBlock(-5,99,2,minecraft:wool:7,10,quark:quilted_wool:7,100)
RandomBlock(-5,99,3,minecraft:wool:7,10,quark:quilted_wool:7,100)
RandomBlock(-5,99,4,minecraft:wool:7,10,quark:quilted_wool:7,100)
RandomBlock(-5,99,5,minecraft:wool:7,10,quark:quilted_wool:7,100)
RandomBlock(-5,99,6,minecraft:wool:7,10,quark:quilted_wool:7,100)
RandomBlock(-5,99,7,minecraft:wool:7,10,quark:quilted_wool:7,100)
RandomBlock(-5,100,-4,minecraft:wool:7,10,quark:quilted_wool:7,100)
RandomBlock(-5,100,-3,minecraft:wool:7,10,quark:quilted_wool:7,100)
RandomBlock(-5,100,-2,minecraft:wool:7,10,quark:quilted_wool:7,100)
RandomBlock(-5,100,-1,minecraft:wool:7,10,quark:quilted_wool:7,100)
RandomBlock(-5,100,0,minecraft:wool:7,10,quark:quilted_wool:7,100)
RandomBlock(-5,100,1,minecraft:wool:7,10,quark:quilted_wool:7,100)
RandomBlock(-5,100,2,minecraft:wool:7,10,quark:quilted_wool:7,100)
RandomBlock(-5,100,3,minecraft:wool:7,10,quark:quilted_wool:7,100)
RandomBlock(-5,100,4,minecraft:wool:7,10,quark:quilted_wool:7,100)
RandomBlock(-5,100,5,minecraft:wool:7,10,quark:quilted_wool:7,100)
RandomBlock(-5,100,6,minecraft:wool:7,10,quark:quilted_wool:7,100)
RandomBlock(-5,101,-3,minecraft:wool:7,10,quark:quilted_wool:7,100)
RandomBlock(-5,101,-2,minecraft:wool:7,10,quark:quilted_wool:7,100)
RandomBlock(-5,101,-1,minecraft:wool:7,10,quark:quilted_wool:7,100)
RandomBlock(-5,101,0,minecraft:wool:7,10,quark:quilted_wool:7,100)
RandomBlock(-5,101,1,minecraft:wool:7,10,quark:quilted_wool:7,100)
RandomBlock(-5,101,2,minecraft:wool:7,10,quark:quilted_wool:7,100)
RandomBlock(-5,101,3,minecraft:wool:7,10,quark:quilted_wool:7,100)
RandomBlock(-5,101,4,minecraft:wool:7,10,quark:quilted_wool:7,100)
RandomBlock(-5,101,5,minecraft:wool:7,10,quark:quilted_wool:7,100)
RandomBlock(-5,102,-2,minecraft:wool:7,10,quark:quilted_wool:7,100)
RandomBlock(-5,102,-1,minecraft:wool:7,10,quark:quilted_wool:7,100)
RandomBlock(-5,102,0,minecraft:wool:7,10,quark:quilted_wool:7,100)
RandomBlock(-5,102,1,minecraft:wool:7,10,quark:quilted_wool:7,100)
RandomBlock(-5,102,2,minecraft:wool:7,10,quark:quilted_wool:7,100)
RandomBlock(-5,102,3,minecraft:wool:7,10,quark:quilted_wool:7,100)
RandomBlock(-5,102,4,minecraft:wool:7,10,quark:quilted_wool:7,100)
RandomBlock(-5,103,0,minecraft:wool:7,10,quark:quilted_wool:7,100)
RandomBlock(-5,103,1,minecraft:wool:7,10,quark:quilted_wool:7,100)
RandomBlock(-5,103,2,minecraft:wool:7,10,quark:quilted_wool:7,100)
Block(-4,4,7,LOG:12)
Block(-4,4,8,LOG:12)
Block(-4,5,7,quark:leaf_carpet)
Block(-4,18,6,LOG:12)
Block(-4,18,7,LOG:12)
Block(-4,18,8,LOG:12)
Block(-4,19,5,LOG:12)
Block(-4,19,6,LOG:12)
Block(-4,19,7,LOG:12)
Block(-4,19,8,LOG:12)
Block(-4,20,6,LOG:12)
Block(-4,20,7,LOG:12)
Block(-4,20,8,LOG:12)
Block(-4,21,7,LOG:12)
Block(-4,22,7,quark:leaf_carpet)
Block(-4,28,4,WOOL:14)
Block(-4,28,5,WOOL:14)
Block(-4,28,6,WOOL:14)
Block(-4,29,3,WOOL:14)
Block(-4,29,4,WOOL:14)
Block(-4,29,5,WOOL:14)
Block(-4,29,6,WOOL:14)
Block(-4,29,7,WOOL:14)
Block(-4,30,2,WOOL:14)
Block(-4,30,3,WOOL:14)
Block(-4,30,4,WOOL:14)
Block(-4,30,5,WOOL:14)
Block(-4,30,6,WOOL:14)
Block(-4,30,7,WOOL:14)
Block(-4,30,8,WOOL:14)
Block(-4,31,2,WOOL:14)
Block(-4,31,3,WOOL:14)
Block(-4,31,4,WOOL:14)
Block(-4,31,5,WOOL:14)
Block(-4,31,6,WOOL:14)
Block(-4,31,7,WOOL:14)
Block(-4,31,8,WOOL:14)
Block(-4,32,1,WOOL:14)
Block(-4,32,2,WOOL:14)
Block(-4,32,3,WOOL:14)
Block(-4,32,4,WOOL:14)
Block(-4,32,5,WOOL:14)
Block(-4,32,6,WOOL:14)
Block(-4,32,7,WOOL:14)
Block(-4,32,8,WOOL:14)
Block(-4,33,1,WOOL:14)
Block(-4,33,2,WOOL:14)
Block(-4,33,3,WOOL:14)
Block(-4,33,4,WOOL:14)
Block(-4,33,5,WOOL:14)
Block(-4,33,6,WOOL:14)
Block(-4,33,7,WOOL:14)
Block(-4,33,8,WOOL:14)
Block(-4,34,1,WOOL:14)
Block(-4,34,2,WOOL:14)
Block(-4,34,3,WOOL:14)
Block(-4,34,4,WOOL:14)
Block(-4,34,5,WOOL:14)
Block(-4,34,6,WOOL:14)
Block(-4,34,7,WOOL:14)
Block(-4,34,8,WOOL:14)
Block(-4,35,1,WOOL:14)
Block(-4,35,2,WOOL:14)
Block(-4,35,3,WOOL:14)
Block(-4,35,4,WOOL:14)
Block(-4,35,5,WOOL:14)
Block(-4,35,6,WOOL:14)
Block(-4,35,7,WOOL:14)
Block(-4,35,8,WOOL:14)
Block(-4,36,1,WOOL:14)
Block(-4,36,2,WOOL:14)
Block(-4,36,3,WOOL:14)
Block(-4,36,4,WOOL:14)
Block(-4,36,5,WOOL:14)
Block(-4,36,6,WOOL:14)
Block(-4,36,7,WOOL:14)
Block(-4,36,8,WOOL:14)
Block(-4,37,2,WOOL:14)
Block(-4,37,3,WOOL:14)
Block(-4,37,4,WOOL:14)
Block(-4,37,5,WOOL:14)
Block(-4,37,6,WOOL:14)
Block(-4,37,7,WOOL:14)
Block(-4,37,8,WOOL:14)
Block(-4,38,2,WOOL:14)
Block(-4,38,3,WOOL:14)
Block(-4,38,4,WOOL:14)
Block(-4,38,5,WOOL:14)
Block(-4,38,6,WOOL:14)
Block(-4,38,7,WOOL:14)
Block(-4,38,8,WOOL:14)
Block(-4,39,3,WOOL:14)
Block(-4,39,4,WOOL:14)
Block(-4,39,5,WOOL:14)
Block(-4,39,6,WOOL:14)
Block(-4,39,7,WOOL:14)
Block(-4,40,4,WOOL:14)
Block(-4,40,5,WOOL:14)
Block(-4,40,6,WOOL:14)
Block(-4,54,8,LEAVES:0)
Block(-4,55,8,LEAVES:0)
Block(-4,56,7,LEAVES:0)
Block(-4,56,8,LEAVES:0)
Block(-4,57,7,LEAVES:0)
Block(-4,57,8,LEAVES:0)
Block(-4,65,5,LEAVES:0)
Block(-4,65,6,LEAVES:0)
Block(-4,65,7,LEAVES:0)
Block(-4,65,8,LOG:12)
Block(-4,66,6,LEAVES:0)
Block(-4,66,7,LOG:12)
Block(-4,66,8,LOG:12)
Block(-4,67,6,VINE:9)
Block(-4,67,7,LOG:12)
Block(-4,67,8,LOG:12)
Block(-4,68,6,VINE:9)
Block(-4,68,7,LOG:12)
Block(-4,68,8,LOG:12)
Block(-4,69,4,LEAVES:0)
Block(-4,69,5,LEAVES:0)
Block(-4,69,6,LEAVES:0)
Block(-4,69,7,LOG:12)
Block(-4,69,8,LOG:12)
Block(-4,70,4,LEAVES:0)
Block(-4,70,5,LEAVES:0)
Block(-4,70,6,LEAVES:0)
Block(-4,70,7,LOG:12)
Block(-4,70,8,LOG:12)
Block(-4,71,4,LEAVES:0)
Block(-4,71,5,LEAVES:0)
Block(-4,71,6,LEAVES:0)
Block(-4,71,7,LOG:12)
Block(-4,71,8,LOG:12)
Block(-4,72,5,LEAVES:0)
Block(-4,72,6,LEAVES:0)
Block(-4,72,7,LOG:12)
Block(-4,72,8,LOG:12)
Block(-4,73,6,LEAVES:0)
Block(-4,73,7,LOG:12)
Block(-4,73,8,LEAVES:0)
Block(-4,74,5,LEAVES:0)
Block(-4,74,6,LEAVES:0)
Block(-4,74,7,LEAVES:0)
Block(-4,74,8,LEAVES:0)
Block(-4,75,5,LEAVES:0)
Block(-4,75,6,LOG:12)
Block(-4,75,7,LEAVES:0)
Block(-4,75,8,LEAVES:0)
Block(-4,76,4,LEAVES:0)
Block(-4,76,5,LEAVES:0)
Block(-4,76,6,LEAVES:0)
Block(-4,76,7,LEAVES:0)
Block(-4,76,8,LEAVES:0)
Block(-4,77,3,LEAVES:0)
Block(-4,77,4,LEAVES:0)
Block(-4,77,5,LEAVES:0)
Block(-4,77,6,LEAVES:0)
Block(-4,77,7,LEAVES:0)
Block(-4,77,8,LEAVES:0)
Block(-4,78,3,LEAVES:0)
Block(-4,78,4,LEAVES:0)
Block(-4,78,5,LEAVES:0)
Block(-4,78,6,LEAVES:0)
Block(-4,78,7,LOG:12)
Block(-4,78,8,LEAVES:0)
Block(-4,79,4,LEAVES:0)
Block(-4,79,5,LEAVES:0)
Block(-4,79,6,LEAVES:0)
Block(-4,79,7,LEAVES:0)
Block(-4,79,8,LEAVES:0)
Block(-4,80,5,LEAVES:0)
Block(-4,80,6,LEAVES:0)
Block(-4,80,7,LEAVES:0)
Block(-4,80,8,LEAVES:0)
Block(-4,81,6,LEAVES:0)
Block(-4,81,7,LEAVES:0)
Block(-4,81,8,LEAVES:0)
RandomBlock(-4,85,-2,minecraft:wool:7,10,quark:quilted_wool:7,100)
RandomBlock(-4,85,-1,minecraft:wool:7,10,quark:quilted_wool:7,100)
RandomBlock(-4,85,0,minecraft:wool:7,10,quark:quilted_wool:7,100)
RandomBlock(-4,85,1,minecraft:wool:7,10,quark:quilted_wool:7,100)
RandomBlock(-4,85,2,minecraft:wool:7,10,quark:quilted_wool:7,100)
RandomBlock(-4,85,3,minecraft:wool:7,10,quark:quilted_wool:7,100)
RandomBlock(-4,85,4,minecraft:wool:7,10,quark:quilted_wool:7,100)
RandomBlock(-4,86,-3,minecraft:wool:7,10,quark:quilted_wool:7,100)
RandomBlock(-4,86,-2,minecraft:wool:7,10,quark:quilted_wool:7,100)
RandomBlock(-4,86,-1,minecraft:wool:7,10,quark:quilted_wool:7,100)
RandomBlock(-4,86,0,minecraft:wool:7,10,quark:quilted_wool:7,100)
RandomBlock(-4,86,1,minecraft:wool:7,10,quark:quilted_wool:7,100)
RandomBlock(-4,86,2,minecraft:wool:7,10,quark:quilted_wool:7,100)
RandomBlock(-4,86,3,minecraft:wool:7,10,quark:quilted_wool:7,100)
RandomBlock(-4,86,4,minecraft:wool:7,10,quark:quilted_wool:7,100)
RandomBlock(-4,86,5,minecraft:wool:7,10,quark:quilted_wool:7,100)
RandomBlock(-4,87,-4,minecraft:wool:7,10,quark:quilted_wool:7,100)
RandomBlock(-4,87,-3,minecraft:wool:7,10,quark:quilted_wool:7,100)
RandomBlock(-4,87,-2,minecraft:wool:7,10,quark:quilted_wool:7,100)
RandomBlock(-4,87,-1,minecraft:wool:7,10,quark:quilted_wool:7,100)
RandomBlock(-4,87,0,minecraft:wool:7,10,quark:quilted_wool:7,100)
RandomBlock(-4,87,1,minecraft:wool:7,10,quark:quilted_wool:7,100)
RandomBlock(-4,87,2,minecraft:wool:7,10,quark:quilted_wool:7,100)
RandomBlock(-4,87,3,minecraft:wool:7,10,quark:quilted_wool:7,100)
RandomBlock(-4,87,4,minecraft:wool:7,10,quark:quilted_wool:7,100)
RandomBlock(-4,87,5,minecraft:wool:7,10,quark:quilted_wool:7,100)
RandomBlock(-4,87,6,minecraft:wool:7,10,quark:quilted_wool:7,100)
RandomBlock(-4,88,-5,minecraft:wool:7,10,quark:quilted_wool:7,100)
RandomBlock(-4,88,-4,minecraft:wool:7,10,quark:quilted_wool:7,100)
RandomBlock(-4,88,-3,minecraft:wool:7,10,quark:quilted_wool:7,100)
RandomBlock(-4,88,-2,minecraft:wool:7,10,quark:quilted_wool:7,100)
RandomBlock(-4,88,-1,minecraft:wool:7,10,quark:quilted_wool:7,100)
RandomBlock(-4,88,0,minecraft:wool:7,10,quark:quilted_wool:7,100)
RandomBlock(-4,88,1,minecraft:wool:7,10,quark:quilted_wool:7,100)
RandomBlock(-4,88,2,minecraft:wool:7,10,quark:quilted_wool:7,100)
RandomBlock(-4,88,3,minecraft:wool:7,10,quark:quilted_wool:7,100)
RandomBlock(-4,88,4,minecraft:wool:7,10,quark:quilted_wool:7,100)
RandomBlock(-4,88,5,minecraft:wool:7,10,quark:quilted_wool:7,100)
RandomBlock(-4,88,6,minecraft:wool:7,10,quark:quilted_wool:7,100)
RandomBlock(-4,88,7,minecraft:wool:7,10,quark:quilted_wool:7,100)
RandomBlock(-4,89,-5,minecraft:wool:7,10,quark:quilted_wool:7,100)
RandomBlock(-4,89,-4,minecraft:wool:7,10,quark:quilted_wool:7,100)
RandomBlock(-4,89,-3,minecraft:wool:7,10,quark:quilted_wool:7,100)
RandomBlock(-4,89,-2,minecraft:wool:7,10,quark:quilted_wool:7,100)
RandomBlock(-4,89,-1,minecraft:wool:7,10,quark:quilted_wool:7,100)
RandomBlock(-4,89,0,minecraft:wool:7,10,quark:quilted_wool:7,100)
RandomBlock(-4,89,1,minecraft:wool:7,10,quark:quilted_wool:7,100)
RandomBlock(-4,89,2,minecraft:wool:7,10,quark:quilted_wool:7,100)
RandomBlock(-4,89,3,minecraft:wool:7,10,quark:quilted_wool:7,100)
RandomBlock(-4,89,4,minecraft:wool:7,10,quark:quilted_wool:7,100)
RandomBlock(-4,89,5,minecraft:wool:7,10,quark:quilted_wool:7,100)
RandomBlock(-4,89,6,minecraft:wool:7,10,quark:quilted_wool:7,100)
RandomBlock(-4,89,7,minecraft:wool:7,10,quark:quilted_wool:7,100)
RandomBlock(-4,90,-6,minecraft:wool:7,10,quark:quilted_wool:7,100)
RandomBlock(-4,90,-5,minecraft:wool:7,10,quark:quilted_wool:7,100)
RandomBlock(-4,90,-4,minecraft:wool:7,10,quark:quilted_wool:7,100)
RandomBlock(-4,90,-3,minecraft:wool:7,10,quark:quilted_wool:7,100)
RandomBlock(-4,90,-2,minecraft:wool:7,10,quark:quilted_wool:7,100)
RandomBlock(-4,90,-1,minecraft:wool:7,10,quark:quilted_wool:7,100)
RandomBlock(-4,90,0,minecraft:wool:7,10,quark:quilted_wool:7,100)
RandomBlock(-4,90,1,minecraft:wool:7,10,quark:quilted_wool:7,100)
RandomBlock(-4,90,2,minecraft:wool:7,10,quark:quilted_wool:7,100)
RandomBlock(-4,90,3,minecraft:wool:7,10,quark:quilted_wool:7,100)
RandomBlock(-4,90,4,minecraft:wool:7,10,quark:quilted_wool:7,100)
RandomBlock(-4,90,5,minecraft:wool:7,10,quark:quilted_wool:7,100)
RandomBlock(-4,90,6,minecraft:wool:7,10,quark:quilted_wool:7,100)
RandomBlock(-4,90,7,minecraft:wool:7,10,quark:quilted_wool:7,100)
RandomBlock(-4,90,8,minecraft:wool:7,10,quark:quilted_wool:7,100)
RandomBlock(-4,91,-6,minecraft:wool:7,10,quark:quilted_wool:7,100)
RandomBlock(-4,91,-5,minecraft:wool:7,10,quark:quilted_wool:7,100)
RandomBlock(-4,91,-4,minecraft:wool:7,10,quark:quilted_wool:7,100)
RandomBlock(-4,91,-3,minecraft:wool:7,10,quark:quilted_wool:7,100)
RandomBlock(-4,91,-2,minecraft:wool:7,10,quark:quilted_wool:7,100)
RandomBlock(-4,91,-1,minecraft:wool:7,10,quark:quilted_wool:7,100)
RandomBlock(-4,91,0,minecraft:wool:7,10,quark:quilted_wool:7,100)
RandomBlock(-4,91,1,minecraft:wool:7,10,quark:quilted_wool:7,100)
RandomBlock(-4,91,2,minecraft:wool:7,10,quark:quilted_wool:7,100)
RandomBlock(-4,91,3,minecraft:wool:7,10,quark:quilted_wool:7,100)
RandomBlock(-4,91,4,minecraft:wool:7,10,quark:quilted_wool:7,100)
RandomBlock(-4,91,5,minecraft:wool:7,10,quark:quilted_wool:7,100)
RandomBlock(-4,91,6,minecraft:wool:7,10,quark:quilted_wool:7,100)
RandomBlock(-4,91,7,minecraft:wool:7,10,quark:quilted_wool:7,100)
RandomBlock(-4,91,8,minecraft:wool:7,10,quark:quilted_wool:7,100)
RandomBlock(-4,92,-6,minecraft:wool:7,10,quark:quilted_wool:7,100)
RandomBlock(-4,92,-5,minecraft:wool:7,10,quark:quilted_wool:7,100)
RandomBlock(-4,92,-4,minecraft:wool:7,10,quark:quilted_wool:7,100)
RandomBlock(-4,92,-3,minecraft:wool:7,10,quark:quilted_wool:7,100)
RandomBlock(-4,92,-2,minecraft:wool:7,10,quark:quilted_wool:7,100)
RandomBlock(-4,92,-1,minecraft:wool:7,10,quark:quilted_wool:7,100)
RandomBlock(-4,92,0,minecraft:wool:7,10,quark:quilted_wool:7,100)
RandomBlock(-4,92,1,minecraft:wool:7,10,quark:quilted_wool:7,100)
RandomBlock(-4,92,2,minecraft:wool:7,10,quark:quilted_wool:7,100)
RandomBlock(-4,92,3,minecraft:wool:7,10,quark:quilted_wool:7,100)
RandomBlock(-4,92,4,minecraft:wool:7,10,quark:quilted_wool:7,100)
RandomBlock(-4,92,5,minecraft:wool:7,10,quark:quilted_wool:7,100)
RandomBlock(-4,92,6,minecraft:wool:7,10,quark:quilted_wool:7,100)
RandomBlock(-4,92,7,minecraft:wool:7,10,quark:quilted_wool:7,100)
RandomBlock(-4,92,8,minecraft:wool:7,10,quark:quilted_wool:7,100)
RandomBlock(-4,93,-6,minecraft:wool:7,10,quark:quilted_wool:7,100)
RandomBlock(-4,93,-5,minecraft:wool:7,10,quark:quilted_wool:7,100)
RandomBlock(-4,93,-4,minecraft:wool:7,10,quark:quilted_wool:7,100)
RandomBlock(-4,93,-3,minecraft:wool:7,10,quark:quilted_wool:7,100)
RandomBlock(-4,93,-2,minecraft:wool:7,10,quark:quilted_wool:7,100)
RandomBlock(-4,93,-1,minecraft:wool:7,10,quark:quilted_wool:7,100)
RandomBlock(-4,93,0,minecraft:wool:7,10,quark:quilted_wool:7,100)
RandomBlock(-4,93,1,minecraft:wool:7,10,quark:quilted_wool:7,100)
RandomBlock(-4,93,2,minecraft:wool:7,10,quark:quilted_wool:7,100)
RandomBlock(-4,93,3,minecraft:wool:7,10,quark:quilted_wool:7,100)
RandomBlock(-4,93,4,minecraft:wool:7,10,quark:quilted_wool:7,100)
RandomBlock(-4,93,5,minecraft:wool:7,10,quark:quilted_wool:7,100)
RandomBlock(-4,93,6,minecraft:wool:7,10,quark:quilted_wool:7,100)
RandomBlock(-4,93,7,minecraft:wool:7,10,quark:quilted_wool:7,100)
RandomBlock(-4,93,8,minecraft:wool:7,10,quark:quilted_wool:7,100)
RandomBlock(-4,94,-6,minecraft:wool:7,10,quark:quilted_wool:7,100)
RandomBlock(-4,94,-5,minecraft:wool:7,10,quark:quilted_wool:7,100)
RandomBlock(-4,94,-4,minecraft:wool:7,10,quark:quilted_wool:7,100)
RandomBlock(-4,94,-3,minecraft:wool:7,10,quark:quilted_wool:7,100)
RandomBlock(-4,94,-2,minecraft:wool:7,10,quark:quilted_wool:7,100)
RandomBlock(-4,94,-1,minecraft:wool:7,10,quark:quilted_wool:7,100)
RandomBlock(-4,94,0,minecraft:wool:7,10,quark:quilted_wool:7,100)
RandomBlock(-4,94,1,minecraft:wool:7,10,quark:quilted_wool:7,100)
RandomBlock(-4,94,2,minecraft:wool:7,10,quark:quilted_wool:7,100)
RandomBlock(-4,94,3,minecraft:wool:7,10,quark:quilted_wool:7,100)
RandomBlock(-4,94,4,minecraft:wool:7,10,quark:quilted_wool:7,100)
RandomBlock(-4,94,5,minecraft:wool:7,10,quark:quilted_wool:7,100)
RandomBlock(-4,94,6,minecraft:wool:7,10,quark:quilted_wool:7,100)
RandomBlock(-4,94,7,minecraft:wool:7,10,quark:quilted_wool:7,100)
RandomBlock(-4,94,8,minecraft:wool:7,10,quark:quilted_wool:7,100)
RandomBlock(-4,95,-6,minecraft:wool:7,10,quark:quilted_wool:7,100)
RandomBlock(-4,95,-5,minecraft:wool:7,10,quark:quilted_wool:7,100)
RandomBlock(-4,95,-4,minecraft:wool:7,10,quark:quilted_wool:7,100)
RandomBlock(-4,95,-3,minecraft:wool:7,10,quark:quilted_wool:7,100)
RandomBlock(-4,95,-2,minecraft:wool:7,10,quark:quilted_wool:7,100)
RandomBlock(-4,95,-1,minecraft:wool:7,10,quark:quilted_wool:7,100)
RandomBlock(-4,95,0,minecraft:wool:7,10,quark:quilted_wool:7,100)
RandomBlock(-4,95,1,minecraft:wool:7,10,quark:quilted_wool:7,100)
RandomBlock(-4,95,2,minecraft:wool:7,10,quark:quilted_wool:7,100)
RandomBlock(-4,95,3,minecraft:wool:7,10,quark:quilted_wool:7,100)
RandomBlock(-4,95,4,minecraft:wool:7,10,quark:quilted_wool:7,100)
RandomBlock(-4,95,5,minecraft:wool:7,10,quark:quilted_wool:7,100)
RandomBlock(-4,95,6,minecraft:wool:7,10,quark:quilted_wool:7,100)
RandomBlock(-4,95,7,minecraft:wool:7,10,quark:quilted_wool:7,100)
RandomBlock(-4,95,8,minecraft:wool:7,10,quark:quilted_wool:7,100)
RandomBlock(-4,96,-6,minecraft:wool:7,10,quark:quilted_wool:7,100)
RandomBlock(-4,96,-5,minecraft:wool:7,10,quark:quilted_wool:7,100)
RandomBlock(-4,96,-4,minecraft:wool:7,10,quark:quilted_wool:7,100)
RandomBlock(-4,96,-3,minecraft:wool:7,10,quark:quilted_wool:7,100)
RandomBlock(-4,96,-2,minecraft:wool:7,10,quark:quilted_wool:7,100)
RandomBlock(-4,96,-1,minecraft:wool:7,10,quark:quilted_wool:7,100)
RandomBlock(-4,96,0,minecraft:wool:7,10,quark:quilted_wool:7,100)
RandomBlock(-4,96,1,minecraft:wool:7,10,quark:quilted_wool:7,100)
RandomBlock(-4,96,2,minecraft:wool:7,10,quark:quilted_wool:7,100)
RandomBlock(-4,96,3,minecraft:wool:7,10,quark:quilted_wool:7,100)
RandomBlock(-4,96,4,minecraft:wool:7,10,quark:quilted_wool:7,100)
RandomBlock(-4,96,5,minecraft:wool:7,10,quark:quilted_wool:7,100)
RandomBlock(-4,96,6,minecraft:wool:7,10,quark:quilted_wool:7,100)
RandomBlock(-4,96,7,minecraft:wool:7,10,quark:quilted_wool:7,100)
RandomBlock(-4,96,8,minecraft:wool:7,10,quark:quilted_wool:7,100)
RandomBlock(-4,97,-6,minecraft:wool:7,10,quark:quilted_wool:7,100)
RandomBlock(-4,97,-5,minecraft:wool:7,10,quark:quilted_wool:7,100)
RandomBlock(-4,97,-4,minecraft:wool:7,10,quark:quilted_wool:7,100)
RandomBlock(-4,97,-3,minecraft:wool:7,10,quark:quilted_wool:7,100)
RandomBlock(-4,97,-2,minecraft:wool:7,10,quark:quilted_wool:7,100)
RandomBlock(-4,97,-1,minecraft:wool:7,10,quark:quilted_wool:7,100)
RandomBlock(-4,97,0,minecraft:wool:7,10,quark:quilted_wool:7,100)
RandomBlock(-4,97,1,minecraft:wool:7,10,quark:quilted_wool:7,100)
RandomBlock(-4,97,2,minecraft:wool:7,10,quark:quilted_wool:7,100)
RandomBlock(-4,97,3,minecraft:wool:7,10,quark:quilted_wool:7,100)
RandomBlock(-4,97,4,minecraft:wool:7,10,quark:quilted_wool:7,100)
RandomBlock(-4,97,5,minecraft:wool:7,10,quark:quilted_wool:7,100)
RandomBlock(-4,97,6,minecraft:wool:7,10,quark:quilted_wool:7,100)
RandomBlock(-4,97,7,minecraft:wool:7,10,quark:quilted_wool:7,100)
RandomBlock(-4,97,8,minecraft:wool:7,10,quark:quilted_wool:7,100)
RandomBlock(-4,98,-6,minecraft:wool:7,10,quark:quilted_wool:7,100)
RandomBlock(-4,98,-5,minecraft:wool:7,10,quark:quilted_wool:7,100)
RandomBlock(-4,98,-4,minecraft:wool:7,10,quark:quilted_wool:7,100)
RandomBlock(-4,98,-3,minecraft:wool:7,10,quark:quilted_wool:7,100)
RandomBlock(-4,98,-2,minecraft:wool:7,10,quark:quilted_wool:7,100)
RandomBlock(-4,98,-1,minecraft:wool:7,10,quark:quilted_wool:7,100)
RandomBlock(-4,98,0,minecraft:wool:7,10,quark:quilted_wool:7,100)
RandomBlock(-4,98,1,minecraft:wool:7,10,quark:quilted_wool:7,100)
RandomBlock(-4,98,2,minecraft:wool:7,10,quark:quilted_wool:7,100)
RandomBlock(-4,98,3,minecraft:wool:7,10,quark:quilted_wool:7,100)
RandomBlock(-4,98,4,minecraft:wool:7,10,quark:quilted_wool:7,100)
RandomBlock(-4,98,5,minecraft:wool:7,10,quark:quilted_wool:7,100)
RandomBlock(-4,98,6,minecraft:wool:7,10,quark:quilted_wool:7,100)
RandomBlock(-4,98,7,minecraft:wool:7,10,quark:quilted_wool:7,100)
RandomBlock(-4,98,8,minecraft:wool:7,10,quark:quilted_wool:7,100)
RandomBlock(-4,99,-5,minecraft:wool:7,10,quark:quilted_wool:7,100)
RandomBlock(-4,99,-4,minecraft:wool:7,10,quark:quilted_wool:7,100)
RandomBlock(-4,99,-3,minecraft:wool:7,10,quark:quilted_wool:7,100)
RandomBlock(-4,99,-2,minecraft:wool:7,10,quark:quilted_wool:7,100)
RandomBlock(-4,99,-1,minecraft:wool:7,10,quark:quilted_wool:7,100)
RandomBlock(-4,99,0,minecraft:wool:7,10,quark:quilted_wool:7,100)
RandomBlock(-4,99,1,minecraft:wool:7,10,quark:quilted_wool:7,100)
RandomBlock(-4,99,2,minecraft:wool:7,10,quark:quilted_wool:7,100)
RandomBlock(-4,99,3,minecraft:wool:7,10,quark:quilted_wool:7,100)
RandomBlock(-4,99,4,minecraft:wool:7,10,quark:quilted_wool:7,100)
RandomBlock(-4,99,5,minecraft:wool:7,10,quark:quilted_wool:7,100)
RandomBlock(-4,99,6,minecraft:wool:7,10,quark:quilted_wool:7,100)
RandomBlock(-4,99,7,minecraft:wool:7,10,quark:quilted_wool:7,100)
RandomBlock(-4,100,-5,minecraft:wool:7,10,quark:quilted_wool:7,100)
RandomBlock(-4,100,-4,minecraft:wool:7,10,quark:quilted_wool:7,100)
RandomBlock(-4,100,-3,minecraft:wool:7,10,quark:quilted_wool:7,100)
RandomBlock(-4,100,-2,minecraft:wool:7,10,quark:quilted_wool:7,100)
RandomBlock(-4,100,-1,minecraft:wool:7,10,quark:quilted_wool:7,100)
RandomBlock(-4,100,0,minecraft:wool:7,10,quark:quilted_wool:7,100)
RandomBlock(-4,100,1,minecraft:wool:7,10,quark:quilted_wool:7,100)
RandomBlock(-4,100,2,minecraft:wool:7,10,quark:quilted_wool:7,100)
RandomBlock(-4,100,3,minecraft:wool:7,10,quark:quilted_wool:7,100)
RandomBlock(-4,100,4,minecraft:wool:7,10,quark:quilted_wool:7,100)
RandomBlock(-4,100,5,minecraft:wool:7,10,quark:quilted_wool:7,100)
RandomBlock(-4,100,6,minecraft:wool:7,10,quark:quilted_wool:7,100)
RandomBlock(-4,100,7,minecraft:wool:7,10,quark:quilted_wool:7,100)
RandomBlock(-4,101,-4,minecraft:wool:7,10,quark:quilted_wool:7,100)
RandomBlock(-4,101,-3,minecraft:wool:7,10,quark:quilted_wool:7,100)
RandomBlock(-4,101,-2,minecraft:wool:7,10,quark:quilted_wool:7,100)
RandomBlock(-4,101,-1,minecraft:wool:7,10,quark:quilted_wool:7,100)
RandomBlock(-4,101,0,minecraft:wool:7,10,quark:quilted_wool:7,100)
RandomBlock(-4,101,1,minecraft:wool:7,10,quark:quilted_wool:7,100)
RandomBlock(-4,101,2,minecraft:wool:7,10,quark:quilted_wool:7,100)
RandomBlock(-4,101,3,minecraft:wool:7,10,quark:quilted_wool:7,100)
RandomBlock(-4,101,4,minecraft:wool:7,10,quark:quilted_wool:7,100)
RandomBlock(-4,101,5,minecraft:wool:7,10,quark:quilted_wool:7,100)
RandomBlock(-4,101,6,minecraft:wool:7,10,quark:quilted_wool:7,100)
RandomBlock(-4,102,-3,minecraft:wool:7,10,quark:quilted_wool:7,100)
RandomBlock(-4,102,-2,minecraft:wool:7,10,quark:quilted_wool:7,100)
RandomBlock(-4,102,-1,minecraft:wool:7,10,quark:quilted_wool:7,100)
RandomBlock(-4,102,0,minecraft:wool:7,10,quark:quilted_wool:7,100)
RandomBlock(-4,102,1,minecraft:wool:7,10,quark:quilted_wool:7,100)
RandomBlock(-4,102,2,minecraft:wool:7,10,quark:quilted_wool:7,100)
RandomBlock(-4,102,3,minecraft:wool:7,10,quark:quilted_wool:7,100)
RandomBlock(-4,102,4,minecraft:wool:7,10,quark:quilted_wool:7,100)
RandomBlock(-4,102,5,minecraft:wool:7,10,quark:quilted_wool:7,100)
RandomBlock(-4,103,-2,minecraft:wool:7,10,quark:quilted_wool:7,100)
RandomBlock(-4,103,-1,minecraft:wool:7,10,quark:quilted_wool:7,100)
RandomBlock(-4,103,0,minecraft:wool:7,10,quark:quilted_wool:7,100)
RandomBlock(-4,103,1,minecraft:wool:7,10,quark:quilted_wool:7,100)
RandomBlock(-4,103,2,minecraft:wool:7,10,quark:quilted_wool:7,100)
RandomBlock(-4,103,3,minecraft:wool:7,10,quark:quilted_wool:7,100)
RandomBlock(-4,103,4,minecraft:wool:7,10,quark:quilted_wool:7,100)
Block(-3,13,8,LOG:12)
Block(-3,14,8,LOG:12)
Block(-3,15,8,LOG:12)
Block(-3,16,7,LOG:12)
Block(-3,16,8,LOG:12)
Block(-3,17,8,LOG:12)
Block(-3,18,7,LOG:12)
Block(-3,18,8,LOG:12)
Block(-3,19,6,LOG:12)
Block(-3,19,7,LOG:12)
Block(-3,19,8,LOG:12)
Block(-3,20,6,LOG:12)
Block(-3,20,7,LOG:12)
Block(-3,20,8,LOG:12)
Block(-3,21,6,LOG:12)
Block(-3,21,7,LOG:12)
Block(-3,21,8,LOG:12)
Block(-3,22,8,quark:leaf_carpet)
Block(-3,29,3,WOOL:14)
Block(-3,29,4,WOOL:14)
Block(-3,29,5,WOOL:14)
Block(-3,29,6,WOOL:14)
Block(-3,29,7,WOOL:14)
Block(-3,30,3,WOOL:14)
Block(-3,30,4,WOOL:14)
Block(-3,30,5,WOOL:14)
Block(-3,30,6,WOOL:14)
Block(-3,30,7,WOOL:14)
Block(-3,31,2,WOOL:14)
Block(-3,31,3,WOOL:14)
Block(-3,31,4,WOOL:14)
Block(-3,31,5,WOOL:14)
Block(-3,31,6,WOOL:14)
Block(-3,31,7,WOOL:14)
Block(-3,31,8,WOOL:14)
Block(-3,32,2,WOOL:14)
Block(-3,32,3,WOOL:14)
Block(-3,32,4,WOOL:14)
Block(-3,32,5,WOOL:14)
Block(-3,32,6,WOOL:14)
Block(-3,32,7,WOOL:14)
Block(-3,32,8,WOOL:14)
Block(-3,33,2,WOOL:14)
Block(-3,33,3,WOOL:14)
Block(-3,33,4,WOOL:14)
Block(-3,33,5,WOOL:14)
Block(-3,33,6,WOOL:14)
Block(-3,33,7,WOOL:14)
Block(-3,33,8,WOOL:14)
Block(-3,34,1,WOOL:14)
Block(-3,34,2,WOOL:14)
Block(-3,34,3,WOOL:14)
Block(-3,34,4,WOOL:14)
Block(-3,34,5,WOOL:14)
Block(-3,34,6,WOOL:14)
Block(-3,34,7,WOOL:14)
Block(-3,34,8,WOOL:14)
Block(-3,35,2,WOOL:14)
Block(-3,35,3,WOOL:14)
Block(-3,35,4,WOOL:14)
Block(-3,35,5,WOOL:14)
Block(-3,35,6,WOOL:14)
Block(-3,35,7,WOOL:14)
Block(-3,35,8,WOOL:14)
Block(-3,36,2,WOOL:14)
Block(-3,36,3,WOOL:14)
Block(-3,36,4,WOOL:14)
Block(-3,36,5,WOOL:14)
Block(-3,36,6,WOOL:14)
Block(-3,36,7,WOOL:14)
Block(-3,36,8,WOOL:14)
Block(-3,37,2,WOOL:14)
Block(-3,37,3,WOOL:14)
Block(-3,37,4,WOOL:14)
Block(-3,37,5,WOOL:14)
Block(-3,37,6,WOOL:14)
Block(-3,37,7,WOOL:14)
Block(-3,37,8,WOOL:14)
Block(-3,38,3,WOOL:14)
Block(-3,38,4,WOOL:14)
Block(-3,38,5,WOOL:14)
Block(-3,38,6,WOOL:14)
Block(-3,38,7,WOOL:14)
Block(-3,39,3,WOOL:14)
Block(-3,39,4,WOOL:14)
Block(-3,39,5,WOOL:14)
Block(-3,39,6,WOOL:14)
Block(-3,39,7,WOOL:14)
Block(-3,47,5,VINE:1)
Block(-3,48,5,VINE:1)
Block(-3,49,5,VINE:1)
Block(-3,50,5,VINE:1)
Block(-3,50,8,WOOD_STEP:8)
Block(-3,51,5,VINE:1)
Block(-3,52,5,VINE:1)
Block(-3,53,5,VINE:1)
Block(-3,54,5,VINE:1)
Block(-3,54,8,LEAVES:0)
Block(-3,55,5,VINE:1)
Block(-3,55,8,LEAVES:0)
Block(-3,56,5,VINE:1)
Block(-3,56,7,LEAVES:0)
Block(-3,56,8,LEAVES:0)
Block(-3,57,5,VINE:1)
Block(-3,57,7,LEAVES:0)
Block(-3,57,8,LEAVES:0)
Block(-3,58,5,VINE:1)
Block(-3,59,5,VINE:1)
Block(-3,60,5,VINE:1)
Block(-3,61,5,VINE:1)
Block(-3,62,5,VINE:1)
Block(-3,63,5,VINE:1)
Block(-3,64,5,VINE:1)
Block(-3,64,7,LOG:12)
Block(-3,64,8,LOG:12)
Block(-3,65,5,VINE:1)
Block(-3,65,6,LOG:12)
Block(-3,65,7,LOG:12)
Block(-3,66,5,VINE:1)
Block(-3,66,6,LOG:12)
Block(-3,67,2,LEAVES:0)
Block(-3,67,3,LEAVES:0)
Block(-3,67,4,LEAVES:0)
Block(-3,67,5,VINE:1)
Block(-3,67,6,LOG:12)
Block(-3,68,1,LEAVES:0)
Block(-3,68,2,LEAVES:0)
Block(-3,68,3,LEAVES:0)
Block(-3,68,4,LEAVES:0)
Block(-3,68,5,VINE:1)
Block(-3,68,6,LOG:12)
Block(-3,68,8,LOG:12)
Block(-3,69,4,LEAVES:0)
Block(-3,69,5,LEAVES:0)
Block(-3,69,6,LOG:12)
Block(-3,69,7,LEAVES:0)
Block(-3,70,4,LEAVES:0)
Block(-3,70,5,LEAVES:0)
Block(-3,70,6,LOG:12)
Block(-3,70,7,LEAVES:0)
Block(-3,70,8,LOG:12)
Block(-3,71,4,LEAVES:0)
Block(-3,71,5,LEAVES:0)
Block(-3,71,6,LOG:12)
Block(-3,71,7,LEAVES:0)
Block(-3,71,8,LOG:12)
Block(-3,72,5,LEAVES:0)
Block(-3,72,6,LOG:12)
Block(-3,72,7,LEAVES:0)
Block(-3,72,8,LOG:12)
Block(-3,73,5,LEAVES:0)
Block(-3,73,6,LEAVES:0)
Block(-3,73,7,LEAVES:0)
Block(-3,73,8,LOG:12)
Block(-3,74,5,LEAVES:0)
Block(-3,74,6,LEAVES:0)
Block(-3,74,7,LOG:12)
Block(-3,74,8,LOG:12)
Block(-3,75,5,LEAVES:0)
Block(-3,75,6,LOG:12)
Block(-3,75,7,LEAVES:0)
Block(-3,75,8,LOG:12)
Block(-3,76,4,LEAVES:0)
Block(-3,76,5,LOG:12)
Block(-3,76,6,LEAVES:0)
Block(-3,76,7,LEAVES:0)
Block(-3,76,8,LEAVES:0)
Block(-3,77,3,LEAVES:0)
Block(-3,77,4,LEAVES:0)
Block(-3,77,5,LEAVES:0)
Block(-3,77,6,LOG:12)
Block(-3,77,7,LEAVES:0)
Block(-3,77,8,LEAVES:0)
Block(-3,78,3,LEAVES:0)
Block(-3,78,4,LEAVES:0)
Block(-3,78,5,LEAVES:0)
Block(-3,78,6,LEAVES:0)
Block(-3,78,7,LOG:12)
Block(-3,78,8,LEAVES:0)
Block(-3,79,4,LEAVES:0)
Block(-3,79,5,LEAVES:0)
Block(-3,79,6,LEAVES:0)
Block(-3,79,7,LEAVES:0)
Block(-3,79,8,LEAVES:0)
Block(-3,80,5,LEAVES:0)
Block(-3,80,6,LEAVES:0)
Block(-3,80,7,LEAVES:0)
Block(-3,80,8,LEAVES:0)
Block(-3,81,6,LEAVES:0)
Block(-3,81,7,LEAVES:0)
Block(-3,81,8,LEAVES:0)
Block(-3,82,8,LEAVES:0)
RandomBlock(-3,84,0,minecraft:wool:7,10,quark:quilted_wool:7,100)
RandomBlock(-3,84,1,minecraft:wool:7,10,quark:quilted_wool:7,100)
RandomBlock(-3,84,2,minecraft:wool:7,10,quark:quilted_wool:7,100)
RandomBlock(-3,85,-2,minecraft:wool:7,10,quark:quilted_wool:7,100)
RandomBlock(-3,85,-1,minecraft:wool:7,10,quark:quilted_wool:7,100)
RandomBlock(-3,85,0,minecraft:wool:7,10,quark:quilted_wool:7,100)
RandomBlock(-3,85,1,minecraft:wool:7,10,quark:quilted_wool:7,100)
RandomBlock(-3,85,2,minecraft:wool:7,10,quark:quilted_wool:7,100)
RandomBlock(-3,85,3,minecraft:wool:7,10,quark:quilted_wool:7,100)
RandomBlock(-3,85,4,minecraft:wool:7,10,quark:quilted_wool:7,100)
RandomBlock(-3,86,-4,minecraft:wool:7,10,quark:quilted_wool:7,100)
RandomBlock(-3,86,-3,minecraft:wool:7,10,quark:quilted_wool:7,100)
RandomBlock(-3,86,-2,minecraft:wool:7,10,quark:quilted_wool:7,100)
RandomBlock(-3,86,-1,minecraft:wool:7,10,quark:quilted_wool:7,100)
RandomBlock(-3,86,0,minecraft:wool:7,10,quark:quilted_wool:7,100)
RandomBlock(-3,86,1,minecraft:wool:7,10,quark:quilted_wool:7,100)
RandomBlock(-3,86,2,minecraft:wool:7,10,quark:quilted_wool:7,100)
RandomBlock(-3,86,3,minecraft:wool:7,10,quark:quilted_wool:7,100)
RandomBlock(-3,86,4,minecraft:wool:7,10,quark:quilted_wool:7,100)
RandomBlock(-3,86,5,minecraft:wool:7,10,quark:quilted_wool:7,100)
RandomBlock(-3,86,6,minecraft:wool:7,10,quark:quilted_wool:7,100)
RandomBlock(-3,87,-5,minecraft:wool:7,10,quark:quilted_wool:7,100)
RandomBlock(-3,87,-4,minecraft:wool:7,10,quark:quilted_wool:7,100)
RandomBlock(-3,87,-3,minecraft:wool:7,10,quark:quilted_wool:7,100)
RandomBlock(-3,87,-2,minecraft:wool:7,10,quark:quilted_wool:7,100)
RandomBlock(-3,87,-1,minecraft:wool:7,10,quark:quilted_wool:7,100)
RandomBlock(-3,87,0,minecraft:wool:7,10,quark:quilted_wool:7,100)
RandomBlock(-3,87,1,minecraft:wool:7,10,quark:quilted_wool:7,100)
RandomBlock(-3,87,2,minecraft:wool:7,10,quark:quilted_wool:7,100)
RandomBlock(-3,87,3,minecraft:wool:7,10,quark:quilted_wool:7,100)
RandomBlock(-3,87,4,minecraft:wool:7,10,quark:quilted_wool:7,100)
RandomBlock(-3,87,5,minecraft:wool:7,10,quark:quilted_wool:7,100)
RandomBlock(-3,87,6,minecraft:wool:7,10,quark:quilted_wool:7,100)
RandomBlock(-3,87,7,minecraft:wool:7,10,quark:quilted_wool:7,100)
RandomBlock(-3,88,-5,minecraft:wool:7,10,quark:quilted_wool:7,100)
RandomBlock(-3,88,-4,minecraft:wool:7,10,quark:quilted_wool:7,100)
RandomBlock(-3,88,-3,minecraft:wool:7,10,quark:quilted_wool:7,100)
RandomBlock(-3,88,-2,minecraft:wool:7,10,quark:quilted_wool:7,100)
RandomBlock(-3,88,-1,minecraft:wool:7,10,quark:quilted_wool:7,100)
RandomBlock(-3,88,0,minecraft:wool:7,10,quark:quilted_wool:7,100)
RandomBlock(-3,88,1,minecraft:wool:7,10,quark:quilted_wool:7,100)
RandomBlock(-3,88,2,minecraft:wool:7,10,quark:quilted_wool:7,100)
RandomBlock(-3,88,3,minecraft:wool:7,10,quark:quilted_wool:7,100)
RandomBlock(-3,88,4,minecraft:wool:7,10,quark:quilted_wool:7,100)
RandomBlock(-3,88,5,minecraft:wool:7,10,quark:quilted_wool:7,100)
RandomBlock(-3,88,6,minecraft:wool:7,10,quark:quilted_wool:7,100)
RandomBlock(-3,88,7,minecraft:wool:7,10,quark:quilted_wool:7,100)
RandomBlock(-3,89,-6,minecraft:wool:7,10,quark:quilted_wool:7,100)
RandomBlock(-3,89,-5,minecraft:wool:7,10,quark:quilted_wool:7,100)
RandomBlock(-3,89,-4,minecraft:wool:7,10,quark:quilted_wool:7,100)
RandomBlock(-3,89,-3,minecraft:wool:7,10,quark:quilted_wool:7,100)
RandomBlock(-3,89,-2,minecraft:wool:7,10,quark:quilted_wool:7,100)
RandomBlock(-3,89,-1,minecraft:wool:7,10,quark:quilted_wool:7,100)
RandomBlock(-3,89,0,minecraft:wool:7,10,quark:quilted_wool:7,100)
RandomBlock(-3,89,1,minecraft:wool:7,10,quark:quilted_wool:7,100)
RandomBlock(-3,89,2,minecraft:wool:7,10,quark:quilted_wool:7,100)
RandomBlock(-3,89,3,minecraft:wool:7,10,quark:quilted_wool:7,100)
RandomBlock(-3,89,4,minecraft:wool:7,10,quark:quilted_wool:7,100)
RandomBlock(-3,89,5,minecraft:wool:7,10,quark:quilted_wool:7,100)
RandomBlock(-3,89,6,minecraft:wool:7,10,quark:quilted_wool:7,100)
RandomBlock(-3,89,7,minecraft:wool:7,10,quark:quilted_wool:7,100)
RandomBlock(-3,89,8,minecraft:wool:7,10,quark:quilted_wool:7,100)
RandomBlock(-3,90,-6,minecraft:wool:7,10,quark:quilted_wool:7,100)
RandomBlock(-3,90,-5,minecraft:wool:7,10,quark:quilted_wool:7,100)
RandomBlock(-3,90,-4,minecraft:wool:7,10,quark:quilted_wool:7,100)
RandomBlock(-3,90,-3,minecraft:wool:7,10,quark:quilted_wool:7,100)
RandomBlock(-3,90,-2,minecraft:wool:7,10,quark:quilted_wool:7,100)
RandomBlock(-3,90,-1,minecraft:wool:7,10,quark:quilted_wool:7,100)
RandomBlock(-3,90,0,minecraft:wool:7,10,quark:quilted_wool:7,100)
RandomBlock(-3,90,1,minecraft:wool:7,10,quark:quilted_wool:7,100)
RandomBlock(-3,90,2,minecraft:wool:7,10,quark:quilted_wool:7,100)
RandomBlock(-3,90,3,minecraft:wool:7,10,quark:quilted_wool:7,100)
RandomBlock(-3,90,4,minecraft:wool:7,10,quark:quilted_wool:7,100)
RandomBlock(-3,90,5,minecraft:wool:7,10,quark:quilted_wool:7,100)
RandomBlock(-3,90,6,minecraft:wool:7,10,quark:quilted_wool:7,100)
RandomBlock(-3,90,7,minecraft:wool:7,10,quark:quilted_wool:7,100)
RandomBlock(-3,90,8,minecraft:wool:7,10,quark:quilted_wool:7,100)
RandomBlock(-3,91,-6,minecraft:wool:7,10,quark:quilted_wool:7,100)
RandomBlock(-3,91,-5,minecraft:wool:7,10,quark:quilted_wool:7,100)
RandomBlock(-3,91,-4,minecraft:wool:7,10,quark:quilted_wool:7,100)
RandomBlock(-3,91,-3,minecraft:wool:7,10,quark:quilted_wool:7,100)
RandomBlock(-3,91,-2,minecraft:wool:7,10,quark:quilted_wool:7,100)
RandomBlock(-3,91,-1,minecraft:wool:7,10,quark:quilted_wool:7,100)
RandomBlock(-3,91,0,minecraft:wool:7,10,quark:quilted_wool:7,100)
RandomBlock(-3,91,1,minecraft:wool:7,10,quark:quilted_wool:7,100)
RandomBlock(-3,91,2,minecraft:wool:7,10,quark:quilted_wool:7,100)
RandomBlock(-3,91,3,minecraft:wool:7,10,quark:quilted_wool:7,100)
RandomBlock(-3,91,4,minecraft:wool:7,10,quark:quilted_wool:7,100)
RandomBlock(-3,91,5,minecraft:wool:7,10,quark:quilted_wool:7,100)
RandomBlock(-3,91,6,minecraft:wool:7,10,quark:quilted_wool:7,100)
RandomBlock(-3,91,7,minecraft:wool:7,10,quark:quilted_wool:7,100)
RandomBlock(-3,91,8,minecraft:wool:7,10,quark:quilted_wool:7,100)
RandomBlock(-3,92,-7,minecraft:wool:7,10,quark:quilted_wool:7,100)
RandomBlock(-3,92,-6,minecraft:wool:7,10,quark:quilted_wool:7,100)
RandomBlock(-3,92,-5,minecraft:wool:7,10,quark:quilted_wool:7,100)
RandomBlock(-3,92,-4,minecraft:wool:7,10,quark:quilted_wool:7,100)
RandomBlock(-3,92,-3,minecraft:wool:7,10,quark:quilted_wool:7,100)
RandomBlock(-3,92,-2,minecraft:wool:7,10,quark:quilted_wool:7,100)
RandomBlock(-3,92,-1,minecraft:wool:7,10,quark:quilted_wool:7,100)
RandomBlock(-3,92,0,minecraft:wool:7,10,quark:quilted_wool:7,100)
RandomBlock(-3,92,1,minecraft:wool:7,10,quark:quilted_wool:7,100)
RandomBlock(-3,92,2,minecraft:wool:7,10,quark:quilted_wool:7,100)
RandomBlock(-3,92,3,minecraft:wool:7,10,quark:quilted_wool:7,100)
RandomBlock(-3,92,4,minecraft:wool:7,10,quark:quilted_wool:7,100)
RandomBlock(-3,92,5,minecraft:wool:7,10,quark:quilted_wool:7,100)
RandomBlock(-3,92,6,minecraft:wool:7,10,quark:quilted_wool:7,100)
RandomBlock(-3,92,7,minecraft:wool:7,10,quark:quilted_wool:7,100)
RandomBlock(-3,92,8,minecraft:wool:7,10,quark:quilted_wool:7,100)
RandomBlock(-3,93,-7,minecraft:wool:7,10,quark:quilted_wool:7,100)
RandomBlock(-3,93,-6,minecraft:wool:7,10,quark:quilted_wool:7,100)
RandomBlock(-3,93,-5,minecraft:wool:7,10,quark:quilted_wool:7,100)
RandomBlock(-3,93,-4,minecraft:wool:7,10,quark:quilted_wool:7,100)
RandomBlock(-3,93,-3,minecraft:wool:7,10,quark:quilted_wool:7,100)
RandomBlock(-3,93,-2,minecraft:wool:7,10,quark:quilted_wool:7,100)
RandomBlock(-3,93,-1,minecraft:wool:7,10,quark:quilted_wool:7,100)
RandomBlock(-3,93,0,minecraft:wool:7,10,quark:quilted_wool:7,100)
RandomBlock(-3,93,1,minecraft:wool:7,10,quark:quilted_wool:7,100)
RandomBlock(-3,93,2,minecraft:wool:7,10,quark:quilted_wool:7,100)
RandomBlock(-3,93,3,minecraft:wool:7,10,quark:quilted_wool:7,100)
RandomBlock(-3,93,4,minecraft:wool:7,10,quark:quilted_wool:7,100)
RandomBlock(-3,93,5,minecraft:wool:7,10,quark:quilted_wool:7,100)
RandomBlock(-3,93,6,minecraft:wool:7,10,quark:quilted_wool:7,100)
RandomBlock(-3,93,7,minecraft:wool:7,10,quark:quilted_wool:7,100)
RandomBlock(-3,93,8,minecraft:wool:7,10,quark:quilted_wool:7,100)
RandomBlock(-3,94,-7,minecraft:wool:7,10,quark:quilted_wool:7,100)
RandomBlock(-3,94,-6,minecraft:wool:7,10,quark:quilted_wool:7,100)
RandomBlock(-3,94,-5,minecraft:wool:7,10,quark:quilted_wool:7,100)
RandomBlock(-3,94,-4,minecraft:wool:7,10,quark:quilted_wool:7,100)
RandomBlock(-3,94,-3,minecraft:wool:7,10,quark:quilted_wool:7,100)
RandomBlock(-3,94,-2,minecraft:wool:7,10,quark:quilted_wool:7,100)
RandomBlock(-3,94,-1,minecraft:wool:7,10,quark:quilted_wool:7,100)
RandomBlock(-3,94,0,minecraft:wool:7,10,quark:quilted_wool:7,100)
RandomBlock(-3,94,1,minecraft:wool:7,10,quark:quilted_wool:7,100)
RandomBlock(-3,94,2,minecraft:wool:7,10,quark:quilted_wool:7,100)
RandomBlock(-3,94,3,minecraft:wool:7,10,quark:quilted_wool:7,100)
RandomBlock(-3,94,4,minecraft:wool:7,10,quark:quilted_wool:7,100)
RandomBlock(-3,94,5,minecraft:wool:7,10,quark:quilted_wool:7,100)
RandomBlock(-3,94,6,minecraft:wool:7,10,quark:quilted_wool:7,100)
RandomBlock(-3,94,7,minecraft:wool:7,10,quark:quilted_wool:7,100)
RandomBlock(-3,94,8,minecraft:wool:7,10,quark:quilted_wool:7,100)
RandomBlock(-3,95,-7,minecraft:wool:7,10,quark:quilted_wool:7,100)
RandomBlock(-3,95,-6,minecraft:wool:7,10,quark:quilted_wool:7,100)
RandomBlock(-3,95,-5,minecraft:wool:7,10,quark:quilted_wool:7,100)
RandomBlock(-3,95,-4,minecraft:wool:7,10,quark:quilted_wool:7,100)
RandomBlock(-3,95,-3,minecraft:wool:7,10,quark:quilted_wool:7,100)
RandomBlock(-3,95,-2,minecraft:wool:7,10,quark:quilted_wool:7,100)
RandomBlock(-3,95,-1,minecraft:wool:7,10,quark:quilted_wool:7,100)
RandomBlock(-3,95,0,minecraft:wool:7,10,quark:quilted_wool:7,100)
RandomBlock(-3,95,1,minecraft:wool:7,10,quark:quilted_wool:7,100)
RandomBlock(-3,95,2,minecraft:wool:7,10,quark:quilted_wool:7,100)
RandomBlock(-3,95,3,minecraft:wool:7,10,quark:quilted_wool:7,100)
RandomBlock(-3,95,4,minecraft:wool:7,10,quark:quilted_wool:7,100)
RandomBlock(-3,95,5,minecraft:wool:7,10,quark:quilted_wool:7,100)
RandomBlock(-3,95,6,minecraft:wool:7,10,quark:quilted_wool:7,100)
RandomBlock(-3,95,7,minecraft:wool:7,10,quark:quilted_wool:7,100)
RandomBlock(-3,95,8,minecraft:wool:7,10,quark:quilted_wool:7,100)
RandomBlock(-3,96,-7,minecraft:wool:7,10,quark:quilted_wool:7,100)
RandomBlock(-3,96,-6,minecraft:wool:7,10,quark:quilted_wool:7,100)
RandomBlock(-3,96,-5,minecraft:wool:7,10,quark:quilted_wool:7,100)
RandomBlock(-3,96,-4,minecraft:wool:7,10,quark:quilted_wool:7,100)
RandomBlock(-3,96,-3,minecraft:wool:7,10,quark:quilted_wool:7,100)
RandomBlock(-3,96,-2,minecraft:wool:7,10,quark:quilted_wool:7,100)
RandomBlock(-3,96,-1,minecraft:wool:7,10,quark:quilted_wool:7,100)
RandomBlock(-3,96,0,minecraft:wool:7,10,quark:quilted_wool:7,100)
RandomBlock(-3,96,1,minecraft:wool:7,10,quark:quilted_wool:7,100)
RandomBlock(-3,96,2,minecraft:wool:7,10,quark:quilted_wool:7,100)
RandomBlock(-3,96,3,minecraft:wool:7,10,quark:quilted_wool:7,100)
RandomBlock(-3,96,4,minecraft:wool:7,10,quark:quilted_wool:7,100)
RandomBlock(-3,96,5,minecraft:wool:7,10,quark:quilted_wool:7,100)
RandomBlock(-3,96,6,minecraft:wool:7,10,quark:quilted_wool:7,100)
RandomBlock(-3,96,7,minecraft:wool:7,10,quark:quilted_wool:7,100)
RandomBlock(-3,96,8,minecraft:wool:7,10,quark:quilted_wool:7,100)
RandomBlock(-3,97,-6,minecraft:wool:7,10,quark:quilted_wool:7,100)
RandomBlock(-3,97,-5,minecraft:wool:7,10,quark:quilted_wool:7,100)
RandomBlock(-3,97,-4,minecraft:wool:7,10,quark:quilted_wool:7,100)
RandomBlock(-3,97,-3,minecraft:wool:7,10,quark:quilted_wool:7,100)
RandomBlock(-3,97,-2,minecraft:wool:7,10,quark:quilted_wool:7,100)
RandomBlock(-3,97,-1,minecraft:wool:7,10,quark:quilted_wool:7,100)
RandomBlock(-3,97,0,minecraft:wool:7,10,quark:quilted_wool:7,100)
RandomBlock(-3,97,1,minecraft:wool:7,10,quark:quilted_wool:7,100)
RandomBlock(-3,97,2,minecraft:wool:7,10,quark:quilted_wool:7,100)
RandomBlock(-3,97,3,minecraft:wool:7,10,quark:quilted_wool:7,100)
RandomBlock(-3,97,4,minecraft:wool:7,10,quark:quilted_wool:7,100)
RandomBlock(-3,97,5,minecraft:wool:7,10,quark:quilted_wool:7,100)
RandomBlock(-3,97,6,minecraft:wool:7,10,quark:quilted_wool:7,100)
RandomBlock(-3,97,7,minecraft:wool:7,10,quark:quilted_wool:7,100)
RandomBlock(-3,97,8,minecraft:wool:7,10,quark:quilted_wool:7,100)
RandomBlock(-3,98,-6,minecraft:wool:7,10,quark:quilted_wool:7,100)
RandomBlock(-3,98,-5,minecraft:wool:7,10,quark:quilted_wool:7,100)
RandomBlock(-3,98,-4,minecraft:wool:7,10,quark:quilted_wool:7,100)
RandomBlock(-3,98,-3,minecraft:wool:7,10,quark:quilted_wool:7,100)
RandomBlock(-3,98,-2,minecraft:wool:7,10,quark:quilted_wool:7,100)
RandomBlock(-3,98,-1,minecraft:wool:7,10,quark:quilted_wool:7,100)
RandomBlock(-3,98,0,minecraft:wool:7,10,quark:quilted_wool:7,100)
RandomBlock(-3,98,1,minecraft:wool:7,10,quark:quilted_wool:7,100)
RandomBlock(-3,98,2,minecraft:wool:7,10,quark:quilted_wool:7,100)
RandomBlock(-3,98,3,minecraft:wool:7,10,quark:quilted_wool:7,100)
RandomBlock(-3,98,4,minecraft:wool:7,10,quark:quilted_wool:7,100)
RandomBlock(-3,98,5,minecraft:wool:7,10,quark:quilted_wool:7,100)
RandomBlock(-3,98,6,minecraft:wool:7,10,quark:quilted_wool:7,100)
RandomBlock(-3,98,7,minecraft:wool:7,10,quark:quilted_wool:7,100)
RandomBlock(-3,98,8,minecraft:wool:7,10,quark:quilted_wool:7,100)
RandomBlock(-3,99,-6,minecraft:wool:7,10,quark:quilted_wool:7,100)
RandomBlock(-3,99,-5,minecraft:wool:7,10,quark:quilted_wool:7,100)
RandomBlock(-3,99,-4,minecraft:wool:7,10,quark:quilted_wool:7,100)
RandomBlock(-3,99,-3,minecraft:wool:7,10,quark:quilted_wool:7,100)
RandomBlock(-3,99,-2,minecraft:wool:7,10,quark:quilted_wool:7,100)
RandomBlock(-3,99,-1,minecraft:wool:7,10,quark:quilted_wool:7,100)
RandomBlock(-3,99,0,minecraft:wool:7,10,quark:quilted_wool:7,100)
RandomBlock(-3,99,1,minecraft:wool:7,10,quark:quilted_wool:7,100)
RandomBlock(-3,99,2,minecraft:wool:7,10,quark:quilted_wool:7,100)
RandomBlock(-3,99,3,minecraft:wool:7,10,quark:quilted_wool:7,100)
RandomBlock(-3,99,4,minecraft:wool:7,10,quark:quilted_wool:7,100)
RandomBlock(-3,99,5,minecraft:wool:7,10,quark:quilted_wool:7,100)
RandomBlock(-3,99,6,minecraft:wool:7,10,quark:quilted_wool:7,100)
RandomBlock(-3,99,7,minecraft:wool:7,10,quark:quilted_wool:7,100)
RandomBlock(-3,99,8,minecraft:wool:7,10,quark:quilted_wool:7,100)
RandomBlock(-3,100,-5,minecraft:wool:7,10,quark:quilted_wool:7,100)
RandomBlock(-3,100,-4,minecraft:wool:7,10,quark:quilted_wool:7,100)
RandomBlock(-3,100,-3,minecraft:wool:7,10,quark:quilted_wool:7,100)
RandomBlock(-3,100,-2,minecraft:wool:7,10,quark:quilted_wool:7,100)
RandomBlock(-3,100,-1,minecraft:wool:7,10,quark:quilted_wool:7,100)
RandomBlock(-3,100,0,minecraft:wool:7,10,quark:quilted_wool:7,100)
RandomBlock(-3,100,1,minecraft:wool:7,10,quark:quilted_wool:7,100)
RandomBlock(-3,100,2,minecraft:wool:7,10,quark:quilted_wool:7,100)
RandomBlock(-3,100,3,minecraft:wool:7,10,quark:quilted_wool:7,100)
RandomBlock(-3,100,4,minecraft:wool:7,10,quark:quilted_wool:7,100)
RandomBlock(-3,100,5,minecraft:wool:7,10,quark:quilted_wool:7,100)
RandomBlock(-3,100,6,minecraft:wool:7,10,quark:quilted_wool:7,100)
RandomBlock(-3,100,7,minecraft:wool:7,10,quark:quilted_wool:7,100)
RandomBlock(-3,101,-5,minecraft:wool:7,10,quark:quilted_wool:7,100)
RandomBlock(-3,101,-4,minecraft:wool:7,10,quark:quilted_wool:7,100)
RandomBlock(-3,101,-3,minecraft:wool:7,10,quark:quilted_wool:7,100)
RandomBlock(-3,101,-2,minecraft:wool:7,10,quark:quilted_wool:7,100)
RandomBlock(-3,101,-1,minecraft:wool:7,10,quark:quilted_wool:7,100)
RandomBlock(-3,101,0,minecraft:wool:7,10,quark:quilted_wool:7,100)
RandomBlock(-3,101,1,minecraft:wool:7,10,quark:quilted_wool:7,100)
RandomBlock(-3,101,2,minecraft:wool:7,10,quark:quilted_wool:7,100)
RandomBlock(-3,101,3,minecraft:wool:7,10,quark:quilted_wool:7,100)
RandomBlock(-3,101,4,minecraft:wool:7,10,quark:quilted_wool:7,100)
RandomBlock(-3,101,5,minecraft:wool:7,10,quark:quilted_wool:7,100)
RandomBlock(-3,101,6,minecraft:wool:7,10,quark:quilted_wool:7,100)
RandomBlock(-3,101,7,minecraft:wool:7,10,quark:quilted_wool:7,100)
RandomBlock(-3,102,-4,minecraft:wool:7,10,quark:quilted_wool:7,100)
RandomBlock(-3,102,-3,minecraft:wool:7,10,quark:quilted_wool:7,100)
RandomBlock(-3,102,-2,minecraft:wool:7,10,quark:quilted_wool:7,100)
RandomBlock(-3,102,-1,minecraft:wool:7,10,quark:quilted_wool:7,100)
RandomBlock(-3,102,0,minecraft:wool:7,10,quark:quilted_wool:7,100)
RandomBlock(-3,102,1,minecraft:wool:7,10,quark:quilted_wool:7,100)
RandomBlock(-3,102,2,minecraft:wool:7,10,quark:quilted_wool:7,100)
