
#######################################################################
# +-----------------------------------------------------------------+ #
# |                            BO4 object                           | #
# +-----------------------------------------------------------------+ #
#######################################################################

Author: NLBlackEagle

Description: No description given

SettingsMode: WriteDisable


#######################################################################
# +-----------------------------------------------------------------+ #
# |                          Main settings                          | #
# +-----------------------------------------------------------------+ #
#######################################################################

FixedRotation: 

Frequency: 0

SpawnHeight: highestBlock

UseCenterForHighestBlock: true

##############################
# Height Limits for the BO4. #
##############################

MinHeight: 0

MaxHeight: 255

InheritBO3: 

InheritBO3Rotation: NORTH

OverrideChildSettings: true

OverrideParentHeight: false

CanOverride: false

BranchFrequency: 0

BranchFrequencyGroup: 

MustBeBelowOther: false

MustBeInside: 

CannotBeInside: 

ReplacesBO3: 

MustBeInsideWorldBorders: false

CanSpawnOnWater: true

SpawnOnWaterOnly: false

SpawnUnderWater: false

SpawnAtWaterLevel: false

HeightOffset: 0

RemoveAir: true

ReplaceAbove: 

ReplaceBelow: 

ReplaceWithBiomeBlocks: true

ReplaceWithSurfaceBlock: GRASS

ReplaceWithGroundBlock: DIRT

ReplaceWithStoneBlock: STONE

SmoothRadius: 0

SmoothHeightOffset: 0

SmoothStartTop: false

SmoothStartWood: false

SmoothingSurfaceBlock: 

SmoothingGroundBlock: 

BO3Group: 

IsSpawnPoint: false

DoReplaceBlocks: true


#######################################################################
# +-----------------------------------------------------------------+ #
# |                              Blocks                             | #
# +-----------------------------------------------------------------+ #
#######################################################################

Block(-5,5,5,LOG:12)
Block(-5,6,5,quark:leaf_carpet)
Block(-4,5,5,LOG:12)
Block(-4,5,6,LOG:12)
Block(-4,6,5,quark:leaf_carpet)
Block(-4,6,6,LOG:12)
Block(-4,7,6,LOG:12)
Block(-4,8,6,LOG:12)
Block(-4,9,6,quark:leaf_carpet)
RandomBlock(-4,29,8,minecraft:wool:7,10,quark:quilted_wool:7,100)
RandomBlock(-4,30,8,minecraft:wool:7,10,quark:quilted_wool:7,100)
RandomBlock(-4,31,8,minecraft:wool:7,10,quark:quilted_wool:7,100)
RandomBlock(-4,32,8,minecraft:wool:7,10,quark:quilted_wool:7,100)
RandomBlock(-4,33,8,minecraft:wool:7,10,quark:quilted_wool:7,100)
Block(-3,7,6,LOG:12)
Block(-3,8,6,LOG:12)
Block(-3,9,6,LOG:12)
Block(-3,9,7,LOG:12)
Block(-3,10,6,LOG:12)
Block(-3,10,7,LOG:12)
Block(-3,11,6,quark:leaf_carpet)
Block(-3,11,7,LOG:12)
Block(-3,12,7,LOG:12)
Block(-3,12,8,LOG:12)
Block(-3,13,7,quark:leaf_carpet)
RandomBlock(-3,28,8,minecraft:wool:7,10,quark:quilted_wool:7,100)
RandomBlock(-3,29,8,minecraft:wool:7,10,quark:quilted_wool:7,100)
RandomBlock(-3,30,8,minecraft:wool:7,10,quark:quilted_wool:7,100)
RandomBlock(-3,31,7,minecraft:wool:7,10,quark:quilted_wool:7,100)
RandomBlock(-3,31,8,minecraft:wool:7,10,quark:quilted_wool:7,100)
RandomBlock(-3,32,8,minecraft:wool:7,10,quark:quilted_wool:7,100)
RandomBlock(-3,33,8,minecraft:wool:7,10,quark:quilted_wool:7,100)
RandomBlock(-3,34,8,minecraft:wool:7,10,quark:quilted_wool:7,100)
Block(-2,10,7,LOG:12)
Block(-2,11,7,LOG:12)
Block(-2,12,7,LOG:12)
Block(-2,12,8,LOG:12)
Block(-2,13,7,LOG:12)
Block(-2,13,8,LOG:12)
Block(-2,14,7,quark:leaf_carpet)
Block(-2,14,8,LOG:12)
Block(-2,15,8,LOG:12)
Block(-2,16,8,quark:leaf_carpet)
RandomBlock(-2,27,8,minecraft:wool:7,10,quark:quilted_wool:7,100)
RandomBlock(-2,28,8,minecraft:wool:7,10,quark:quilted_wool:7,100)
RandomBlock(-2,29,7,minecraft:wool:7,10,quark:quilted_wool:7,100)
RandomBlock(-2,29,8,minecraft:wool:7,10,quark:quilted_wool:7,100)
RandomBlock(-2,30,7,minecraft:wool:7,10,quark:quilted_wool:7,100)
RandomBlock(-2,30,8,minecraft:wool:7,10,quark:quilted_wool:7,100)
RandomBlock(-2,31,7,minecraft:wool:7,10,quark:quilted_wool:7,100)
RandomBlock(-2,31,8,minecraft:wool:7,10,quark:quilted_wool:7,100)
RandomBlock(-2,32,7,minecraft:wool:7,10,quark:quilted_wool:7,100)
RandomBlock(-2,32,8,minecraft:wool:7,10,quark:quilted_wool:7,100)
RandomBlock(-2,33,7,minecraft:wool:7,10,quark:quilted_wool:7,100)
RandomBlock(-2,33,8,minecraft:wool:7,10,quark:quilted_wool:7,100)
RandomBlock(-2,34,8,minecraft:wool:7,10,quark:quilted_wool:7,100)
RandomBlock(-2,35,8,minecraft:wool:7,10,quark:quilted_wool:7,100)
Block(-1,13,8,LOG:12)
Block(-1,14,8,LOG:12)
Block(-1,15,8,LOG:12)
Block(-1,16,8,LOG:12)
Block(-1,17,8,quark:leaf_carpet)
RandomBlock(-1,27,8,minecraft:wool:7,10,quark:quilted_wool:7,100)
RandomBlock(-1,28,8,minecraft:wool:7,10,quark:quilted_wool:7,100)
RandomBlock(-1,29,7,minecraft:wool:7,10,quark:quilted_wool:7,100)
RandomBlock(-1,29,8,minecraft:wool:7,10,quark:quilted_wool:7,100)
RandomBlock(-1,30,7,minecraft:wool:7,10,quark:quilted_wool:7,100)
RandomBlock(-1,30,8,minecraft:wool:7,10,quark:quilted_wool:7,100)
RandomBlock(-1,31,7,minecraft:wool:7,10,quark:quilted_wool:7,100)
RandomBlock(-1,31,8,minecraft:wool:7,10,quark:quilted_wool:7,100)
RandomBlock(-1,32,7,minecraft:wool:7,10,quark:quilted_wool:7,100)
RandomBlock(-1,32,8,minecraft:wool:7,10,quark:quilted_wool:7,100)
RandomBlock(-1,33,7,minecraft:wool:7,10,quark:quilted_wool:7,100)
RandomBlock(-1,33,8,minecraft:wool:7,10,quark:quilted_wool:7,100)
RandomBlock(-1,34,8,minecraft:wool:7,10,quark:quilted_wool:7,100)
RandomBlock(-1,35,8,minecraft:wool:7,10,quark:quilted_wool:7,100)
Block(-1,83,8,WOOL:14)
Block(-1,84,8,WOOL:14)
Block(-1,85,8,WOOL:14)
Block(0,15,8,LOG:12)
RandomBlock(0,27,8,minecraft:wool:7,10,quark:quilted_wool:7,100)
RandomBlock(0,28,8,minecraft:wool:7,10,quark:quilted_wool:7,100)
RandomBlock(0,29,7,minecraft:wool:7,10,quark:quilted_wool:7,100)
RandomBlock(0,29,8,minecraft:wool:7,10,quark:quilted_wool:7,100)
RandomBlock(0,30,7,minecraft:wool:7,10,quark:quilted_wool:7,100)
RandomBlock(0,30,8,minecraft:wool:7,10,quark:quilted_wool:7,100)
RandomBlock(0,31,7,minecraft:wool:7,10,quark:quilted_wool:7,100)
RandomBlock(0,31,8,minecraft:wool:7,10,quark:quilted_wool:7,100)
RandomBlock(0,32,7,minecraft:wool:7,10,quark:quilted_wool:7,100)
RandomBlock(0,32,8,minecraft:wool:7,10,quark:quilted_wool:7,100)
RandomBlock(0,33,7,minecraft:wool:7,10,quark:quilted_wool:7,100)
RandomBlock(0,33,8,minecraft:wool:7,10,quark:quilted_wool:7,100)
RandomBlock(0,34,8,minecraft:wool:7,10,quark:quilted_wool:7,100)
RandomBlock(0,35,8,minecraft:wool:7,10,quark:quilted_wool:7,100)
Block(0,82,8,WOOL:14)
Block(0,83,8,WOOL:14)
Block(0,84,8,WOOL:14)
Block(0,85,8,WOOL:14)
Block(0,86,8,WOOL:14)
RandomBlock(1,28,8,minecraft:wool:7,10,quark:quilted_wool:7,100)
RandomBlock(1,29,8,minecraft:wool:7,10,quark:quilted_wool:7,100)
RandomBlock(1,30,8,minecraft:wool:7,10,quark:quilted_wool:7,100)
RandomBlock(1,31,7,minecraft:wool:7,10,quark:quilted_wool:7,100)
RandomBlock(1,31,8,minecraft:wool:7,10,quark:quilted_wool:7,100)
RandomBlock(1,32,8,minecraft:wool:7,10,quark:quilted_wool:7,100)
RandomBlock(1,33,8,minecraft:wool:7,10,quark:quilted_wool:7,100)
RandomBlock(1,34,8,minecraft:wool:7,10,quark:quilted_wool:7,100)
Block(1,83,8,WOOL:14)
Block(1,84,8,WOOL:14)
Block(1,85,8,WOOL:14)
Block(2,9,8,LEAVES:0)
RandomBlock(2,29,8,minecraft:wool:7,10,quark:quilted_wool:7,100)
RandomBlock(2,30,8,minecraft:wool:7,10,quark:quilted_wool:7,100)
RandomBlock(2,31,8,minecraft:wool:7,10,quark:quilted_wool:7,100)
RandomBlock(2,32,8,minecraft:wool:7,10,quark:quilted_wool:7,100)
RandomBlock(2,33,8,minecraft:wool:7,10,quark:quilted_wool:7,100)
Block(4,12,8,LEAVES:0)
Block(6,9,4,LOG:12)
Block(6,10,3,LOG:12)
Block(6,10,4,LOG:12)
Block(6,10,5,LOG:12)
Block(6,11,2,LOG:12)
Block(6,11,3,LOG:12)
Block(6,11,4,LOG:12)
Block(6,11,5,LOG:12)
Block(6,12,2,LOG:12)
Block(6,12,3,LOG:12)
Block(6,12,4,LOG:12)
Block(6,13,3,LOG:12)
Block(6,13,4,LOG:12)
Block(6,13,5,LOG:12)
Block(6,14,4,LOG:12)
Block(6,14,5,LOG:12)
Block(6,14,6,LOG:12)
Block(6,15,4,quark:leaf_carpet)
Block(6,15,5,LOG:12)
Block(7,7,3,LOG:12)
Block(7,7,4,LOG:12)
Block(7,8,2,LOG:12)
Block(7,8,3,LOG:12)
Block(7,8,4,LOG:12)
Block(7,9,2,LOG:12)
Block(7,9,3,LOG:12)
Block(7,9,4,LOG:12)
Block(7,9,5,LOG:12)
Block(7,10,2,LOG:12)
Block(7,10,3,LOG:12)
Block(7,10,4,LOG:12)
Block(7,10,5,LOG:12)
Block(7,11,2,LOG:12)
Block(7,11,3,LOG:12)
Block(7,11,4,LOG:12)
Block(7,11,5,LOG:12)
Block(7,12,2,LOG:12)
Block(7,12,3,LOG:12)
Block(7,12,4,LOG:12)
Block(7,12,5,LOG:12)
Block(7,13,2,LOG:12)
Block(7,13,3,LOG:12)
Block(7,13,4,LOG:12)
Block(7,13,5,LOG:12)
Block(7,13,6,LOG:12)
Block(7,14,2,quark:leaf_carpet)
Block(7,14,3,LOG:12)
Block(7,14,4,LOG:12)
Block(7,14,5,LOG:12)
Block(7,14,6,LOG:12)
Block(7,15,4,LOG:12)
Block(7,15,5,LOG:12)
Block(7,15,6,LOG:12)
Block(7,16,4,quark:leaf_carpet)
Block(7,16,5,LOG:12)
Block(7,16,6,LOG:12)
Block(7,16,7,LOG:12)
Block(7,17,5,quark:leaf_carpet)
Block(7,17,6,LOG:12)
Block(7,32,4,WOOL:14)
Block(7,32,5,WOOL:14)
Block(7,32,6,WOOL:14)
Block(7,33,4,WOOL:14)
Block(7,33,5,WOOL:14)
Block(7,33,6,WOOL:14)
Block(7,34,3,WOOL:14)
Block(7,34,4,WOOL:14)
Block(7,34,5,WOOL:14)
Block(7,34,6,WOOL:14)
Block(7,34,7,WOOL:14)
Block(7,35,4,WOOL:14)
Block(7,35,5,WOOL:14)
Block(7,35,6,WOOL:14)
Block(7,36,4,WOOL:14)
Block(7,36,5,WOOL:14)
Block(7,36,6,WOOL:14)
Block(7,66,8,LEAVES:0)
Block(7,67,8,LEAVES:0)
Block(7,73,8,VINE:1)
Block(7,76,8,LEAVES:0)
Block(7,77,8,LEAVES:0)
RandomBlock(7,91,0,minecraft:wool:7,10,quark:quilted_wool:7,100)
RandomBlock(7,91,1,minecraft:wool:7,10,quark:quilted_wool:7,100)
RandomBlock(7,91,2,minecraft:wool:7,10,quark:quilted_wool:7,100)
RandomBlock(7,92,-1,minecraft:wool:7,10,quark:quilted_wool:7,100)
RandomBlock(7,92,0,minecraft:wool:7,10,quark:quilted_wool:7,100)
RandomBlock(7,92,1,minecraft:wool:7,10,quark:quilted_wool:7,100)
RandomBlock(7,92,2,minecraft:wool:7,10,quark:quilted_wool:7,100)
RandomBlock(7,92,3,minecraft:wool:7,10,quark:quilted_wool:7,100)
RandomBlock(7,93,-1,minecraft:wool:7,10,quark:quilted_wool:7,100)
RandomBlock(7,93,0,minecraft:wool:7,10,quark:quilted_wool:7,100)
RandomBlock(7,93,1,minecraft:wool:7,10,quark:quilted_wool:7,100)
RandomBlock(7,93,2,minecraft:wool:7,10,quark:quilted_wool:7,100)
RandomBlock(7,93,3,minecraft:wool:7,10,quark:quilted_wool:7,100)
RandomBlock(7,94,-1,minecraft:wool:7,10,quark:quilted_wool:7,100)
RandomBlock(7,94,0,minecraft:wool:7,10,quark:quilted_wool:7,100)
RandomBlock(7,94,1,minecraft:wool:7,10,quark:quilted_wool:7,100)
RandomBlock(7,94,2,minecraft:wool:7,10,quark:quilted_wool:7,100)
RandomBlock(7,94,3,minecraft:wool:7,10,quark:quilted_wool:7,100)
RandomBlock(7,95,-1,minecraft:wool:7,10,quark:quilted_wool:7,100)
RandomBlock(7,95,0,minecraft:wool:7,10,quark:quilted_wool:7,100)
RandomBlock(7,95,1,minecraft:wool:7,10,quark:quilted_wool:7,100)
RandomBlock(7,95,2,minecraft:wool:7,10,quark:quilted_wool:7,100)
RandomBlock(7,95,3,minecraft:wool:7,10,quark:quilted_wool:7,100)
RandomBlock(7,96,-1,minecraft:wool:7,10,quark:quilted_wool:7,100)
RandomBlock(7,96,0,minecraft:wool:7,10,quark:quilted_wool:7,100)
RandomBlock(7,96,1,minecraft:wool:7,10,quark:quilted_wool:7,100)
RandomBlock(7,96,2,minecraft:wool:7,10,quark:quilted_wool:7,100)
RandomBlock(7,96,3,minecraft:wool:7,10,quark:quilted_wool:7,100)
RandomBlock(7,97,0,minecraft:wool:7,10,quark:quilted_wool:7,100)
RandomBlock(7,97,1,minecraft:wool:7,10,quark:quilted_wool:7,100)
RandomBlock(7,97,2,minecraft:wool:7,10,quark:quilted_wool:7,100)

#######################################################################
# +-----------------------------------------------------------------+ #
# |                             Branches                            | #
# +-----------------------------------------------------------------+ #
#######################################################################

Branch(16,0,0,true,TreeTestC1R0,NORTH,100.0,0)

#######################################################################
# +-----------------------------------------------------------------+ #
# |                             Entities                            | #
# +-----------------------------------------------------------------+ #
#######################################################################


#######################################################################
# +-----------------------------------------------------------------+ #
# |                            Particles                            | #
# +-----------------------------------------------------------------+ #
#######################################################################


#######################################################################
# +-----------------------------------------------------------------+ #
# |                             Spawners                            | #
# +-----------------------------------------------------------------+ #
#######################################################################


#######################################################################
# +-----------------------------------------------------------------+ #
# |                             ModData                             | #
# +-----------------------------------------------------------------+ #
#######################################################################

