
#######################################################################
# +-----------------------------------------------------------------+ #
# |                            BO4 object                           | #
# +-----------------------------------------------------------------+ #
#######################################################################

Author: NLBlackEagle

Description: No description given

SettingsMode: WriteDisable


#######################################################################
# +-----------------------------------------------------------------+ #
# |                          Main settings                          | #
# +-----------------------------------------------------------------+ #
#######################################################################

FixedRotation: 

Frequency: 0

SpawnHeight: highestBlock

UseCenterForHighestBlock: true

##############################
# Height Limits for the BO4. #
##############################

MinHeight: 0

MaxHeight: 255

InheritBO3: 

InheritBO3Rotation: NORTH

OverrideChildSettings: true

OverrideParentHeight: false

CanOverride: false

BranchFrequency: 0

BranchFrequencyGroup: 

MustBeBelowOther: false

MustBeInside: 

CannotBeInside: 

ReplacesBO3: 

MustBeInsideWorldBorders: false

CanSpawnOnWater: true

SpawnOnWaterOnly: false

SpawnUnderWater: false

SpawnAtWaterLevel: false

HeightOffset: 0

RemoveAir: true

ReplaceAbove: 

ReplaceBelow: 

ReplaceWithBiomeBlocks: true

ReplaceWithSurfaceBlock: GRASS

ReplaceWithGroundBlock: DIRT

ReplaceWithStoneBlock: STONE

SmoothRadius: 0

SmoothHeightOffset: 0

SmoothStartTop: false

SmoothStartWood: false

SmoothingSurfaceBlock: 

SmoothingGroundBlock: 

BO3Group: 

IsSpawnPoint: false

DoReplaceBlocks: true


#######################################################################
# +-----------------------------------------------------------------+ #
# |                              Blocks                             | #
# +-----------------------------------------------------------------+ #
#######################################################################

Block(-5,3,-3,LOG:12)
Block(-5,3,-2,LOG:12)
Block(-5,4,-3,LOG:12)
Block(-5,4,-2,quark:leaf_carpet)
Block(-5,5,-3,quark:leaf_carpet)
Block(-5,7,-4,LEAVES:0)
Block(-5,7,-3,LEAVES:0)
Block(-4,4,-3,LOG:12)
Block(-4,5,-4,LOG:12)
Block(-4,5,-3,LOG:12)
Block(-4,6,-4,LOG:12)
Block(-4,6,-3,LOG:12)
Block(-4,7,-5,LEAVES:0)
Block(-4,7,-4,LEAVES:0)
Block(-4,7,-3,quark:leaf_carpet)
Block(-4,7,-2,LEAVES:0)
Block(-4,8,-4,LEAVES:0)
Block(-4,8,-3,LEAVES:0)
Block(-3,0,2,LOG:12)
Block(-3,1,2,quark:leaf_carpet)
Block(-3,6,-4,LOG:12)
Block(-3,6,-3,LOG:12)
Block(-3,7,-5,LOG:12)
Block(-3,7,-4,LOG:12)
Block(-3,7,-3,LOG:12)
Block(-3,8,-5,LEAVES:0)
Block(-3,8,-4,LOG:12)
Block(-3,8,-3,quark:leaf_carpet)
Block(-3,9,-5,LEAVES:0)
Block(-3,9,-4,quark:leaf_carpet)
Block(-2,0,0,LOG:12)
Block(-2,0,1,LOG:12)
Block(-2,0,2,LOG:12)
Block(-2,1,0,LOG:12)
Block(-2,1,1,LOG:12)
Block(-2,2,0,LOG:12)
Block(-2,2,1,LOG:12)
Block(-2,3,0,LOG:12)
Block(-2,3,1,quark:leaf_carpet)
Block(-2,4,0,quark:leaf_carpet)
Block(-2,5,-4,LOG:12)
Block(-2,6,-5,LOG:12)
Block(-2,6,-4,LOG:12)
Block(-2,6,-3,LOG:12)
Block(-2,7,-6,LOG:12)
Block(-2,7,-5,LOG:12)
Block(-2,7,-4,LOG:12)
Block(-2,7,-3,LOG:12)
Block(-2,8,-6,LEAVES:0)
Block(-2,8,-5,LOG:12)
Block(-2,8,-4,LOG:12)
Block(-2,8,-3,LOG:12)
Block(-2,9,-6,LEAVES:0)
Block(-2,9,-5,LEAVES:0)
Block(-2,9,-4,quark:leaf_carpet)
Block(-2,10,-6,LEAVES:0)
Block(-2,10,-5,LEAVES:0)
Block(-2,18,1,WOOL:14)
Block(-2,19,0,WOOL:14)
Block(-2,19,1,WOOL:14)
Block(-2,19,2,WOOL:14)
Block(-2,20,0,WOOL:14)
Block(-2,20,1,WOOL:14)
Block(-2,20,2,WOOL:14)
Block(-2,21,0,WOOL:14)
Block(-2,21,1,WOOL:14)
Block(-2,21,2,WOOL:14)
Block(-2,22,1,WOOL:14)
Block(-2,59,-7,LEAVES:0)
Block(-2,60,-7,LEAVES:0)
Block(-2,60,-6,LEAVES:0)
Block(-2,75,-6,LEAVES:0)
Block(-2,75,-5,LEAVES:0)
Block(-2,75,-4,LEAVES:0)
Block(-2,76,-5,LEAVES:0)
RandomBlock(-2,89,-7,minecraft:wool:7,10,quark:quilted_wool:7,100)
Block(-1,3,0,LOG:12)
Block(-1,3,1,LOG:12)
Block(-1,4,0,LOG:12)
Block(-1,4,1,LOG:12)
Block(-1,5,0,quark:leaf_carpet)
Block(-1,5,1,quark:leaf_carpet)
Block(-1,6,-6,LOG:12)
Block(-1,6,-5,LOG:12)
Block(-1,6,-4,LOG:12)
Block(-1,7,-6,LOG:12)
Block(-1,7,-5,LOG:12)
Block(-1,7,-4,LOG:12)
Block(-1,7,-3,LOG:12)
Block(-1,8,-6,LOG:12)
Block(-1,8,-5,LOG:12)
Block(-1,8,-4,LOG:12)
Block(-1,9,-7,LOG:12)
Block(-1,9,-6,LOG:12)
Block(-1,9,-5,LOG:12)
Block(-1,9,-4,quark:leaf_carpet)
Block(-1,10,-7,LEAVES:0)
Block(-1,10,-6,LOG:12)
Block(-1,10,-5,LEAVES:0)
Block(-1,11,-7,LEAVES:0)
Block(-1,11,-6,LEAVES:0)
Block(-1,17,0,WOOL:14)
Block(-1,17,1,WOOL:14)
Block(-1,17,2,WOOL:14)
Block(-1,18,-1,WOOL:14)
Block(-1,18,0,WOOL:14)
Block(-1,18,1,WOOL:14)
Block(-1,18,2,WOOL:14)
Block(-1,18,3,WOOL:14)
Block(-1,19,-1,WOOL:14)
Block(-1,19,0,WOOL:14)
Block(-1,19,1,WOOL:14)
Block(-1,19,2,WOOL:14)
Block(-1,19,3,WOOL:14)
Block(-1,20,-1,WOOL:14)
Block(-1,20,0,WOOL:14)
Block(-1,20,1,WOOL:14)
Block(-1,20,2,WOOL:14)
Block(-1,20,3,WOOL:14)
Block(-1,21,-1,WOOL:14)
Block(-1,21,0,WOOL:14)
Block(-1,21,1,WOOL:14)
Block(-1,21,2,WOOL:14)
Block(-1,21,3,WOOL:14)
Block(-1,22,-1,WOOL:14)
Block(-1,22,0,WOOL:14)
Block(-1,22,1,WOOL:14)
Block(-1,22,2,WOOL:14)
Block(-1,22,3,WOOL:14)
Block(-1,23,0,WOOL:14)
Block(-1,23,1,WOOL:14)
Block(-1,23,2,WOOL:14)
Block(-1,57,-7,LEAVES:0)
Block(-1,57,-6,LEAVES:0)
Block(-1,58,-7,LEAVES:0)
Block(-1,58,-6,LEAVES:0)
Block(-1,59,-7,LEAVES:0)
Block(-1,59,-6,LEAVES:0)
Block(-1,60,-7,LEAVES:0)
Block(-1,60,-6,LEAVES:0)
Block(-1,74,-5,LEAVES:0)
Block(-1,75,-7,LEAVES:0)
Block(-1,75,-6,LEAVES:0)
Block(-1,75,-5,LEAVES:0)
Block(-1,75,-4,LEAVES:0)
Block(-1,75,-3,LEAVES:0)
Block(-1,76,-7,LEAVES:0)
Block(-1,76,-6,LEAVES:0)
Block(-1,76,-5,LEAVES:0)
Block(-1,76,-4,LEAVES:0)
Block(-1,77,-5,LEAVES:0)
RandomBlock(-1,87,-7,minecraft:wool:7,10,quark:quilted_wool:7,100)
RandomBlock(-1,88,-7,minecraft:wool:7,10,quark:quilted_wool:7,100)
RandomBlock(-1,89,-7,minecraft:wool:7,10,quark:quilted_wool:7,100)
RandomBlock(-1,90,-7,minecraft:wool:7,10,quark:quilted_wool:7,100)
RandomBlock(-1,91,-7,minecraft:wool:7,10,quark:quilted_wool:7,100)
Block(0,3,0,LOG:12)
Block(0,4,0,LOG:12)
Block(0,4,1,LOG:12)
Block(0,5,0,LOG:12)
Block(0,5,1,LOG:12)
Block(0,6,-5,LOG:12)
Block(0,6,-1,LOG:12)
Block(0,6,0,LOG:12)
Block(0,6,1,LOG:12)
Block(0,7,-6,LOG:12)
Block(0,7,-5,LOG:12)
Block(0,7,-4,LOG:12)
Block(0,7,0,LOG:12)
Block(0,7,1,quark:leaf_carpet)
Block(0,8,-7,LOG:12)
Block(0,8,-6,LOG:12)
Block(0,8,-5,LOG:12)
Block(0,8,-4,LOG:12)
Block(0,8,0,quark:leaf_carpet)
Block(0,9,-7,LOG:12)
Block(0,9,-6,LOG:12)
Block(0,9,-5,LOG:12)
Block(0,9,-4,LOG:12)
Block(0,10,-7,LOG:12)
Block(0,10,-6,LOG:12)
Block(0,10,-5,LOG:12)
Block(0,11,-7,LOG:12)
Block(0,11,-6,LOG:12)
Block(0,11,-5,quark:leaf_carpet)
Block(0,12,-7,LOG:12)
Block(0,12,-6,quark:leaf_carpet)
Block(0,13,-7,LOG:12)
Block(0,14,-7,LEAVES:0)
Block(0,16,0,WOOL:14)
Block(0,16,1,WOOL:14)
Block(0,16,2,WOOL:14)
Block(0,17,-1,WOOL:14)
Block(0,17,0,WOOL:14)
Block(0,17,1,WOOL:14)
Block(0,17,2,WOOL:14)
Block(0,17,3,WOOL:14)
Block(0,18,-1,WOOL:14)
Block(0,18,0,WOOL:14)
Block(0,18,1,WOOL:14)
Block(0,18,2,WOOL:14)
Block(0,18,3,WOOL:14)
Block(0,19,-2,WOOL:14)
Block(0,19,-1,WOOL:14)
Block(0,19,0,WOOL:14)
Block(0,19,1,WOOL:14)
Block(0,19,2,WOOL:14)
Block(0,19,3,WOOL:14)
Block(0,19,4,WOOL:14)
Block(0,20,-2,WOOL:14)
Block(0,20,-1,WOOL:14)
Block(0,20,0,WOOL:14)
Block(0,20,1,WOOL:14)
Block(0,20,2,WOOL:14)
Block(0,20,3,WOOL:14)
Block(0,20,4,WOOL:14)
Block(0,21,-2,WOOL:14)
Block(0,21,-1,WOOL:14)
Block(0,21,0,WOOL:14)
Block(0,21,1,WOOL:14)
Block(0,21,2,WOOL:14)
Block(0,21,3,WOOL:14)
Block(0,21,4,WOOL:14)
Block(0,22,-1,WOOL:14)
Block(0,22,0,WOOL:14)
Block(0,22,1,WOOL:14)
Block(0,22,2,WOOL:14)
Block(0,22,3,WOOL:14)
Block(0,23,-1,WOOL:14)
Block(0,23,0,WOOL:14)
Block(0,23,1,WOOL:14)
Block(0,23,2,WOOL:14)
Block(0,23,3,WOOL:14)
Block(0,24,0,WOOL:14)
Block(0,24,1,WOOL:14)
Block(0,24,2,WOOL:14)
RandomBlock(0,36,-7,minecraft:wool:0,10,quark:quilted_wool:0,100)
RandomBlock(0,37,-7,minecraft:wool:0,10,quark:quilted_wool:0,100)
RandomBlock(0,38,-7,minecraft:wool:0,10,quark:quilted_wool:0,100)
Block(0,39,-7,VINE:12)
Block(0,40,-7,VINE:12)
Block(0,41,-7,VINE:12)
Block(0,42,-7,VINE:12)
Block(0,43,-7,VINE:12)
Block(0,44,-7,VINE:12)
Block(0,45,-7,VINE:12)
Block(0,46,-7,VINE:12)
Block(0,47,-7,VINE:12)
Block(0,48,-7,VINE:12)
Block(0,49,-7,VINE:12)
Block(0,50,-7,VINE:12)
Block(0,51,-7,VINE:12)
Block(0,52,-7,VINE:12)
Block(0,53,-7,VINE:12)
Block(0,54,-7,VINE:12)
Block(0,55,-7,VINE:12)
Block(0,56,-7,VINE:12)
Block(0,57,-7,LEAVES:0)
Block(0,57,-6,LEAVES:0)
Block(0,57,-5,LEAVES:0)
Block(0,58,-7,LEAVES:0)
Block(0,58,-6,LEAVES:0)
Block(0,58,-5,LEAVES:0)
Block(0,59,-7,LEAVES:0)
Block(0,59,-6,LEAVES:0)
Block(0,60,-7,LEAVES:0)
Block(0,60,-6,LEAVES:0)
Block(0,61,-7,LEAVES:0)
Block(0,61,-6,VINE:8)
Block(0,62,-7,LEAVES:0)
Block(0,62,-6,VINE:8)
Block(0,63,-6,VINE:8)
Block(0,64,-6,VINE:8)
Block(0,65,-6,VINE:8)
Block(0,66,-6,VINE:8)
Block(0,67,-6,VINE:8)
Block(0,68,-6,VINE:8)
Block(0,69,-6,VINE:8)
Block(0,69,-5,VINE:8)
Block(0,70,-6,VINE:8)
Block(0,70,-5,VINE:8)
Block(0,71,-6,VINE:8)
Block(0,71,-5,VINE:8)
Block(0,72,-6,VINE:8)
Block(0,72,-5,VINE:8)
Block(0,73,-6,VINE:8)
Block(0,73,-5,VINE:8)
Block(0,74,-7,LEAVES:0)
Block(0,74,-6,LEAVES:0)
Block(0,74,-5,LOG:12)
Block(0,74,-4,LEAVES:0)
Block(0,75,-7,LEAVES:0)
Block(0,75,-6,LEAVES:0)
Block(0,75,-5,LEAVES:0)
Block(0,75,-4,LEAVES:0)
Block(0,75,-3,LEAVES:0)
Block(0,75,-2,LEAVES:0)
Block(0,76,-7,LEAVES:0)
Block(0,76,-6,LEAVES:0)
Block(0,76,-5,LEAVES:0)
Block(0,76,-4,LEAVES:0)
Block(0,76,-3,LEAVES:0)
Block(0,77,-6,LEAVES:0)
Block(0,77,-5,LEAVES:0)
Block(0,77,-4,LEAVES:0)
RandomBlock(0,87,-7,minecraft:wool:7,10,quark:quilted_wool:7,100)
RandomBlock(0,88,-7,minecraft:wool:7,10,quark:quilted_wool:7,100)
RandomBlock(0,89,-7,minecraft:wool:7,10,quark:quilted_wool:7,100)
RandomBlock(0,90,-7,minecraft:wool:7,10,quark:quilted_wool:7,100)
RandomBlock(0,91,-7,minecraft:wool:7,10,quark:quilted_wool:7,100)
Block(1,3,0,LOG:12)
Block(1,4,-7,LEAVES:0)
Block(1,4,0,LOG:12)
Block(1,4,1,LOG:12)
Block(1,5,-7,LEAVES:0)
Block(1,5,-1,LOG:12)
Block(1,5,0,LOG:12)
Block(1,5,1,LOG:12)
Block(1,6,-1,LOG:12)
Block(1,6,0,LOG:12)
Block(1,6,1,LOG:12)
Block(1,7,-5,LOG:12)
Block(1,7,-1,LOG:12)
Block(1,7,0,LOG:12)
Block(1,7,1,LOG:12)
Block(1,8,-6,LOG:12)
Block(1,8,-5,LOG:12)
Block(1,8,-4,LOG:12)
Block(1,8,0,LOG:12)
Block(1,8,1,inspirations:rope:1)
Block(1,9,-7,LOG:12)
Block(1,9,-6,LOG:12)
Block(1,9,-5,LOG:12)
Block(1,9,1,inspirations:rope:1)
Block(1,10,-7,LOG:12)
Block(1,10,-6,LOG:12)
Block(1,10,-5,LOG:12)
Block(1,10,1,inspirations:rope:1)
Block(1,11,-7,LOG:12)
Block(1,11,-6,LOG:12)
Block(1,11,-5,LOG:12)
Block(1,11,1,inspirations:rope:1)
Block(1,12,-7,LOG:12)
Block(1,12,-6,LOG:12)
Block(1,12,1,inspirations:rope:1)
Block(1,13,-7,LOG:12)
Block(1,13,-6,quark:leaf_carpet)
Block(1,13,1,inspirations:rope:1)
Block(1,14,-7,LOG:12)
Block(1,14,1,inspirations:rope:1)
Block(1,15,-7,quark:leaf_carpet)
Block(1,15,1,inspirations:rope:1)
Block(1,16,0,WOOL:14)
Block(1,16,1,WOOL:14)
Block(1,16,2,WOOL:14)
Block(1,17,-1,WOOL:14)
Block(1,17,0,WOOL:14)
Block(1,17,1,WOOL:14)
Block(1,17,2,WOOL:14)
Block(1,17,3,WOOL:14)
Block(1,18,-2,WOOL:14)
Block(1,18,-1,WOOL:14)
Block(1,18,0,WOOL:14)
Block(1,18,1,WOOL:14)
Block(1,18,2,WOOL:14)
Block(1,18,3,WOOL:14)
Block(1,18,4,WOOL:14)
Block(1,19,-2,WOOL:14)
Block(1,19,-1,WOOL:14)
Block(1,19,0,WOOL:14)
Block(1,19,1,WOOL:14)
Block(1,19,2,WOOL:14)
Block(1,19,3,WOOL:14)
Block(1,19,4,WOOL:14)
Block(1,20,-2,WOOL:14)
Block(1,20,-1,WOOL:14)
Block(1,20,0,WOOL:14)
Block(1,20,1,WOOL:14)
Block(1,20,2,WOOL:14)
Block(1,20,3,WOOL:14)
Block(1,20,4,WOOL:14)
Block(1,21,-2,WOOL:14)
Block(1,21,-1,WOOL:14)
Block(1,21,0,WOOL:14)
Block(1,21,1,WOOL:14)
Block(1,21,2,WOOL:14)
Block(1,21,3,WOOL:14)
Block(1,21,4,WOOL:14)
Block(1,22,-2,WOOL:14)
Block(1,22,-1,WOOL:14)
Block(1,22,0,WOOL:14)
Block(1,22,1,WOOL:14)
Block(1,22,2,WOOL:14)
Block(1,22,3,WOOL:14)
Block(1,22,4,WOOL:14)
Block(1,23,-1,WOOL:14)
Block(1,23,0,WOOL:14)
Block(1,23,1,WOOL:14)
Block(1,23,2,WOOL:14)
Block(1,23,3,WOOL:14)
Block(1,24,0,WOOL:14)
Block(1,24,1,WOOL:14)
Block(1,24,2,WOOL:14)
RandomBlock(1,35,-7,minecraft:wool:0,10,quark:quilted_wool:0,100)
RandomBlock(1,36,-7,minecraft:wool:0,10,quark:quilted_wool:0,100)
RandomBlock(1,37,-7,minecraft:wool:0,10,quark:quilted_wool:0,100)
Block(1,37,-6,VINE:4)
RandomBlock(1,38,-7,minecraft:wool:0,10,quark:quilted_wool:0,100)
Block(1,38,-6,VINE:4)
RandomBlock(1,39,-7,minecraft:wool:0,10,quark:quilted_wool:0,100)
Block(1,39,-6,VINE:4)
Block(1,40,-6,VINE:4)
Block(1,41,-6,VINE:4)
Block(1,42,-6,VINE:4)
Block(1,43,-6,VINE:4)
Block(1,44,-6,VINE:4)
Block(1,45,-6,VINE:4)
Block(1,46,-6,VINE:4)
Block(1,46,-4,VINE:4)
Block(1,47,-6,VINE:4)
Block(1,47,-4,VINE:4)
Block(1,48,-6,VINE:4)
Block(1,48,-4,VINE:4)
Block(1,49,-6,VINE:4)
Block(1,49,-4,VINE:4)
Block(1,50,-6,VINE:4)
Block(1,50,-4,VINE:4)
Block(1,51,-6,VINE:4)
Block(1,51,-4,VINE:4)
Block(1,52,-6,VINE:4)
Block(1,52,-4,VINE:4)
Block(1,53,-7,LOG:12)
Block(1,53,-6,VINE:4)
Block(1,53,-4,VINE:4)
Block(1,54,-7,LOG:12)
Block(1,54,-6,VINE:4)
Block(1,54,-4,VINE:4)
Block(1,55,-7,LOG:12)
Block(1,55,-6,VINE:4)
Block(1,55,-4,VINE:4)
Block(1,56,-7,LOG:12)
Block(1,56,-6,VINE:4)
Block(1,56,-4,VINE:4)
Block(1,57,-7,LOG:12)
Block(1,57,-6,LEAVES:0)
Block(1,57,-5,LEAVES:0)
Block(1,57,-4,VINE:4)
Block(1,58,-7,LOG:12)
Block(1,58,-6,LEAVES:0)
Block(1,58,-5,LEAVES:0)
Block(1,58,-4,VINE:4)
Block(1,59,-7,LOG:12)
Block(1,59,-6,LEAVES:0)
Block(1,59,-4,VINE:4)
Block(1,60,-7,LEAVES:0)
Block(1,60,-6,LEAVES:0)
Block(1,60,-4,VINE:4)
Block(1,61,-7,LEAVES:0)
Block(1,61,-4,VINE:4)
Block(1,62,-7,LEAVES:0)
Block(1,62,-4,VINE:4)
Block(1,63,-4,VINE:4)
Block(1,64,-4,VINE:4)
Block(1,65,-4,VINE:4)
Block(1,66,-4,VINE:4)
Block(1,67,-4,VINE:4)
Block(1,68,-4,VINE:4)
Block(1,69,-7,LEAVES:0)
Block(1,69,-4,VINE:4)
Block(1,70,-7,LEAVES:0)
Block(1,70,-6,LEAVES:0)
Block(1,70,-5,VINE:4)
Block(1,70,-4,VINE:4)
Block(1,71,-4,VINE:14)
Block(1,72,-7,LEAVES:0)
Block(1,72,-6,LEAVES:0)
Block(1,72,-5,LEAVES:0)
Block(1,72,-4,VINE:14)
Block(1,73,-7,LEAVES:0)
Block(1,73,-6,LOG:12)
Block(1,73,-5,LEAVES:0)
Block(1,73,-4,VINE:14)
Block(1,74,-7,LEAVES:0)
Block(1,74,-6,LEAVES:0)
Block(1,74,-5,LEAVES:0)
Block(1,74,-4,VINE:14)
Block(1,74,-3,LEAVES:0)
Block(1,75,-7,LEAVES:0)
Block(1,75,-6,LEAVES:0)
Block(1,75,-5,LEAVES:0)
Block(1,75,-4,LEAVES:0)
Block(1,75,-3,LEAVES:0)
Block(1,75,-2,LEAVES:0)
Block(1,75,-1,LEAVES:0)
Block(1,76,-7,LEAVES:0)
Block(1,76,-6,LEAVES:0)
Block(1,76,-5,LEAVES:0)
Block(1,76,-4,LEAVES:0)
Block(1,76,-3,LEAVES:0)
Block(1,76,-2,LEAVES:0)
Block(1,77,-7,LEAVES:0)
Block(1,77,-6,LEAVES:0)
Block(1,77,-5,LEAVES:0)
Block(1,77,-3,LEAVES:0)
Block(1,78,-7,LEAVES:0)
RandomBlock(1,87,-7,minecraft:wool:7,10,quark:quilted_wool:7,100)
RandomBlock(1,88,-7,minecraft:wool:7,10,quark:quilted_wool:7,100)
RandomBlock(1,89,-7,minecraft:wool:7,10,quark:quilted_wool:7,100)
RandomBlock(1,90,-7,minecraft:wool:7,10,quark:quilted_wool:7,100)
RandomBlock(1,91,-7,minecraft:wool:7,10,quark:quilted_wool:7,100)
Block(2,5,0,LOG:12)
Block(2,6,-1,LOG:12)
Block(2,6,0,LOG:12)
Block(2,6,1,LOG:12)
Block(2,7,-1,LOG:12)
Block(2,7,0,LOG:12)
Block(2,7,1,LOG:12)
Block(2,8,-1,LOG:12)
Block(2,8,0,LOG:12)
Block(2,8,1,LOG:12)
Block(2,9,-6,LOG:12)
Block(2,9,-1,quark:leaf_carpet)
Block(2,9,0,quark:leaf_carpet)
Block(2,10,-7,LOG:12)
Block(2,10,-6,LOG:12)
Block(2,10,-5,LOG:12)
Block(2,11,-7,LOG:12)
Block(2,11,-6,LOG:12)
Block(2,12,-7,LOG:12)
Block(2,13,-7,LOG:12)
Block(2,14,-7,LOG:12)
Block(2,15,-7,LOG:12)
Block(2,16,0,WOOL:14)
Block(2,16,1,WOOL:14)
Block(2,16,2,WOOL:14)
Block(2,17,-1,WOOL:14)
Block(2,17,0,WOOL:14)
Block(2,17,1,WOOL:14)
Block(2,17,2,WOOL:14)
Block(2,17,3,WOOL:14)
Block(2,18,-1,WOOL:14)
Block(2,18,0,WOOL:14)
Block(2,18,1,WOOL:14)
Block(2,18,2,WOOL:14)
Block(2,18,3,WOOL:14)
Block(2,19,-2,WOOL:14)
Block(2,19,-1,WOOL:14)
Block(2,19,0,WOOL:14)
Block(2,19,1,WOOL:14)
Block(2,19,2,WOOL:14)
Block(2,19,3,WOOL:14)
Block(2,19,4,WOOL:14)
Block(2,20,-2,WOOL:14)
Block(2,20,-1,WOOL:14)
Block(2,20,0,WOOL:14)
Block(2,20,1,WOOL:14)
Block(2,20,2,WOOL:14)
Block(2,20,3,WOOL:14)
Block(2,20,4,WOOL:14)
Block(2,21,-2,WOOL:14)
Block(2,21,-1,WOOL:14)
Block(2,21,0,WOOL:14)
Block(2,21,1,WOOL:14)
Block(2,21,2,WOOL:14)
Block(2,21,3,WOOL:14)
Block(2,21,4,WOOL:14)
Block(2,22,-1,WOOL:14)
Block(2,22,0,WOOL:14)
Block(2,22,1,WOOL:14)
Block(2,22,2,WOOL:14)
Block(2,22,3,WOOL:14)
Block(2,23,-1,WOOL:14)
Block(2,23,0,WOOL:14)
Block(2,23,1,WOOL:14)
Block(2,23,2,WOOL:14)
Block(2,23,3,WOOL:14)
Block(2,24,0,WOOL:14)
Block(2,24,1,WOOL:14)
Block(2,24,2,WOOL:14)
RandomBlock(2,36,-7,minecraft:wool:0,10,quark:quilted_wool:0,100)
RandomBlock(2,37,-7,minecraft:wool:0,10,quark:quilted_wool:0,100)
RandomBlock(2,38,-7,minecraft:wool:0,10,quark:quilted_wool:0,100)
Block(2,39,-7,VINE:2)
Block(2,40,-7,VINE:2)
Block(2,41,-7,VINE:2)
Block(2,42,-7,VINE:2)
Block(2,43,-7,VINE:2)
Block(2,44,-7,VINE:2)
Block(2,45,-7,VINE:2)
Block(2,46,-7,VINE:2)
Block(2,47,-7,VINE:2)
Block(2,48,-7,VINE:2)
Block(2,49,-7,VINE:2)
Block(2,50,-7,VINE:2)
Block(2,51,-7,VINE:2)
Block(2,52,-7,VINE:2)
Block(2,53,-7,VINE:2)
Block(2,54,-7,VINE:2)
Block(2,55,-7,VINE:2)
Block(2,56,-7,VINE:2)
Block(2,57,-7,LEAVES:0)
Block(2,57,-6,LEAVES:0)
Block(2,57,-5,LEAVES:0)
Block(2,58,-7,LEAVES:0)
Block(2,58,-6,LEAVES:0)
Block(2,58,-5,LEAVES:0)
Block(2,59,-7,LEAVES:0)
Block(2,59,-6,LEAVES:0)
Block(2,60,-7,LEAVES:0)
Block(2,60,-6,LEAVES:0)
Block(2,61,-7,LEAVES:0)
Block(2,62,-7,VINE:8)
Block(2,63,-7,VINE:8)
Block(2,64,-7,VINE:8)
Block(2,65,-7,VINE:8)
Block(2,66,-7,VINE:8)
Block(2,67,-7,VINE:8)
Block(2,68,-7,LEAVES:0)
Block(2,68,-6,LEAVES:0)
Block(2,68,-5,LEAVES:0)
Block(2,69,-7,LEAVES:0)
Block(2,69,-6,LEAVES:0)
Block(2,69,-5,LEAVES:0)
Block(2,69,-4,LEAVES:0)
Block(2,70,-7,LEAVES:0)
Block(2,70,-6,LEAVES:0)
Block(2,70,-5,VINE:12)
Block(2,71,-6,LEAVES:0)
Block(2,71,-5,VINE:12)
Block(2,72,-7,LEAVES:0)
Block(2,72,-6,LEAVES:0)
Block(2,72,-5,LEAVES:0)
Block(2,72,-4,LEAVES:0)
Block(2,73,-7,LOG:12)
Block(2,73,-6,LOG:12)
Block(2,73,-5,LEAVES:0)
Block(2,73,-4,LEAVES:0)
Block(2,74,-7,LEAVES:0)
Block(2,74,-6,LEAVES:0)
Block(2,74,-5,LEAVES:0)
Block(2,74,-4,LOG:12)
Block(2,74,-3,LOG:12)
Block(2,74,-2,LEAVES:0)
Block(2,75,-7,LEAVES:0)
Block(2,75,-6,LEAVES:0)
Block(2,75,-5,LEAVES:0)
Block(2,75,-4,LEAVES:0)
Block(2,75,-3,LEAVES:0)
Block(2,75,-2,LEAVES:0)
Block(2,75,-1,LEAVES:0)
Block(2,76,-7,LEAVES:0)
Block(2,76,-6,LEAVES:0)
Block(2,76,-5,LEAVES:0)
Block(2,76,-4,LEAVES:0)
Block(2,76,-3,LEAVES:0)
Block(2,76,-2,LEAVES:0)
Block(2,76,-1,LEAVES:0)
Block(2,77,-7,LEAVES:0)
Block(2,77,-6,LEAVES:0)
Block(2,77,-5,LEAVES:0)
Block(2,77,-4,LEAVES:0)
Block(2,77,-3,LEAVES:0)
Block(2,77,-2,LEAVES:0)
Block(2,78,-7,LEAVES:0)
Block(2,78,-6,LEAVES:0)
Block(2,79,-7,LEAVES:0)
RandomBlock(2,89,-7,minecraft:wool:7,10,quark:quilted_wool:7,100)
RandomBlock(2,94,-3,minecraft:wool:0,10,quark:quilted_wool:0,100)
RandomBlock(2,95,-4,minecraft:wool:0,10,quark:quilted_wool:0,100)
RandomBlock(2,95,-3,minecraft:wool:0,10,quark:quilted_wool:0,100)
RandomBlock(2,95,-2,minecraft:wool:0,10,quark:quilted_wool:0,100)
RandomBlock(2,96,-5,minecraft:wool:0,10,quark:quilted_wool:0,100)
RandomBlock(2,96,-4,minecraft:wool:0,10,quark:quilted_wool:0,100)
RandomBlock(2,96,-3,minecraft:wool:0,10,quark:quilted_wool:0,100)
RandomBlock(2,96,-2,minecraft:wool:0,10,quark:quilted_wool:0,100)
RandomBlock(2,96,-1,minecraft:wool:0,10,quark:quilted_wool:0,100)
RandomBlock(2,97,-5,minecraft:wool:0,10,quark:quilted_wool:0,100)
RandomBlock(2,97,-4,minecraft:wool:0,10,quark:quilted_wool:0,100)
RandomBlock(2,97,-3,minecraft:wool:0,10,quark:quilted_wool:0,100)
RandomBlock(2,97,-2,minecraft:wool:0,10,quark:quilted_wool:0,100)
RandomBlock(2,97,-1,minecraft:wool:0,10,quark:quilted_wool:0,100)
RandomBlock(2,98,-5,minecraft:wool:0,10,quark:quilted_wool:0,100)
RandomBlock(2,98,-4,minecraft:wool:0,10,quark:quilted_wool:0,100)
RandomBlock(2,98,-3,minecraft:wool:0,10,quark:quilted_wool:0,100)
RandomBlock(2,98,-2,minecraft:wool:0,10,quark:quilted_wool:0,100)
RandomBlock(2,98,-1,minecraft:wool:0,10,quark:quilted_wool:0,100)
RandomBlock(2,99,-5,minecraft:wool:0,10,quark:quilted_wool:0,100)
RandomBlock(2,99,-4,minecraft:wool:0,10,quark:quilted_wool:0,100)
RandomBlock(2,99,-3,minecraft:wool:0,10,quark:quilted_wool:0,100)
RandomBlock(2,99,-2,minecraft:wool:0,10,quark:quilted_wool:0,100)
RandomBlock(2,99,-1,minecraft:wool:0,10,quark:quilted_wool:0,100)
RandomBlock(2,100,-5,minecraft:wool:0,10,quark:quilted_wool:0,100)
RandomBlock(2,100,-4,minecraft:wool:0,10,quark:quilted_wool:0,100)
RandomBlock(2,100,-3,minecraft:wool:0,10,quark:quilted_wool:0,100)
RandomBlock(2,100,-2,minecraft:wool:0,10,quark:quilted_wool:0,100)
RandomBlock(2,100,-1,minecraft:wool:0,10,quark:quilted_wool:0,100)
RandomBlock(2,101,-4,minecraft:wool:0,10,quark:quilted_wool:0,100)
RandomBlock(2,101,-3,minecraft:wool:0,10,quark:quilted_wool:0,100)
RandomBlock(2,101,-2,minecraft:wool:0,10,quark:quilted_wool:0,100)
RandomBlock(2,102,-3,minecraft:wool:0,10,quark:quilted_wool:0,100)
Block(3,6,-1,LOG:12)
Block(3,6,0,LOG:12)
Block(3,6,1,LOG:12)
Block(3,7,-1,LOG:12)
Block(3,7,0,LOG:12)
Block(3,7,1,LOG:12)
Block(3,8,-1,LOG:12)
Block(3,8,0,LOG:12)
Block(3,8,1,LOG:12)
Block(3,9,0,LOG:12)
Block(3,10,0,quark:leaf_carpet)
Block(3,14,-7,LOG:12)
Block(3,17,0,WOOL:14)
Block(3,17,1,WOOL:14)
Block(3,17,2,WOOL:14)
Block(3,18,-1,WOOL:14)
Block(3,18,0,WOOL:14)
Block(3,18,1,WOOL:14)
Block(3,18,2,WOOL:14)
Block(3,18,3,WOOL:14)
Block(3,19,-1,WOOL:14)
Block(3,19,0,WOOL:14)
Block(3,19,1,WOOL:14)
Block(3,19,2,WOOL:14)
Block(3,19,3,WOOL:14)
Block(3,20,-1,WOOL:14)
Block(3,20,0,WOOL:14)
Block(3,20,1,WOOL:14)
Block(3,20,2,WOOL:14)
Block(3,20,3,WOOL:14)
Block(3,21,-1,WOOL:14)
Block(3,21,0,WOOL:14)
Block(3,21,1,WOOL:14)
Block(3,21,2,WOOL:14)
Block(3,21,3,WOOL:14)
Block(3,22,-1,WOOL:14)
Block(3,22,0,WOOL:14)
Block(3,22,1,WOOL:14)
Block(3,22,2,WOOL:14)
Block(3,22,3,WOOL:14)
Block(3,23,0,WOOL:14)
Block(3,23,1,WOOL:14)
Block(3,23,2,WOOL:14)
Block(3,55,-7,LEAVES:0)
Block(3,56,-7,LEAVES:0)
Block(3,57,-7,LEAVES:0)
Block(3,57,-6,LEAVES:0)
Block(3,57,-5,LEAVES:0)
Block(3,58,-7,LEAVES:0)
Block(3,58,-6,LEAVES:0)
Block(3,59,-7,LEAVES:0)
Block(3,59,-6,LEAVES:0)
Block(3,60,-7,LEAVES:0)
Block(3,60,-6,LEAVES:0)
Block(3,61,-6,VINE:12)
Block(3,62,-6,VINE:12)
Block(3,63,-7,LOG:12)
Block(3,63,-6,VINE:12)
Block(3,64,-7,LOG:12)
Block(3,64,-6,VINE:12)
Block(3,65,-7,LOG:12)
Block(3,65,-6,VINE:12)
Block(3,66,-7,LOG:12)
Block(3,66,-6,VINE:12)
Block(3,67,-7,LOG:12)
Block(3,67,-6,VINE:12)
Block(3,68,-7,LOG:12)
Block(3,68,-6,LEAVES:0)
Block(3,68,-5,LEAVES:0)
Block(3,68,-4,LEAVES:0)
Block(3,69,-7,LOG:12)
Block(3,69,-6,LEAVES:0)
Block(3,69,-5,LEAVES:0)
Block(3,69,-4,LEAVES:0)
Block(3,70,-7,LOG:12)
Block(3,70,-6,LEAVES:0)
Block(3,70,-5,LEAVES:0)
Block(3,71,-7,LOG:12)
Block(3,71,-6,LOG:12)
Block(3,71,-5,LEAVES:0)
Block(3,72,-7,LOG:12)
Block(3,72,-6,LEAVES:0)
Block(3,72,-5,LEAVES:0)
Block(3,72,-4,LEAVES:0)
Block(3,72,-3,LEAVES:0)
Block(3,73,-7,LOG:12)
Block(3,73,-6,LOG:12)
Block(3,73,-5,LOG:12)
Block(3,73,-4,LEAVES:0)
Block(3,73,-3,LEAVES:0)
Block(3,74,-7,LOG:12)
Block(3,74,-6,LEAVES:0)
Block(3,74,-5,LEAVES:0)
Block(3,74,-4,LEAVES:0)
Block(3,74,-3,LEAVES:0)
Block(3,75,-7,LOG:12)
Block(3,75,-6,LEAVES:0)
Block(3,75,-5,LEAVES:0)
Block(3,75,-4,LEAVES:0)
Block(3,75,-3,LEAVES:0)
Block(3,75,-2,LEAVES:0)
Block(3,75,-1,LEAVES:0)
Block(3,76,-7,LOG:12)
Block(3,76,-6,LEAVES:0)
Block(3,76,-5,LEAVES:0)
Block(3,76,-4,LEAVES:0)
Block(3,76,-3,LEAVES:0)
Block(3,76,-2,LEAVES:0)
Block(3,77,-7,LEAVES:0)
Block(3,77,-6,LEAVES:0)
Block(3,77,-5,LEAVES:0)
Block(3,77,-4,LEAVES:0)
Block(3,77,-3,LEAVES:0)
Block(3,78,-7,LEAVES:0)
Block(3,78,-6,LEAVES:0)
Block(3,78,-5,LEAVES:0)
Block(3,79,-7,LEAVES:0)
Block(3,79,-6,LEAVES:0)
Block(3,81,-7,LEAVES:0)
RandomBlock(3,91,-3,minecraft:wool:0,10,quark:quilted_wool:0,100)
RandomBlock(3,92,-5,minecraft:wool:0,10,quark:quilted_wool:0,100)
RandomBlock(3,92,-4,minecraft:wool:0,10,quark:quilted_wool:0,100)
RandomBlock(3,92,-3,minecraft:wool:0,10,quark:quilted_wool:0,100)
RandomBlock(3,92,-2,minecraft:wool:0,10,quark:quilted_wool:0,100)
RandomBlock(3,92,-1,minecraft:wool:0,10,quark:quilted_wool:0,100)
RandomBlock(3,93,-5,minecraft:wool:0,10,quark:quilted_wool:0,100)
RandomBlock(3,93,-4,minecraft:wool:0,10,quark:quilted_wool:0,100)
RandomBlock(3,93,-3,minecraft:wool:0,10,quark:quilted_wool:0,100)
RandomBlock(3,93,-2,minecraft:wool:0,10,quark:quilted_wool:0,100)
RandomBlock(3,93,-1,minecraft:wool:0,10,quark:quilted_wool:0,100)
RandomBlock(3,94,-6,minecraft:wool:0,10,quark:quilted_wool:0,100)
RandomBlock(3,94,-5,minecraft:wool:0,10,quark:quilted_wool:0,100)
RandomBlock(3,94,-4,minecraft:wool:0,10,quark:quilted_wool:0,100)
RandomBlock(3,94,-3,minecraft:wool:0,10,quark:quilted_wool:0,100)
RandomBlock(3,94,-2,minecraft:wool:0,10,quark:quilted_wool:0,100)
RandomBlock(3,94,-1,minecraft:wool:0,10,quark:quilted_wool:0,100)
RandomBlock(3,94,0,minecraft:wool:0,10,quark:quilted_wool:0,100)
RandomBlock(3,95,-6,minecraft:wool:0,10,quark:quilted_wool:0,100)
RandomBlock(3,95,-5,minecraft:wool:0,10,quark:quilted_wool:0,100)
RandomBlock(3,95,-4,minecraft:wool:0,10,quark:quilted_wool:0,100)
RandomBlock(3,95,-3,minecraft:wool:0,10,quark:quilted_wool:0,100)
RandomBlock(3,95,-2,minecraft:wool:0,10,quark:quilted_wool:0,100)
RandomBlock(3,95,-1,minecraft:wool:0,10,quark:quilted_wool:0,100)
RandomBlock(3,95,0,minecraft:wool:0,10,quark:quilted_wool:0,100)
RandomBlock(3,96,-6,minecraft:wool:0,10,quark:quilted_wool:0,100)
RandomBlock(3,96,-5,minecraft:wool:0,10,quark:quilted_wool:0,100)
RandomBlock(3,96,-4,minecraft:wool:0,10,quark:quilted_wool:0,100)
RandomBlock(3,96,-3,minecraft:wool:0,10,quark:quilted_wool:0,100)
RandomBlock(3,96,-2,minecraft:wool:0,10,quark:quilted_wool:0,100)
RandomBlock(3,96,-1,minecraft:wool:0,10,quark:quilted_wool:0,100)
RandomBlock(3,96,0,minecraft:wool:0,10,quark:quilted_wool:0,100)
RandomBlock(3,97,-6,minecraft:wool:0,10,quark:quilted_wool:0,100)
RandomBlock(3,97,-5,minecraft:wool:0,10,quark:quilted_wool:0,100)
RandomBlock(3,97,-4,minecraft:wool:0,10,quark:quilted_wool:0,100)
RandomBlock(3,97,-3,minecraft:wool:0,10,quark:quilted_wool:0,100)
RandomBlock(3,97,-2,minecraft:wool:0,10,quark:quilted_wool:0,100)
RandomBlock(3,97,-1,minecraft:wool:0,10,quark:quilted_wool:0,100)
RandomBlock(3,97,0,minecraft:wool:0,10,quark:quilted_wool:0,100)
RandomBlock(3,98,-6,minecraft:wool:0,10,quark:quilted_wool:0,100)
RandomBlock(3,98,-5,minecraft:wool:0,10,quark:quilted_wool:0,100)
RandomBlock(3,98,-4,minecraft:wool:0,10,quark:quilted_wool:0,100)
RandomBlock(3,98,-3,minecraft:wool:0,10,quark:quilted_wool:0,100)
RandomBlock(3,98,-2,minecraft:wool:0,10,quark:quilted_wool:0,100)
RandomBlock(3,98,-1,minecraft:wool:0,10,quark:quilted_wool:0,100)
RandomBlock(3,98,0,minecraft:wool:0,10,quark:quilted_wool:0,100)
RandomBlock(3,99,-6,minecraft:wool:0,10,quark:quilted_wool:0,100)
RandomBlock(3,99,-5,minecraft:wool:0,10,quark:quilted_wool:0,100)
RandomBlock(3,99,-4,minecraft:wool:0,10,quark:quilted_wool:0,100)
RandomBlock(3,99,-3,minecraft:wool:0,10,quark:quilted_wool:0,100)
RandomBlock(3,99,-2,minecraft:wool:0,10,quark:quilted_wool:0,100)
RandomBlock(3,99,-1,minecraft:wool:0,10,quark:quilted_wool:0,100)
RandomBlock(3,99,0,minecraft:wool:0,10,quark:quilted_wool:0,100)
RandomBlock(3,100,-6,minecraft:wool:0,10,quark:quilted_wool:0,100)
RandomBlock(3,100,-5,minecraft:wool:0,10,quark:quilted_wool:0,100)
RandomBlock(3,100,-4,minecraft:wool:0,10,quark:quilted_wool:0,100)
RandomBlock(3,100,-3,minecraft:wool:0,10,quark:quilted_wool:0,100)
RandomBlock(3,100,-2,minecraft:wool:0,10,quark:quilted_wool:0,100)
RandomBlock(3,100,-1,minecraft:wool:0,10,quark:quilted_wool:0,100)
RandomBlock(3,100,0,minecraft:wool:0,10,quark:quilted_wool:0,100)
RandomBlock(3,101,-6,minecraft:wool:0,10,quark:quilted_wool:0,100)
RandomBlock(3,101,-5,minecraft:wool:0,10,quark:quilted_wool:0,100)
RandomBlock(3,101,-4,minecraft:wool:0,10,quark:quilted_wool:0,100)
RandomBlock(3,101,-3,minecraft:wool:0,10,quark:quilted_wool:0,100)
RandomBlock(3,101,-2,minecraft:wool:0,10,quark:quilted_wool:0,100)
RandomBlock(3,101,-1,minecraft:wool:0,10,quark:quilted_wool:0,100)
RandomBlock(3,101,0,minecraft:wool:0,10,quark:quilted_wool:0,100)
RandomBlock(3,102,-6,minecraft:wool:0,10,quark:quilted_wool:0,100)
RandomBlock(3,102,-5,minecraft:wool:0,10,quark:quilted_wool:0,100)
RandomBlock(3,102,-4,minecraft:wool:0,10,quark:quilted_wool:0,100)
RandomBlock(3,102,-3,minecraft:wool:0,10,quark:quilted_wool:0,100)
RandomBlock(3,102,-2,minecraft:wool:0,10,quark:quilted_wool:0,100)
RandomBlock(3,102,-1,minecraft:wool:0,10,quark:quilted_wool:0,100)
RandomBlock(3,102,0,minecraft:wool:0,10,quark:quilted_wool:0,100)
RandomBlock(3,103,-5,minecraft:wool:0,10,quark:quilted_wool:0,100)
RandomBlock(3,103,-4,minecraft:wool:0,10,quark:quilted_wool:0,100)
RandomBlock(3,103,-3,minecraft:wool:0,10,quark:quilted_wool:0,100)
RandomBlock(3,103,-2,minecraft:wool:0,10,quark:quilted_wool:0,100)
RandomBlock(3,103,-1,minecraft:wool:0,10,quark:quilted_wool:0,100)
RandomBlock(3,104,-5,minecraft:wool:0,10,quark:quilted_wool:0,100)
RandomBlock(3,104,-4,minecraft:wool:0,10,quark:quilted_wool:0,100)
RandomBlock(3,104,-3,minecraft:wool:0,10,quark:quilted_wool:0,100)
RandomBlock(3,104,-2,minecraft:wool:0,10,quark:quilted_wool:0,100)
RandomBlock(3,104,-1,minecraft:wool:0,10,quark:quilted_wool:0,100)
RandomBlock(3,105,-3,minecraft:wool:0,10,quark:quilted_wool:0,100)
Block(4,5,-3,LOG:12)
Block(4,6,-4,LOG:12)
Block(4,6,-3,LOG:12)
Block(4,6,-2,LOG:12)
Block(4,6,0,LOG:12)
Block(4,7,-3,LOG:12)
Block(4,7,-1,LOG:12)
Block(4,7,0,LOG:12)
Block(4,7,1,LOG:12)
Block(4,8,-1,LOG:12)
Block(4,8,0,LOG:12)
Block(4,8,1,LOG:12)
Block(4,9,-1,LOG:12)
Block(4,9,0,LOG:12)
Block(4,9,1,LOG:12)
Block(4,10,0,LOG:12)
Block(4,10,1,quark:leaf_carpet)
Block(4,18,1,WOOL:14)
Block(4,19,0,WOOL:14)
Block(4,19,1,WOOL:14)
Block(4,19,2,WOOL:14)
Block(4,20,0,WOOL:14)
Block(4,20,1,WOOL:14)
Block(4,20,2,WOOL:14)
Block(4,21,0,WOOL:14)
Block(4,21,1,WOOL:14)
Block(4,21,2,WOOL:14)
Block(4,22,1,WOOL:14)
Block(4,34,-5,VINE:4)
Block(4,35,-5,VINE:4)
Block(4,36,-5,VINE:4)
Block(4,37,-5,VINE:4)
Block(4,38,-5,VINE:4)
Block(4,39,-5,VINE:4)
Block(4,40,-5,VINE:4)
Block(4,41,-5,VINE:4)
Block(4,42,-5,VINE:4)
Block(4,43,-5,VINE:4)
Block(4,44,-5,VINE:4)
Block(4,45,-5,VINE:4)
Block(4,46,-5,VINE:4)
Block(4,47,-5,VINE:4)
Block(4,48,-5,VINE:4)
Block(4,49,-5,VINE:4)
Block(4,50,-5,VINE:4)
Block(4,51,-5,VINE:4)
Block(4,52,-5,VINE:4)
Block(4,53,-5,VINE:4)
Block(4,54,-5,VINE:4)
Block(4,54,-4,LEAVES:0)
Block(4,54,-3,LEAVES:0)
Block(4,54,-2,LEAVES:0)
Block(4,54,-1,LEAVES:0)
Block(4,55,-7,LEAVES:0)
Block(4,55,-6,LEAVES:0)
Block(4,55,-5,VINE:4)
Block(4,55,-4,LEAVES:0)
Block(4,55,-3,LEAVES:0)
Block(4,55,-2,LEAVES:0)
Block(4,55,-1,LEAVES:0)
Block(4,55,0,LEAVES:0)
Block(4,56,-7,LEAVES:0)
Block(4,56,-6,LEAVES:0)
Block(4,56,-5,VINE:4)
Block(4,57,-7,LEAVES:0)
Block(4,57,-5,VINE:4)
Block(4,58,-7,LEAVES:0)
Block(4,58,-5,VINE:4)
Block(4,59,-7,LEAVES:0)
Block(4,59,-5,VINE:4)
Block(4,60,-5,VINE:4)
Block(4,61,-5,VINE:4)
Block(4,62,-7,LOG:12)
Block(4,62,-6,LOG:12)
Block(4,62,-5,VINE:4)
Block(4,63,-6,LOG:12)
Block(4,63,-5,VINE:4)
Block(4,64,-6,LOG:12)
Block(4,64,-5,VINE:4)
Block(4,65,-6,LOG:12)
Block(4,65,-5,VINE:4)
Block(4,66,-6,LOG:12)
Block(4,66,-5,VINE:4)
Block(4,67,-6,LOG:12)
Block(4,67,-5,VINE:4)
Block(4,68,-7,LEAVES:0)
Block(4,68,-6,LOG:12)
Block(4,68,-5,LEAVES:0)
Block(4,68,-4,LEAVES:0)
Block(4,69,-7,LEAVES:0)
Block(4,69,-6,LOG:12)
Block(4,69,-5,LEAVES:0)
Block(4,69,-4,LEAVES:0)
Block(4,70,-7,LEAVES:0)
Block(4,70,-6,LOG:12)
Block(4,70,-5,LOG:12)
Block(4,71,-7,LEAVES:0)
Block(4,71,-6,LEAVES:0)
Block(4,71,-5,LEAVES:0)
Block(4,71,-4,LEAVES:0)
Block(4,72,-7,LEAVES:0)
Block(4,72,-6,LEAVES:0)
Block(4,72,-5,LEAVES:0)
Block(4,72,-4,LEAVES:0)
Block(4,72,-3,LEAVES:0)
Block(4,72,-2,LEAVES:0)
Block(4,73,-7,LEAVES:0)
Block(4,73,-6,LEAVES:0)
Block(4,73,-5,LEAVES:0)
Block(4,73,-4,LEAVES:0)
Block(4,73,-3,LEAVES:0)
Block(4,73,-2,LEAVES:0)
Block(4,74,-7,LEAVES:0)
Block(4,74,-6,LEAVES:0)
Block(4,74,-5,LEAVES:0)
Block(4,74,-4,LEAVES:0)
Block(4,75,-7,LEAVES:0)
Block(4,75,-6,LOG:12)
Block(4,75,-5,LEAVES:0)
Block(4,75,-4,LEAVES:0)
Block(4,75,-3,LEAVES:0)
Block(4,75,-2,LEAVES:0)
Block(4,76,-7,LEAVES:0)
Block(4,76,-6,LEAVES:0)
Block(4,76,-5,LEAVES:0)
Block(4,76,-4,LEAVES:0)
Block(4,76,-3,LEAVES:0)
Block(4,76,-2,LEAVES:0)
Block(4,77,-7,LEAVES:0)
Block(4,77,-6,LEAVES:0)
Block(4,77,-5,LEAVES:0)
Block(4,77,-4,LEAVES:0)
Block(4,77,-3,LEAVES:0)
Block(4,78,-7,LEAVES:0)
Block(4,78,-6,LEAVES:0)
Block(4,78,-5,LEAVES:0)
Block(4,79,-7,LEAVES:0)
Block(4,80,-7,LEAVES:0)
Block(4,80,-6,LEAVES:0)
Block(4,81,-7,LEAVES:0)
Block(4,81,-6,LEAVES:0)
Block(4,82,-7,LEAVES:0)
RandomBlock(4,90,-4,minecraft:wool:0,10,quark:quilted_wool:0,100)
RandomBlock(4,90,-3,minecraft:wool:0,10,quark:quilted_wool:0,100)
RandomBlock(4,90,-2,minecraft:wool:0,10,quark:quilted_wool:0,100)
RandomBlock(4,91,-5,minecraft:wool:0,10,quark:quilted_wool:0,100)
RandomBlock(4,91,-4,minecraft:wool:0,10,quark:quilted_wool:0,100)
RandomBlock(4,91,-3,minecraft:wool:0,10,quark:quilted_wool:0,100)
RandomBlock(4,91,-2,minecraft:wool:0,10,quark:quilted_wool:0,100)
RandomBlock(4,91,-1,minecraft:wool:0,10,quark:quilted_wool:0,100)
RandomBlock(4,92,-6,minecraft:wool:0,10,quark:quilted_wool:0,100)
RandomBlock(4,92,-5,minecraft:wool:0,10,quark:quilted_wool:0,100)
RandomBlock(4,92,-4,minecraft:wool:0,10,quark:quilted_wool:0,100)
RandomBlock(4,92,-3,minecraft:wool:0,10,quark:quilted_wool:0,100)
RandomBlock(4,92,-2,minecraft:wool:0,10,quark:quilted_wool:0,100)
RandomBlock(4,92,-1,minecraft:wool:0,10,quark:quilted_wool:0,100)
RandomBlock(4,92,0,minecraft:wool:0,10,quark:quilted_wool:0,100)
RandomBlock(4,93,-6,minecraft:wool:0,10,quark:quilted_wool:0,100)
RandomBlock(4,93,-5,minecraft:wool:0,10,quark:quilted_wool:0,100)
RandomBlock(4,93,-4,minecraft:wool:0,10,quark:quilted_wool:0,100)
RandomBlock(4,93,-3,minecraft:wool:0,10,quark:quilted_wool:0,100)
RandomBlock(4,93,-2,minecraft:wool:0,10,quark:quilted_wool:0,100)
RandomBlock(4,93,-1,minecraft:wool:0,10,quark:quilted_wool:0,100)
RandomBlock(4,93,0,minecraft:wool:0,10,quark:quilted_wool:0,100)
RandomBlock(4,94,-7,minecraft:wool:0,10,quark:quilted_wool:0,100)
RandomBlock(4,94,-6,minecraft:wool:0,10,quark:quilted_wool:0,100)
RandomBlock(4,94,-5,minecraft:wool:0,10,quark:quilted_wool:0,100)
RandomBlock(4,94,-4,minecraft:wool:0,10,quark:quilted_wool:0,100)
RandomBlock(4,94,-3,minecraft:wool:0,10,quark:quilted_wool:0,100)
RandomBlock(4,94,-2,minecraft:wool:0,10,quark:quilted_wool:0,100)
RandomBlock(4,94,-1,minecraft:wool:0,10,quark:quilted_wool:0,100)
RandomBlock(4,94,0,minecraft:wool:0,10,quark:quilted_wool:0,100)
RandomBlock(4,94,1,minecraft:wool:0,10,quark:quilted_wool:0,100)
RandomBlock(4,95,-7,minecraft:wool:0,10,quark:quilted_wool:0,100)
RandomBlock(4,95,-6,minecraft:wool:0,10,quark:quilted_wool:0,100)
RandomBlock(4,95,-5,minecraft:wool:0,10,quark:quilted_wool:0,100)
RandomBlock(4,95,-4,minecraft:wool:0,10,quark:quilted_wool:0,100)
RandomBlock(4,95,-3,minecraft:wool:0,10,quark:quilted_wool:0,100)
RandomBlock(4,95,-2,minecraft:wool:0,10,quark:quilted_wool:0,100)
RandomBlock(4,95,-1,minecraft:wool:0,10,quark:quilted_wool:0,100)
RandomBlock(4,95,0,minecraft:wool:0,10,quark:quilted_wool:0,100)
RandomBlock(4,95,1,minecraft:wool:0,10,quark:quilted_wool:0,100)
RandomBlock(4,96,-7,minecraft:wool:0,10,quark:quilted_wool:0,100)
RandomBlock(4,96,-6,minecraft:wool:0,10,quark:quilted_wool:0,100)
RandomBlock(4,96,-5,minecraft:wool:0,10,quark:quilted_wool:0,100)
RandomBlock(4,96,-4,minecraft:wool:0,10,quark:quilted_wool:0,100)
RandomBlock(4,96,-3,minecraft:wool:0,10,quark:quilted_wool:0,100)
RandomBlock(4,96,-2,minecraft:wool:0,10,quark:quilted_wool:0,100)
RandomBlock(4,96,-1,minecraft:wool:0,10,quark:quilted_wool:0,100)
RandomBlock(4,96,0,minecraft:wool:0,10,quark:quilted_wool:0,100)
RandomBlock(4,96,1,minecraft:wool:0,10,quark:quilted_wool:0,100)
RandomBlock(4,97,-7,minecraft:wool:0,10,quark:quilted_wool:0,100)
RandomBlock(4,97,-6,minecraft:wool:0,10,quark:quilted_wool:0,100)
RandomBlock(4,97,-5,minecraft:wool:0,10,quark:quilted_wool:0,100)
RandomBlock(4,97,-4,minecraft:wool:0,10,quark:quilted_wool:0,100)
RandomBlock(4,97,-3,minecraft:wool:0,10,quark:quilted_wool:0,100)
RandomBlock(4,97,-2,minecraft:wool:0,10,quark:quilted_wool:0,100)
RandomBlock(4,97,-1,minecraft:wool:0,10,quark:quilted_wool:0,100)
RandomBlock(4,97,0,minecraft:wool:0,10,quark:quilted_wool:0,100)
RandomBlock(4,97,1,minecraft:wool:0,10,quark:quilted_wool:0,100)
RandomBlock(4,98,-7,minecraft:wool:0,10,quark:quilted_wool:0,100)
RandomBlock(4,98,-6,minecraft:wool:0,10,quark:quilted_wool:0,100)
RandomBlock(4,98,-5,minecraft:wool:0,10,quark:quilted_wool:0,100)
RandomBlock(4,98,-4,minecraft:wool:0,10,quark:quilted_wool:0,100)
RandomBlock(4,98,-3,minecraft:wool:0,10,quark:quilted_wool:0,100)
RandomBlock(4,98,-2,minecraft:wool:0,10,quark:quilted_wool:0,100)
RandomBlock(4,98,-1,minecraft:wool:0,10,quark:quilted_wool:0,100)
RandomBlock(4,98,0,minecraft:wool:0,10,quark:quilted_wool:0,100)
RandomBlock(4,98,1,minecraft:wool:0,10,quark:quilted_wool:0,100)
RandomBlock(4,99,-7,minecraft:wool:0,10,quark:quilted_wool:0,100)
RandomBlock(4,99,-6,minecraft:wool:0,10,quark:quilted_wool:0,100)
RandomBlock(4,99,-5,minecraft:wool:0,10,quark:quilted_wool:0,100)
RandomBlock(4,99,-4,minecraft:wool:0,10,quark:quilted_wool:0,100)
RandomBlock(4,99,-3,minecraft:wool:0,10,quark:quilted_wool:0,100)
RandomBlock(4,99,-2,minecraft:wool:0,10,quark:quilted_wool:0,100)
RandomBlock(4,99,-1,minecraft:wool:0,10,quark:quilted_wool:0,100)
RandomBlock(4,99,0,minecraft:wool:0,10,quark:quilted_wool:0,100)
RandomBlock(4,99,1,minecraft:wool:0,10,quark:quilted_wool:0,100)
RandomBlock(4,100,-7,minecraft:wool:0,10,quark:quilted_wool:0,100)
RandomBlock(4,100,-6,minecraft:wool:0,10,quark:quilted_wool:0,100)
RandomBlock(4,100,-5,minecraft:wool:0,10,quark:quilted_wool:0,100)
RandomBlock(4,100,-4,minecraft:wool:0,10,quark:quilted_wool:0,100)
RandomBlock(4,100,-3,minecraft:wool:0,10,quark:quilted_wool:0,100)
RandomBlock(4,100,-2,minecraft:wool:0,10,quark:quilted_wool:0,100)
RandomBlock(4,100,-1,minecraft:wool:0,10,quark:quilted_wool:0,100)
RandomBlock(4,100,0,minecraft:wool:0,10,quark:quilted_wool:0,100)
RandomBlock(4,100,1,minecraft:wool:0,10,quark:quilted_wool:0,100)
RandomBlock(4,101,-7,minecraft:wool:0,10,quark:quilted_wool:0,100)
RandomBlock(4,101,-6,minecraft:wool:0,10,quark:quilted_wool:0,100)
RandomBlock(4,101,-5,minecraft:wool:0,10,quark:quilted_wool:0,100)
RandomBlock(4,101,-4,minecraft:wool:0,10,quark:quilted_wool:0,100)
RandomBlock(4,101,-3,minecraft:wool:0,10,quark:quilted_wool:0,100)
RandomBlock(4,101,-2,minecraft:wool:0,10,quark:quilted_wool:0,100)
RandomBlock(4,101,-1,minecraft:wool:0,10,quark:quilted_wool:0,100)
RandomBlock(4,101,0,minecraft:wool:0,10,quark:quilted_wool:0,100)
RandomBlock(4,101,1,minecraft:wool:0,10,quark:quilted_wool:0,100)
RandomBlock(4,102,-7,minecraft:wool:0,10,quark:quilted_wool:0,100)
RandomBlock(4,102,-6,minecraft:wool:0,10,quark:quilted_wool:0,100)
RandomBlock(4,102,-5,minecraft:wool:0,10,quark:quilted_wool:0,100)
RandomBlock(4,102,-4,minecraft:wool:0,10,quark:quilted_wool:0,100)
RandomBlock(4,102,-3,minecraft:wool:0,10,quark:quilted_wool:0,100)
RandomBlock(4,102,-2,minecraft:wool:0,10,quark:quilted_wool:0,100)
RandomBlock(4,102,-1,minecraft:wool:0,10,quark:quilted_wool:0,100)
RandomBlock(4,102,0,minecraft:wool:0,10,quark:quilted_wool:0,100)
RandomBlock(4,102,1,minecraft:wool:0,10,quark:quilted_wool:0,100)
RandomBlock(4,103,-6,minecraft:wool:0,10,quark:quilted_wool:0,100)
RandomBlock(4,103,-5,minecraft:wool:0,10,quark:quilted_wool:0,100)
RandomBlock(4,103,-4,minecraft:wool:0,10,quark:quilted_wool:0,100)
RandomBlock(4,103,-3,minecraft:wool:0,10,quark:quilted_wool:0,100)
RandomBlock(4,103,-2,minecraft:wool:0,10,quark:quilted_wool:0,100)
RandomBlock(4,103,-1,minecraft:wool:0,10,quark:quilted_wool:0,100)
RandomBlock(4,103,0,minecraft:wool:0,10,quark:quilted_wool:0,100)
RandomBlock(4,104,-6,minecraft:wool:0,10,quark:quilted_wool:0,100)
RandomBlock(4,104,-5,minecraft:wool:0,10,quark:quilted_wool:0,100)
RandomBlock(4,104,-4,minecraft:wool:0,10,quark:quilted_wool:0,100)
RandomBlock(4,104,-3,minecraft:wool:0,10,quark:quilted_wool:0,100)
RandomBlock(4,104,-2,minecraft:wool:0,10,quark:quilted_wool:0,100)
RandomBlock(4,104,-1,minecraft:wool:0,10,quark:quilted_wool:0,100)
RandomBlock(4,104,0,minecraft:wool:0,10,quark:quilted_wool:0,100)
RandomBlock(4,105,-5,minecraft:wool:0,10,quark:quilted_wool:0,100)
RandomBlock(4,105,-4,minecraft:wool:0,10,quark:quilted_wool:0,100)
RandomBlock(4,105,-3,minecraft:wool:0,10,quark:quilted_wool:0,100)
RandomBlock(4,105,-2,minecraft:wool:0,10,quark:quilted_wool:0,100)
RandomBlock(4,105,-1,minecraft:wool:0,10,quark:quilted_wool:0,100)
RandomBlock(4,106,-4,minecraft:wool:0,10,quark:quilted_wool:0,100)
RandomBlock(4,106,-3,minecraft:wool:0,10,quark:quilted_wool:0,100)
RandomBlock(4,106,-2,minecraft:wool:0,10,quark:quilted_wool:0,100)
Block(5,5,-4,LOG:12)
Block(5,5,-3,LOG:12)
Block(5,5,-2,LOG:12)
Block(5,6,-4,LOG:12)
Block(5,6,-3,LOG:12)
Block(5,6,-2,LOG:12)
Block(5,7,-5,LOG:12)
Block(5,7,-4,LOG:12)
Block(5,7,-3,LOG:12)
Block(5,7,-2,LOG:12)
Block(5,7,0,LOG:12)
Block(5,8,-4,LOG:12)
Block(5,8,-3,quark:leaf_carpet)
Block(5,8,-1,LOG:12)
Block(5,8,0,LOG:12)
Block(5,8,1,LOG:12)
Block(5,9,-4,quark:leaf_carpet)
Block(5,9,-1,LOG:12)
Block(5,9,0,LOG:12)
Block(5,9,1,LOG:12)
Block(5,10,-1,LOG:12)
Block(5,10,0,LOG:12)
Block(5,10,1,LOG:12)
Block(5,11,-1,quark:leaf_carpet)
Block(5,11,0,quark:leaf_carpet)
Block(5,16,-7,LOG:12)
RandomBlock(5,35,-1,minecraft:wool:7,10,quark:quilted_wool:7,100)
RandomBlock(5,35,0,minecraft:wool:7,10,quark:quilted_wool:7,100)
RandomBlock(5,35,1,minecraft:wool:7,10,quark:quilted_wool:7,100)
RandomBlock(5,36,-1,minecraft:wool:7,10,quark:quilted_wool:7,100)
RandomBlock(5,36,0,minecraft:wool:7,10,quark:quilted_wool:7,100)
RandomBlock(5,36,1,minecraft:wool:7,10,quark:quilted_wool:7,100)
RandomBlock(5,37,-2,minecraft:wool:7,10,quark:quilted_wool:7,100)
RandomBlock(5,37,-1,minecraft:wool:7,10,quark:quilted_wool:7,100)
RandomBlock(5,37,0,minecraft:wool:7,10,quark:quilted_wool:7,100)
RandomBlock(5,37,1,minecraft:wool:7,10,quark:quilted_wool:7,100)
RandomBlock(5,37,2,minecraft:wool:7,10,quark:quilted_wool:7,100)
RandomBlock(5,38,-1,minecraft:wool:7,10,quark:quilted_wool:7,100)
RandomBlock(5,38,0,minecraft:wool:7,10,quark:quilted_wool:7,100)
RandomBlock(5,38,1,minecraft:wool:7,10,quark:quilted_wool:7,100)
RandomBlock(5,39,-1,minecraft:wool:7,10,quark:quilted_wool:7,100)
RandomBlock(5,39,0,minecraft:wool:7,10,quark:quilted_wool:7,100)
RandomBlock(5,39,1,minecraft:wool:7,10,quark:quilted_wool:7,100)
Block(5,54,-4,LEAVES:0)
Block(5,54,-3,LEAVES:0)
Block(5,54,-2,LEAVES:0)
Block(5,54,-1,LEAVES:0)
Block(5,54,0,LEAVES:0)
Block(5,55,-7,LEAVES:0)
Block(5,55,-6,LEAVES:0)
Block(5,55,-4,LEAVES:0)
Block(5,55,-3,LEAVES:0)
Block(5,55,-2,LEAVES:0)
Block(5,55,-1,LEAVES:0)
Block(5,55,0,LEAVES:0)
Block(5,56,-7,LEAVES:0)
Block(5,56,-6,LEAVES:0)
Block(5,56,-2,LEAVES:0)
Block(5,57,-7,LEAVES:0)
Block(5,57,-5,LEAVES:0)
Block(5,57,-4,LEAVES:0)
Block(5,57,-3,LEAVES:0)
Block(5,57,-2,LEAVES:0)
Block(5,58,-7,LEAVES:0)
Block(5,58,-6,LEAVES:0)
Block(5,58,-5,LEAVES:0)
Block(5,58,-4,LEAVES:0)
Block(5,58,-3,LEAVES:0)
Block(5,59,-6,VINE:2)
Block(5,60,-6,VINE:2)
Block(5,61,-6,VINE:2)
Block(5,62,-6,VINE:2)
Block(5,63,-7,LOG:12)
Block(5,63,-6,VINE:2)
Block(5,64,-7,LOG:12)
Block(5,64,-6,VINE:2)
Block(5,65,-7,LOG:12)
Block(5,65,-6,VINE:2)
Block(5,66,-7,LOG:12)
Block(5,66,-6,VINE:2)
Block(5,67,-7,LOG:12)
Block(5,68,-7,LOG:12)
Block(5,68,-6,LEAVES:0)
Block(5,68,-5,LEAVES:0)
Block(5,68,-4,LEAVES:0)
Block(5,69,-7,LOG:12)
Block(5,69,-6,LEAVES:0)
Block(5,69,-5,LEAVES:0)
Block(5,69,-4,LEAVES:0)
Block(5,70,-7,LOG:12)
Block(5,70,-6,LEAVES:0)
Block(5,70,-5,LEAVES:0)
Block(5,71,-7,LOG:12)
Block(5,71,-6,LEAVES:0)
Block(5,71,-5,LEAVES:0)
Block(5,71,-4,LOG:12)
Block(5,71,-3,LEAVES:0)
Block(5,72,-7,LEAVES:0)
Block(5,72,-6,LEAVES:0)
Block(5,72,-5,LEAVES:0)
Block(5,72,-4,LEAVES:0)
Block(5,72,-3,LEAVES:0)
Block(5,72,-2,LEAVES:0)
Block(5,73,-7,LEAVES:0)
Block(5,73,-6,LEAVES:0)
Block(5,73,-5,LEAVES:0)
Block(5,73,-4,LEAVES:0)
Block(5,73,-3,LEAVES:0)
Block(5,73,-2,LEAVES:0)
Block(5,74,-7,LEAVES:0)
Block(5,74,-6,LEAVES:0)
Block(5,74,-5,LEAVES:0)
Block(5,74,-4,LEAVES:0)
Block(5,74,-3,LEAVES:0)
Block(5,75,-7,LOG:12)
Block(5,75,-6,LEAVES:0)
Block(5,75,-5,LEAVES:0)
Block(5,75,-4,rustic:iron_lantern:0)
Block(5,76,-7,LEAVES:0)
Block(5,76,-6,LEAVES:0)
Block(5,76,-5,LEAVES:0)
Block(5,76,-4,LEAVES:0)
Block(5,76,-3,LEAVES:0)
Block(5,76,-2,LEAVES:0)
Block(5,77,-7,LEAVES:0)
Block(5,77,-6,LEAVES:0)
Block(5,77,-5,LEAVES:0)
Block(5,77,-4,LEAVES:0)
Block(5,77,-3,LEAVES:0)
Block(5,77,-2,LEAVES:0)
Block(5,78,-7,LEAVES:0)
Block(5,78,-6,LEAVES:0)
Block(5,78,-4,LEAVES:0)
Block(5,79,-7,LEAVES:0)
Block(5,79,-4,LEAVES:0)
Block(5,80,-7,LEAVES:0)
Block(5,80,-6,LEAVES:0)
Block(5,80,-5,LEAVES:0)
Block(5,81,-7,LEAVES:0)
Block(5,81,-6,LEAVES:0)
Block(5,81,-5,LEAVES:0)
Block(5,82,-7,LEAVES:0)
Block(5,82,-6,LEAVES:0)
Block(5,83,-7,LEAVES:0)
RandomBlock(5,89,-5,minecraft:wool:0,10,quark:quilted_wool:0,100)
RandomBlock(5,89,-4,minecraft:wool:0,10,quark:quilted_wool:0,100)
RandomBlock(5,89,-3,minecraft:wool:0,10,quark:quilted_wool:0,100)
RandomBlock(5,89,-2,minecraft:wool:0,10,quark:quilted_wool:0,100)
RandomBlock(5,89,-1,minecraft:wool:0,10,quark:quilted_wool:0,100)
RandomBlock(5,90,-5,minecraft:wool:0,10,quark:quilted_wool:0,100)
RandomBlock(5,90,-4,minecraft:wool:0,10,quark:quilted_wool:0,100)
RandomBlock(5,90,-3,minecraft:wool:0,10,quark:quilted_wool:0,100)
RandomBlock(5,90,-2,minecraft:wool:0,10,quark:quilted_wool:0,100)
RandomBlock(5,90,-1,minecraft:wool:0,10,quark:quilted_wool:0,100)
RandomBlock(5,91,-6,minecraft:wool:0,10,quark:quilted_wool:0,100)
RandomBlock(5,91,-5,minecraft:wool:0,10,quark:quilted_wool:0,100)
RandomBlock(5,91,-4,minecraft:wool:0,10,quark:quilted_wool:0,100)
RandomBlock(5,91,-3,minecraft:wool:0,10,quark:quilted_wool:0,100)
RandomBlock(5,91,-2,minecraft:wool:0,10,quark:quilted_wool:0,100)
RandomBlock(5,91,-1,minecraft:wool:0,10,quark:quilted_wool:0,100)
RandomBlock(5,91,0,minecraft:wool:0,10,quark:quilted_wool:0,100)
RandomBlock(5,92,-7,minecraft:wool:0,10,quark:quilted_wool:0,100)
RandomBlock(5,92,-6,minecraft:wool:0,10,quark:quilted_wool:0,100)
RandomBlock(5,92,-5,minecraft:wool:0,10,quark:quilted_wool:0,100)
RandomBlock(5,92,-4,minecraft:wool:0,10,quark:quilted_wool:0,100)
RandomBlock(5,92,-3,minecraft:wool:0,10,quark:quilted_wool:0,100)
RandomBlock(5,92,-2,minecraft:wool:0,10,quark:quilted_wool:0,100)
RandomBlock(5,92,-1,minecraft:wool:0,10,quark:quilted_wool:0,100)
RandomBlock(5,92,0,minecraft:wool:0,10,quark:quilted_wool:0,100)
RandomBlock(5,92,1,minecraft:wool:0,10,quark:quilted_wool:0,100)
RandomBlock(5,93,-7,minecraft:wool:0,10,quark:quilted_wool:0,100)
RandomBlock(5,93,-6,minecraft:wool:0,10,quark:quilted_wool:0,100)
RandomBlock(5,93,-5,minecraft:wool:0,10,quark:quilted_wool:0,100)
RandomBlock(5,93,-4,minecraft:wool:0,10,quark:quilted_wool:0,100)
RandomBlock(5,93,-3,minecraft:wool:0,10,quark:quilted_wool:0,100)
RandomBlock(5,93,-2,minecraft:wool:0,10,quark:quilted_wool:0,100)
RandomBlock(5,93,-1,minecraft:wool:0,10,quark:quilted_wool:0,100)
RandomBlock(5,93,0,minecraft:wool:0,10,quark:quilted_wool:0,100)
RandomBlock(5,93,1,minecraft:wool:0,10,quark:quilted_wool:0,100)
RandomBlock(5,94,-7,minecraft:wool:0,10,quark:quilted_wool:0,100)
RandomBlock(5,94,-6,minecraft:wool:0,10,quark:quilted_wool:0,100)
RandomBlock(5,94,-5,minecraft:wool:0,10,quark:quilted_wool:0,100)
RandomBlock(5,94,-4,minecraft:wool:0,10,quark:quilted_wool:0,100)
RandomBlock(5,94,-3,minecraft:wool:0,10,quark:quilted_wool:0,100)
RandomBlock(5,94,-2,minecraft:wool:0,10,quark:quilted_wool:0,100)
RandomBlock(5,94,-1,minecraft:wool:0,10,quark:quilted_wool:0,100)
RandomBlock(5,94,0,minecraft:wool:0,10,quark:quilted_wool:0,100)
RandomBlock(5,94,1,minecraft:wool:0,10,quark:quilted_wool:0,100)
RandomBlock(5,95,-7,minecraft:wool:0,10,quark:quilted_wool:0,100)
RandomBlock(5,95,-6,minecraft:wool:0,10,quark:quilted_wool:0,100)
RandomBlock(5,95,-5,minecraft:wool:0,10,quark:quilted_wool:0,100)
RandomBlock(5,95,-4,minecraft:wool:0,10,quark:quilted_wool:0,100)
RandomBlock(5,95,-3,minecraft:wool:0,10,quark:quilted_wool:0,100)
RandomBlock(5,95,-2,minecraft:wool:0,10,quark:quilted_wool:0,100)
RandomBlock(5,95,-1,minecraft:wool:0,10,quark:quilted_wool:0,100)
RandomBlock(5,95,0,minecraft:wool:0,10,quark:quilted_wool:0,100)
RandomBlock(5,95,1,minecraft:wool:0,10,quark:quilted_wool:0,100)
RandomBlock(5,96,-7,minecraft:wool:0,10,quark:quilted_wool:0,100)
RandomBlock(5,96,-6,minecraft:wool:0,10,quark:quilted_wool:0,100)
RandomBlock(5,96,-5,minecraft:wool:0,10,quark:quilted_wool:0,100)
RandomBlock(5,96,-4,minecraft:wool:0,10,quark:quilted_wool:0,100)
RandomBlock(5,96,-3,minecraft:wool:0,10,quark:quilted_wool:0,100)
RandomBlock(5,96,-2,minecraft:wool:0,10,quark:quilted_wool:0,100)
RandomBlock(5,96,-1,minecraft:wool:0,10,quark:quilted_wool:0,100)
RandomBlock(5,96,0,minecraft:wool:0,10,quark:quilted_wool:0,100)
RandomBlock(5,96,1,minecraft:wool:0,10,quark:quilted_wool:0,100)
RandomBlock(5,96,2,minecraft:wool:0,10,quark:quilted_wool:0,100)
RandomBlock(5,97,-7,minecraft:wool:0,10,quark:quilted_wool:0,100)
RandomBlock(5,97,-6,minecraft:wool:0,10,quark:quilted_wool:0,100)
RandomBlock(5,97,-5,minecraft:wool:0,10,quark:quilted_wool:0,100)
RandomBlock(5,97,-4,minecraft:wool:0,10,quark:quilted_wool:0,100)
RandomBlock(5,97,-3,minecraft:wool:0,10,quark:quilted_wool:0,100)
RandomBlock(5,97,-2,minecraft:wool:0,10,quark:quilted_wool:0,100)
RandomBlock(5,97,-1,minecraft:wool:0,10,quark:quilted_wool:0,100)
RandomBlock(5,97,0,minecraft:wool:0,10,quark:quilted_wool:0,100)
RandomBlock(5,97,1,minecraft:wool:0,10,quark:quilted_wool:0,100)
RandomBlock(5,97,2,minecraft:wool:0,10,quark:quilted_wool:0,100)
RandomBlock(5,98,-7,minecraft:wool:0,10,quark:quilted_wool:0,100)
RandomBlock(5,98,-6,minecraft:wool:0,10,quark:quilted_wool:0,100)
RandomBlock(5,98,-5,minecraft:wool:0,10,quark:quilted_wool:0,100)
RandomBlock(5,98,-4,minecraft:wool:0,10,quark:quilted_wool:0,100)
RandomBlock(5,98,-3,minecraft:wool:0,10,quark:quilted_wool:0,100)
RandomBlock(5,98,-2,minecraft:wool:0,10,quark:quilted_wool:0,100)
RandomBlock(5,98,-1,minecraft:wool:0,10,quark:quilted_wool:0,100)
RandomBlock(5,98,0,minecraft:wool:0,10,quark:quilted_wool:0,100)
RandomBlock(5,98,1,minecraft:wool:0,10,quark:quilted_wool:0,100)
RandomBlock(5,98,2,minecraft:wool:0,10,quark:quilted_wool:0,100)
RandomBlock(5,99,-7,minecraft:wool:0,10,quark:quilted_wool:0,100)
RandomBlock(5,99,-6,minecraft:wool:0,10,quark:quilted_wool:0,100)
RandomBlock(5,99,-5,minecraft:wool:0,10,quark:quilted_wool:0,100)
RandomBlock(5,99,-4,minecraft:wool:0,10,quark:quilted_wool:0,100)
RandomBlock(5,99,-3,minecraft:wool:0,10,quark:quilted_wool:0,100)
RandomBlock(5,99,-2,minecraft:wool:0,10,quark:quilted_wool:0,100)
RandomBlock(5,99,-1,minecraft:wool:0,10,quark:quilted_wool:0,100)
RandomBlock(5,99,0,minecraft:wool:0,10,quark:quilted_wool:0,100)
RandomBlock(5,99,1,minecraft:wool:0,10,quark:quilted_wool:0,100)
RandomBlock(5,99,2,minecraft:wool:0,10,quark:quilted_wool:0,100)
RandomBlock(5,100,-7,minecraft:wool:0,10,quark:quilted_wool:0,100)
RandomBlock(5,100,-6,minecraft:wool:0,10,quark:quilted_wool:0,100)
RandomBlock(5,100,-5,minecraft:wool:0,10,quark:quilted_wool:0,100)
RandomBlock(5,100,-4,minecraft:wool:0,10,quark:quilted_wool:0,100)
RandomBlock(5,100,-3,minecraft:wool:0,10,quark:quilted_wool:0,100)
RandomBlock(5,100,-2,minecraft:wool:0,10,quark:quilted_wool:0,100)
RandomBlock(5,100,-1,minecraft:wool:0,10,quark:quilted_wool:0,100)
RandomBlock(5,100,0,minecraft:wool:0,10,quark:quilted_wool:0,100)
RandomBlock(5,100,1,minecraft:wool:0,10,quark:quilted_wool:0,100)
RandomBlock(5,100,2,minecraft:wool:0,10,quark:quilted_wool:0,100)
RandomBlock(5,101,-7,minecraft:wool:0,10,quark:quilted_wool:0,100)
RandomBlock(5,101,-6,minecraft:wool:0,10,quark:quilted_wool:0,100)
RandomBlock(5,101,-5,minecraft:wool:0,10,quark:quilted_wool:0,100)
RandomBlock(5,101,-4,minecraft:wool:0,10,quark:quilted_wool:0,100)
RandomBlock(5,101,-3,minecraft:wool:0,10,quark:quilted_wool:0,100)
RandomBlock(5,101,-2,minecraft:wool:0,10,quark:quilted_wool:0,100)
RandomBlock(5,101,-1,minecraft:wool:0,10,quark:quilted_wool:0,100)
RandomBlock(5,101,0,minecraft:wool:0,10,quark:quilted_wool:0,100)
RandomBlock(5,101,1,minecraft:wool:0,10,quark:quilted_wool:0,100)
RandomBlock(5,102,-7,minecraft:wool:0,10,quark:quilted_wool:0,100)
RandomBlock(5,102,-6,minecraft:wool:0,10,quark:quilted_wool:0,100)
RandomBlock(5,102,-5,minecraft:wool:0,10,quark:quilted_wool:0,100)
RandomBlock(5,102,-4,minecraft:wool:0,10,quark:quilted_wool:0,100)
RandomBlock(5,102,-3,minecraft:wool:0,10,quark:quilted_wool:0,100)
RandomBlock(5,102,-2,minecraft:wool:0,10,quark:quilted_wool:0,100)
RandomBlock(5,102,-1,minecraft:wool:0,10,quark:quilted_wool:0,100)
RandomBlock(5,102,0,minecraft:wool:0,10,quark:quilted_wool:0,100)
RandomBlock(5,102,1,minecraft:wool:0,10,quark:quilted_wool:0,100)
RandomBlock(5,103,-7,minecraft:wool:0,10,quark:quilted_wool:0,100)
RandomBlock(5,103,-6,minecraft:wool:0,10,quark:quilted_wool:0,100)
RandomBlock(5,103,-5,minecraft:wool:0,10,quark:quilted_wool:0,100)
RandomBlock(5,103,-4,minecraft:wool:0,10,quark:quilted_wool:0,100)
RandomBlock(5,103,-3,minecraft:wool:0,10,quark:quilted_wool:0,100)
RandomBlock(5,103,-2,minecraft:wool:0,10,quark:quilted_wool:0,100)
RandomBlock(5,103,-1,minecraft:wool:0,10,quark:quilted_wool:0,100)
RandomBlock(5,103,0,minecraft:wool:0,10,quark:quilted_wool:0,100)
RandomBlock(5,103,1,minecraft:wool:0,10,quark:quilted_wool:0,100)
RandomBlock(5,104,-7,minecraft:wool:0,10,quark:quilted_wool:0,100)
RandomBlock(5,104,-6,minecraft:wool:0,10,quark:quilted_wool:0,100)
RandomBlock(5,104,-5,minecraft:wool:0,10,quark:quilted_wool:0,100)
RandomBlock(5,104,-4,minecraft:wool:0,10,quark:quilted_wool:0,100)
RandomBlock(5,104,-3,minecraft:wool:0,10,quark:quilted_wool:0,100)
RandomBlock(5,104,-2,minecraft:wool:0,10,quark:quilted_wool:0,100)
RandomBlock(5,104,-1,minecraft:wool:0,10,quark:quilted_wool:0,100)
RandomBlock(5,104,0,minecraft:wool:0,10,quark:quilted_wool:0,100)
RandomBlock(5,104,1,minecraft:wool:0,10,quark:quilted_wool:0,100)
RandomBlock(5,105,-6,minecraft:wool:0,10,quark:quilted_wool:0,100)
RandomBlock(5,105,-5,minecraft:wool:0,10,quark:quilted_wool:0,100)
RandomBlock(5,105,-4,minecraft:wool:0,10,quark:quilted_wool:0,100)
RandomBlock(5,105,-3,minecraft:wool:0,10,quark:quilted_wool:0,100)
RandomBlock(5,105,-2,minecraft:wool:0,10,quark:quilted_wool:0,100)
RandomBlock(5,105,-1,minecraft:wool:0,10,quark:quilted_wool:0,100)
RandomBlock(5,105,0,minecraft:wool:0,10,quark:quilted_wool:0,100)
RandomBlock(5,106,-5,minecraft:wool:0,10,quark:quilted_wool:0,100)
RandomBlock(5,106,-4,minecraft:wool:0,10,quark:quilted_wool:0,100)
RandomBlock(5,106,-3,minecraft:wool:0,10,quark:quilted_wool:0,100)
RandomBlock(5,106,-2,minecraft:wool:0,10,quark:quilted_wool:0,100)
RandomBlock(5,106,-1,minecraft:wool:0,10,quark:quilted_wool:0,100)
RandomBlock(5,107,-5,minecraft:wool:0,10,quark:quilted_wool:0,100)
RandomBlock(5,107,-4,minecraft:wool:0,10,quark:quilted_wool:0,100)
RandomBlock(5,107,-3,minecraft:wool:0,10,quark:quilted_wool:0,100)
RandomBlock(5,107,-2,minecraft:wool:0,10,quark:quilted_wool:0,100)
RandomBlock(5,107,-1,minecraft:wool:0,10,quark:quilted_wool:0,100)
Block(6,5,-4,LOG:12)
Block(6,5,-3,LOG:12)
Block(6,5,-2,LOG:12)
Block(6,6,-5,LOG:12)
Block(6,6,-4,LOG:12)
Block(6,6,-3,LOG:12)
Block(6,6,-2,LOG:12)
Block(6,7,-6,LOG:12)
Block(6,7,-5,LOG:12)
Block(6,7,-4,LOG:12)
Block(6,7,-3,LOG:12)
Block(6,7,-2,LOG:12)
Block(6,8,-5,LOG:12)
Block(6,8,-4,LOG:12)
Block(6,8,-3,LOG:12)
Block(6,8,-1,LOG:12)
Block(6,8,0,LOG:12)
Block(6,8,1,LOG:12)
Block(6,9,-3,quark:leaf_carpet)
Block(6,9,-1,LOG:12)
Block(6,9,0,LOG:12)
Block(6,9,1,LOG:12)
Block(6,10,-1,LOG:12)
Block(6,10,0,LOG:12)
Block(6,10,1,LOG:12)
Block(6,11,0,LOG:12)
Block(6,12,-1,LOG:12)
Block(6,12,0,LOG:12)
Block(6,12,1,LOG:12)
Block(6,13,-1,LOG:12)
Block(6,13,0,LOG:12)
Block(6,13,1,LOG:12)
Block(6,14,-1,LOG:12)
Block(6,14,0,LOG:12)
Block(6,14,1,LOG:12)
Block(6,15,-7,LOG:12)
Block(6,15,-2,LOG:12)
Block(6,15,-1,LOG:12)
Block(6,15,0,LOG:12)
Block(6,15,1,quark:leaf_carpet)
Block(6,16,-7,LOG:12)
Block(6,16,-6,LOG:12)
Block(6,16,-1,LOG:12)
Block(6,17,-7,LOG:12)
Block(6,17,-6,LOG:12)
Block(6,17,-5,LOG:12)
Block(6,17,-4,LOG:12)
Block(6,18,-7,LOG:12)
Block(6,18,-6,LOG:12)
Block(6,18,-5,LOG:12)
Block(6,18,-4,LOG:12)
Block(6,18,-3,LOG:12)
Block(6,19,-7,quark:leaf_carpet)
Block(6,19,-6,LOG:12)
Block(6,19,-5,LOG:12)
Block(6,19,-4,LOG:12)
Block(6,20,-5,quark:leaf_carpet)
Block(6,20,-4,quark:leaf_carpet)
Block(6,31,-7,VINE:8)
Block(6,31,-6,VINE:8)
Block(6,32,-7,VINE:8)
Block(6,32,-6,VINE:8)
Block(6,33,-7,VINE:8)
Block(6,33,-6,VINE:8)
RandomBlock(6,33,0,minecraft:wool:7,10,quark:quilted_wool:7,100)
Block(6,34,-7,VINE:8)
Block(6,34,-6,VINE:8)
RandomBlock(6,34,-2,minecraft:wool:7,10,quark:quilted_wool:7,100)
RandomBlock(6,34,-1,minecraft:wool:7,10,quark:quilted_wool:7,100)
RandomBlock(6,34,0,minecraft:wool:7,10,quark:quilted_wool:7,100)
RandomBlock(6,34,1,minecraft:wool:7,10,quark:quilted_wool:7,100)
RandomBlock(6,34,2,minecraft:wool:7,10,quark:quilted_wool:7,100)
Block(6,35,-7,VINE:8)
RandomBlock(6,35,-2,minecraft:wool:7,10,quark:quilted_wool:7,100)
RandomBlock(6,35,-1,minecraft:wool:7,10,quark:quilted_wool:7,100)
RandomBlock(6,35,0,minecraft:wool:7,10,quark:quilted_wool:7,100)
RandomBlock(6,35,1,minecraft:wool:7,10,quark:quilted_wool:7,100)
RandomBlock(6,35,2,minecraft:wool:7,10,quark:quilted_wool:7,100)
RandomBlock(6,36,-3,minecraft:wool:7,10,quark:quilted_wool:7,100)
RandomBlock(6,36,-2,minecraft:wool:7,10,quark:quilted_wool:7,100)
RandomBlock(6,36,-1,minecraft:wool:7,10,quark:quilted_wool:7,100)
RandomBlock(6,36,0,minecraft:wool:7,10,quark:quilted_wool:7,100)
RandomBlock(6,36,1,minecraft:wool:7,10,quark:quilted_wool:7,100)
RandomBlock(6,36,2,minecraft:wool:7,10,quark:quilted_wool:7,100)
RandomBlock(6,36,3,minecraft:wool:7,10,quark:quilted_wool:7,100)
RandomBlock(6,37,-3,minecraft:wool:7,10,quark:quilted_wool:7,100)
RandomBlock(6,37,-2,minecraft:wool:7,10,quark:quilted_wool:7,100)
RandomBlock(6,37,-1,minecraft:wool:7,10,quark:quilted_wool:7,100)
RandomBlock(6,37,0,minecraft:wool:7,10,quark:quilted_wool:7,100)
RandomBlock(6,37,1,minecraft:wool:7,10,quark:quilted_wool:7,100)
RandomBlock(6,37,2,minecraft:wool:7,10,quark:quilted_wool:7,100)
RandomBlock(6,37,3,minecraft:wool:7,10,quark:quilted_wool:7,100)
RandomBlock(6,38,-3,minecraft:wool:7,10,quark:quilted_wool:7,100)
RandomBlock(6,38,-2,minecraft:wool:7,10,quark:quilted_wool:7,100)
RandomBlock(6,38,-1,minecraft:wool:7,10,quark:quilted_wool:7,100)
RandomBlock(6,38,0,minecraft:wool:7,10,quark:quilted_wool:7,100)
RandomBlock(6,38,1,minecraft:wool:7,10,quark:quilted_wool:7,100)
RandomBlock(6,38,2,minecraft:wool:7,10,quark:quilted_wool:7,100)
RandomBlock(6,38,3,minecraft:wool:7,10,quark:quilted_wool:7,100)
RandomBlock(6,39,-2,minecraft:wool:7,10,quark:quilted_wool:7,100)
RandomBlock(6,39,-1,minecraft:wool:7,10,quark:quilted_wool:7,100)
RandomBlock(6,39,0,minecraft:wool:7,10,quark:quilted_wool:7,100)
RandomBlock(6,39,1,minecraft:wool:7,10,quark:quilted_wool:7,100)
RandomBlock(6,39,2,minecraft:wool:7,10,quark:quilted_wool:7,100)
RandomBlock(6,40,-2,minecraft:wool:7,10,quark:quilted_wool:7,100)
RandomBlock(6,40,-1,minecraft:wool:7,10,quark:quilted_wool:7,100)
RandomBlock(6,40,0,minecraft:wool:7,10,quark:quilted_wool:7,100)
RandomBlock(6,40,1,minecraft:wool:7,10,quark:quilted_wool:7,100)
RandomBlock(6,40,2,minecraft:wool:7,10,quark:quilted_wool:7,100)
RandomBlock(6,41,0,minecraft:wool:7,10,quark:quilted_wool:7,100)
Block(6,48,-7,LEAVES:0)
Block(6,51,-2,LOG:12)
Block(6,52,-7,LEAVES:0)
Block(6,52,-6,LEAVES:0)
Block(6,52,-5,LEAVES:0)
Block(6,52,-4,LEAVES:0)
Block(6,52,-2,LOG:12)
Block(6,53,-7,LEAVES:0)
Block(6,53,-6,LEAVES:0)
Block(6,53,-5,LEAVES:0)
Block(6,53,-4,LEAVES:0)
Block(6,53,-2,LOG:12)
Block(6,54,-7,LEAVES:0)
Block(6,54,-6,LEAVES:0)
Block(6,54,-5,LEAVES:0)
Block(6,54,-4,LEAVES:0)
Block(6,54,-3,LEAVES:0)
Block(6,54,-2,LOG:12)
Block(6,54,-1,LEAVES:0)
Block(6,54,0,LEAVES:0)
Block(6,55,-7,LEAVES:0)
Block(6,55,-6,LEAVES:0)
Block(6,55,-4,LEAVES:0)
Block(6,55,-3,LEAVES:0)
Block(6,55,-2,LOG:12)
Block(6,55,-1,LEAVES:0)
Block(6,55,0,LEAVES:0)
Block(6,56,-7,LEAVES:0)
Block(6,56,-6,LEAVES:0)
Block(6,56,-3,LEAVES:0)
Block(6,56,-2,LOG:12)
Block(6,56,-1,LEAVES:0)
Block(6,57,-7,LEAVES:0)
Block(6,57,-6,LEAVES:0)
Block(6,57,-5,LEAVES:0)
Block(6,57,-4,LEAVES:0)
Block(6,57,-3,LEAVES:0)
Block(6,57,-2,LEAVES:0)
Block(6,57,-1,LEAVES:0)
Block(6,58,-6,LEAVES:0)
Block(6,58,-5,LEAVES:0)
Block(6,58,-4,LEAVES:0)
Block(6,58,-3,LEAVES:0)
Block(6,58,-2,LEAVES:0)
Block(6,59,-4,LEAVES:0)
Block(6,59,-3,LEAVES:0)
Block(6,60,-4,LEAVES:0)
Block(6,68,-7,LEAVES:0)
Block(6,68,-6,LEAVES:0)
Block(6,68,-5,LEAVES:0)
Block(6,69,-7,LEAVES:0)
Block(6,69,-6,LEAVES:0)
Block(6,69,-5,LEAVES:0)
Block(6,69,-4,LEAVES:0)
Block(6,70,-7,LEAVES:0)
Block(6,70,-6,LEAVES:0)
Block(6,70,-5,LEAVES:0)
Block(6,70,3,LEAVES:0)
Block(6,70,4,LEAVES:0)
Block(6,70,5,LEAVES:0)
Block(6,70,6,LEAVES:0)
Block(6,71,-7,LEAVES:0)
Block(6,71,-4,LEAVES:0)
Block(6,71,2,LEAVES:0)
Block(6,71,3,LEAVES:0)
Block(6,71,4,LEAVES:0)
Block(6,71,5,LEAVES:0)
Block(6,71,6,LEAVES:0)
Block(6,72,-7,LEAVES:0)
Block(6,72,-6,LEAVES:0)
Block(6,72,-5,LEAVES:0)
Block(6,72,-4,LEAVES:0)
Block(6,72,-3,LEAVES:0)
Block(6,72,-2,LEAVES:0)
Block(6,72,-1,LEAVES:0)
Block(6,72,0,LEAVES:0)
Block(6,73,-7,LEAVES:0)
Block(6,73,-6,LEAVES:0)
Block(6,73,-5,LEAVES:0)
Block(6,73,-4,LEAVES:0)
Block(6,73,-3,LEAVES:0)
Block(6,73,-2,LEAVES:0)
Block(6,73,-1,LEAVES:0)
Block(6,74,-7,LEAVES:0)
Block(6,74,-6,LEAVES:0)
Block(6,74,-4,LOG:12)
Block(6,75,-7,LEAVES:0)
Block(6,75,-6,LEAVES:0)
Block(6,75,-5,LEAVES:0)
Block(6,75,-4,LOG:12)
Block(6,76,-7,LEAVES:0)
Block(6,76,-6,LEAVES:0)
Block(6,76,-5,LEAVES:0)
Block(6,76,-4,LOG:12)
Block(6,76,-3,LEAVES:0)
Block(6,76,-2,LEAVES:0)
Block(6,77,-7,LEAVES:0)
Block(6,77,-6,LEAVES:0)
Block(6,77,-5,LEAVES:0)
Block(6,77,-4,LOG:12)
Block(6,77,-3,LEAVES:0)
Block(6,77,-2,LEAVES:0)
Block(6,78,-7,LEAVES:0)
Block(6,78,-6,LEAVES:0)
Block(6,78,-5,LEAVES:0)
Block(6,78,-4,LOG:12)
Block(6,78,-3,LEAVES:0)
Block(6,79,-7,LOG:12)
Block(6,79,-6,LEAVES:0)
Block(6,79,-5,LEAVES:0)
Block(6,79,-4,LEAVES:0)
Block(6,79,-3,LEAVES:0)
Block(6,80,-7,LEAVES:0)
Block(6,80,-6,LEAVES:0)
Block(6,80,-5,LEAVES:0)
Block(6,81,-7,LEAVES:0)
Block(6,81,-6,LEAVES:0)
Block(6,81,-5,LEAVES:0)
Block(6,82,-7,LEAVES:0)
Block(6,82,-6,LEAVES:0)
RandomBlock(6,88,-4,minecraft:wool:0,10,quark:quilted_wool:0,100)
RandomBlock(6,88,-3,minecraft:wool:0,10,quark:quilted_wool:0,100)
RandomBlock(6,88,-2,minecraft:wool:0,10,quark:quilted_wool:0,100)
RandomBlock(6,89,-5,minecraft:wool:0,10,quark:quilted_wool:0,100)
RandomBlock(6,89,-4,minecraft:wool:0,10,quark:quilted_wool:0,100)
RandomBlock(6,89,-3,minecraft:wool:0,10,quark:quilted_wool:0,100)
RandomBlock(6,89,-2,minecraft:wool:0,10,quark:quilted_wool:0,100)
RandomBlock(6,89,-1,minecraft:wool:0,10,quark:quilted_wool:0,100)
RandomBlock(6,90,-6,minecraft:wool:0,10,quark:quilted_wool:0,100)
RandomBlock(6,90,-5,minecraft:wool:0,10,quark:quilted_wool:0,100)
RandomBlock(6,90,-4,minecraft:wool:0,10,quark:quilted_wool:0,100)
RandomBlock(6,90,-3,minecraft:wool:0,10,quark:quilted_wool:0,100)
RandomBlock(6,90,-2,minecraft:wool:0,10,quark:quilted_wool:0,100)
RandomBlock(6,90,-1,minecraft:wool:0,10,quark:quilted_wool:0,100)
RandomBlock(6,90,0,minecraft:wool:0,10,quark:quilted_wool:0,100)
RandomBlock(6,91,-6,minecraft:wool:0,10,quark:quilted_wool:0,100)
RandomBlock(6,91,-5,minecraft:wool:0,10,quark:quilted_wool:0,100)
RandomBlock(6,91,-4,minecraft:wool:0,10,quark:quilted_wool:0,100)
RandomBlock(6,91,-3,minecraft:wool:0,10,quark:quilted_wool:0,100)
RandomBlock(6,91,-2,minecraft:wool:0,10,quark:quilted_wool:0,100)
RandomBlock(6,91,-1,minecraft:wool:0,10,quark:quilted_wool:0,100)
RandomBlock(6,91,0,minecraft:wool:0,10,quark:quilted_wool:0,100)
RandomBlock(6,92,-7,minecraft:wool:0,10,quark:quilted_wool:0,100)
RandomBlock(6,92,-6,minecraft:wool:0,10,quark:quilted_wool:0,100)
RandomBlock(6,92,-5,minecraft:wool:0,10,quark:quilted_wool:0,100)
RandomBlock(6,92,-4,minecraft:wool:0,10,quark:quilted_wool:0,100)
RandomBlock(6,92,-3,minecraft:wool:0,10,quark:quilted_wool:0,100)
RandomBlock(6,92,-2,minecraft:wool:0,10,quark:quilted_wool:0,100)
RandomBlock(6,92,-1,minecraft:wool:0,10,quark:quilted_wool:0,100)
RandomBlock(6,92,0,minecraft:wool:0,10,quark:quilted_wool:0,100)
RandomBlock(6,92,1,minecraft:wool:0,10,quark:quilted_wool:0,100)
RandomBlock(6,93,-7,minecraft:wool:0,10,quark:quilted_wool:0,100)
RandomBlock(6,93,-6,minecraft:wool:0,10,quark:quilted_wool:0,100)
RandomBlock(6,93,-5,minecraft:wool:0,10,quark:quilted_wool:0,100)
RandomBlock(6,93,-4,minecraft:wool:0,10,quark:quilted_wool:0,100)
RandomBlock(6,93,-3,minecraft:wool:0,10,quark:quilted_wool:0,100)
RandomBlock(6,93,-2,minecraft:wool:0,10,quark:quilted_wool:0,100)
RandomBlock(6,93,-1,minecraft:wool:0,10,quark:quilted_wool:0,100)
RandomBlock(6,93,0,minecraft:wool:0,10,quark:quilted_wool:0,100)
RandomBlock(6,93,1,minecraft:wool:0,10,quark:quilted_wool:0,100)
RandomBlock(6,94,-7,minecraft:wool:0,10,quark:quilted_wool:0,100)
RandomBlock(6,94,-6,minecraft:wool:0,10,quark:quilted_wool:0,100)
RandomBlock(6,94,-5,minecraft:wool:0,10,quark:quilted_wool:0,100)
RandomBlock(6,94,-4,minecraft:wool:0,10,quark:quilted_wool:0,100)
RandomBlock(6,94,-3,minecraft:wool:0,10,quark:quilted_wool:0,100)
RandomBlock(6,94,-2,minecraft:wool:0,10,quark:quilted_wool:0,100)
RandomBlock(6,94,-1,minecraft:wool:0,10,quark:quilted_wool:0,100)
RandomBlock(6,94,0,minecraft:wool:0,10,quark:quilted_wool:0,100)
RandomBlock(6,94,1,minecraft:wool:0,10,quark:quilted_wool:0,100)
RandomBlock(6,95,-7,minecraft:wool:0,10,quark:quilted_wool:0,100)
RandomBlock(6,95,-6,minecraft:wool:0,10,quark:quilted_wool:0,100)
RandomBlock(6,95,-5,minecraft:wool:0,10,quark:quilted_wool:0,100)
RandomBlock(6,95,-4,minecraft:wool:0,10,quark:quilted_wool:0,100)
RandomBlock(6,95,-3,minecraft:wool:0,10,quark:quilted_wool:0,100)
RandomBlock(6,95,-2,minecraft:wool:0,10,quark:quilted_wool:0,100)
RandomBlock(6,95,-1,minecraft:wool:0,10,quark:quilted_wool:0,100)
RandomBlock(6,95,0,minecraft:wool:0,10,quark:quilted_wool:0,100)
RandomBlock(6,95,1,minecraft:wool:0,10,quark:quilted_wool:0,100)
RandomBlock(6,95,2,minecraft:wool:0,10,quark:quilted_wool:0,100)
RandomBlock(6,96,-7,minecraft:wool:0,10,quark:quilted_wool:0,100)
RandomBlock(6,96,-6,minecraft:wool:0,10,quark:quilted_wool:0,100)
RandomBlock(6,96,-5,minecraft:wool:0,10,quark:quilted_wool:0,100)
RandomBlock(6,96,-4,minecraft:wool:0,10,quark:quilted_wool:0,100)
RandomBlock(6,96,-3,minecraft:wool:0,10,quark:quilted_wool:0,100)
RandomBlock(6,96,-2,minecraft:wool:0,10,quark:quilted_wool:0,100)
RandomBlock(6,96,-1,minecraft:wool:0,10,quark:quilted_wool:0,100)
RandomBlock(6,96,0,minecraft:wool:0,10,quark:quilted_wool:0,100)
RandomBlock(6,96,1,minecraft:wool:0,10,quark:quilted_wool:0,100)
RandomBlock(6,96,2,minecraft:wool:0,10,quark:quilted_wool:0,100)
RandomBlock(6,97,-7,minecraft:wool:0,10,quark:quilted_wool:0,100)
RandomBlock(6,97,-6,minecraft:wool:0,10,quark:quilted_wool:0,100)
RandomBlock(6,97,-5,minecraft:wool:0,10,quark:quilted_wool:0,100)
RandomBlock(6,97,-4,minecraft:wool:0,10,quark:quilted_wool:0,100)
RandomBlock(6,97,-3,minecraft:wool:0,10,quark:quilted_wool:0,100)
RandomBlock(6,97,-2,minecraft:wool:0,10,quark:quilted_wool:0,100)
RandomBlock(6,97,-1,minecraft:wool:0,10,quark:quilted_wool:0,100)
RandomBlock(6,97,0,minecraft:wool:0,10,quark:quilted_wool:0,100)
RandomBlock(6,97,1,minecraft:wool:0,10,quark:quilted_wool:0,100)
RandomBlock(6,97,2,minecraft:wool:0,10,quark:quilted_wool:0,100)
RandomBlock(6,98,-7,minecraft:wool:0,10,quark:quilted_wool:0,100)
RandomBlock(6,98,-6,minecraft:wool:0,10,quark:quilted_wool:0,100)
RandomBlock(6,98,-5,minecraft:wool:0,10,quark:quilted_wool:0,100)
RandomBlock(6,98,-4,minecraft:wool:0,10,quark:quilted_wool:0,100)
RandomBlock(6,98,-3,minecraft:wool:0,10,quark:quilted_wool:0,100)
RandomBlock(6,98,-2,minecraft:wool:0,10,quark:quilted_wool:0,100)
RandomBlock(6,98,-1,minecraft:wool:0,10,quark:quilted_wool:0,100)
RandomBlock(6,98,0,minecraft:wool:0,10,quark:quilted_wool:0,100)
RandomBlock(6,98,1,minecraft:wool:0,10,quark:quilted_wool:0,100)
RandomBlock(6,98,2,minecraft:wool:0,10,quark:quilted_wool:0,100)
RandomBlock(6,99,-7,minecraft:wool:0,10,quark:quilted_wool:0,100)
RandomBlock(6,99,-6,minecraft:wool:0,10,quark:quilted_wool:0,100)
RandomBlock(6,99,-5,minecraft:wool:0,10,quark:quilted_wool:0,100)
RandomBlock(6,99,-4,minecraft:wool:0,10,quark:quilted_wool:0,100)
RandomBlock(6,99,-3,minecraft:wool:0,10,quark:quilted_wool:0,100)
RandomBlock(6,99,-2,minecraft:wool:0,10,quark:quilted_wool:0,100)
RandomBlock(6,99,-1,minecraft:wool:0,10,quark:quilted_wool:0,100)
RandomBlock(6,99,0,minecraft:wool:0,10,quark:quilted_wool:0,100)
RandomBlock(6,99,1,minecraft:wool:0,10,quark:quilted_wool:0,100)
RandomBlock(6,99,2,minecraft:wool:0,10,quark:quilted_wool:0,100)
RandomBlock(6,100,-7,minecraft:wool:0,10,quark:quilted_wool:0,100)
RandomBlock(6,100,-6,minecraft:wool:0,10,quark:quilted_wool:0,100)
RandomBlock(6,100,-5,minecraft:wool:0,10,quark:quilted_wool:0,100)
RandomBlock(6,100,-4,minecraft:wool:0,10,quark:quilted_wool:0,100)
RandomBlock(6,100,-3,minecraft:wool:0,10,quark:quilted_wool:0,100)
RandomBlock(6,100,-2,minecraft:wool:0,10,quark:quilted_wool:0,100)
RandomBlock(6,100,-1,minecraft:wool:0,10,quark:quilted_wool:0,100)
RandomBlock(6,100,0,minecraft:wool:0,10,quark:quilted_wool:0,100)
RandomBlock(6,100,1,minecraft:wool:0,10,quark:quilted_wool:0,100)
RandomBlock(6,100,2,minecraft:wool:0,10,quark:quilted_wool:0,100)
RandomBlock(6,101,-7,minecraft:wool:0,10,quark:quilted_wool:0,100)
RandomBlock(6,101,-6,minecraft:wool:0,10,quark:quilted_wool:0,100)
RandomBlock(6,101,-5,minecraft:wool:0,10,quark:quilted_wool:0,100)
RandomBlock(6,101,-4,minecraft:wool:0,10,quark:quilted_wool:0,100)
RandomBlock(6,101,-3,minecraft:wool:0,10,quark:quilted_wool:0,100)
RandomBlock(6,101,-2,minecraft:wool:0,10,quark:quilted_wool:0,100)
RandomBlock(6,101,-1,minecraft:wool:0,10,quark:quilted_wool:0,100)
RandomBlock(6,101,0,minecraft:wool:0,10,quark:quilted_wool:0,100)
RandomBlock(6,101,1,minecraft:wool:0,10,quark:quilted_wool:0,100)
RandomBlock(6,101,2,minecraft:wool:0,10,quark:quilted_wool:0,100)
RandomBlock(6,102,-7,minecraft:wool:0,10,quark:quilted_wool:0,100)
RandomBlock(6,102,-6,minecraft:wool:0,10,quark:quilted_wool:0,100)
RandomBlock(6,102,-5,minecraft:wool:0,10,quark:quilted_wool:0,100)
RandomBlock(6,102,-4,minecraft:wool:0,10,quark:quilted_wool:0,100)
RandomBlock(6,102,-3,minecraft:wool:0,10,quark:quilted_wool:0,100)
RandomBlock(6,102,-2,minecraft:wool:0,10,quark:quilted_wool:0,100)
RandomBlock(6,102,-1,minecraft:wool:0,10,quark:quilted_wool:0,100)
RandomBlock(6,102,0,minecraft:wool:0,10,quark:quilted_wool:0,100)
RandomBlock(6,102,1,minecraft:wool:0,10,quark:quilted_wool:0,100)
RandomBlock(6,103,-7,minecraft:wool:0,10,quark:quilted_wool:0,100)
RandomBlock(6,103,-6,minecraft:wool:0,10,quark:quilted_wool:0,100)
RandomBlock(6,103,-5,minecraft:wool:0,10,quark:quilted_wool:0,100)
RandomBlock(6,103,-4,minecraft:wool:0,10,quark:quilted_wool:0,100)
RandomBlock(6,103,-3,minecraft:wool:0,10,quark:quilted_wool:0,100)
RandomBlock(6,103,-2,minecraft:wool:0,10,quark:quilted_wool:0,100)
RandomBlock(6,103,-1,minecraft:wool:0,10,quark:quilted_wool:0,100)
RandomBlock(6,103,0,minecraft:wool:0,10,quark:quilted_wool:0,100)
RandomBlock(6,103,1,minecraft:wool:0,10,quark:quilted_wool:0,100)
RandomBlock(6,104,-7,minecraft:wool:0,10,quark:quilted_wool:0,100)
RandomBlock(6,104,-6,minecraft:wool:0,10,quark:quilted_wool:0,100)
RandomBlock(6,104,-5,minecraft:wool:0,10,quark:quilted_wool:0,100)
RandomBlock(6,104,-4,minecraft:wool:0,10,quark:quilted_wool:0,100)
RandomBlock(6,104,-3,minecraft:wool:0,10,quark:quilted_wool:0,100)
RandomBlock(6,104,-2,minecraft:wool:0,10,quark:quilted_wool:0,100)
RandomBlock(6,104,-1,minecraft:wool:0,10,quark:quilted_wool:0,100)
RandomBlock(6,104,0,minecraft:wool:0,10,quark:quilted_wool:0,100)
RandomBlock(6,104,1,minecraft:wool:0,10,quark:quilted_wool:0,100)
RandomBlock(6,105,-6,minecraft:wool:0,10,quark:quilted_wool:0,100)
RandomBlock(6,105,-5,minecraft:wool:0,10,quark:quilted_wool:0,100)
RandomBlock(6,105,-4,minecraft:wool:0,10,quark:quilted_wool:0,100)
RandomBlock(6,105,-3,minecraft:wool:0,10,quark:quilted_wool:0,100)
RandomBlock(6,105,-2,minecraft:wool:0,10,quark:quilted_wool:0,100)
RandomBlock(6,105,-1,minecraft:wool:0,10,quark:quilted_wool:0,100)
RandomBlock(6,105,0,minecraft:wool:0,10,quark:quilted_wool:0,100)
RandomBlock(6,106,-6,minecraft:wool:0,10,quark:quilted_wool:0,100)
RandomBlock(6,106,-5,minecraft:wool:0,10,quark:quilted_wool:0,100)
RandomBlock(6,106,-4,minecraft:wool:0,10,quark:quilted_wool:0,100)
RandomBlock(6,106,-3,minecraft:wool:0,10,quark:quilted_wool:0,100)
RandomBlock(6,106,-2,minecraft:wool:0,10,quark:quilted_wool:0,100)
RandomBlock(6,106,-1,minecraft:wool:0,10,quark:quilted_wool:0,100)
RandomBlock(6,106,0,minecraft:wool:0,10,quark:quilted_wool:0,100)
RandomBlock(6,107,-5,minecraft:wool:0,10,quark:quilted_wool:0,100)
RandomBlock(6,107,-4,minecraft:wool:0,10,quark:quilted_wool:0,100)
RandomBlock(6,107,-3,minecraft:wool:0,10,quark:quilted_wool:0,100)
RandomBlock(6,107,-2,minecraft:wool:0,10,quark:quilted_wool:0,100)
RandomBlock(6,107,-1,minecraft:wool:0,10,quark:quilted_wool:0,100)
RandomBlock(6,108,-4,minecraft:wool:0,10,quark:quilted_wool:0,100)
RandomBlock(6,108,-3,minecraft:wool:0,10,quark:quilted_wool:0,100)
RandomBlock(6,108,-2,minecraft:wool:0,10,quark:quilted_wool:0,100)
Block(7,5,-3,LOG:12)
Block(7,6,-6,LOG:12)
Block(7,6,-5,LOG:12)
Block(7,6,-4,LOG:12)
Block(7,6,-3,LOG:12)
Block(7,6,-2,LOG:12)
Block(7,7,-6,LOG:12)
Block(7,7,-5,LOG:12)
Block(7,7,-4,LOG:12)
Block(7,7,-3,LOG:12)
Block(7,8,-6,LOG:12)
Block(7,8,-5,LOG:12)
Block(7,8,-4,LOG:12)
Block(7,8,0,LOG:12)
Block(7,9,-7,LOG:12)
Block(7,9,-6,LOG:12)
Block(7,9,-5,LOG:12)
Block(7,9,-1,LOG:12)
Block(7,9,0,LOG:12)
Block(7,9,1,LOG:12)
Block(7,10,-6,LOG:12)
Block(7,10,-5,quark:leaf_carpet)
Block(7,10,-1,LOG:12)
Block(7,10,0,LOG:12)
Block(7,10,1,LOG:12)
Block(7,11,-1,LOG:12)
Block(7,11,0,LOG:12)
Block(7,11,1,LOG:12)
Block(7,12,-1,LOG:12)
Block(7,12,0,LOG:12)
Block(7,12,1,LOG:12)
Block(7,13,-1,LOG:12)
Block(7,13,0,LOG:12)
Block(7,13,1,LOG:12)
Block(7,14,-2,LOG:12)
Block(7,14,-1,LOG:12)
Block(7,14,0,LOG:12)
Block(7,14,1,LOG:12)
Block(7,15,-7,LOG:12)
Block(7,15,-6,LOG:12)
Block(7,15,-2,LOG:12)
Block(7,15,-1,LOG:12)
Block(7,15,0,LOG:12)
Block(7,15,1,LOG:12)
Block(7,16,-7,LOG:12)
Block(7,16,-6,LOG:12)
Block(7,16,-5,LOG:12)
Block(7,16,-2,LOG:12)
Block(7,16,-1,LOG:12)
Block(7,16,0,LOG:12)
Block(7,16,1,quark:leaf_carpet)
Block(7,17,-7,LOG:12)
Block(7,17,-6,LOG:12)
Block(7,17,-5,LOG:12)
Block(7,17,-4,LOG:12)
Block(7,17,-3,LOG:12)
Block(7,17,-2,LOG:12)
Block(7,17,-1,LOG:12)
Block(7,17,0,quark:leaf_carpet)
Block(7,18,-7,LOG:12)
Block(7,18,-6,LOG:12)
Block(7,18,-5,LOG:12)
Block(7,18,-4,LOG:12)
Block(7,18,-3,LOG:12)
Block(7,18,-2,LOG:12)
Block(7,18,-1,quark:leaf_carpet)
Block(7,19,-7,LOG:12)
Block(7,19,-6,LOG:12)
Block(7,19,-5,LOG:12)
Block(7,19,-4,LOG:12)
Block(7,19,-3,LOG:12)
Block(7,19,-2,quark:leaf_carpet)
Block(7,20,-6,quark:leaf_carpet)
Block(7,20,-4,LOG:12)
Block(7,20,-3,quark:leaf_carpet)
Block(7,21,-4,quark:leaf_carpet)
Block(7,26,-5,VINE:4)
Block(7,27,-5,VINE:4)
Block(7,28,-5,VINE:4)
Block(7,29,-5,VINE:12)
Block(7,30,-5,VINE:12)
Block(7,31,-5,VINE:12)
Block(7,32,-5,VINE:12)
Block(7,33,-7,LOG:12)
Block(7,33,-5,VINE:12)
RandomBlock(7,33,-2,minecraft:wool:7,10,quark:quilted_wool:7,100)
RandomBlock(7,33,-1,minecraft:wool:7,10,quark:quilted_wool:7,100)
RandomBlock(7,33,0,minecraft:wool:7,10,quark:quilted_wool:7,100)
RandomBlock(7,33,1,minecraft:wool:7,10,quark:quilted_wool:7,100)
RandomBlock(7,33,2,minecraft:wool:7,10,quark:quilted_wool:7,100)
Block(7,34,-7,LOG:12)
Block(7,34,-6,LOG:12)
Block(7,34,-5,VINE:12)
RandomBlock(7,34,-3,minecraft:wool:7,10,quark:quilted_wool:7,100)
RandomBlock(7,34,-2,minecraft:wool:7,10,quark:quilted_wool:7,100)
RandomBlock(7,34,-1,minecraft:wool:7,10,quark:quilted_wool:7,100)
RandomBlock(7,34,0,minecraft:wool:7,10,quark:quilted_wool:7,100)
RandomBlock(7,34,1,minecraft:wool:7,10,quark:quilted_wool:7,100)
RandomBlock(7,34,2,minecraft:wool:7,10,quark:quilted_wool:7,100)
RandomBlock(7,34,3,minecraft:wool:7,10,quark:quilted_wool:7,100)
Block(7,35,-7,LOG:12)
Block(7,35,-5,VINE:8)
RandomBlock(7,35,-3,minecraft:wool:7,10,quark:quilted_wool:7,100)
RandomBlock(7,35,-2,minecraft:wool:7,10,quark:quilted_wool:7,100)
RandomBlock(7,35,-1,minecraft:wool:7,10,quark:quilted_wool:7,100)
RandomBlock(7,35,0,minecraft:wool:7,10,quark:quilted_wool:7,100)
RandomBlock(7,35,1,minecraft:wool:7,10,quark:quilted_wool:7,100)
RandomBlock(7,35,2,minecraft:wool:7,10,quark:quilted_wool:7,100)
RandomBlock(7,35,3,minecraft:wool:7,10,quark:quilted_wool:7,100)
Block(7,36,-5,VINE:8)
RandomBlock(7,36,-3,minecraft:wool:7,10,quark:quilted_wool:7,100)
RandomBlock(7,36,-2,minecraft:wool:7,10,quark:quilted_wool:7,100)
RandomBlock(7,36,-1,minecraft:wool:7,10,quark:quilted_wool:7,100)
RandomBlock(7,36,0,minecraft:wool:7,10,quark:quilted_wool:7,100)
RandomBlock(7,36,1,minecraft:wool:7,10,quark:quilted_wool:7,100)
RandomBlock(7,36,2,minecraft:wool:7,10,quark:quilted_wool:7,100)
RandomBlock(7,36,3,minecraft:wool:7,10,quark:quilted_wool:7,100)
Block(7,37,-5,VINE:8)
RandomBlock(7,37,-4,minecraft:wool:7,10,quark:quilted_wool:7,100)
RandomBlock(7,37,-3,minecraft:wool:7,10,quark:quilted_wool:7,100)
RandomBlock(7,37,-2,minecraft:wool:7,10,quark:quilted_wool:7,100)
RandomBlock(7,37,-1,minecraft:wool:7,10,quark:quilted_wool:7,100)
RandomBlock(7,37,0,minecraft:wool:7,10,quark:quilted_wool:7,100)
RandomBlock(7,37,1,minecraft:wool:7,10,quark:quilted_wool:7,100)
RandomBlock(7,37,2,minecraft:wool:7,10,quark:quilted_wool:7,100)
RandomBlock(7,37,3,minecraft:wool:7,10,quark:quilted_wool:7,100)
RandomBlock(7,37,4,minecraft:wool:7,10,quark:quilted_wool:7,100)
Block(7,38,-5,VINE:8)
RandomBlock(7,38,-3,minecraft:wool:7,10,quark:quilted_wool:7,100)
RandomBlock(7,38,-2,minecraft:wool:7,10,quark:quilted_wool:7,100)
RandomBlock(7,38,-1,minecraft:wool:7,10,quark:quilted_wool:7,100)
RandomBlock(7,38,0,minecraft:wool:7,10,quark:quilted_wool:7,100)
RandomBlock(7,38,1,minecraft:wool:7,10,quark:quilted_wool:7,100)
RandomBlock(7,38,2,minecraft:wool:7,10,quark:quilted_wool:7,100)
RandomBlock(7,38,3,minecraft:wool:7,10,quark:quilted_wool:7,100)
Block(7,39,-5,VINE:8)
RandomBlock(7,39,-3,minecraft:wool:7,10,quark:quilted_wool:7,100)
RandomBlock(7,39,-2,minecraft:wool:7,10,quark:quilted_wool:7,100)
RandomBlock(7,39,-1,minecraft:wool:7,10,quark:quilted_wool:7,100)
RandomBlock(7,39,0,minecraft:wool:7,10,quark:quilted_wool:7,100)
RandomBlock(7,39,1,minecraft:wool:7,10,quark:quilted_wool:7,100)
RandomBlock(7,39,2,minecraft:wool:7,10,quark:quilted_wool:7,100)
RandomBlock(7,39,3,minecraft:wool:7,10,quark:quilted_wool:7,100)
Block(7,40,-5,VINE:8)
RandomBlock(7,40,-3,minecraft:wool:7,10,quark:quilted_wool:7,100)
RandomBlock(7,40,-2,minecraft:wool:7,10,quark:quilted_wool:7,100)
RandomBlock(7,40,-1,minecraft:wool:7,10,quark:quilted_wool:7,100)
RandomBlock(7,40,0,minecraft:wool:7,10,quark:quilted_wool:7,100)
RandomBlock(7,40,1,minecraft:wool:7,10,quark:quilted_wool:7,100)
RandomBlock(7,40,2,minecraft:wool:7,10,quark:quilted_wool:7,100)
RandomBlock(7,40,3,minecraft:wool:7,10,quark:quilted_wool:7,100)
Block(7,41,-5,VINE:8)
RandomBlock(7,41,-2,minecraft:wool:7,10,quark:quilted_wool:7,100)
RandomBlock(7,41,-1,minecraft:wool:7,10,quark:quilted_wool:7,100)
RandomBlock(7,41,0,minecraft:wool:7,10,quark:quilted_wool:7,100)
RandomBlock(7,41,1,minecraft:wool:7,10,quark:quilted_wool:7,100)
RandomBlock(7,41,2,minecraft:wool:7,10,quark:quilted_wool:7,100)
Block(7,42,-5,VINE:8)
Block(7,43,-5,VINE:8)
Block(7,44,-5,VINE:8)
Block(7,45,-5,VINE:8)
Block(7,46,-5,VINE:8)
Block(7,47,-5,VINE:8)
Block(7,48,-7,LEAVES:0)
Block(7,48,-5,VINE:8)
Block(7,49,-5,VINE:8)
Block(7,50,-5,VINE:8)
Block(7,50,-3,LOG:12)
Block(7,50,-2,LOG:12)
Block(7,50,4,VINE:8)
Block(7,51,-5,VINE:8)
Block(7,51,-2,LOG:12)
Block(7,51,4,VINE:8)
Block(7,52,-7,LEAVES:0)
Block(7,52,-6,LEAVES:0)
Block(7,52,-5,LEAVES:0)
Block(7,52,-4,LEAVES:0)
Block(7,52,4,VINE:8)
Block(7,53,-7,LEAVES:0)
Block(7,53,-6,LEAVES:0)
Block(7,53,-5,LEAVES:0)
Block(7,53,-4,LEAVES:0)
Block(7,53,-3,LEAVES:0)
Block(7,53,4,VINE:8)
Block(7,54,-7,LEAVES:0)
Block(7,54,-6,LEAVES:0)
Block(7,54,-5,LEAVES:0)
Block(7,54,-4,LEAVES:0)
Block(7,54,-3,LEAVES:0)
Block(7,54,-2,LEAVES:0)
Block(7,54,-1,LEAVES:0)
Block(7,54,0,LEAVES:0)
Block(7,54,4,VINE:8)
Block(7,55,-7,LEAVES:0)
Block(7,55,-6,LEAVES:0)
Block(7,55,-5,LEAVES:0)
Block(7,55,-3,LEAVES:0)
Block(7,55,-2,LEAVES:0)
Block(7,55,-1,LEAVES:0)
Block(7,55,0,LEAVES:0)
Block(7,55,4,VINE:8)
Block(7,56,-7,LEAVES:0)
Block(7,56,-5,LEAVES:0)
Block(7,56,-4,LOG:12)
Block(7,56,-2,LEAVES:0)
Block(7,56,-1,LEAVES:0)
Block(7,56,4,VINE:8)
Block(7,57,-6,LEAVES:0)
Block(7,57,-5,LEAVES:0)
Block(7,57,-4,LOG:12)
Block(7,57,-3,LEAVES:0)
Block(7,57,-2,LEAVES:0)
Block(7,57,4,VINE:8)
Block(7,58,-6,LEAVES:0)
Block(7,58,-5,LEAVES:0)
Block(7,58,-4,LOG:12)
Block(7,58,-3,LEAVES:0)
Block(7,58,-2,LEAVES:0)
Block(7,58,4,VINE:8)
Block(7,59,-6,WOOD_STEP:8)
Block(7,59,-5,WOOD_STEP:8)
Block(7,59,-4,LOG:12)
Block(7,59,-3,WOOD_STEP:8)
Block(7,59,-2,WOOD_STEP:8)
Block(7,59,4,VINE:8)
Block(7,60,-6,FENCE:0)
Block(7,60,-5,FENCE:0)
Block(7,60,-4,FENCE:0)
Block(7,60,-3,FENCE:0)
Block(7,60,-2,FENCE:0)
Block(7,60,4,VINE:8)
Block(7,61,-6,FENCE:0)
Block(7,61,-5,FENCE:0)
Block(7,61,-4,FENCE:0)
Block(7,61,-3,FENCE:0)
Block(7,61,-2,FENCE:0)
Block(7,61,4,VINE:8)
Block(7,62,4,VINE:8)
Block(7,63,4,VINE:8)
Block(7,64,4,VINE:8)
Block(7,65,-6,LEAVES:0)
Block(7,65,-5,LEAVES:0)
Block(7,65,-4,LEAVES:0)
Block(7,65,-3,LEAVES:0)
Block(7,65,4,VINE:8)
Block(7,66,-5,LEAVES:0)
Block(7,66,-4,LEAVES:0)
Block(7,66,-3,LEAVES:0)
Block(7,66,-2,LEAVES:0)
Block(7,66,4,VINE:8)
Block(7,67,-2,VINE:8)
Block(7,67,4,VINE:8)
Block(7,68,-7,LEAVES:0)
Block(7,68,-2,VINE:8)
Block(7,68,4,VINE:8)
Block(7,69,-7,LEAVES:0)
Block(7,69,-6,LEAVES:0)
Block(7,69,-2,VINE:8)
Block(7,69,4,VINE:8)
Block(7,70,-7,LEAVES:0)
Block(7,70,-6,LEAVES:0)
Block(7,70,-5,LEAVES:0)
Block(7,70,-2,VINE:8)
Block(7,70,2,LEAVES:0)
Block(7,70,3,LEAVES:0)
Block(7,70,4,LEAVES:0)
Block(7,70,5,LEAVES:0)
Block(7,70,6,LEAVES:0)
Block(7,71,-2,VINE:8)
Block(7,71,2,LEAVES:0)
Block(7,71,3,LEAVES:0)
Block(7,71,4,LEAVES:0)
Block(7,71,5,LEAVES:0)
Block(7,71,6,LEAVES:0)
Block(7,72,-5,LEAVES:0)
Block(7,72,-4,LEAVES:0)
Block(7,72,-3,LEAVES:0)
Block(7,72,-2,LEAVES:0)
Block(7,72,-1,LEAVES:0)
Block(7,72,0,LEAVES:0)
Block(7,72,3,LEAVES:0)
Block(7,72,4,LEAVES:0)
Block(7,73,-7,LEAVES:0)
Block(7,73,-5,LEAVES:0)
Block(7,73,-4,LEAVES:0)
Block(7,73,-3,LEAVES:0)
Block(7,73,-2,LEAVES:0)
Block(7,73,-1,LEAVES:0)
Block(7,73,0,LEAVES:0)
Block(7,73,4,LEAVES:0)
Block(7,74,-7,LEAVES:0)
Block(7,74,-6,LEAVES:0)
Block(7,74,-5,LEAVES:0)
Block(7,74,-4,LEAVES:0)
Block(7,74,-2,LEAVES:0)
Block(7,75,-7,LEAVES:0)
Block(7,75,-6,LEAVES:0)
Block(7,75,-5,LEAVES:0)
Block(7,75,-2,LEAVES:0)
Block(7,75,5,LEAVES:0)
Block(7,75,6,LEAVES:0)
Block(7,76,-7,LEAVES:0)
Block(7,76,-6,LEAVES:0)
Block(7,76,-5,LEAVES:0)
Block(7,76,-4,LEAVES:0)
Block(7,76,-3,LEAVES:0)
Block(7,76,-2,LEAVES:0)
Block(7,76,4,LEAVES:0)
Block(7,76,5,LEAVES:0)
Block(7,76,6,LEAVES:0)
Block(7,77,-7,LEAVES:0)
Block(7,77,-6,LEAVES:0)
Block(7,77,-5,LEAVES:0)
Block(7,77,-4,LEAVES:0)
Block(7,77,-3,LEAVES:0)
Block(7,77,-2,LEAVES:0)
Block(7,77,5,LEAVES:0)
Block(7,77,6,LEAVES:0)
Block(7,77,7,LEAVES:0)
Block(7,78,-7,LOG:12)
Block(7,78,-6,LEAVES:0)
Block(7,78,-4,LEAVES:0)
Block(7,78,6,LEAVES:0)
Block(7,78,7,LEAVES:0)
Block(7,79,-7,LEAVES:0)
Block(7,79,-6,LEAVES:0)
Block(7,79,-4,LEAVES:0)
Block(7,80,-7,LEAVES:0)
Block(7,80,-6,LEAVES:0)
Block(7,80,-5,LEAVES:0)
Block(7,80,-4,LEAVES:0)
Block(7,80,-3,LEAVES:0)
Block(7,80,-2,LEAVES:0)
Block(7,80,-1,LEAVES:0)
Block(7,80,0,LEAVES:0)
Block(7,81,-7,LEAVES:0)
Block(7,81,-6,LEAVES:0)
Block(7,81,-5,LEAVES:0)
Block(7,81,-4,LEAVES:0)
Block(7,81,-3,LEAVES:0)
Block(7,81,-2,LEAVES:0)
Block(7,81,-1,LEAVES:0)
Block(7,82,-7,LEAVES:0)
Block(7,82,-6,LEAVES:0)
Block(7,82,-3,inspirations:rope:1)
Block(7,83,-7,LEAVES:0)
Block(7,83,-3,inspirations:rope:1)
Block(7,84,-3,inspirations:rope:1)
Block(7,85,-3,inspirations:rope:1)
Block(7,86,-3,inspirations:rope:1)
Block(7,87,-3,inspirations:rope:1)
RandomBlock(7,88,-4,minecraft:wool:0,10,quark:quilted_wool:0,100)
RandomBlock(7,88,-3,minecraft:wool:0,10,quark:quilted_wool:0,100)
RandomBlock(7,88,-2,minecraft:wool:0,10,quark:quilted_wool:0,100)
RandomBlock(7,89,-5,minecraft:wool:0,10,quark:quilted_wool:0,100)
RandomBlock(7,89,-4,minecraft:wool:0,10,quark:quilted_wool:0,100)
RandomBlock(7,89,-3,minecraft:wool:0,10,quark:quilted_wool:0,100)
RandomBlock(7,89,-2,minecraft:wool:0,10,quark:quilted_wool:0,100)
RandomBlock(7,89,-1,minecraft:wool:0,10,quark:quilted_wool:0,100)
RandomBlock(7,89,7,minecraft:wool:7,10,quark:quilted_wool:7,100)
RandomBlock(7,90,-6,minecraft:wool:0,10,quark:quilted_wool:0,100)
RandomBlock(7,90,-5,minecraft:wool:0,10,quark:quilted_wool:0,100)
RandomBlock(7,90,-4,minecraft:wool:0,10,quark:quilted_wool:0,100)
RandomBlock(7,90,-3,minecraft:wool:0,10,quark:quilted_wool:0,100)
RandomBlock(7,90,-2,minecraft:wool:0,10,quark:quilted_wool:0,100)
RandomBlock(7,90,-1,minecraft:wool:0,10,quark:quilted_wool:0,100)
RandomBlock(7,90,0,minecraft:wool:0,10,quark:quilted_wool:0,100)
RandomBlock(7,90,6,minecraft:wool:7,10,quark:quilted_wool:7,100)
RandomBlock(7,90,7,minecraft:wool:7,10,quark:quilted_wool:7,100)
RandomBlock(7,90,8,minecraft:wool:7,10,quark:quilted_wool:7,100)
RandomBlock(7,91,-7,minecraft:wool:0,10,quark:quilted_wool:0,100)
RandomBlock(7,91,-6,minecraft:wool:0,10,quark:quilted_wool:0,100)
RandomBlock(7,91,-5,minecraft:wool:0,10,quark:quilted_wool:0,100)
RandomBlock(7,91,-4,minecraft:wool:0,10,quark:quilted_wool:0,100)
RandomBlock(7,91,-3,minecraft:wool:0,10,quark:quilted_wool:0,100)
RandomBlock(7,91,-2,minecraft:wool:0,10,quark:quilted_wool:0,100)
RandomBlock(7,91,-1,minecraft:wool:0,10,quark:quilted_wool:0,100)
RandomBlock(7,91,0,minecraft:wool:0,10,quark:quilted_wool:0,100)
RandomBlock(7,91,1,minecraft:wool:0,10,quark:quilted_wool:0,100)
RandomBlock(7,91,5,minecraft:wool:7,10,quark:quilted_wool:7,100)
RandomBlock(7,91,6,minecraft:wool:7,10,quark:quilted_wool:7,100)
RandomBlock(7,91,7,minecraft:wool:7,10,quark:quilted_wool:7,100)
RandomBlock(7,91,8,minecraft:wool:7,10,quark:quilted_wool:7,100)
RandomBlock(7,92,-7,minecraft:wool:0,10,quark:quilted_wool:0,100)
RandomBlock(7,92,-6,minecraft:wool:0,10,quark:quilted_wool:0,100)
RandomBlock(7,92,-5,minecraft:wool:0,10,quark:quilted_wool:0,100)
RandomBlock(7,92,-4,minecraft:wool:0,10,quark:quilted_wool:0,100)
RandomBlock(7,92,-3,minecraft:wool:0,10,quark:quilted_wool:0,100)
RandomBlock(7,92,-2,minecraft:wool:0,10,quark:quilted_wool:0,100)
RandomBlock(7,92,-1,minecraft:wool:0,10,quark:quilted_wool:0,100)
RandomBlock(7,92,0,minecraft:wool:0,10,quark:quilted_wool:0,100)
RandomBlock(7,92,1,minecraft:wool:0,10,quark:quilted_wool:0,100)
RandomBlock(7,92,5,minecraft:wool:7,10,quark:quilted_wool:7,100)
RandomBlock(7,92,6,minecraft:wool:7,10,quark:quilted_wool:7,100)
RandomBlock(7,92,7,minecraft:wool:7,10,quark:quilted_wool:7,100)
RandomBlock(7,92,8,minecraft:wool:7,10,quark:quilted_wool:7,100)
RandomBlock(7,93,-7,minecraft:wool:0,10,quark:quilted_wool:0,100)
RandomBlock(7,93,-6,minecraft:wool:0,10,quark:quilted_wool:0,100)
RandomBlock(7,93,-5,minecraft:wool:0,10,quark:quilted_wool:0,100)
RandomBlock(7,93,-4,minecraft:wool:0,10,quark:quilted_wool:0,100)
RandomBlock(7,93,-3,minecraft:wool:0,10,quark:quilted_wool:0,100)
RandomBlock(7,93,-2,minecraft:wool:0,10,quark:quilted_wool:0,100)
RandomBlock(7,93,-1,minecraft:wool:0,10,quark:quilted_wool:0,100)
RandomBlock(7,93,0,minecraft:wool:0,10,quark:quilted_wool:0,100)
RandomBlock(7,93,1,minecraft:wool:0,10,quark:quilted_wool:0,100)
RandomBlock(7,93,5,minecraft:wool:7,10,quark:quilted_wool:7,100)
RandomBlock(7,93,6,minecraft:wool:7,10,quark:quilted_wool:7,100)
RandomBlock(7,93,7,minecraft:wool:7,10,quark:quilted_wool:7,100)
RandomBlock(7,93,8,minecraft:wool:7,10,quark:quilted_wool:7,100)
RandomBlock(7,94,-7,minecraft:wool:0,10,quark:quilted_wool:0,100)
RandomBlock(7,94,-6,minecraft:wool:0,10,quark:quilted_wool:0,100)
RandomBlock(7,94,-5,minecraft:wool:0,10,quark:quilted_wool:0,100)
RandomBlock(7,94,-4,minecraft:wool:0,10,quark:quilted_wool:0,100)
RandomBlock(7,94,-3,minecraft:wool:0,10,quark:quilted_wool:0,100)
RandomBlock(7,94,-2,minecraft:wool:0,10,quark:quilted_wool:0,100)
RandomBlock(7,94,-1,minecraft:wool:0,10,quark:quilted_wool:0,100)
RandomBlock(7,94,0,minecraft:wool:0,10,quark:quilted_wool:0,100)
RandomBlock(7,94,1,minecraft:wool:0,10,quark:quilted_wool:0,100)
RandomBlock(7,94,2,minecraft:wool:0,10,quark:quilted_wool:0,100)
RandomBlock(7,94,6,minecraft:wool:7,10,quark:quilted_wool:7,100)
RandomBlock(7,94,7,minecraft:wool:7,10,quark:quilted_wool:7,100)
RandomBlock(7,94,8,minecraft:wool:7,10,quark:quilted_wool:7,100)
RandomBlock(7,95,-7,minecraft:wool:0,10,quark:quilted_wool:0,100)
RandomBlock(7,95,-6,minecraft:wool:0,10,quark:quilted_wool:0,100)
RandomBlock(7,95,-5,minecraft:wool:0,10,quark:quilted_wool:0,100)
RandomBlock(7,95,-4,minecraft:wool:0,10,quark:quilted_wool:0,100)
RandomBlock(7,95,-3,minecraft:wool:0,10,quark:quilted_wool:0,100)
RandomBlock(7,95,-2,minecraft:wool:0,10,quark:quilted_wool:0,100)
RandomBlock(7,95,-1,minecraft:wool:0,10,quark:quilted_wool:0,100)
RandomBlock(7,95,0,minecraft:wool:0,10,quark:quilted_wool:0,100)
RandomBlock(7,95,1,minecraft:wool:0,10,quark:quilted_wool:0,100)
RandomBlock(7,95,2,minecraft:wool:0,10,quark:quilted_wool:0,100)
RandomBlock(7,95,7,minecraft:wool:7,10,quark:quilted_wool:7,100)
RandomBlock(7,96,-7,minecraft:wool:0,10,quark:quilted_wool:0,100)
RandomBlock(7,96,-6,minecraft:wool:0,10,quark:quilted_wool:0,100)
RandomBlock(7,96,-5,minecraft:wool:0,10,quark:quilted_wool:0,100)
RandomBlock(7,96,-4,minecraft:wool:0,10,quark:quilted_wool:0,100)
RandomBlock(7,96,-3,minecraft:wool:0,10,quark:quilted_wool:0,100)
RandomBlock(7,96,-2,minecraft:wool:0,10,quark:quilted_wool:0,100)
RandomBlock(7,96,-1,minecraft:wool:0,10,quark:quilted_wool:0,100)
RandomBlock(7,96,0,minecraft:wool:0,10,quark:quilted_wool:0,100)
RandomBlock(7,96,1,minecraft:wool:0,10,quark:quilted_wool:0,100)
RandomBlock(7,96,2,minecraft:wool:0,10,quark:quilted_wool:0,100)
RandomBlock(7,97,-7,minecraft:wool:0,10,quark:quilted_wool:0,100)
RandomBlock(7,97,-6,minecraft:wool:0,10,quark:quilted_wool:0,100)
RandomBlock(7,97,-5,minecraft:wool:0,10,quark:quilted_wool:0,100)
RandomBlock(7,97,-4,minecraft:wool:0,10,quark:quilted_wool:0,100)
RandomBlock(7,97,-3,minecraft:wool:0,10,quark:quilted_wool:0,100)
RandomBlock(7,97,-2,minecraft:wool:0,10,quark:quilted_wool:0,100)
RandomBlock(7,97,-1,minecraft:wool:0,10,quark:quilted_wool:0,100)
RandomBlock(7,97,0,minecraft:wool:0,10,quark:quilted_wool:0,100)
RandomBlock(7,97,1,minecraft:wool:0,10,quark:quilted_wool:0,100)
RandomBlock(7,97,2,minecraft:wool:0,10,quark:quilted_wool:0,100)
RandomBlock(7,98,-7,minecraft:wool:0,10,quark:quilted_wool:0,100)
RandomBlock(7,98,-6,minecraft:wool:0,10,quark:quilted_wool:0,100)
RandomBlock(7,98,-5,minecraft:wool:0,10,quark:quilted_wool:0,100)
RandomBlock(7,98,-4,minecraft:wool:0,10,quark:quilted_wool:0,100)
RandomBlock(7,98,-3,minecraft:wool:0,10,quark:quilted_wool:0,100)
RandomBlock(7,98,-2,minecraft:wool:0,10,quark:quilted_wool:0,100)
RandomBlock(7,98,-1,minecraft:wool:0,10,quark:quilted_wool:0,100)
RandomBlock(7,98,0,minecraft:wool:0,10,quark:quilted_wool:0,100)
RandomBlock(7,98,1,minecraft:wool:0,10,quark:quilted_wool:0,100)
RandomBlock(7,98,2,minecraft:wool:0,10,quark:quilted_wool:0,100)
RandomBlock(7,99,-7,minecraft:wool:0,10,quark:quilted_wool:0,100)
RandomBlock(7,99,-6,minecraft:wool:0,10,quark:quilted_wool:0,100)
RandomBlock(7,99,-5,minecraft:wool:0,10,quark:quilted_wool:0,100)
RandomBlock(7,99,-4,minecraft:wool:0,10,quark:quilted_wool:0,100)
RandomBlock(7,99,-3,minecraft:wool:0,10,quark:quilted_wool:0,100)
RandomBlock(7,99,-2,minecraft:wool:0,10,quark:quilted_wool:0,100)
RandomBlock(7,99,-1,minecraft:wool:0,10,quark:quilted_wool:0,100)
RandomBlock(7,99,0,minecraft:wool:0,10,quark:quilted_wool:0,100)
RandomBlock(7,99,1,minecraft:wool:0,10,quark:quilted_wool:0,100)
RandomBlock(7,99,2,minecraft:wool:0,10,quark:quilted_wool:0,100)
RandomBlock(7,100,-7,minecraft:wool:0,10,quark:quilted_wool:0,100)
RandomBlock(7,100,-6,minecraft:wool:0,10,quark:quilted_wool:0,100)
RandomBlock(7,100,-5,minecraft:wool:0,10,quark:quilted_wool:0,100)
RandomBlock(7,100,-4,minecraft:wool:0,10,quark:quilted_wool:0,100)
RandomBlock(7,100,-3,minecraft:wool:0,10,quark:quilted_wool:0,100)
RandomBlock(7,100,-2,minecraft:wool:0,10,quark:quilted_wool:0,100)
RandomBlock(7,100,-1,minecraft:wool:0,10,quark:quilted_wool:0,100)
RandomBlock(7,100,0,minecraft:wool:0,10,quark:quilted_wool:0,100)
RandomBlock(7,100,1,minecraft:wool:0,10,quark:quilted_wool:0,100)
RandomBlock(7,100,2,minecraft:wool:0,10,quark:quilted_wool:0,100)
RandomBlock(7,101,-7,minecraft:wool:0,10,quark:quilted_wool:0,100)
RandomBlock(7,101,-6,minecraft:wool:0,10,quark:quilted_wool:0,100)
RandomBlock(7,101,-5,minecraft:wool:0,10,quark:quilted_wool:0,100)
RandomBlock(7,101,-4,minecraft:wool:0,10,quark:quilted_wool:0,100)
RandomBlock(7,101,-3,minecraft:wool:0,10,quark:quilted_wool:0,100)
RandomBlock(7,101,-2,minecraft:wool:0,10,quark:quilted_wool:0,100)
RandomBlock(7,101,-1,minecraft:wool:0,10,quark:quilted_wool:0,100)
RandomBlock(7,101,0,minecraft:wool:0,10,quark:quilted_wool:0,100)
RandomBlock(7,101,1,minecraft:wool:0,10,quark:quilted_wool:0,100)
RandomBlock(7,101,2,minecraft:wool:0,10,quark:quilted_wool:0,100)
RandomBlock(7,102,-7,minecraft:wool:0,10,quark:quilted_wool:0,100)
RandomBlock(7,102,-6,minecraft:wool:0,10,quark:quilted_wool:0,100)
RandomBlock(7,102,-5,minecraft:wool:0,10,quark:quilted_wool:0,100)
RandomBlock(7,102,-4,minecraft:wool:0,10,quark:quilted_wool:0,100)
RandomBlock(7,102,-3,minecraft:wool:0,10,quark:quilted_wool:0,100)
RandomBlock(7,102,-2,minecraft:wool:0,10,quark:quilted_wool:0,100)
RandomBlock(7,102,-1,minecraft:wool:0,10,quark:quilted_wool:0,100)
RandomBlock(7,102,0,minecraft:wool:0,10,quark:quilted_wool:0,100)
RandomBlock(7,102,1,minecraft:wool:0,10,quark:quilted_wool:0,100)
RandomBlock(7,102,2,minecraft:wool:0,10,quark:quilted_wool:0,100)
RandomBlock(7,103,-7,minecraft:wool:0,10,quark:quilted_wool:0,100)
RandomBlock(7,103,-6,minecraft:wool:0,10,quark:quilted_wool:0,100)
RandomBlock(7,103,-5,minecraft:wool:0,10,quark:quilted_wool:0,100)
RandomBlock(7,103,-4,minecraft:wool:0,10,quark:quilted_wool:0,100)
RandomBlock(7,103,-3,minecraft:wool:0,10,quark:quilted_wool:0,100)
RandomBlock(7,103,-2,minecraft:wool:0,10,quark:quilted_wool:0,100)
RandomBlock(7,103,-1,minecraft:wool:0,10,quark:quilted_wool:0,100)
RandomBlock(7,103,0,minecraft:wool:0,10,quark:quilted_wool:0,100)
RandomBlock(7,103,1,minecraft:wool:0,10,quark:quilted_wool:0,100)
RandomBlock(7,104,-7,minecraft:wool:0,10,quark:quilted_wool:0,100)
RandomBlock(7,104,-6,minecraft:wool:0,10,quark:quilted_wool:0,100)
RandomBlock(7,104,-5,minecraft:wool:0,10,quark:quilted_wool:0,100)
RandomBlock(7,104,-4,minecraft:wool:0,10,quark:quilted_wool:0,100)
RandomBlock(7,104,-3,minecraft:wool:0,10,quark:quilted_wool:0,100)
RandomBlock(7,104,-2,minecraft:wool:0,10,quark:quilted_wool:0,100)
RandomBlock(7,104,-1,minecraft:wool:0,10,quark:quilted_wool:0,100)
RandomBlock(7,104,0,minecraft:wool:0,10,quark:quilted_wool:0,100)
RandomBlock(7,104,1,minecraft:wool:0,10,quark:quilted_wool:0,100)
RandomBlock(7,105,-7,minecraft:wool:0,10,quark:quilted_wool:0,100)
RandomBlock(7,105,-6,minecraft:wool:0,10,quark:quilted_wool:0,100)
RandomBlock(7,105,-5,minecraft:wool:0,10,quark:quilted_wool:0,100)
RandomBlock(7,105,-4,minecraft:wool:0,10,quark:quilted_wool:0,100)
RandomBlock(7,105,-3,minecraft:wool:0,10,quark:quilted_wool:0,100)
RandomBlock(7,105,-2,minecraft:wool:0,10,quark:quilted_wool:0,100)
RandomBlock(7,105,-1,minecraft:wool:0,10,quark:quilted_wool:0,100)
RandomBlock(7,105,0,minecraft:wool:0,10,quark:quilted_wool:0,100)
RandomBlock(7,105,1,minecraft:wool:0,10,quark:quilted_wool:0,100)
RandomBlock(7,106,-6,minecraft:wool:0,10,quark:quilted_wool:0,100)
RandomBlock(7,106,-5,minecraft:wool:0,10,quark:quilted_wool:0,100)
RandomBlock(7,106,-4,minecraft:wool:0,10,quark:quilted_wool:0,100)
RandomBlock(7,106,-3,minecraft:wool:0,10,quark:quilted_wool:0,100)
RandomBlock(7,106,-2,minecraft:wool:0,10,quark:quilted_wool:0,100)
RandomBlock(7,106,-1,minecraft:wool:0,10,quark:quilted_wool:0,100)
RandomBlock(7,106,0,minecraft:wool:0,10,quark:quilted_wool:0,100)
RandomBlock(7,107,-5,minecraft:wool:0,10,quark:quilted_wool:0,100)
RandomBlock(7,107,-4,minecraft:wool:0,10,quark:quilted_wool:0,100)
RandomBlock(7,107,-3,minecraft:wool:0,10,quark:quilted_wool:0,100)
RandomBlock(7,107,-2,minecraft:wool:0,10,quark:quilted_wool:0,100)
RandomBlock(7,107,-1,minecraft:wool:0,10,quark:quilted_wool:0,100)
RandomBlock(7,108,-4,minecraft:wool:0,10,quark:quilted_wool:0,100)
RandomBlock(7,108,-3,minecraft:wool:0,10,quark:quilted_wool:0,100)
RandomBlock(7,108,-2,minecraft:wool:0,10,quark:quilted_wool:0,100)

#######################################################################
# +-----------------------------------------------------------------+ #
# |                             Branches                            | #
# +-----------------------------------------------------------------+ #
#######################################################################

Branch(0,0,-16,true,TreeTestC0R1,NORTH,100.0,0)

