
#######################################################################
# +-----------------------------------------------------------------+ #
# |                            BO4 object                           | #
# +-----------------------------------------------------------------+ #
#######################################################################

Author: NLBlackEagle

Description: No description given

SettingsMode: WriteDisable


#######################################################################
# +-----------------------------------------------------------------+ #
# |                          Main settings                          | #
# +-----------------------------------------------------------------+ #
#######################################################################

FixedRotation: 

Frequency: 0

SpawnHeight: highestBlock

UseCenterForHighestBlock: true

##############################
# Height Limits for the BO4. #
##############################

MinHeight: 0

MaxHeight: 255

InheritBO3: 

InheritBO3Rotation: NORTH

OverrideChildSettings: true

OverrideParentHeight: false

CanOverride: false

BranchFrequency: 0

BranchFrequencyGroup: 

MustBeBelowOther: false

MustBeInside: 

CannotBeInside: 

ReplacesBO3: 

MustBeInsideWorldBorders: false

CanSpawnOnWater: true

SpawnOnWaterOnly: false

SpawnUnderWater: false

SpawnAtWaterLevel: false

HeightOffset: 0

RemoveAir: true

ReplaceAbove: 

ReplaceBelow: 

ReplaceWithBiomeBlocks: true

ReplaceWithSurfaceBlock: GRASS

ReplaceWithGroundBlock: DIRT

ReplaceWithStoneBlock: STONE

SmoothRadius: 0

SmoothHeightOffset: 0

SmoothStartTop: false

SmoothStartWood: false

SmoothingSurfaceBlock: 

SmoothingGroundBlock: 

BO3Group: 

IsSpawnPoint: false

DoReplaceBlocks: true


#######################################################################
# +-----------------------------------------------------------------+ #
# |                              Blocks                             | #
# +-----------------------------------------------------------------+ #
#######################################################################

Block(-8,56,-2,LEAVES:0)
Block(-8,56,-1,LEAVES:0)
Block(-8,56,0,LEAVES:0)
Block(-8,56,1,LEAVES:0)
Block(-8,57,-2,LEAVES:0)
Block(-8,57,-1,LEAVES:0)
Block(-8,57,0,LEAVES:0)
Block(-8,57,1,LEAVES:0)
Block(-7,56,-2,LEAVES:0)
Block(-7,56,-1,LEAVES:0)
Block(-7,56,0,LEAVES:0)
Block(-7,56,1,LEAVES:0)
Block(-7,56,2,LEAVES:0)
Block(-7,57,-2,LEAVES:0)
Block(-7,57,-1,LEAVES:0)
Block(-7,57,0,LEAVES:0)
Block(-7,57,1,LEAVES:0)
Block(-7,57,2,LEAVES:0)
Block(-7,58,0,LEAVES:0)
Block(-7,59,0,LEAVES:0)
Block(-6,54,0,LOG:12)
Block(-6,55,0,LOG:12)
Block(-6,56,-2,LEAVES:0)
Block(-6,56,-1,LEAVES:0)
Block(-6,56,0,LOG:12)
Block(-6,56,1,LEAVES:0)
Block(-6,56,2,LEAVES:0)
Block(-6,57,-2,LEAVES:0)
Block(-6,57,-1,LEAVES:0)
Block(-6,57,0,LOG:12)
Block(-6,57,1,LEAVES:0)
Block(-6,57,2,LEAVES:0)
Block(-6,57,3,LEAVES:0)
Block(-6,57,4,LEAVES:0)
Block(-6,57,5,LEAVES:0)
Block(-6,57,6,LEAVES:0)
Block(-6,58,-1,LEAVES:0)
Block(-6,58,0,LOG:12)
Block(-6,58,1,LEAVES:0)
Block(-6,58,2,LEAVES:0)
Block(-6,58,3,LEAVES:0)
Block(-6,58,4,LEAVES:0)
Block(-6,58,5,LEAVES:0)
Block(-6,58,6,LEAVES:0)
Block(-6,58,7,LEAVES:0)
Block(-6,59,-1,LEAVES:0)
Block(-6,59,0,LEAVES:0)
Block(-6,59,1,LEAVES:0)
Block(-5,2,-4,LOG:12)
Block(-5,3,-4,LOG:12)
Block(-5,4,-4,quark:leaf_carpet)
Block(-5,28,5,VINE:8)
RandomBlock(-5,29,-6,minecraft:wool:7,10,quark:quilted_wool:7,100)
RandomBlock(-5,29,-5,minecraft:wool:7,10,quark:quilted_wool:7,100)
RandomBlock(-5,29,-4,minecraft:wool:7,10,quark:quilted_wool:7,100)
Block(-5,29,5,VINE:8)
RandomBlock(-5,30,-6,minecraft:wool:7,10,quark:quilted_wool:7,100)
RandomBlock(-5,30,-5,minecraft:wool:7,10,quark:quilted_wool:7,100)
RandomBlock(-5,30,-4,minecraft:wool:7,10,quark:quilted_wool:7,100)
Block(-5,30,5,VINE:8)
RandomBlock(-5,31,-7,minecraft:wool:7,10,quark:quilted_wool:7,100)
RandomBlock(-5,31,-6,minecraft:wool:7,10,quark:quilted_wool:7,100)
RandomBlock(-5,31,-5,minecraft:wool:7,10,quark:quilted_wool:7,100)
RandomBlock(-5,31,-4,minecraft:wool:7,10,quark:quilted_wool:7,100)
RandomBlock(-5,31,-3,minecraft:wool:7,10,quark:quilted_wool:7,100)
Block(-5,31,5,VINE:8)
RandomBlock(-5,32,-6,minecraft:wool:7,10,quark:quilted_wool:7,100)
RandomBlock(-5,32,-5,minecraft:wool:7,10,quark:quilted_wool:7,100)
RandomBlock(-5,32,-4,minecraft:wool:7,10,quark:quilted_wool:7,100)
Block(-5,32,5,VINE:8)
RandomBlock(-5,33,-6,minecraft:wool:7,10,quark:quilted_wool:7,100)
RandomBlock(-5,33,-5,minecraft:wool:7,10,quark:quilted_wool:7,100)
RandomBlock(-5,33,-4,minecraft:wool:7,10,quark:quilted_wool:7,100)
Block(-5,33,5,VINE:8)
Block(-5,34,5,VINE:8)
Block(-5,35,5,VINE:8)
Block(-5,36,4,VINE:8)
Block(-5,36,5,VINE:8)
Block(-5,37,4,VINE:8)
Block(-5,37,5,VINE:8)
Block(-5,38,4,VINE:8)
Block(-5,38,5,VINE:8)
Block(-5,39,4,VINE:8)
Block(-5,39,5,VINE:8)
Block(-5,40,4,VINE:8)
Block(-5,40,5,VINE:8)
Block(-5,41,4,VINE:8)
Block(-5,41,5,VINE:8)
Block(-5,42,4,VINE:8)
Block(-5,42,5,VINE:8)
Block(-5,43,4,VINE:8)
Block(-5,43,5,VINE:8)
Block(-5,44,4,VINE:8)
Block(-5,44,5,VINE:8)
Block(-5,45,4,VINE:8)
Block(-5,45,5,VINE:8)
Block(-5,46,4,VINE:8)
Block(-5,46,5,VINE:8)
Block(-5,47,4,VINE:8)
Block(-5,47,5,VINE:8)
Block(-5,48,4,VINE:8)
Block(-5,48,5,VINE:8)
Block(-5,49,4,VINE:8)
Block(-5,49,5,VINE:8)
Block(-5,50,4,VINE:8)
Block(-5,50,5,VINE:8)
Block(-5,51,4,VINE:8)
Block(-5,51,5,VINE:8)
Block(-5,52,4,VINE:8)
Block(-5,52,5,VINE:8)
Block(-5,53,4,VINE:8)
Block(-5,53,5,VINE:8)
Block(-5,54,0,LOG:12)
Block(-5,54,4,VINE:8)
Block(-5,54,5,VINE:8)
Block(-5,55,4,VINE:8)
Block(-5,55,5,VINE:8)
Block(-5,56,-2,LEAVES:0)
Block(-5,56,-1,LEAVES:0)
Block(-5,56,0,LEAVES:0)
Block(-5,56,1,LEAVES:0)
Block(-5,56,2,LEAVES:0)
Block(-5,56,4,VINE:8)
Block(-5,56,5,VINE:8)
Block(-5,57,-2,LEAVES:0)
Block(-5,57,-1,LEAVES:0)
Block(-5,57,0,LEAVES:0)
Block(-5,57,1,LEAVES:0)
Block(-5,57,2,LEAVES:0)
Block(-5,57,3,LEAVES:0)
Block(-5,57,4,LEAVES:0)
Block(-5,57,5,LEAVES:0)
Block(-5,57,6,LEAVES:0)
Block(-5,57,7,LEAVES:0)
Block(-5,58,0,LEAVES:0)
Block(-5,58,1,LEAVES:0)
Block(-5,58,2,LEAVES:0)
Block(-5,58,3,LEAVES:0)
Block(-5,58,4,LEAVES:0)
Block(-5,58,5,LEAVES:0)
Block(-5,58,6,LEAVES:0)
Block(-5,58,7,LEAVES:0)
Block(-5,59,0,LEAVES:0)
Block(-5,59,3,LEAVES:0)
Block(-5,59,4,LEAVES:0)
Block(-5,59,5,LEAVES:0)
Block(-5,59,6,LEAVES:0)
Block(-5,60,4,LEAVES:0)
Block(-5,60,5,LEAVES:0)
Block(-5,73,1,LEAVES:0)
Block(-5,73,2,LEAVES:0)
Block(-5,73,3,LEAVES:0)
Block(-5,74,0,LEAVES:0)
Block(-5,74,1,LEAVES:0)
Block(-5,74,2,LEAVES:0)
Block(-5,75,1,LEAVES:0)
Block(-4,3,-4,LOG:12)
Block(-4,4,-4,LOG:12)
RandomBlock(-4,27,-6,minecraft:wool:7,10,quark:quilted_wool:7,100)
RandomBlock(-4,27,-5,minecraft:wool:7,10,quark:quilted_wool:7,100)
RandomBlock(-4,27,-4,minecraft:wool:7,10,quark:quilted_wool:7,100)
RandomBlock(-4,28,-7,minecraft:wool:7,10,quark:quilted_wool:7,100)
RandomBlock(-4,28,-6,minecraft:wool:7,10,quark:quilted_wool:7,100)
RandomBlock(-4,28,-5,minecraft:wool:7,10,quark:quilted_wool:7,100)
RandomBlock(-4,28,-4,minecraft:wool:7,10,quark:quilted_wool:7,100)
RandomBlock(-4,28,-3,minecraft:wool:7,10,quark:quilted_wool:7,100)
RandomBlock(-4,29,-7,minecraft:wool:7,10,quark:quilted_wool:7,100)
RandomBlock(-4,29,-6,minecraft:wool:7,10,quark:quilted_wool:7,100)
RandomBlock(-4,29,-5,minecraft:wool:7,10,quark:quilted_wool:7,100)
RandomBlock(-4,29,-4,minecraft:wool:7,10,quark:quilted_wool:7,100)
RandomBlock(-4,29,-3,minecraft:wool:7,10,quark:quilted_wool:7,100)
RandomBlock(-4,29,-2,minecraft:wool:7,10,quark:quilted_wool:7,100)
RandomBlock(-4,30,-7,minecraft:wool:7,10,quark:quilted_wool:7,100)
RandomBlock(-4,30,-6,minecraft:wool:7,10,quark:quilted_wool:7,100)
RandomBlock(-4,30,-5,minecraft:wool:7,10,quark:quilted_wool:7,100)
RandomBlock(-4,30,-4,minecraft:wool:7,10,quark:quilted_wool:7,100)
RandomBlock(-4,30,-3,minecraft:wool:7,10,quark:quilted_wool:7,100)
RandomBlock(-4,30,-2,minecraft:wool:7,10,quark:quilted_wool:7,100)
Block(-4,30,6,VINE:4)
RandomBlock(-4,31,-7,minecraft:wool:7,10,quark:quilted_wool:7,100)
RandomBlock(-4,31,-6,minecraft:wool:7,10,quark:quilted_wool:7,100)
RandomBlock(-4,31,-5,minecraft:wool:7,10,quark:quilted_wool:7,100)
RandomBlock(-4,31,-4,minecraft:wool:7,10,quark:quilted_wool:7,100)
RandomBlock(-4,31,-3,minecraft:wool:7,10,quark:quilted_wool:7,100)
RandomBlock(-4,31,-2,minecraft:wool:7,10,quark:quilted_wool:7,100)
Block(-4,31,6,VINE:4)
RandomBlock(-4,32,-7,minecraft:wool:7,10,quark:quilted_wool:7,100)
RandomBlock(-4,32,-6,minecraft:wool:7,10,quark:quilted_wool:7,100)
RandomBlock(-4,32,-5,minecraft:wool:7,10,quark:quilted_wool:7,100)
RandomBlock(-4,32,-4,minecraft:wool:7,10,quark:quilted_wool:7,100)
RandomBlock(-4,32,-3,minecraft:wool:7,10,quark:quilted_wool:7,100)
RandomBlock(-4,32,-2,minecraft:wool:7,10,quark:quilted_wool:7,100)
Block(-4,32,6,VINE:4)
RandomBlock(-4,33,-7,minecraft:wool:7,10,quark:quilted_wool:7,100)
RandomBlock(-4,33,-6,minecraft:wool:7,10,quark:quilted_wool:7,100)
RandomBlock(-4,33,-5,minecraft:wool:7,10,quark:quilted_wool:7,100)
RandomBlock(-4,33,-4,minecraft:wool:7,10,quark:quilted_wool:7,100)
RandomBlock(-4,33,-3,minecraft:wool:7,10,quark:quilted_wool:7,100)
RandomBlock(-4,33,-2,minecraft:wool:7,10,quark:quilted_wool:7,100)
Block(-4,33,6,VINE:4)
RandomBlock(-4,34,-7,minecraft:wool:7,10,quark:quilted_wool:7,100)
RandomBlock(-4,34,-6,minecraft:wool:7,10,quark:quilted_wool:7,100)
RandomBlock(-4,34,-5,minecraft:wool:7,10,quark:quilted_wool:7,100)
RandomBlock(-4,34,-4,minecraft:wool:7,10,quark:quilted_wool:7,100)
RandomBlock(-4,34,-3,minecraft:wool:7,10,quark:quilted_wool:7,100)
Block(-4,34,6,VINE:4)
RandomBlock(-4,35,-6,minecraft:wool:7,10,quark:quilted_wool:7,100)
RandomBlock(-4,35,-5,minecraft:wool:7,10,quark:quilted_wool:7,100)
RandomBlock(-4,35,-4,minecraft:wool:7,10,quark:quilted_wool:7,100)
Block(-4,35,6,VINE:4)
Block(-4,36,6,VINE:4)
Block(-4,37,6,VINE:4)
Block(-4,38,6,VINE:4)
Block(-4,39,6,VINE:4)
Block(-4,40,6,VINE:4)
Block(-4,41,6,VINE:4)
Block(-4,42,6,VINE:4)
Block(-4,43,6,VINE:4)
Block(-4,44,6,VINE:4)
Block(-4,45,6,VINE:4)
Block(-4,46,6,VINE:4)
Block(-4,47,6,VINE:4)
Block(-4,48,3,VINE:1)
Block(-4,48,6,VINE:4)
Block(-4,49,3,VINE:1)
Block(-4,49,6,VINE:4)
Block(-4,50,3,VINE:1)
Block(-4,50,6,VINE:4)
Block(-4,51,3,VINE:1)
Block(-4,51,6,VINE:4)
Block(-4,52,3,VINE:1)
Block(-4,52,6,VINE:4)
Block(-4,53,3,VINE:1)
Block(-4,53,6,VINE:4)
Block(-4,54,0,LOG:12)
Block(-4,54,3,VINE:1)
Block(-4,54,4,LOG:12)
Block(-4,54,5,LOG:12)
Block(-4,54,6,VINE:4)
Block(-4,55,3,VINE:1)
Block(-4,55,4,LOG:12)
Block(-4,55,5,LOG:12)
Block(-4,55,6,VINE:4)
Block(-4,56,-1,LEAVES:0)
Block(-4,56,0,LEAVES:0)
Block(-4,56,1,LEAVES:0)
Block(-4,56,2,LEAVES:0)
Block(-4,56,3,VINE:1)
Block(-4,56,4,LOG:12)
Block(-4,56,5,LOG:12)
Block(-4,56,6,VINE:4)
Block(-4,57,-1,LEAVES:0)
Block(-4,57,0,LEAVES:0)
Block(-4,57,1,LEAVES:0)
Block(-4,57,2,LEAVES:0)
Block(-4,57,3,LEAVES:0)
Block(-4,57,4,LOG:12)
Block(-4,57,5,LOG:12)
Block(-4,57,6,LEAVES:0)
Block(-4,57,7,LEAVES:0)
Block(-4,58,2,LEAVES:0)
Block(-4,58,3,LEAVES:0)
Block(-4,58,4,LOG:12)
Block(-4,58,5,LOG:12)
Block(-4,58,6,LEAVES:0)
Block(-4,58,7,LEAVES:0)
Block(-4,59,3,LEAVES:0)
Block(-4,59,4,LOG:12)
Block(-4,59,5,LOG:12)
Block(-4,59,6,LEAVES:0)
Block(-4,59,7,LEAVES:0)
Block(-4,60,3,LEAVES:0)
Block(-4,60,4,LEAVES:0)
Block(-4,60,5,LEAVES:0)
Block(-4,60,6,LEAVES:0)
Block(-4,61,5,LEAVES:0)
Block(-4,67,5,LEAVES:0)
Block(-4,67,6,LEAVES:0)
Block(-4,67,7,LEAVES:0)
Block(-4,68,4,LEAVES:0)
Block(-4,68,5,LEAVES:0)
Block(-4,68,6,LEAVES:0)
Block(-4,68,7,LEAVES:0)
Block(-4,69,1,LEAVES:0)
Block(-4,69,2,LEAVES:0)
Block(-4,69,3,LEAVES:0)
Block(-4,69,4,LEAVES:0)
Block(-4,70,0,LEAVES:0)
Block(-4,70,2,LEAVES:0)
Block(-4,70,3,LEAVES:0)
Block(-4,70,4,LEAVES:0)
Block(-4,70,5,LEAVES:0)
Block(-4,71,-1,LEAVES:0)
Block(-4,71,0,LEAVES:0)
Block(-4,72,0,LEAVES:0)
Block(-4,72,1,LEAVES:0)
Block(-4,72,2,LEAVES:0)
Block(-4,73,0,LEAVES:0)
Block(-4,73,1,LEAVES:0)
Block(-4,73,2,LEAVES:0)
Block(-4,73,3,LEAVES:0)
Block(-4,73,4,LEAVES:0)
Block(-4,74,-1,LEAVES:0)
Block(-4,74,0,LEAVES:0)
Block(-4,74,1,LEAVES:0)
Block(-4,74,2,LEAVES:0)
Block(-4,74,3,LEAVES:0)
Block(-4,75,0,LEAVES:0)
Block(-4,75,1,LEAVES:0)
Block(-4,75,2,LEAVES:0)
Block(-4,76,1,LEAVES:0)
RandomBlock(-4,87,4,minecraft:wool:7,10,quark:quilted_wool:7,100)
RandomBlock(-4,87,5,minecraft:wool:7,10,quark:quilted_wool:7,100)
RandomBlock(-4,87,6,minecraft:wool:7,10,quark:quilted_wool:7,100)
RandomBlock(-4,88,4,minecraft:wool:7,10,quark:quilted_wool:7,100)
RandomBlock(-4,88,5,minecraft:wool:7,10,quark:quilted_wool:7,100)
RandomBlock(-4,88,6,minecraft:wool:7,10,quark:quilted_wool:7,100)
RandomBlock(-4,89,3,minecraft:wool:7,10,quark:quilted_wool:7,100)
RandomBlock(-4,89,4,minecraft:wool:7,10,quark:quilted_wool:7,100)
RandomBlock(-4,89,5,minecraft:wool:7,10,quark:quilted_wool:7,100)
RandomBlock(-4,89,6,minecraft:wool:7,10,quark:quilted_wool:7,100)
RandomBlock(-4,89,7,minecraft:wool:7,10,quark:quilted_wool:7,100)
RandomBlock(-4,90,4,minecraft:wool:7,10,quark:quilted_wool:7,100)
RandomBlock(-4,90,5,minecraft:wool:7,10,quark:quilted_wool:7,100)
RandomBlock(-4,90,6,minecraft:wool:7,10,quark:quilted_wool:7,100)
RandomBlock(-4,91,4,minecraft:wool:7,10,quark:quilted_wool:7,100)
RandomBlock(-4,91,5,minecraft:wool:7,10,quark:quilted_wool:7,100)
RandomBlock(-4,91,6,minecraft:wool:7,10,quark:quilted_wool:7,100)
Block(-3,4,-4,LOG:12)
Block(-3,5,-4,quark:leaf_carpet)
RandomBlock(-3,26,-7,minecraft:wool:7,10,quark:quilted_wool:7,100)
RandomBlock(-3,26,-6,minecraft:wool:7,10,quark:quilted_wool:7,100)
RandomBlock(-3,26,-5,minecraft:wool:7,10,quark:quilted_wool:7,100)
RandomBlock(-3,26,-4,minecraft:wool:7,10,quark:quilted_wool:7,100)
RandomBlock(-3,26,-3,minecraft:wool:7,10,quark:quilted_wool:7,100)
RandomBlock(-3,27,-7,minecraft:wool:7,10,quark:quilted_wool:7,100)
RandomBlock(-3,27,-6,minecraft:wool:7,10,quark:quilted_wool:7,100)
RandomBlock(-3,27,-5,minecraft:wool:7,10,quark:quilted_wool:7,100)
RandomBlock(-3,27,-4,minecraft:wool:7,10,quark:quilted_wool:7,100)
RandomBlock(-3,27,-3,minecraft:wool:7,10,quark:quilted_wool:7,100)
RandomBlock(-3,28,-7,minecraft:wool:7,10,quark:quilted_wool:7,100)
RandomBlock(-3,28,-6,minecraft:wool:7,10,quark:quilted_wool:7,100)
RandomBlock(-3,28,-5,minecraft:wool:7,10,quark:quilted_wool:7,100)
RandomBlock(-3,28,-4,minecraft:wool:7,10,quark:quilted_wool:7,100)
RandomBlock(-3,28,-3,minecraft:wool:7,10,quark:quilted_wool:7,100)
RandomBlock(-3,28,-2,minecraft:wool:7,10,quark:quilted_wool:7,100)
RandomBlock(-3,29,-7,minecraft:wool:7,10,quark:quilted_wool:7,100)
RandomBlock(-3,29,-6,minecraft:wool:7,10,quark:quilted_wool:7,100)
RandomBlock(-3,29,-5,minecraft:wool:7,10,quark:quilted_wool:7,100)
RandomBlock(-3,29,-4,minecraft:wool:7,10,quark:quilted_wool:7,100)
RandomBlock(-3,29,-3,minecraft:wool:7,10,quark:quilted_wool:7,100)
RandomBlock(-3,29,-2,minecraft:wool:7,10,quark:quilted_wool:7,100)
RandomBlock(-3,30,-7,minecraft:wool:7,10,quark:quilted_wool:7,100)
RandomBlock(-3,30,-6,minecraft:wool:7,10,quark:quilted_wool:7,100)
RandomBlock(-3,30,-5,minecraft:wool:7,10,quark:quilted_wool:7,100)
RandomBlock(-3,30,-4,minecraft:wool:7,10,quark:quilted_wool:7,100)
RandomBlock(-3,30,-3,minecraft:wool:7,10,quark:quilted_wool:7,100)
RandomBlock(-3,30,-2,minecraft:wool:7,10,quark:quilted_wool:7,100)
RandomBlock(-3,31,-7,minecraft:wool:7,10,quark:quilted_wool:7,100)
RandomBlock(-3,31,-6,minecraft:wool:7,10,quark:quilted_wool:7,100)
RandomBlock(-3,31,-5,minecraft:wool:7,10,quark:quilted_wool:7,100)
RandomBlock(-3,31,-4,minecraft:wool:7,10,quark:quilted_wool:7,100)
RandomBlock(-3,31,-3,minecraft:wool:7,10,quark:quilted_wool:7,100)
RandomBlock(-3,31,-2,minecraft:wool:7,10,quark:quilted_wool:7,100)
RandomBlock(-3,31,-1,minecraft:wool:7,10,quark:quilted_wool:7,100)
RandomBlock(-3,32,-7,minecraft:wool:7,10,quark:quilted_wool:7,100)
RandomBlock(-3,32,-6,minecraft:wool:7,10,quark:quilted_wool:7,100)
RandomBlock(-3,32,-5,minecraft:wool:7,10,quark:quilted_wool:7,100)
RandomBlock(-3,32,-4,minecraft:wool:7,10,quark:quilted_wool:7,100)
RandomBlock(-3,32,-3,minecraft:wool:7,10,quark:quilted_wool:7,100)
RandomBlock(-3,32,-2,minecraft:wool:7,10,quark:quilted_wool:7,100)
RandomBlock(-3,33,-7,minecraft:wool:7,10,quark:quilted_wool:7,100)
RandomBlock(-3,33,-6,minecraft:wool:7,10,quark:quilted_wool:7,100)
RandomBlock(-3,33,-5,minecraft:wool:7,10,quark:quilted_wool:7,100)
RandomBlock(-3,33,-4,minecraft:wool:7,10,quark:quilted_wool:7,100)
RandomBlock(-3,33,-3,minecraft:wool:7,10,quark:quilted_wool:7,100)
RandomBlock(-3,33,-2,minecraft:wool:7,10,quark:quilted_wool:7,100)
RandomBlock(-3,34,-7,minecraft:wool:7,10,quark:quilted_wool:7,100)
RandomBlock(-3,34,-6,minecraft:wool:7,10,quark:quilted_wool:7,100)
RandomBlock(-3,34,-5,minecraft:wool:7,10,quark:quilted_wool:7,100)
RandomBlock(-3,34,-4,minecraft:wool:7,10,quark:quilted_wool:7,100)
RandomBlock(-3,34,-3,minecraft:wool:7,10,quark:quilted_wool:7,100)
RandomBlock(-3,34,-2,minecraft:wool:7,10,quark:quilted_wool:7,100)
RandomBlock(-3,35,-7,minecraft:wool:7,10,quark:quilted_wool:7,100)
RandomBlock(-3,35,-6,minecraft:wool:7,10,quark:quilted_wool:7,100)
RandomBlock(-3,35,-5,minecraft:wool:7,10,quark:quilted_wool:7,100)
RandomBlock(-3,35,-4,minecraft:wool:7,10,quark:quilted_wool:7,100)
RandomBlock(-3,35,-3,minecraft:wool:7,10,quark:quilted_wool:7,100)
RandomBlock(-3,36,-7,minecraft:wool:7,10,quark:quilted_wool:7,100)
RandomBlock(-3,36,-6,minecraft:wool:7,10,quark:quilted_wool:7,100)
RandomBlock(-3,36,-5,minecraft:wool:7,10,quark:quilted_wool:7,100)
RandomBlock(-3,36,-4,minecraft:wool:7,10,quark:quilted_wool:7,100)
RandomBlock(-3,36,-3,minecraft:wool:7,10,quark:quilted_wool:7,100)
Block(-3,51,3,VINE:1)
Block(-3,52,3,VINE:1)
Block(-3,53,3,VINE:1)
Block(-3,54,0,LOG:12)
Block(-3,54,1,LOG:12)
Block(-3,54,3,VINE:1)
Block(-3,54,4,LOG:12)
Block(-3,54,5,LOG:12)
Block(-3,55,3,VINE:1)
Block(-3,55,4,LOG:12)
Block(-3,55,5,LOG:12)
Block(-3,56,3,VINE:1)
Block(-3,56,4,LOG:12)
Block(-3,56,5,LOG:12)
Block(-3,57,2,LEAVES:0)
Block(-3,57,3,LEAVES:0)
Block(-3,57,4,LOG:12)
Block(-3,57,5,LOG:12)
Block(-3,57,6,LEAVES:0)
Block(-3,57,7,LEAVES:0)
Block(-3,58,-2,LEAVES:0)
Block(-3,58,-1,LEAVES:0)
Block(-3,58,0,LEAVES:0)
Block(-3,58,1,LEAVES:0)
Block(-3,58,2,LEAVES:0)
Block(-3,58,3,LEAVES:0)
Block(-3,58,4,LOG:12)
Block(-3,58,5,LOG:12)
Block(-3,58,6,LEAVES:0)
Block(-3,58,7,LEAVES:0)
Block(-3,59,-2,LEAVES:0)
Block(-3,59,-1,LEAVES:0)
Block(-3,59,0,LEAVES:0)
Block(-3,59,1,LEAVES:0)
Block(-3,59,3,LEAVES:0)
Block(-3,59,4,LOG:12)
Block(-3,59,5,LOG:12)
Block(-3,59,6,LEAVES:0)
Block(-3,59,7,LEAVES:0)
Block(-3,60,3,LEAVES:0)
Block(-3,60,4,LEAVES:0)
Block(-3,60,5,LOG:12)
Block(-3,60,6,LEAVES:0)
Block(-3,61,3,VINE:8)
Block(-3,61,4,LEAVES:0)
Block(-3,61,5,LEAVES:0)
Block(-3,61,6,LEAVES:0)
Block(-3,62,3,VINE:8)
Block(-3,62,6,VINE:8)
Block(-3,63,3,VINE:8)
Block(-3,63,6,VINE:8)
Block(-3,64,3,VINE:8)
Block(-3,64,6,VINE:8)
Block(-3,65,3,VINE:8)
Block(-3,65,6,VINE:8)
Block(-3,66,3,VINE:8)
Block(-3,66,6,VINE:8)
Block(-3,67,3,VINE:8)
Block(-3,67,4,LEAVES:0)
Block(-3,67,5,LEAVES:0)
Block(-3,67,6,LEAVES:0)
Block(-3,67,7,LEAVES:0)
Block(-3,67,8,LEAVES:0)
Block(-3,68,0,LEAVES:0)
Block(-3,68,1,LEAVES:0)
Block(-3,68,2,LEAVES:0)
Block(-3,68,3,LEAVES:0)
Block(-3,68,4,LEAVES:0)
Block(-3,68,5,LEAVES:0)
Block(-3,68,6,LEAVES:0)
Block(-3,68,7,LEAVES:0)
Block(-3,68,8,LEAVES:0)
Block(-3,69,1,LEAVES:0)
Block(-3,69,2,LEAVES:0)
Block(-3,69,3,LEAVES:0)
Block(-3,69,4,LEAVES:0)
Block(-3,69,5,LEAVES:0)
Block(-3,69,6,LEAVES:0)
Block(-3,69,7,LEAVES:0)
Block(-3,70,-3,LEAVES:0)
Block(-3,70,-1,LEAVES:0)
Block(-3,70,0,LEAVES:0)
Block(-3,70,1,LEAVES:0)
Block(-3,70,2,LEAVES:0)
Block(-3,70,3,LEAVES:0)
Block(-3,70,4,LEAVES:0)
Block(-3,70,5,LEAVES:0)
Block(-3,70,6,LEAVES:0)
Block(-3,71,-3,LEAVES:0)
Block(-3,71,-2,LEAVES:0)
Block(-3,71,-1,LEAVES:0)
Block(-3,71,0,LEAVES:0)
Block(-3,71,1,LEAVES:0)
Block(-3,71,2,LEAVES:0)
Block(-3,71,3,LEAVES:0)
Block(-3,71,4,LEAVES:0)
Block(-3,71,5,LEAVES:0)
Block(-3,72,-1,LEAVES:0)
Block(-3,72,0,LEAVES:0)
Block(-3,72,1,LEAVES:0)
Block(-3,72,2,LOG:12)
Block(-3,72,3,LEAVES:0)
Block(-3,72,4,LEAVES:0)
Block(-3,72,5,LEAVES:0)
Block(-3,73,-1,LEAVES:0)
Block(-3,73,0,LEAVES:0)
Block(-3,73,1,LOG:12)
Block(-3,73,2,LEAVES:0)
Block(-3,73,3,LEAVES:0)
Block(-3,73,4,LEAVES:0)
Block(-3,74,-1,LEAVES:0)
Block(-3,74,0,LEAVES:0)
Block(-3,74,1,LEAVES:0)
Block(-3,74,2,LEAVES:0)
Block(-3,74,3,LEAVES:0)
Block(-3,74,4,LEAVES:0)
Block(-3,75,-1,LEAVES:0)
Block(-3,75,0,LEAVES:0)
Block(-3,75,1,LEAVES:0)
Block(-3,75,2,LEAVES:0)
Block(-3,75,3,LEAVES:0)
Block(-3,76,0,LEAVES:0)
Block(-3,76,1,LEAVES:0)
Block(-3,76,2,LEAVES:0)
Block(-3,82,-5,WOOL:14)
Block(-3,83,-6,WOOL:14)
Block(-3,83,-5,WOOL:14)
Block(-3,83,-4,WOOL:14)
Block(-3,84,-6,WOOL:14)
Block(-3,84,-5,WOOL:14)
Block(-3,84,-4,WOOL:14)
Block(-3,85,-6,WOOL:14)
Block(-3,85,-5,WOOL:14)
Block(-3,85,-4,WOOL:14)
RandomBlock(-3,85,5,minecraft:wool:7,10,quark:quilted_wool:7,100)
Block(-3,86,-5,WOOL:14)
RandomBlock(-3,86,3,minecraft:wool:7,10,quark:quilted_wool:7,100)
RandomBlock(-3,86,4,minecraft:wool:7,10,quark:quilted_wool:7,100)
RandomBlock(-3,86,5,minecraft:wool:7,10,quark:quilted_wool:7,100)
RandomBlock(-3,86,6,minecraft:wool:7,10,quark:quilted_wool:7,100)
RandomBlock(-3,86,7,minecraft:wool:7,10,quark:quilted_wool:7,100)
RandomBlock(-3,87,3,minecraft:wool:7,10,quark:quilted_wool:7,100)
RandomBlock(-3,87,4,minecraft:wool:7,10,quark:quilted_wool:7,100)
RandomBlock(-3,87,5,minecraft:wool:7,10,quark:quilted_wool:7,100)
RandomBlock(-3,87,6,minecraft:wool:7,10,quark:quilted_wool:7,100)
RandomBlock(-3,87,7,minecraft:wool:7,10,quark:quilted_wool:7,100)
RandomBlock(-3,88,2,minecraft:wool:7,10,quark:quilted_wool:7,100)
RandomBlock(-3,88,3,minecraft:wool:7,10,quark:quilted_wool:7,100)
RandomBlock(-3,88,4,minecraft:wool:7,10,quark:quilted_wool:7,100)
RandomBlock(-3,88,5,minecraft:wool:7,10,quark:quilted_wool:7,100)
RandomBlock(-3,88,6,minecraft:wool:7,10,quark:quilted_wool:7,100)
RandomBlock(-3,88,7,minecraft:wool:7,10,quark:quilted_wool:7,100)
RandomBlock(-3,88,8,minecraft:wool:7,10,quark:quilted_wool:7,100)
RandomBlock(-3,89,2,minecraft:wool:7,10,quark:quilted_wool:7,100)
RandomBlock(-3,89,3,minecraft:wool:7,10,quark:quilted_wool:7,100)
RandomBlock(-3,89,4,minecraft:wool:7,10,quark:quilted_wool:7,100)
RandomBlock(-3,89,5,minecraft:wool:7,10,quark:quilted_wool:7,100)
RandomBlock(-3,89,6,minecraft:wool:7,10,quark:quilted_wool:7,100)
RandomBlock(-3,89,7,minecraft:wool:7,10,quark:quilted_wool:7,100)
RandomBlock(-3,89,8,minecraft:wool:7,10,quark:quilted_wool:7,100)
RandomBlock(-3,90,2,minecraft:wool:7,10,quark:quilted_wool:7,100)
RandomBlock(-3,90,3,minecraft:wool:7,10,quark:quilted_wool:7,100)
RandomBlock(-3,90,4,minecraft:wool:7,10,quark:quilted_wool:7,100)
RandomBlock(-3,90,5,minecraft:wool:7,10,quark:quilted_wool:7,100)
RandomBlock(-3,90,6,minecraft:wool:7,10,quark:quilted_wool:7,100)
RandomBlock(-3,90,7,minecraft:wool:7,10,quark:quilted_wool:7,100)
RandomBlock(-3,90,8,minecraft:wool:7,10,quark:quilted_wool:7,100)
RandomBlock(-3,91,3,minecraft:wool:7,10,quark:quilted_wool:7,100)
RandomBlock(-3,91,4,minecraft:wool:7,10,quark:quilted_wool:7,100)
RandomBlock(-3,91,5,minecraft:wool:7,10,quark:quilted_wool:7,100)
RandomBlock(-3,91,6,minecraft:wool:7,10,quark:quilted_wool:7,100)
RandomBlock(-3,91,7,minecraft:wool:7,10,quark:quilted_wool:7,100)
RandomBlock(-3,92,3,minecraft:wool:7,10,quark:quilted_wool:7,100)
RandomBlock(-3,92,4,minecraft:wool:7,10,quark:quilted_wool:7,100)
RandomBlock(-3,92,5,minecraft:wool:7,10,quark:quilted_wool:7,100)
RandomBlock(-3,92,6,minecraft:wool:7,10,quark:quilted_wool:7,100)
RandomBlock(-3,92,7,minecraft:wool:7,10,quark:quilted_wool:7,100)
RandomBlock(-3,93,5,minecraft:wool:7,10,quark:quilted_wool:7,100)
Block(-2,4,-5,LOG:12)
Block(-2,4,-4,LOG:12)
Block(-2,5,-5,LOG:12)
Block(-2,6,-5,quark:leaf_carpet)
Block(-2,13,-7,LOG:12)
Block(-2,14,-7,LOG:12)
Block(-2,15,-7,LOG:12)
Block(-2,15,-6,LOG:12)
Block(-2,16,-7,LOG:12)
Block(-2,16,-6,LOG:12)
Block(-2,16,-5,LOG:12)
Block(-2,17,-6,LOG:12)
RandomBlock(-2,25,-6,minecraft:wool:7,10,quark:quilted_wool:7,100)
RandomBlock(-2,25,-5,minecraft:wool:7,10,quark:quilted_wool:7,100)
RandomBlock(-2,25,-4,minecraft:wool:7,10,quark:quilted_wool:7,100)
RandomBlock(-2,26,-7,minecraft:wool:7,10,quark:quilted_wool:7,100)
RandomBlock(-2,26,-6,minecraft:wool:7,10,quark:quilted_wool:7,100)
RandomBlock(-2,26,-5,minecraft:wool:7,10,quark:quilted_wool:7,100)
RandomBlock(-2,26,-4,minecraft:wool:7,10,quark:quilted_wool:7,100)
RandomBlock(-2,26,-3,minecraft:wool:7,10,quark:quilted_wool:7,100)
RandomBlock(-2,27,-7,minecraft:wool:7,10,quark:quilted_wool:7,100)
RandomBlock(-2,27,-6,minecraft:wool:7,10,quark:quilted_wool:7,100)
RandomBlock(-2,27,-5,minecraft:wool:7,10,quark:quilted_wool:7,100)
RandomBlock(-2,27,-4,minecraft:wool:7,10,quark:quilted_wool:7,100)
RandomBlock(-2,27,-3,minecraft:wool:7,10,quark:quilted_wool:7,100)
RandomBlock(-2,27,-2,minecraft:wool:7,10,quark:quilted_wool:7,100)
RandomBlock(-2,28,-7,minecraft:wool:7,10,quark:quilted_wool:7,100)
RandomBlock(-2,28,-6,minecraft:wool:7,10,quark:quilted_wool:7,100)
RandomBlock(-2,28,-5,minecraft:wool:7,10,quark:quilted_wool:7,100)
RandomBlock(-2,28,-4,minecraft:wool:7,10,quark:quilted_wool:7,100)
RandomBlock(-2,28,-3,minecraft:wool:7,10,quark:quilted_wool:7,100)
RandomBlock(-2,28,-2,minecraft:wool:7,10,quark:quilted_wool:7,100)
RandomBlock(-2,29,-7,minecraft:wool:7,10,quark:quilted_wool:7,100)
RandomBlock(-2,29,-6,minecraft:wool:7,10,quark:quilted_wool:7,100)
RandomBlock(-2,29,-5,minecraft:wool:7,10,quark:quilted_wool:7,100)
RandomBlock(-2,29,-4,minecraft:wool:7,10,quark:quilted_wool:7,100)
RandomBlock(-2,29,-3,minecraft:wool:7,10,quark:quilted_wool:7,100)
RandomBlock(-2,29,-2,minecraft:wool:7,10,quark:quilted_wool:7,100)
RandomBlock(-2,29,-1,minecraft:wool:7,10,quark:quilted_wool:7,100)
RandomBlock(-2,30,-7,minecraft:wool:7,10,quark:quilted_wool:7,100)
RandomBlock(-2,30,-6,minecraft:wool:7,10,quark:quilted_wool:7,100)
RandomBlock(-2,30,-5,minecraft:wool:7,10,quark:quilted_wool:7,100)
RandomBlock(-2,30,-4,minecraft:wool:7,10,quark:quilted_wool:7,100)
RandomBlock(-2,30,-3,minecraft:wool:7,10,quark:quilted_wool:7,100)
RandomBlock(-2,30,-2,minecraft:wool:7,10,quark:quilted_wool:7,100)
RandomBlock(-2,30,-1,minecraft:wool:7,10,quark:quilted_wool:7,100)
RandomBlock(-2,31,-7,minecraft:wool:7,10,quark:quilted_wool:7,100)
RandomBlock(-2,31,-6,minecraft:wool:7,10,quark:quilted_wool:7,100)
RandomBlock(-2,31,-5,minecraft:wool:7,10,quark:quilted_wool:7,100)
RandomBlock(-2,31,-4,minecraft:wool:7,10,quark:quilted_wool:7,100)
RandomBlock(-2,31,-3,minecraft:wool:7,10,quark:quilted_wool:7,100)
RandomBlock(-2,31,-2,minecraft:wool:7,10,quark:quilted_wool:7,100)
RandomBlock(-2,31,-1,minecraft:wool:7,10,quark:quilted_wool:7,100)
RandomBlock(-2,32,-7,minecraft:wool:7,10,quark:quilted_wool:7,100)
RandomBlock(-2,32,-6,minecraft:wool:7,10,quark:quilted_wool:7,100)
RandomBlock(-2,32,-5,minecraft:wool:7,10,quark:quilted_wool:7,100)
RandomBlock(-2,32,-4,minecraft:wool:7,10,quark:quilted_wool:7,100)
RandomBlock(-2,32,-3,minecraft:wool:7,10,quark:quilted_wool:7,100)
RandomBlock(-2,32,-2,minecraft:wool:7,10,quark:quilted_wool:7,100)
RandomBlock(-2,32,-1,minecraft:wool:7,10,quark:quilted_wool:7,100)
RandomBlock(-2,33,-7,minecraft:wool:7,10,quark:quilted_wool:7,100)
RandomBlock(-2,33,-6,minecraft:wool:7,10,quark:quilted_wool:7,100)
RandomBlock(-2,33,-5,minecraft:wool:7,10,quark:quilted_wool:7,100)
RandomBlock(-2,33,-4,minecraft:wool:7,10,quark:quilted_wool:7,100)
RandomBlock(-2,33,-3,minecraft:wool:7,10,quark:quilted_wool:7,100)
RandomBlock(-2,33,-2,minecraft:wool:7,10,quark:quilted_wool:7,100)
RandomBlock(-2,33,-1,minecraft:wool:7,10,quark:quilted_wool:7,100)
RandomBlock(-2,34,-7,minecraft:wool:7,10,quark:quilted_wool:7,100)
RandomBlock(-2,34,-6,minecraft:wool:7,10,quark:quilted_wool:7,100)
RandomBlock(-2,34,-5,minecraft:wool:7,10,quark:quilted_wool:7,100)
RandomBlock(-2,34,-4,minecraft:wool:7,10,quark:quilted_wool:7,100)
RandomBlock(-2,34,-3,minecraft:wool:7,10,quark:quilted_wool:7,100)
RandomBlock(-2,34,-2,minecraft:wool:7,10,quark:quilted_wool:7,100)
RandomBlock(-2,35,-7,minecraft:wool:7,10,quark:quilted_wool:7,100)
RandomBlock(-2,35,-6,minecraft:wool:7,10,quark:quilted_wool:7,100)
RandomBlock(-2,35,-5,minecraft:wool:7,10,quark:quilted_wool:7,100)
RandomBlock(-2,35,-4,minecraft:wool:7,10,quark:quilted_wool:7,100)
RandomBlock(-2,35,-3,minecraft:wool:7,10,quark:quilted_wool:7,100)
RandomBlock(-2,35,-2,minecraft:wool:7,10,quark:quilted_wool:7,100)
RandomBlock(-2,35,6,minecraft:wool:0,10,quark:quilted_wool:0,100)
RandomBlock(-2,36,-7,minecraft:wool:7,10,quark:quilted_wool:7,100)
RandomBlock(-2,36,-6,minecraft:wool:7,10,quark:quilted_wool:7,100)
RandomBlock(-2,36,-5,minecraft:wool:7,10,quark:quilted_wool:7,100)
RandomBlock(-2,36,-4,minecraft:wool:7,10,quark:quilted_wool:7,100)
RandomBlock(-2,36,-3,minecraft:wool:7,10,quark:quilted_wool:7,100)
RandomBlock(-2,36,5,minecraft:wool:0,10,quark:quilted_wool:0,100)
RandomBlock(-2,36,6,minecraft:wool:0,10,quark:quilted_wool:0,100)
RandomBlock(-2,36,7,minecraft:wool:0,10,quark:quilted_wool:0,100)
RandomBlock(-2,37,-6,minecraft:wool:7,10,quark:quilted_wool:7,100)
RandomBlock(-2,37,-5,minecraft:wool:7,10,quark:quilted_wool:7,100)
RandomBlock(-2,37,-4,minecraft:wool:7,10,quark:quilted_wool:7,100)
RandomBlock(-2,37,5,minecraft:wool:0,10,quark:quilted_wool:0,100)
RandomBlock(-2,37,6,minecraft:wool:0,10,quark:quilted_wool:0,100)
RandomBlock(-2,37,7,minecraft:wool:0,10,quark:quilted_wool:0,100)
RandomBlock(-2,38,5,minecraft:wool:0,10,quark:quilted_wool:0,100)
RandomBlock(-2,38,6,minecraft:wool:0,10,quark:quilted_wool:0,100)
RandomBlock(-2,38,7,minecraft:wool:0,10,quark:quilted_wool:0,100)
RandomBlock(-2,39,6,minecraft:wool:0,10,quark:quilted_wool:0,100)
Block(-2,54,1,LOG:12)
Block(-2,54,4,LOG:12)
Block(-2,54,5,LOG:12)
Block(-2,55,4,LOG:12)
Block(-2,55,5,LOG:12)
Block(-2,57,-3,LEAVES:0)
Block(-2,57,-2,LEAVES:0)
Block(-2,57,-1,LEAVES:0)
Block(-2,57,0,LEAVES:0)
Block(-2,57,2,LEAVES:0)
Block(-2,57,3,LEAVES:0)
Block(-2,57,4,LEAVES:0)
Block(-2,57,5,LEAVES:0)
Block(-2,57,6,LEAVES:0)
Block(-2,58,-2,LEAVES:0)
Block(-2,58,-1,LEAVES:0)
Block(-2,58,0,LEAVES:0)
Block(-2,58,1,LEAVES:0)
Block(-2,58,2,LEAVES:0)
Block(-2,58,3,LEAVES:0)
Block(-2,58,4,LEAVES:0)
Block(-2,58,5,LEAVES:0)
Block(-2,58,6,LEAVES:0)
Block(-2,58,7,LEAVES:0)
Block(-2,59,-2,LEAVES:0)
Block(-2,59,-1,LEAVES:0)
Block(-2,59,0,LEAVES:0)
Block(-2,59,1,LEAVES:0)
Block(-2,59,2,LEAVES:0)
Block(-2,59,3,LEAVES:0)
Block(-2,59,4,LEAVES:0)
Block(-2,59,5,LEAVES:0)
Block(-2,59,6,LEAVES:0)
Block(-2,59,7,LEAVES:0)
Block(-2,59,8,LEAVES:0)
Block(-2,60,-1,LEAVES:0)
Block(-2,60,0,LEAVES:0)
Block(-2,60,1,LEAVES:0)
Block(-2,60,2,LEAVES:0)
Block(-2,60,3,LEAVES:0)
Block(-2,60,4,LEAVES:0)
Block(-2,60,5,LEAVES:0)
Block(-2,60,7,LEAVES:0)
Block(-2,60,8,LEAVES:0)
Block(-2,61,0,LEAVES:0)
Block(-2,61,2,VINE:8)
Block(-2,61,5,LEAVES:0)
Block(-2,61,7,VINE:4)
Block(-2,62,2,VINE:8)
Block(-2,62,5,VINE:1)
Block(-2,62,7,VINE:4)
Block(-2,63,2,VINE:8)
Block(-2,63,5,VINE:1)
Block(-2,63,7,VINE:4)
Block(-2,64,2,VINE:8)
Block(-2,64,5,VINE:1)
Block(-2,64,6,LOG:12)
Block(-2,64,7,VINE:4)
Block(-2,65,2,VINE:8)
Block(-2,65,3,LOG:12)
Block(-2,65,5,VINE:1)
Block(-2,65,6,LOG:12)
Block(-2,65,7,VINE:4)
Block(-2,66,2,VINE:8)
Block(-2,66,3,LOG:12)
Block(-2,66,5,VINE:1)
Block(-2,66,6,LOG:12)
Block(-2,66,7,VINE:4)
Block(-2,66,8,VINE:0)
Block(-2,67,2,VINE:8)
Block(-2,67,3,LOG:12)
Block(-2,67,4,LEAVES:0)
Block(-2,67,5,LEAVES:0)
Block(-2,67,6,LOG:12)
Block(-2,67,7,LEAVES:0)
Block(-2,67,8,LEAVES:0)
Block(-2,68,0,LEAVES:0)
Block(-2,68,1,LEAVES:0)
Block(-2,68,2,LEAVES:0)
Block(-2,68,3,LOG:12)
Block(-2,68,4,LEAVES:0)
Block(-2,68,5,LEAVES:0)
Block(-2,68,6,LOG:12)
Block(-2,68,7,LEAVES:0)
Block(-2,68,8,LEAVES:0)
Block(-2,69,-1,LEAVES:0)
Block(-2,69,0,LEAVES:0)
Block(-2,69,1,LEAVES:0)
Block(-2,69,2,LEAVES:0)
Block(-2,69,3,LOG:12)
Block(-2,69,4,LEAVES:0)
Block(-2,69,5,LEAVES:0)
Block(-2,69,6,LOG:12)
Block(-2,69,7,LEAVES:0)
Block(-2,70,-3,LEAVES:0)
Block(-2,70,-2,LEAVES:0)
Block(-2,70,-1,LEAVES:0)
Block(-2,70,0,LEAVES:0)
Block(-2,70,1,LEAVES:0)
Block(-2,70,2,LEAVES:0)
Block(-2,70,3,LOG:12)
Block(-2,70,4,LEAVES:0)
Block(-2,70,5,LEAVES:0)
Block(-2,70,6,LEAVES:0)
Block(-2,70,7,LEAVES:0)
Block(-2,71,-3,LEAVES:0)
Block(-2,71,-2,LEAVES:0)
Block(-2,71,-1,LEAVES:0)
Block(-2,71,0,LEAVES:0)
Block(-2,71,1,LOG:12)
Block(-2,71,2,LOG:12)
Block(-2,71,3,LOG:12)
Block(-2,71,4,LEAVES:0)
Block(-2,71,5,LEAVES:0)
Block(-2,71,6,LEAVES:0)
Block(-2,71,7,LEAVES:0)
Block(-2,72,-4,LEAVES:0)
Block(-2,72,-3,LEAVES:0)
Block(-2,72,-2,LEAVES:0)
Block(-2,72,-1,LEAVES:0)
Block(-2,72,0,LEAVES:0)
Block(-2,72,1,LOG:12)
Block(-2,72,2,LEAVES:0)
Block(-2,72,3,LEAVES:0)
Block(-2,72,4,LEAVES:0)
Block(-2,72,5,LEAVES:0)
Block(-2,72,6,LEAVES:0)
Block(-2,72,7,LEAVES:0)
Block(-2,73,-3,LEAVES:0)
Block(-2,73,-1,LEAVES:0)
Block(-2,73,0,LEAVES:0)
Block(-2,73,1,LOG:12)
Block(-2,73,2,LEAVES:0)
Block(-2,73,3,LEAVES:0)
Block(-2,73,4,LEAVES:0)
Block(-2,73,5,LEAVES:0)
Block(-2,73,6,LEAVES:0)
Block(-2,74,-1,LEAVES:0)
Block(-2,74,0,LEAVES:0)
Block(-2,74,1,LEAVES:0)
Block(-2,74,2,LEAVES:0)
Block(-2,74,3,LEAVES:0)
Block(-2,74,4,LEAVES:0)
Block(-2,74,5,LEAVES:0)
Block(-2,75,-1,LEAVES:0)
Block(-2,75,0,LEAVES:0)
Block(-2,75,1,LEAVES:0)
Block(-2,75,2,LEAVES:0)
Block(-2,75,3,LEAVES:0)
Block(-2,76,0,LEAVES:0)
Block(-2,76,1,LEAVES:0)
Block(-2,76,2,LEAVES:0)
Block(-2,81,-6,WOOL:14)
Block(-2,81,-5,WOOL:14)
Block(-2,81,-4,WOOL:14)
Block(-2,82,-7,WOOL:14)
Block(-2,82,-6,WOOL:14)
Block(-2,82,-5,WOOL:14)
Block(-2,82,-4,WOOL:14)
Block(-2,82,-3,WOOL:14)
Block(-2,83,-7,WOOL:14)
Block(-2,83,-6,WOOL:14)
Block(-2,83,-5,WOOL:14)
Block(-2,83,-4,WOOL:14)
Block(-2,83,-3,WOOL:14)
Block(-2,84,-7,WOOL:14)
Block(-2,84,-6,WOOL:14)
Block(-2,84,-5,WOOL:14)
Block(-2,84,-4,WOOL:14)
Block(-2,84,-3,WOOL:14)
Block(-2,85,-7,WOOL:14)
Block(-2,85,-6,WOOL:14)
Block(-2,85,-5,WOOL:14)
Block(-2,85,-4,WOOL:14)
Block(-2,85,-3,WOOL:14)
RandomBlock(-2,85,3,minecraft:wool:7,10,quark:quilted_wool:7,100)
RandomBlock(-2,85,4,minecraft:wool:7,10,quark:quilted_wool:7,100)
RandomBlock(-2,85,5,minecraft:wool:7,10,quark:quilted_wool:7,100)
RandomBlock(-2,85,6,minecraft:wool:7,10,quark:quilted_wool:7,100)
RandomBlock(-2,85,7,minecraft:wool:7,10,quark:quilted_wool:7,100)
Block(-2,86,-7,WOOL:14)
Block(-2,86,-6,WOOL:14)
Block(-2,86,-5,WOOL:14)
Block(-2,86,-4,WOOL:14)
Block(-2,86,-3,WOOL:14)
RandomBlock(-2,86,2,minecraft:wool:7,10,quark:quilted_wool:7,100)
RandomBlock(-2,86,3,minecraft:wool:7,10,quark:quilted_wool:7,100)
RandomBlock(-2,86,4,minecraft:wool:7,10,quark:quilted_wool:7,100)
RandomBlock(-2,86,5,minecraft:wool:7,10,quark:quilted_wool:7,100)
RandomBlock(-2,86,6,minecraft:wool:7,10,quark:quilted_wool:7,100)
RandomBlock(-2,86,7,minecraft:wool:7,10,quark:quilted_wool:7,100)
RandomBlock(-2,86,8,minecraft:wool:7,10,quark:quilted_wool:7,100)
Block(-2,87,-6,WOOL:14)
Block(-2,87,-5,WOOL:14)
Block(-2,87,-4,WOOL:14)
RandomBlock(-2,87,2,minecraft:wool:7,10,quark:quilted_wool:7,100)
RandomBlock(-2,87,3,minecraft:wool:7,10,quark:quilted_wool:7,100)
RandomBlock(-2,87,4,minecraft:wool:7,10,quark:quilted_wool:7,100)
RandomBlock(-2,87,5,minecraft:wool:7,10,quark:quilted_wool:7,100)
RandomBlock(-2,87,6,minecraft:wool:7,10,quark:quilted_wool:7,100)
RandomBlock(-2,87,7,minecraft:wool:7,10,quark:quilted_wool:7,100)
RandomBlock(-2,87,8,minecraft:wool:7,10,quark:quilted_wool:7,100)
RandomBlock(-2,88,2,minecraft:wool:7,10,quark:quilted_wool:7,100)
RandomBlock(-2,88,3,minecraft:wool:7,10,quark:quilted_wool:7,100)
RandomBlock(-2,88,4,minecraft:wool:7,10,quark:quilted_wool:7,100)
RandomBlock(-2,88,5,minecraft:wool:7,10,quark:quilted_wool:7,100)
RandomBlock(-2,88,6,minecraft:wool:7,10,quark:quilted_wool:7,100)
RandomBlock(-2,88,7,minecraft:wool:7,10,quark:quilted_wool:7,100)
RandomBlock(-2,88,8,minecraft:wool:7,10,quark:quilted_wool:7,100)
RandomBlock(-2,89,1,minecraft:wool:7,10,quark:quilted_wool:7,100)
RandomBlock(-2,89,2,minecraft:wool:7,10,quark:quilted_wool:7,100)
RandomBlock(-2,89,3,minecraft:wool:7,10,quark:quilted_wool:7,100)
RandomBlock(-2,89,4,minecraft:wool:7,10,quark:quilted_wool:7,100)
RandomBlock(-2,89,5,minecraft:wool:7,10,quark:quilted_wool:7,100)
RandomBlock(-2,89,6,minecraft:wool:7,10,quark:quilted_wool:7,100)
RandomBlock(-2,89,7,minecraft:wool:7,10,quark:quilted_wool:7,100)
RandomBlock(-2,89,8,minecraft:wool:7,10,quark:quilted_wool:7,100)
RandomBlock(-2,90,2,minecraft:wool:7,10,quark:quilted_wool:7,100)
RandomBlock(-2,90,3,minecraft:wool:7,10,quark:quilted_wool:7,100)
RandomBlock(-2,90,4,minecraft:wool:7,10,quark:quilted_wool:7,100)
RandomBlock(-2,90,5,minecraft:wool:7,10,quark:quilted_wool:7,100)
RandomBlock(-2,90,6,minecraft:wool:7,10,quark:quilted_wool:7,100)
RandomBlock(-2,90,7,minecraft:wool:7,10,quark:quilted_wool:7,100)
RandomBlock(-2,90,8,minecraft:wool:7,10,quark:quilted_wool:7,100)
RandomBlock(-2,91,2,minecraft:wool:7,10,quark:quilted_wool:7,100)
RandomBlock(-2,91,3,minecraft:wool:7,10,quark:quilted_wool:7,100)
RandomBlock(-2,91,4,minecraft:wool:7,10,quark:quilted_wool:7,100)
RandomBlock(-2,91,5,minecraft:wool:7,10,quark:quilted_wool:7,100)
RandomBlock(-2,91,6,minecraft:wool:7,10,quark:quilted_wool:7,100)
RandomBlock(-2,91,7,minecraft:wool:7,10,quark:quilted_wool:7,100)
RandomBlock(-2,91,8,minecraft:wool:7,10,quark:quilted_wool:7,100)
RandomBlock(-2,92,2,minecraft:wool:7,10,quark:quilted_wool:7,100)
RandomBlock(-2,92,3,minecraft:wool:7,10,quark:quilted_wool:7,100)
RandomBlock(-2,92,4,minecraft:wool:7,10,quark:quilted_wool:7,100)
RandomBlock(-2,92,5,minecraft:wool:7,10,quark:quilted_wool:7,100)
RandomBlock(-2,92,6,minecraft:wool:7,10,quark:quilted_wool:7,100)
RandomBlock(-2,92,7,minecraft:wool:7,10,quark:quilted_wool:7,100)
RandomBlock(-2,92,8,minecraft:wool:7,10,quark:quilted_wool:7,100)
RandomBlock(-2,93,3,minecraft:wool:7,10,quark:quilted_wool:7,100)
RandomBlock(-2,93,4,minecraft:wool:7,10,quark:quilted_wool:7,100)
RandomBlock(-2,93,5,minecraft:wool:7,10,quark:quilted_wool:7,100)
RandomBlock(-2,93,6,minecraft:wool:7,10,quark:quilted_wool:7,100)
RandomBlock(-2,93,7,minecraft:wool:7,10,quark:quilted_wool:7,100)
Block(-1,5,-6,LOG:12)
Block(-1,5,-5,LOG:12)
Block(-1,6,-6,LOG:12)
Block(-1,6,-5,LOG:12)
Block(-1,7,-6,LOG:12)
Block(-1,7,-5,LOG:12)
Block(-1,8,-5,quark:leaf_carpet)
Block(-1,13,8,LEAVES:0)
Block(-1,14,-7,LOG:12)
Block(-1,14,-6,LOG:12)
Block(-1,14,8,LEAVES:0)
Block(-1,15,-7,LOG:12)
Block(-1,15,-6,LOG:12)
Block(-1,15,-5,LOG:12)
Block(-1,16,-7,LOG:12)
Block(-1,16,-6,LOG:12)
Block(-1,16,-5,LOG:12)
Block(-1,16,-4,LOG:12)
Block(-1,17,-7,LOG:12)
Block(-1,17,-6,LOG:12)
Block(-1,17,-5,LOG:12)
Block(-1,17,-4,LOG:12)
Block(-1,17,-3,LOG:12)
Block(-1,18,-6,quark:leaf_carpet)
Block(-1,18,-5,inspirations:rope:1)
Block(-1,18,-4,LOG:12)
Block(-1,18,-3,LOG:12)
Block(-1,18,-2,LOG:12)
Block(-1,19,-5,inspirations:rope:1)
Block(-1,19,-3,LOG:12)
Block(-1,20,-5,inspirations:rope:1)
Block(-1,21,-5,inspirations:rope:1)
Block(-1,22,-5,inspirations:rope:1)
Block(-1,23,-5,inspirations:rope:1)
Block(-1,24,-5,inspirations:rope:1)
RandomBlock(-1,25,-6,minecraft:wool:7,10,quark:quilted_wool:7,100)
RandomBlock(-1,25,-5,minecraft:wool:7,10,quark:quilted_wool:7,100)
RandomBlock(-1,25,-4,minecraft:wool:7,10,quark:quilted_wool:7,100)
RandomBlock(-1,26,-7,minecraft:wool:7,10,quark:quilted_wool:7,100)
RandomBlock(-1,26,-6,minecraft:wool:7,10,quark:quilted_wool:7,100)
RandomBlock(-1,26,-5,minecraft:wool:7,10,quark:quilted_wool:7,100)
RandomBlock(-1,26,-4,minecraft:wool:7,10,quark:quilted_wool:7,100)
RandomBlock(-1,26,-3,minecraft:wool:7,10,quark:quilted_wool:7,100)
RandomBlock(-1,27,-7,minecraft:wool:7,10,quark:quilted_wool:7,100)
RandomBlock(-1,27,-6,minecraft:wool:7,10,quark:quilted_wool:7,100)
RandomBlock(-1,27,-5,minecraft:wool:7,10,quark:quilted_wool:7,100)
RandomBlock(-1,27,-4,minecraft:wool:7,10,quark:quilted_wool:7,100)
RandomBlock(-1,27,-3,minecraft:wool:7,10,quark:quilted_wool:7,100)
RandomBlock(-1,27,-2,minecraft:wool:7,10,quark:quilted_wool:7,100)
RandomBlock(-1,28,-7,minecraft:wool:7,10,quark:quilted_wool:7,100)
RandomBlock(-1,28,-6,minecraft:wool:7,10,quark:quilted_wool:7,100)
RandomBlock(-1,28,-5,minecraft:wool:7,10,quark:quilted_wool:7,100)
RandomBlock(-1,28,-4,minecraft:wool:7,10,quark:quilted_wool:7,100)
RandomBlock(-1,28,-3,minecraft:wool:7,10,quark:quilted_wool:7,100)
RandomBlock(-1,28,-2,minecraft:wool:7,10,quark:quilted_wool:7,100)
RandomBlock(-1,29,-7,minecraft:wool:7,10,quark:quilted_wool:7,100)
RandomBlock(-1,29,-6,minecraft:wool:7,10,quark:quilted_wool:7,100)
RandomBlock(-1,29,-5,minecraft:wool:7,10,quark:quilted_wool:7,100)
RandomBlock(-1,29,-4,minecraft:wool:7,10,quark:quilted_wool:7,100)
RandomBlock(-1,29,-3,minecraft:wool:7,10,quark:quilted_wool:7,100)
RandomBlock(-1,29,-2,minecraft:wool:7,10,quark:quilted_wool:7,100)
RandomBlock(-1,29,-1,minecraft:wool:7,10,quark:quilted_wool:7,100)
RandomBlock(-1,30,-7,minecraft:wool:7,10,quark:quilted_wool:7,100)
RandomBlock(-1,30,-6,minecraft:wool:7,10,quark:quilted_wool:7,100)
RandomBlock(-1,30,-5,minecraft:wool:7,10,quark:quilted_wool:7,100)
RandomBlock(-1,30,-4,minecraft:wool:7,10,quark:quilted_wool:7,100)
RandomBlock(-1,30,-3,minecraft:wool:7,10,quark:quilted_wool:7,100)
RandomBlock(-1,30,-2,minecraft:wool:7,10,quark:quilted_wool:7,100)
RandomBlock(-1,30,-1,minecraft:wool:7,10,quark:quilted_wool:7,100)
RandomBlock(-1,31,-7,minecraft:wool:7,10,quark:quilted_wool:7,100)
RandomBlock(-1,31,-6,minecraft:wool:7,10,quark:quilted_wool:7,100)
RandomBlock(-1,31,-5,minecraft:wool:7,10,quark:quilted_wool:7,100)
RandomBlock(-1,31,-4,minecraft:wool:7,10,quark:quilted_wool:7,100)
RandomBlock(-1,31,-3,minecraft:wool:7,10,quark:quilted_wool:7,100)
RandomBlock(-1,31,-2,minecraft:wool:7,10,quark:quilted_wool:7,100)
RandomBlock(-1,31,-1,minecraft:wool:7,10,quark:quilted_wool:7,100)
RandomBlock(-1,32,-7,minecraft:wool:7,10,quark:quilted_wool:7,100)
RandomBlock(-1,32,-6,minecraft:wool:7,10,quark:quilted_wool:7,100)
RandomBlock(-1,32,-5,minecraft:wool:7,10,quark:quilted_wool:7,100)
RandomBlock(-1,32,-4,minecraft:wool:7,10,quark:quilted_wool:7,100)
RandomBlock(-1,32,-3,minecraft:wool:7,10,quark:quilted_wool:7,100)
RandomBlock(-1,32,-2,minecraft:wool:7,10,quark:quilted_wool:7,100)
RandomBlock(-1,32,-1,minecraft:wool:7,10,quark:quilted_wool:7,100)
RandomBlock(-1,33,-7,minecraft:wool:7,10,quark:quilted_wool:7,100)
RandomBlock(-1,33,-6,minecraft:wool:7,10,quark:quilted_wool:7,100)
RandomBlock(-1,33,-5,minecraft:wool:7,10,quark:quilted_wool:7,100)
RandomBlock(-1,33,-4,minecraft:wool:7,10,quark:quilted_wool:7,100)
RandomBlock(-1,33,-3,minecraft:wool:7,10,quark:quilted_wool:7,100)
RandomBlock(-1,33,-2,minecraft:wool:7,10,quark:quilted_wool:7,100)
RandomBlock(-1,33,-1,minecraft:wool:7,10,quark:quilted_wool:7,100)
RandomBlock(-1,34,-7,minecraft:wool:7,10,quark:quilted_wool:7,100)
RandomBlock(-1,34,-6,minecraft:wool:7,10,quark:quilted_wool:7,100)
RandomBlock(-1,34,-5,minecraft:wool:7,10,quark:quilted_wool:7,100)
RandomBlock(-1,34,-4,minecraft:wool:7,10,quark:quilted_wool:7,100)
RandomBlock(-1,34,-3,minecraft:wool:7,10,quark:quilted_wool:7,100)
RandomBlock(-1,34,-2,minecraft:wool:7,10,quark:quilted_wool:7,100)
Block(-1,34,-1,VINE:13)
RandomBlock(-1,34,5,minecraft:wool:0,10,quark:quilted_wool:0,100)
RandomBlock(-1,34,6,minecraft:wool:0,10,quark:quilted_wool:0,100)
RandomBlock(-1,34,7,minecraft:wool:0,10,quark:quilted_wool:0,100)
RandomBlock(-1,35,-7,minecraft:wool:7,10,quark:quilted_wool:7,100)
RandomBlock(-1,35,-6,minecraft:wool:7,10,quark:quilted_wool:7,100)
RandomBlock(-1,35,-5,minecraft:wool:7,10,quark:quilted_wool:7,100)
RandomBlock(-1,35,-4,minecraft:wool:7,10,quark:quilted_wool:7,100)
RandomBlock(-1,35,-3,minecraft:wool:7,10,quark:quilted_wool:7,100)
RandomBlock(-1,35,-2,minecraft:wool:7,10,quark:quilted_wool:7,100)
Block(-1,35,-1,VINE:13)
RandomBlock(-1,35,4,minecraft:wool:0,10,quark:quilted_wool:0,100)
RandomBlock(-1,35,5,minecraft:wool:0,10,quark:quilted_wool:0,100)
RandomBlock(-1,35,6,minecraft:wool:0,10,quark:quilted_wool:0,100)
RandomBlock(-1,35,7,minecraft:wool:0,10,quark:quilted_wool:0,100)
RandomBlock(-1,35,8,minecraft:wool:0,10,quark:quilted_wool:0,100)
RandomBlock(-1,36,-7,minecraft:wool:7,10,quark:quilted_wool:7,100)
RandomBlock(-1,36,-6,minecraft:wool:7,10,quark:quilted_wool:7,100)
RandomBlock(-1,36,-5,minecraft:wool:7,10,quark:quilted_wool:7,100)
RandomBlock(-1,36,-4,minecraft:wool:7,10,quark:quilted_wool:7,100)
RandomBlock(-1,36,-3,minecraft:wool:7,10,quark:quilted_wool:7,100)
Block(-1,36,-1,VINE:9)
RandomBlock(-1,36,4,minecraft:wool:0,10,quark:quilted_wool:0,100)
RandomBlock(-1,36,5,minecraft:wool:0,10,quark:quilted_wool:0,100)
RandomBlock(-1,36,6,minecraft:wool:0,10,quark:quilted_wool:0,100)
RandomBlock(-1,36,7,minecraft:wool:0,10,quark:quilted_wool:0,100)
RandomBlock(-1,36,8,minecraft:wool:0,10,quark:quilted_wool:0,100)
RandomBlock(-1,37,-6,minecraft:wool:7,10,quark:quilted_wool:7,100)
RandomBlock(-1,37,-5,minecraft:wool:7,10,quark:quilted_wool:7,100)
RandomBlock(-1,37,-4,minecraft:wool:7,10,quark:quilted_wool:7,100)
Block(-1,37,-1,VINE:9)
RandomBlock(-1,37,4,minecraft:wool:0,10,quark:quilted_wool:0,100)
RandomBlock(-1,37,5,minecraft:wool:0,10,quark:quilted_wool:0,100)
RandomBlock(-1,37,6,minecraft:wool:0,10,quark:quilted_wool:0,100)
RandomBlock(-1,37,7,minecraft:wool:0,10,quark:quilted_wool:0,100)
RandomBlock(-1,37,8,minecraft:wool:0,10,quark:quilted_wool:0,100)
Block(-1,38,-1,VINE:9)
RandomBlock(-1,38,4,minecraft:wool:0,10,quark:quilted_wool:0,100)
RandomBlock(-1,38,5,minecraft:wool:0,10,quark:quilted_wool:0,100)
RandomBlock(-1,38,6,minecraft:wool:0,10,quark:quilted_wool:0,100)
RandomBlock(-1,38,7,minecraft:wool:0,10,quark:quilted_wool:0,100)
RandomBlock(-1,38,8,minecraft:wool:0,10,quark:quilted_wool:0,100)
Block(-1,39,-1,VINE:9)
RandomBlock(-1,39,4,minecraft:wool:0,10,quark:quilted_wool:0,100)
RandomBlock(-1,39,5,minecraft:wool:0,10,quark:quilted_wool:0,100)
RandomBlock(-1,39,6,minecraft:wool:0,10,quark:quilted_wool:0,100)
RandomBlock(-1,39,7,minecraft:wool:0,10,quark:quilted_wool:0,100)
RandomBlock(-1,39,8,minecraft:wool:0,10,quark:quilted_wool:0,100)
Block(-1,40,-1,VINE:9)
RandomBlock(-1,40,5,minecraft:wool:0,10,quark:quilted_wool:0,100)
RandomBlock(-1,40,6,minecraft:wool:0,10,quark:quilted_wool:0,100)
RandomBlock(-1,40,7,minecraft:wool:0,10,quark:quilted_wool:0,100)
Block(-1,41,-1,VINE:9)
Block(-1,42,-1,VINE:9)
Block(-1,43,-1,VINE:9)
Block(-1,44,-1,VINE:9)
Block(-1,45,-1,VINE:9)
Block(-1,46,-1,VINE:9)
Block(-1,47,-1,VINE:9)
Block(-1,48,-1,VINE:9)
Block(-1,49,-1,VINE:9)
Block(-1,50,-1,VINE:9)
Block(-1,51,-1,VINE:9)
Block(-1,52,-1,VINE:9)
Block(-1,53,-1,VINE:9)
Block(-1,54,-1,VINE:9)
Block(-1,54,0,LOG:12)
Block(-1,54,1,LOG:12)
Block(-1,54,2,LOG:12)
Block(-1,54,3,LOG:12)
Block(-1,54,4,LOG:12)
Block(-1,54,5,LOG:12)
Block(-1,55,-1,VINE:9)
Block(-1,55,0,LOG:12)
Block(-1,55,1,LOG:12)
Block(-1,55,2,LOG:12)
Block(-1,55,3,LOG:12)
Block(-1,55,4,LOG:12)
Block(-1,55,5,LOG:12)
Block(-1,56,-1,VINE:9)
Block(-1,56,0,LOG:12)
Block(-1,57,-3,LEAVES:0)
Block(-1,57,-2,LEAVES:0)
Block(-1,57,-1,LEAVES:0)
Block(-1,57,0,LOG:12)
Block(-1,57,1,LEAVES:0)
Block(-1,57,2,LEAVES:0)
Block(-1,57,3,LEAVES:0)
Block(-1,57,4,LEAVES:0)
Block(-1,57,5,LEAVES:0)
Block(-1,57,7,LEAVES:0)
Block(-1,57,8,LEAVES:0)
Block(-1,58,-3,LEAVES:0)
Block(-1,58,-2,LEAVES:0)
Block(-1,58,-1,LEAVES:0)
Block(-1,58,0,LOG:12)
Block(-1,58,1,LEAVES:0)
Block(-1,58,2,LEAVES:0)
Block(-1,58,3,LEAVES:0)
Block(-1,58,4,LEAVES:0)
Block(-1,58,5,LEAVES:0)
Block(-1,58,6,LEAVES:0)
Block(-1,58,7,LEAVES:0)
Block(-1,58,8,LEAVES:0)
Block(-1,59,-2,LEAVES:0)
Block(-1,59,-1,LEAVES:0)
Block(-1,59,0,LOG:12)
Block(-1,59,1,LEAVES:0)
Block(-1,59,2,LEAVES:0)
Block(-1,59,3,LEAVES:0)
Block(-1,59,4,LEAVES:0)
Block(-1,59,5,LEAVES:0)
Block(-1,59,6,LEAVES:0)
Block(-1,59,7,LEAVES:0)
Block(-1,59,8,LEAVES:0)
Block(-1,60,-2,LEAVES:0)
Block(-1,60,-1,LEAVES:0)
Block(-1,60,0,LOG:12)
Block(-1,60,1,LEAVES:0)
Block(-1,60,2,LEAVES:0)
Block(-1,60,3,LEAVES:0)
Block(-1,60,6,LEAVES:0)
Block(-1,60,7,LEAVES:0)
Block(-1,60,8,LEAVES:0)
Block(-1,61,-1,LEAVES:0)
Block(-1,61,0,LEAVES:0)
Block(-1,61,1,LEAVES:0)
Block(-1,61,2,LEAVES:0)
Block(-1,61,3,VINE:4)
Block(-1,61,7,LEAVES:0)
Block(-1,61,8,LEAVES:0)
Block(-1,62,0,LEAVES:0)
Block(-1,62,1,LEAVES:0)
Block(-1,62,8,LEAVES:0)
Block(-1,64,2,LOG:12)
Block(-1,64,3,LOG:12)
Block(-1,64,4,LOG:12)
Block(-1,64,5,LOG:12)
Block(-1,64,6,LOG:12)
Block(-1,65,2,LOG:12)
Block(-1,65,3,LOG:12)
Block(-1,66,2,LOG:12)
Block(-1,66,3,LEAVES:0)
Block(-1,66,4,LEAVES:0)
Block(-1,66,5,LEAVES:0)
Block(-1,66,6,LEAVES:0)
Block(-1,67,2,LOG:12)
Block(-1,67,3,LEAVES:0)
Block(-1,67,4,LEAVES:0)
Block(-1,67,5,LEAVES:0)
Block(-1,67,6,LEAVES:0)
Block(-1,67,7,LEAVES:0)
Block(-1,67,8,LEAVES:0)
Block(-1,68,0,LEAVES:0)
Block(-1,68,1,LEAVES:0)
Block(-1,68,2,LOG:12)
Block(-1,68,3,LEAVES:0)
Block(-1,68,4,LEAVES:0)
Block(-1,68,5,LEAVES:0)
Block(-1,68,6,LEAVES:0)
Block(-1,68,7,LEAVES:0)
Block(-1,68,8,LEAVES:0)
Block(-1,69,-1,LEAVES:0)
Block(-1,69,0,LEAVES:0)
Block(-1,69,1,LEAVES:0)
Block(-1,69,2,LOG:12)
Block(-1,69,3,LEAVES:0)
Block(-1,69,4,LEAVES:0)
Block(-1,69,5,LEAVES:0)
Block(-1,69,6,LEAVES:0)
Block(-1,69,7,LEAVES:0)
Block(-1,70,-3,LEAVES:0)
Block(-1,70,-2,LEAVES:0)
Block(-1,70,-1,LEAVES:0)
Block(-1,70,0,LEAVES:0)
Block(-1,70,1,LEAVES:0)
Block(-1,70,2,LOG:12)
Block(-1,70,3,LEAVES:0)
Block(-1,70,4,LOG:12)
Block(-1,70,5,LEAVES:0)
Block(-1,70,6,LEAVES:0)
Block(-1,71,-3,LEAVES:0)
Block(-1,71,-2,LEAVES:0)
Block(-1,71,-1,LEAVES:0)
Block(-1,71,0,LEAVES:0)
Block(-1,71,1,LOG:12)
Block(-1,71,2,LOG:12)
Block(-1,71,3,LEAVES:0)
Block(-1,71,4,LEAVES:0)
Block(-1,71,5,LEAVES:0)
Block(-1,71,6,LEAVES:0)
Block(-1,71,7,LEAVES:0)
Block(-1,71,8,LEAVES:0)
Block(-1,72,-5,LEAVES:0)
Block(-1,72,-4,LEAVES:0)
Block(-1,72,-3,LEAVES:0)
Block(-1,72,-2,LEAVES:0)
Block(-1,72,-1,LEAVES:0)
Block(-1,72,0,LEAVES:0)
Block(-1,72,1,LEAVES:0)
Block(-1,72,2,LOG:12)
Block(-1,72,3,LEAVES:0)
Block(-1,72,4,LEAVES:0)
Block(-1,72,5,LEAVES:0)
Block(-1,72,6,LEAVES:0)
Block(-1,72,7,LEAVES:0)
Block(-1,72,8,LEAVES:0)
Block(-1,73,-4,LEAVES:0)
Block(-1,73,-3,LEAVES:0)
Block(-1,73,-2,LEAVES:0)
Block(-1,73,-1,LEAVES:0)
Block(-1,73,0,LEAVES:0)
Block(-1,73,1,LOG:12)
Block(-1,73,2,LEAVES:0)
Block(-1,73,3,LEAVES:0)
Block(-1,73,4,LEAVES:0)
Block(-1,73,5,LEAVES:0)
Block(-1,73,6,LEAVES:0)
Block(-1,73,7,LEAVES:0)
Block(-1,74,-3,LEAVES:0)
Block(-1,74,-1,LEAVES:0)
Block(-1,74,0,LEAVES:0)
Block(-1,74,1,LEAVES:0)
Block(-1,74,2,LEAVES:0)
Block(-1,74,3,LEAVES:0)
Block(-1,74,4,LEAVES:0)
Block(-1,74,5,LEAVES:0)
Block(-1,74,6,LEAVES:0)
Block(-1,74,7,LEAVES:0)
Block(-1,75,-1,LEAVES:0)
Block(-1,75,0,LEAVES:0)
Block(-1,75,1,LEAVES:0)
Block(-1,75,2,LEAVES:0)
Block(-1,75,3,LEAVES:0)
Block(-1,75,4,LEAVES:0)
Block(-1,75,5,LEAVES:0)
Block(-1,76,0,LEAVES:0)
Block(-1,76,1,LEAVES:0)
Block(-1,76,2,LEAVES:0)
Block(-1,76,3,LEAVES:0)
Block(-1,76,4,LEAVES:0)
Block(-1,77,0,LEAVES:0)
Block(-1,77,1,LEAVES:0)
Block(-1,77,2,LEAVES:0)
Block(-1,80,-6,WOOL:14)
Block(-1,80,-5,WOOL:14)
Block(-1,80,-4,WOOL:14)
Block(-1,81,-7,WOOL:14)
Block(-1,81,-6,WOOL:14)
Block(-1,81,-5,WOOL:14)
Block(-1,81,-4,WOOL:14)
Block(-1,81,-3,WOOL:14)
Block(-1,82,-7,WOOL:14)
Block(-1,82,-6,WOOL:14)
Block(-1,82,-5,WOOL:14)
Block(-1,82,-4,WOOL:14)
Block(-1,82,-3,WOOL:14)
Block(-1,83,-7,WOOL:14)
Block(-1,83,-6,WOOL:14)
Block(-1,83,-5,WOOL:14)
Block(-1,83,-4,WOOL:14)
Block(-1,83,-3,WOOL:14)
Block(-1,83,-2,WOOL:14)
Block(-1,84,-7,WOOL:14)
Block(-1,84,-6,WOOL:14)
Block(-1,84,-5,WOOL:14)
Block(-1,84,-4,WOOL:14)
Block(-1,84,-3,WOOL:14)
Block(-1,84,-2,WOOL:14)
RandomBlock(-1,84,4,minecraft:wool:7,10,quark:quilted_wool:7,100)
RandomBlock(-1,84,5,minecraft:wool:7,10,quark:quilted_wool:7,100)
RandomBlock(-1,84,6,minecraft:wool:7,10,quark:quilted_wool:7,100)
Block(-1,85,-7,WOOL:14)
Block(-1,85,-6,WOOL:14)
Block(-1,85,-5,WOOL:14)
Block(-1,85,-4,WOOL:14)
Block(-1,85,-3,WOOL:14)
Block(-1,85,-2,WOOL:14)
RandomBlock(-1,85,3,minecraft:wool:7,10,quark:quilted_wool:7,100)
RandomBlock(-1,85,4,minecraft:wool:7,10,quark:quilted_wool:7,100)
RandomBlock(-1,85,5,minecraft:wool:7,10,quark:quilted_wool:7,100)
RandomBlock(-1,85,6,minecraft:wool:7,10,quark:quilted_wool:7,100)
RandomBlock(-1,85,7,minecraft:wool:7,10,quark:quilted_wool:7,100)
Block(-1,86,-7,WOOL:14)
Block(-1,86,-6,WOOL:14)
Block(-1,86,-5,WOOL:14)
Block(-1,86,-4,WOOL:14)
Block(-1,86,-3,WOOL:14)
RandomBlock(-1,86,2,minecraft:wool:7,10,quark:quilted_wool:7,100)
RandomBlock(-1,86,3,minecraft:wool:7,10,quark:quilted_wool:7,100)
RandomBlock(-1,86,4,minecraft:wool:7,10,quark:quilted_wool:7,100)
RandomBlock(-1,86,5,minecraft:wool:7,10,quark:quilted_wool:7,100)
RandomBlock(-1,86,6,minecraft:wool:7,10,quark:quilted_wool:7,100)
RandomBlock(-1,86,7,minecraft:wool:7,10,quark:quilted_wool:7,100)
RandomBlock(-1,86,8,minecraft:wool:7,10,quark:quilted_wool:7,100)
Block(-1,87,-7,WOOL:14)
Block(-1,87,-6,WOOL:14)
Block(-1,87,-5,WOOL:14)
Block(-1,87,-4,WOOL:14)
Block(-1,87,-3,WOOL:14)
RandomBlock(-1,87,1,minecraft:wool:7,10,quark:quilted_wool:7,100)
RandomBlock(-1,87,2,minecraft:wool:7,10,quark:quilted_wool:7,100)
RandomBlock(-1,87,3,minecraft:wool:7,10,quark:quilted_wool:7,100)
RandomBlock(-1,87,4,minecraft:wool:7,10,quark:quilted_wool:7,100)
RandomBlock(-1,87,5,minecraft:wool:7,10,quark:quilted_wool:7,100)
RandomBlock(-1,87,6,minecraft:wool:7,10,quark:quilted_wool:7,100)
RandomBlock(-1,87,7,minecraft:wool:7,10,quark:quilted_wool:7,100)
RandomBlock(-1,87,8,minecraft:wool:7,10,quark:quilted_wool:7,100)
Block(-1,88,-6,WOOL:14)
Block(-1,88,-5,WOOL:14)
Block(-1,88,-4,WOOL:14)
RandomBlock(-1,88,1,minecraft:wool:7,10,quark:quilted_wool:7,100)
RandomBlock(-1,88,2,minecraft:wool:7,10,quark:quilted_wool:7,100)
RandomBlock(-1,88,3,minecraft:wool:7,10,quark:quilted_wool:7,100)
RandomBlock(-1,88,4,minecraft:wool:7,10,quark:quilted_wool:7,100)
RandomBlock(-1,88,5,minecraft:wool:7,10,quark:quilted_wool:7,100)
RandomBlock(-1,88,6,minecraft:wool:7,10,quark:quilted_wool:7,100)
RandomBlock(-1,88,7,minecraft:wool:7,10,quark:quilted_wool:7,100)
RandomBlock(-1,88,8,minecraft:wool:7,10,quark:quilted_wool:7,100)
RandomBlock(-1,89,1,minecraft:wool:7,10,quark:quilted_wool:7,100)
RandomBlock(-1,89,2,minecraft:wool:7,10,quark:quilted_wool:7,100)
RandomBlock(-1,89,3,minecraft:wool:7,10,quark:quilted_wool:7,100)
RandomBlock(-1,89,4,minecraft:wool:7,10,quark:quilted_wool:7,100)
RandomBlock(-1,89,5,minecraft:wool:7,10,quark:quilted_wool:7,100)
RandomBlock(-1,89,6,minecraft:wool:7,10,quark:quilted_wool:7,100)
RandomBlock(-1,89,7,minecraft:wool:7,10,quark:quilted_wool:7,100)
RandomBlock(-1,89,8,minecraft:wool:7,10,quark:quilted_wool:7,100)
RandomBlock(-1,90,1,minecraft:wool:7,10,quark:quilted_wool:7,100)
RandomBlock(-1,90,2,minecraft:wool:7,10,quark:quilted_wool:7,100)
RandomBlock(-1,90,3,minecraft:wool:7,10,quark:quilted_wool:7,100)
RandomBlock(-1,90,4,minecraft:wool:7,10,quark:quilted_wool:7,100)
RandomBlock(-1,90,5,minecraft:wool:7,10,quark:quilted_wool:7,100)
RandomBlock(-1,90,6,minecraft:wool:7,10,quark:quilted_wool:7,100)
RandomBlock(-1,90,7,minecraft:wool:7,10,quark:quilted_wool:7,100)
RandomBlock(-1,90,8,minecraft:wool:7,10,quark:quilted_wool:7,100)
RandomBlock(-1,91,1,minecraft:wool:7,10,quark:quilted_wool:7,100)
RandomBlock(-1,91,2,minecraft:wool:7,10,quark:quilted_wool:7,100)
RandomBlock(-1,91,3,minecraft:wool:7,10,quark:quilted_wool:7,100)
RandomBlock(-1,91,4,minecraft:wool:7,10,quark:quilted_wool:7,100)
RandomBlock(-1,91,5,minecraft:wool:7,10,quark:quilted_wool:7,100)
RandomBlock(-1,91,6,minecraft:wool:7,10,quark:quilted_wool:7,100)
RandomBlock(-1,91,7,minecraft:wool:7,10,quark:quilted_wool:7,100)
RandomBlock(-1,91,8,minecraft:wool:7,10,quark:quilted_wool:7,100)
RandomBlock(-1,92,2,minecraft:wool:7,10,quark:quilted_wool:7,100)
RandomBlock(-1,92,3,minecraft:wool:7,10,quark:quilted_wool:7,100)
RandomBlock(-1,92,4,minecraft:wool:7,10,quark:quilted_wool:7,100)
RandomBlock(-1,92,5,minecraft:wool:7,10,quark:quilted_wool:7,100)
RandomBlock(-1,92,6,minecraft:wool:7,10,quark:quilted_wool:7,100)
RandomBlock(-1,92,7,minecraft:wool:7,10,quark:quilted_wool:7,100)
RandomBlock(-1,92,8,minecraft:wool:7,10,quark:quilted_wool:7,100)
RandomBlock(-1,93,3,minecraft:wool:7,10,quark:quilted_wool:7,100)
RandomBlock(-1,93,4,minecraft:wool:7,10,quark:quilted_wool:7,100)
RandomBlock(-1,93,5,minecraft:wool:7,10,quark:quilted_wool:7,100)
RandomBlock(-1,93,6,minecraft:wool:7,10,quark:quilted_wool:7,100)
RandomBlock(-1,93,7,minecraft:wool:7,10,quark:quilted_wool:7,100)
RandomBlock(-1,94,4,minecraft:wool:7,10,quark:quilted_wool:7,100)
RandomBlock(-1,94,5,minecraft:wool:7,10,quark:quilted_wool:7,100)
RandomBlock(-1,94,6,minecraft:wool:7,10,quark:quilted_wool:7,100)
Block(0,1,8,LEAVES:12)
Block(0,2,8,LEAVES:4)
Block(0,3,7,LOG:12)
Block(0,3,8,LEAVES:4)
Block(0,4,7,LOG:12)
Block(0,4,8,LEAVES:0)
Block(0,5,-5,LOG:12)
Block(0,5,7,LOG:12)
Block(0,5,8,LEAVES:0)
Block(0,6,-6,LOG:12)
Block(0,6,-5,LOG:12)
Block(0,7,-7,LEAVES:0)
Block(0,7,-6,LOG:12)
Block(0,7,-5,LOG:12)
Block(0,7,-4,LOG:12)
Block(0,8,-6,LEAVES:0)
Block(0,8,-5,LOG:12)
Block(0,11,8,LOG:12)
Block(0,12,7,LOG:12)
Block(0,12,8,LOG:12)
Block(0,13,7,LOG:12)
Block(0,13,8,LOG:12)
Block(0,14,-7,LOG:12)
Block(0,14,7,LEAVES:0)
Block(0,14,8,LOG:12)
Block(0,15,-7,LOG:12)
Block(0,15,-6,LOG:12)
Block(0,15,-5,LOG:12)
Block(0,15,-4,LOG:12)
Block(0,15,8,LEAVES:0)
Block(0,16,-7,LOG:12)
Block(0,16,-6,LOG:12)
Block(0,16,-5,LOG:12)
Block(0,16,-4,LOG:12)
Block(0,16,-3,LOG:12)
Block(0,16,7,LEAVES:0)
Block(0,17,-6,LOG:12)
Block(0,17,-5,LOG:12)
Block(0,17,-4,LOG:12)
Block(0,17,-3,LOG:12)
Block(0,17,-2,LOG:12)
Block(0,18,-5,LOG:12)
Block(0,18,-4,LOG:12)
Block(0,18,-3,LOG:12)
Block(0,18,-2,LOG:12)
Block(0,18,-1,LOG:12)
Block(0,18,6,LEAVES:0)
Block(0,19,-5,quark:leaf_carpet)
Block(0,19,-4,LOG:12)
Block(0,19,-3,LOG:12)
Block(0,19,-2,LOG:12)
Block(0,19,6,LEAVES:0)
Block(0,20,-3,LOG:12)
Block(0,20,-2,LOG:12)
Block(0,20,-1,LOG:12)
Block(0,21,-2,LOG:12)
RandomBlock(0,25,-6,minecraft:wool:7,10,quark:quilted_wool:7,100)
RandomBlock(0,25,-5,minecraft:wool:7,10,quark:quilted_wool:7,100)
RandomBlock(0,25,-4,minecraft:wool:7,10,quark:quilted_wool:7,100)
RandomBlock(0,26,-7,minecraft:wool:7,10,quark:quilted_wool:7,100)
RandomBlock(0,26,-6,minecraft:wool:7,10,quark:quilted_wool:7,100)
RandomBlock(0,26,-5,minecraft:wool:7,10,quark:quilted_wool:7,100)
RandomBlock(0,26,-4,minecraft:wool:7,10,quark:quilted_wool:7,100)
RandomBlock(0,26,-3,minecraft:wool:7,10,quark:quilted_wool:7,100)
RandomBlock(0,27,-7,minecraft:wool:7,10,quark:quilted_wool:7,100)
RandomBlock(0,27,-6,minecraft:wool:7,10,quark:quilted_wool:7,100)
RandomBlock(0,27,-5,minecraft:wool:7,10,quark:quilted_wool:7,100)
RandomBlock(0,27,-4,minecraft:wool:7,10,quark:quilted_wool:7,100)
RandomBlock(0,27,-3,minecraft:wool:7,10,quark:quilted_wool:7,100)
RandomBlock(0,27,-2,minecraft:wool:7,10,quark:quilted_wool:7,100)
RandomBlock(0,28,-7,minecraft:wool:7,10,quark:quilted_wool:7,100)
RandomBlock(0,28,-6,minecraft:wool:7,10,quark:quilted_wool:7,100)
RandomBlock(0,28,-5,minecraft:wool:7,10,quark:quilted_wool:7,100)
RandomBlock(0,28,-4,minecraft:wool:7,10,quark:quilted_wool:7,100)
RandomBlock(0,28,-3,minecraft:wool:7,10,quark:quilted_wool:7,100)
RandomBlock(0,28,-2,minecraft:wool:7,10,quark:quilted_wool:7,100)
RandomBlock(0,29,-7,minecraft:wool:7,10,quark:quilted_wool:7,100)
RandomBlock(0,29,-6,minecraft:wool:7,10,quark:quilted_wool:7,100)
RandomBlock(0,29,-5,minecraft:wool:7,10,quark:quilted_wool:7,100)
RandomBlock(0,29,-4,minecraft:wool:7,10,quark:quilted_wool:7,100)
RandomBlock(0,29,-3,minecraft:wool:7,10,quark:quilted_wool:7,100)
RandomBlock(0,29,-2,minecraft:wool:7,10,quark:quilted_wool:7,100)
RandomBlock(0,29,-1,minecraft:wool:7,10,quark:quilted_wool:7,100)
RandomBlock(0,30,-7,minecraft:wool:7,10,quark:quilted_wool:7,100)
RandomBlock(0,30,-6,minecraft:wool:7,10,quark:quilted_wool:7,100)
RandomBlock(0,30,-5,minecraft:wool:7,10,quark:quilted_wool:7,100)
RandomBlock(0,30,-4,minecraft:wool:7,10,quark:quilted_wool:7,100)
RandomBlock(0,30,-3,minecraft:wool:7,10,quark:quilted_wool:7,100)
RandomBlock(0,30,-2,minecraft:wool:7,10,quark:quilted_wool:7,100)
RandomBlock(0,30,-1,minecraft:wool:7,10,quark:quilted_wool:7,100)
RandomBlock(0,31,-7,minecraft:wool:7,10,quark:quilted_wool:7,100)
RandomBlock(0,31,-6,minecraft:wool:7,10,quark:quilted_wool:7,100)
RandomBlock(0,31,-5,minecraft:wool:7,10,quark:quilted_wool:7,100)
RandomBlock(0,31,-4,minecraft:wool:7,10,quark:quilted_wool:7,100)
RandomBlock(0,31,-3,minecraft:wool:7,10,quark:quilted_wool:7,100)
RandomBlock(0,31,-2,minecraft:wool:7,10,quark:quilted_wool:7,100)
RandomBlock(0,31,-1,minecraft:wool:7,10,quark:quilted_wool:7,100)
RandomBlock(0,32,-7,minecraft:wool:7,10,quark:quilted_wool:7,100)
RandomBlock(0,32,-6,minecraft:wool:7,10,quark:quilted_wool:7,100)
RandomBlock(0,32,-5,minecraft:wool:7,10,quark:quilted_wool:7,100)
RandomBlock(0,32,-4,minecraft:wool:7,10,quark:quilted_wool:7,100)
RandomBlock(0,32,-3,minecraft:wool:7,10,quark:quilted_wool:7,100)
RandomBlock(0,32,-2,minecraft:wool:7,10,quark:quilted_wool:7,100)
RandomBlock(0,32,-1,minecraft:wool:7,10,quark:quilted_wool:7,100)
RandomBlock(0,33,-7,minecraft:wool:7,10,quark:quilted_wool:7,100)
RandomBlock(0,33,-6,minecraft:wool:7,10,quark:quilted_wool:7,100)
RandomBlock(0,33,-5,minecraft:wool:7,10,quark:quilted_wool:7,100)
RandomBlock(0,33,-4,minecraft:wool:7,10,quark:quilted_wool:7,100)
RandomBlock(0,33,-3,minecraft:wool:7,10,quark:quilted_wool:7,100)
RandomBlock(0,33,-2,minecraft:wool:7,10,quark:quilted_wool:7,100)
RandomBlock(0,33,-1,minecraft:wool:7,10,quark:quilted_wool:7,100)
RandomBlock(0,33,5,minecraft:wool:0,10,quark:quilted_wool:0,100)
RandomBlock(0,33,6,minecraft:wool:0,10,quark:quilted_wool:0,100)
RandomBlock(0,33,7,minecraft:wool:0,10,quark:quilted_wool:0,100)
RandomBlock(0,34,-7,minecraft:wool:7,10,quark:quilted_wool:7,100)
RandomBlock(0,34,-6,minecraft:wool:7,10,quark:quilted_wool:7,100)
RandomBlock(0,34,-5,minecraft:wool:7,10,quark:quilted_wool:7,100)
RandomBlock(0,34,-4,minecraft:wool:7,10,quark:quilted_wool:7,100)
RandomBlock(0,34,-3,minecraft:wool:7,10,quark:quilted_wool:7,100)
RandomBlock(0,34,-2,minecraft:wool:7,10,quark:quilted_wool:7,100)
RandomBlock(0,34,4,minecraft:wool:0,10,quark:quilted_wool:0,100)
RandomBlock(0,34,5,minecraft:wool:0,10,quark:quilted_wool:0,100)
RandomBlock(0,34,6,minecraft:wool:0,10,quark:quilted_wool:0,100)
RandomBlock(0,34,7,minecraft:wool:0,10,quark:quilted_wool:0,100)
RandomBlock(0,34,8,minecraft:wool:0,10,quark:quilted_wool:0,100)
RandomBlock(0,35,-7,minecraft:wool:7,10,quark:quilted_wool:7,100)
RandomBlock(0,35,-6,minecraft:wool:7,10,quark:quilted_wool:7,100)
RandomBlock(0,35,-5,minecraft:wool:7,10,quark:quilted_wool:7,100)
RandomBlock(0,35,-4,minecraft:wool:7,10,quark:quilted_wool:7,100)
RandomBlock(0,35,-3,minecraft:wool:7,10,quark:quilted_wool:7,100)
RandomBlock(0,35,-2,minecraft:wool:7,10,quark:quilted_wool:7,100)
RandomBlock(0,35,4,minecraft:wool:0,10,quark:quilted_wool:0,100)
RandomBlock(0,35,5,minecraft:wool:0,10,quark:quilted_wool:0,100)
RandomBlock(0,35,6,minecraft:wool:0,10,quark:quilted_wool:0,100)
RandomBlock(0,35,7,minecraft:wool:0,10,quark:quilted_wool:0,100)
RandomBlock(0,35,8,minecraft:wool:0,10,quark:quilted_wool:0,100)
RandomBlock(0,36,-7,minecraft:wool:7,10,quark:quilted_wool:7,100)
RandomBlock(0,36,-6,minecraft:wool:7,10,quark:quilted_wool:7,100)
RandomBlock(0,36,-5,minecraft:wool:7,10,quark:quilted_wool:7,100)
RandomBlock(0,36,-4,minecraft:wool:7,10,quark:quilted_wool:7,100)
RandomBlock(0,36,-3,minecraft:wool:7,10,quark:quilted_wool:7,100)
RandomBlock(0,36,3,minecraft:wool:0,10,quark:quilted_wool:0,100)
RandomBlock(0,36,4,minecraft:wool:0,10,quark:quilted_wool:0,100)
RandomBlock(0,36,5,minecraft:wool:0,10,quark:quilted_wool:0,100)
RandomBlock(0,36,6,minecraft:wool:0,10,quark:quilted_wool:0,100)
RandomBlock(0,36,7,minecraft:wool:0,10,quark:quilted_wool:0,100)
RandomBlock(0,36,8,minecraft:wool:0,10,quark:quilted_wool:0,100)
RandomBlock(0,37,-6,minecraft:wool:7,10,quark:quilted_wool:7,100)
RandomBlock(0,37,-5,minecraft:wool:7,10,quark:quilted_wool:7,100)
RandomBlock(0,37,-4,minecraft:wool:7,10,quark:quilted_wool:7,100)
RandomBlock(0,37,3,minecraft:wool:0,10,quark:quilted_wool:0,100)
RandomBlock(0,37,4,minecraft:wool:0,10,quark:quilted_wool:0,100)
RandomBlock(0,37,5,minecraft:wool:0,10,quark:quilted_wool:0,100)
RandomBlock(0,37,6,minecraft:wool:0,10,quark:quilted_wool:0,100)
RandomBlock(0,37,7,minecraft:wool:0,10,quark:quilted_wool:0,100)
RandomBlock(0,37,8,minecraft:wool:0,10,quark:quilted_wool:0,100)
RandomBlock(0,38,3,minecraft:wool:0,10,quark:quilted_wool:0,100)
RandomBlock(0,38,4,minecraft:wool:0,10,quark:quilted_wool:0,100)
RandomBlock(0,38,5,minecraft:wool:0,10,quark:quilted_wool:0,100)
RandomBlock(0,38,6,minecraft:wool:0,10,quark:quilted_wool:0,100)
RandomBlock(0,38,7,minecraft:wool:0,10,quark:quilted_wool:0,100)
RandomBlock(0,38,8,minecraft:wool:0,10,quark:quilted_wool:0,100)
RandomBlock(0,39,4,minecraft:wool:0,10,quark:quilted_wool:0,100)
RandomBlock(0,39,5,minecraft:wool:0,10,quark:quilted_wool:0,100)
RandomBlock(0,39,6,minecraft:wool:0,10,quark:quilted_wool:0,100)
RandomBlock(0,39,7,minecraft:wool:0,10,quark:quilted_wool:0,100)
RandomBlock(0,39,8,minecraft:wool:0,10,quark:quilted_wool:0,100)
RandomBlock(0,40,4,minecraft:wool:0,10,quark:quilted_wool:0,100)
RandomBlock(0,40,5,minecraft:wool:0,10,quark:quilted_wool:0,100)
RandomBlock(0,40,6,minecraft:wool:0,10,quark:quilted_wool:0,100)
RandomBlock(0,40,7,minecraft:wool:0,10,quark:quilted_wool:0,100)
RandomBlock(0,40,8,minecraft:wool:0,10,quark:quilted_wool:0,100)
RandomBlock(0,41,5,minecraft:wool:0,10,quark:quilted_wool:0,100)
RandomBlock(0,41,6,minecraft:wool:0,10,quark:quilted_wool:0,100)
RandomBlock(0,41,7,minecraft:wool:0,10,quark:quilted_wool:0,100)
Block(0,53,-1,LOG:12)
Block(0,53,0,LOG:12)
Block(0,53,1,LOG:12)
Block(0,53,2,LOG:12)
Block(0,53,3,LOG:12)
Block(0,53,4,LOG:12)
Block(0,54,-1,LOG:12)
Block(0,54,0,LEAVES:4)
Block(0,54,1,LEAVES:4)
Block(0,54,2,LEAVES:4)
Block(0,54,4,LEAVES:4)
Block(0,54,5,LOG:12)
Block(0,54,6,LOG:12)
Block(0,54,7,LOG:12)
Block(0,54,8,LOG:12)
Block(0,55,-1,LOG:12)
Block(0,55,0,LEAVES:4)
Block(0,55,4,LEAVES:4)
Block(0,55,5,LOG:12)
Block(0,55,6,LOG:12)
Block(0,55,7,LOG:12)
Block(0,55,8,LOG:12)
Block(0,56,-1,LOG:12)
Block(0,56,0,LOG:12)
Block(0,56,1,LOG:12)
Block(0,56,2,LOG:12)
Block(0,56,3,LOG:12)
Block(0,56,4,LOG:12)
Block(0,56,8,LOG:12)
Block(0,57,-3,LEAVES:0)
Block(0,57,-2,LEAVES:0)
Block(0,57,-1,LOG:12)
Block(0,57,0,LOG:12)
Block(0,57,1,LOG:12)
Block(0,57,7,LEAVES:0)
Block(0,57,8,LOG:12)
Block(0,58,-3,LEAVES:0)
Block(0,58,-2,LEAVES:0)
Block(0,58,-1,LOG:12)
Block(0,58,0,LOG:12)
Block(0,58,1,LOG:12)
Block(0,58,2,LEAVES:0)
Block(0,58,3,LEAVES:0)
Block(0,58,5,LEAVES:0)
Block(0,58,6,LEAVES:0)
Block(0,58,7,LEAVES:0)
Block(0,58,8,LOG:12)
Block(0,59,-2,LEAVES:0)
Block(0,59,-1,LOG:12)
Block(0,59,0,LOG:12)
Block(0,59,1,LOG:12)
Block(0,59,2,LEAVES:0)
Block(0,59,3,LEAVES:0)
Block(0,59,5,LEAVES:0)
Block(0,59,6,LEAVES:0)
Block(0,59,7,LEAVES:0)
Block(0,59,8,LOG:12)
Block(0,60,-2,LEAVES:0)
Block(0,60,-1,LEAVES:0)
Block(0,60,0,LOG:12)
Block(0,60,1,LOG:12)
Block(0,60,2,LEAVES:0)
Block(0,60,3,LEAVES:0)
Block(0,60,6,LEAVES:0)
Block(0,60,7,LEAVES:0)
Block(0,60,8,LOG:12)
Block(0,61,-1,LEAVES:0)
Block(0,61,0,LOG:12)
Block(0,61,1,LOG:12)
Block(0,61,2,LEAVES:0)
Block(0,61,7,LEAVES:0)
Block(0,61,8,LOG:12)
Block(0,62,-1,LEAVES:0)
Block(0,62,0,LEAVES:0)
Block(0,62,1,LEAVES:0)
Block(0,62,2,LEAVES:0)
Block(0,62,7,LEAVES:0)
Block(0,62,8,LEAVES:0)
Block(0,63,0,VINE:1)
Block(0,63,3,LOG:12)
Block(0,64,0,VINE:1)
Block(0,64,1,LOG:12)
Block(0,64,2,LOG:12)
Block(0,64,3,LOG:12)
Block(0,65,-3,VINE:1)
Block(0,65,0,VINE:1)
Block(0,65,1,LOG:12)
Block(0,65,2,LOG:12)
Block(0,66,-3,VINE:1)
Block(0,66,0,VINE:1)
Block(0,66,1,LOG:12)
Block(0,66,2,LOG:12)
Block(0,66,3,LEAVES:0)
Block(0,66,4,LEAVES:0)
Block(0,66,5,LEAVES:0)
Block(0,66,6,LEAVES:0)
Block(0,67,-3,VINE:1)
Block(0,67,0,VINE:1)
Block(0,67,1,LOG:12)
Block(0,67,2,LOG:12)
Block(0,67,3,LEAVES:0)
Block(0,67,4,LEAVES:0)
Block(0,67,5,LEAVES:0)
Block(0,67,6,LEAVES:0)
Block(0,67,7,LEAVES:0)
Block(0,68,-3,VINE:1)
Block(0,68,0,LEAVES:0)
Block(0,68,1,LOG:12)
Block(0,68,2,LOG:12)
Block(0,68,3,LEAVES:0)
Block(0,68,4,LEAVES:0)
Block(0,68,5,LEAVES:0)
Block(0,68,6,LEAVES:0)
Block(0,68,7,LEAVES:0)
Block(0,69,-3,VINE:1)
Block(0,69,-1,LEAVES:0)
Block(0,69,0,LEAVES:0)
Block(0,69,1,LOG:12)
Block(0,69,2,LOG:12)
Block(0,69,3,LEAVES:0)
Block(0,69,4,LEAVES:0)
Block(0,70,-3,VINE:1)
Block(0,70,-2,LEAVES:0)
Block(0,70,-1,LEAVES:0)
Block(0,70,0,LEAVES:0)
Block(0,70,1,LOG:12)
Block(0,70,2,LOG:12)
Block(0,70,3,LOG:12)
Block(0,70,4,LEAVES:0)
Block(0,70,5,LEAVES:0)
Block(0,70,6,LEAVES:0)
Block(0,70,7,LEAVES:0)
Block(0,71,-4,LEAVES:0)
Block(0,71,-3,LOG:12)
Block(0,71,-2,LEAVES:0)
Block(0,71,-1,LEAVES:0)
Block(0,71,0,LEAVES:0)
Block(0,71,1,LOG:12)
Block(0,71,2,LOG:12)
Block(0,71,3,LEAVES:0)
Block(0,71,4,LEAVES:0)
Block(0,71,5,LEAVES:0)
Block(0,71,6,LEAVES:0)
Block(0,71,7,LEAVES:0)
Block(0,71,8,LEAVES:0)
Block(0,72,-5,LEAVES:0)
Block(0,72,-4,LEAVES:0)
Block(0,72,-3,LEAVES:0)
Block(0,72,-2,LEAVES:0)
Block(0,72,-1,LEAVES:0)
Block(0,72,0,LEAVES:0)
Block(0,72,1,LEAVES:0)
Block(0,72,2,LOG:12)
Block(0,72,3,LEAVES:0)
Block(0,72,4,LEAVES:0)
Block(0,72,5,LOG:12)
Block(0,72,6,LEAVES:0)
Block(0,72,7,LEAVES:0)
Block(0,72,8,LEAVES:0)
Block(0,73,-5,LEAVES:0)
Block(0,73,-4,LEAVES:0)
Block(0,73,-3,LEAVES:0)
Block(0,73,-2,LEAVES:0)
Block(0,73,-1,LEAVES:0)
Block(0,73,0,LEAVES:0)
Block(0,73,1,LEAVES:0)
Block(0,73,2,LOG:12)
Block(0,73,3,LEAVES:0)
Block(0,73,4,LEAVES:0)
Block(0,73,5,LEAVES:0)
Block(0,73,6,LEAVES:0)
Block(0,73,7,LEAVES:0)
Block(0,74,-5,inspirations:rope:1)
Block(0,74,-4,LEAVES:0)
Block(0,74,-3,LEAVES:0)
Block(0,74,-2,LEAVES:0)
Block(0,74,-1,LEAVES:0)
Block(0,74,0,LEAVES:0)
Block(0,74,1,LEAVES:0)
Block(0,74,2,LOG:12)
Block(0,74,3,LEAVES:0)
Block(0,74,4,LEAVES:0)
Block(0,74,5,LEAVES:0)
Block(0,74,6,LEAVES:0)
Block(0,74,7,LEAVES:0)
Block(0,74,8,LEAVES:0)
Block(0,75,-5,inspirations:rope:1)
Block(0,75,0,LEAVES:0)
Block(0,75,1,LEAVES:0)
Block(0,75,2,LEAVES:0)
Block(0,75,3,LEAVES:0)
Block(0,75,4,LEAVES:0)
Block(0,75,5,LEAVES:0)
Block(0,75,6,LEAVES:0)
Block(0,75,8,LEAVES:0)
Block(0,76,-5,inspirations:rope:1)
Block(0,76,-1,LEAVES:0)
Block(0,76,0,LEAVES:0)
Block(0,76,1,LEAVES:0)
Block(0,76,2,LEAVES:0)
Block(0,76,3,LEAVES:0)
Block(0,76,4,LEAVES:0)
Block(0,76,6,LEAVES:0)
Block(0,76,7,LEAVES:0)
Block(0,76,8,LEAVES:0)
Block(0,77,-5,inspirations:rope:1)
Block(0,77,-1,LEAVES:0)
Block(0,77,0,LEAVES:0)
Block(0,77,1,LEAVES:0)
Block(0,77,2,LEAVES:0)
Block(0,77,3,LEAVES:0)
Block(0,77,4,LEAVES:12)
Block(0,77,6,LEAVES:0)
Block(0,77,7,LEAVES:0)
Block(0,78,-5,inspirations:rope:1)
Block(0,78,1,LEAVES:0)
Block(0,78,3,LEAVES:0)
Block(0,78,5,LEAVES:0)
Block(0,79,-5,inspirations:rope:1)
Block(0,79,4,LEAVES:0)
Block(0,79,5,LEAVES:0)
Block(0,80,-6,WOOL:14)
Block(0,80,-5,WOOL:14)
Block(0,80,-4,WOOL:14)
Block(0,80,5,inspirations:rope:1)
Block(0,81,-7,WOOL:14)
Block(0,81,-6,WOOL:14)
Block(0,81,-5,WOOL:14)
Block(0,81,-4,WOOL:14)
Block(0,81,-3,WOOL:14)
Block(0,81,5,inspirations:rope:1)
Block(0,82,-7,WOOL:14)
Block(0,82,-6,WOOL:14)
Block(0,82,-5,WOOL:14)
Block(0,82,-4,WOOL:14)
Block(0,82,-3,WOOL:14)
Block(0,82,-2,WOOL:14)
Block(0,82,5,inspirations:rope:1)
Block(0,83,-7,WOOL:14)
Block(0,83,-6,WOOL:14)
Block(0,83,-5,WOOL:14)
Block(0,83,-4,WOOL:14)
Block(0,83,-3,WOOL:14)
Block(0,83,-2,WOOL:14)
Block(0,83,5,inspirations:rope:1)
Block(0,84,-7,WOOL:14)
Block(0,84,-6,WOOL:14)
Block(0,84,-5,WOOL:14)
Block(0,84,-4,WOOL:14)
Block(0,84,-3,WOOL:14)
Block(0,84,-2,WOOL:14)
RandomBlock(0,84,4,minecraft:wool:7,10,quark:quilted_wool:7,100)
RandomBlock(0,84,5,minecraft:wool:7,10,quark:quilted_wool:7,100)
RandomBlock(0,84,6,minecraft:wool:7,10,quark:quilted_wool:7,100)
Block(0,85,-7,WOOL:14)
Block(0,85,-6,WOOL:14)
Block(0,85,-5,WOOL:14)
Block(0,85,-4,WOOL:14)
Block(0,85,-3,WOOL:14)
Block(0,85,-2,WOOL:14)
RandomBlock(0,85,2,minecraft:wool:7,10,quark:quilted_wool:7,100)
RandomBlock(0,85,3,minecraft:wool:7,10,quark:quilted_wool:7,100)
RandomBlock(0,85,4,minecraft:wool:7,10,quark:quilted_wool:7,100)
RandomBlock(0,85,5,minecraft:wool:7,10,quark:quilted_wool:7,100)
RandomBlock(0,85,6,minecraft:wool:7,10,quark:quilted_wool:7,100)
RandomBlock(0,85,7,minecraft:wool:7,10,quark:quilted_wool:7,100)
RandomBlock(0,85,8,minecraft:wool:7,10,quark:quilted_wool:7,100)
Block(0,86,-7,WOOL:14)
Block(0,86,-6,WOOL:14)
Block(0,86,-5,WOOL:14)
Block(0,86,-4,WOOL:14)
Block(0,86,-3,WOOL:14)
Block(0,86,-2,WOOL:14)
RandomBlock(0,86,2,minecraft:wool:7,10,quark:quilted_wool:7,100)
RandomBlock(0,86,3,minecraft:wool:7,10,quark:quilted_wool:7,100)
RandomBlock(0,86,4,minecraft:wool:7,10,quark:quilted_wool:7,100)
RandomBlock(0,86,5,minecraft:wool:7,10,quark:quilted_wool:7,100)
RandomBlock(0,86,6,minecraft:wool:7,10,quark:quilted_wool:7,100)
RandomBlock(0,86,7,minecraft:wool:7,10,quark:quilted_wool:7,100)
RandomBlock(0,86,8,minecraft:wool:7,10,quark:quilted_wool:7,100)
Block(0,87,-7,WOOL:14)
Block(0,87,-6,WOOL:14)
Block(0,87,-5,WOOL:14)
Block(0,87,-4,WOOL:14)
Block(0,87,-3,WOOL:14)
RandomBlock(0,87,1,minecraft:wool:7,10,quark:quilted_wool:7,100)
RandomBlock(0,87,2,minecraft:wool:7,10,quark:quilted_wool:7,100)
RandomBlock(0,87,3,minecraft:wool:7,10,quark:quilted_wool:7,100)
RandomBlock(0,87,4,minecraft:wool:7,10,quark:quilted_wool:7,100)
RandomBlock(0,87,5,minecraft:wool:7,10,quark:quilted_wool:7,100)
RandomBlock(0,87,6,minecraft:wool:7,10,quark:quilted_wool:7,100)
RandomBlock(0,87,7,minecraft:wool:7,10,quark:quilted_wool:7,100)
RandomBlock(0,87,8,minecraft:wool:7,10,quark:quilted_wool:7,100)
Block(0,88,-6,WOOL:14)
Block(0,88,-5,WOOL:14)
Block(0,88,-4,WOOL:14)
RandomBlock(0,88,1,minecraft:wool:7,10,quark:quilted_wool:7,100)
RandomBlock(0,88,2,minecraft:wool:7,10,quark:quilted_wool:7,100)
RandomBlock(0,88,3,minecraft:wool:7,10,quark:quilted_wool:7,100)
RandomBlock(0,88,4,minecraft:wool:7,10,quark:quilted_wool:7,100)
RandomBlock(0,88,5,minecraft:wool:7,10,quark:quilted_wool:7,100)
RandomBlock(0,88,6,minecraft:wool:7,10,quark:quilted_wool:7,100)
RandomBlock(0,88,7,minecraft:wool:7,10,quark:quilted_wool:7,100)
RandomBlock(0,88,8,minecraft:wool:7,10,quark:quilted_wool:7,100)
RandomBlock(0,89,1,minecraft:wool:7,10,quark:quilted_wool:7,100)
RandomBlock(0,89,2,minecraft:wool:7,10,quark:quilted_wool:7,100)
RandomBlock(0,89,3,minecraft:wool:7,10,quark:quilted_wool:7,100)
RandomBlock(0,89,4,minecraft:wool:7,10,quark:quilted_wool:7,100)
RandomBlock(0,89,5,minecraft:wool:7,10,quark:quilted_wool:7,100)
RandomBlock(0,89,6,minecraft:wool:7,10,quark:quilted_wool:7,100)
RandomBlock(0,89,7,minecraft:wool:7,10,quark:quilted_wool:7,100)
RandomBlock(0,89,8,minecraft:wool:7,10,quark:quilted_wool:7,100)
RandomBlock(0,90,1,minecraft:wool:7,10,quark:quilted_wool:7,100)
RandomBlock(0,90,2,minecraft:wool:7,10,quark:quilted_wool:7,100)
RandomBlock(0,90,3,minecraft:wool:7,10,quark:quilted_wool:7,100)
RandomBlock(0,90,4,minecraft:wool:7,10,quark:quilted_wool:7,100)
RandomBlock(0,90,5,minecraft:wool:7,10,quark:quilted_wool:7,100)
RandomBlock(0,90,6,minecraft:wool:7,10,quark:quilted_wool:7,100)
RandomBlock(0,90,7,minecraft:wool:7,10,quark:quilted_wool:7,100)
RandomBlock(0,90,8,minecraft:wool:7,10,quark:quilted_wool:7,100)
RandomBlock(0,91,1,minecraft:wool:7,10,quark:quilted_wool:7,100)
RandomBlock(0,91,2,minecraft:wool:7,10,quark:quilted_wool:7,100)
RandomBlock(0,91,3,minecraft:wool:7,10,quark:quilted_wool:7,100)
RandomBlock(0,91,4,minecraft:wool:7,10,quark:quilted_wool:7,100)
RandomBlock(0,91,5,minecraft:wool:7,10,quark:quilted_wool:7,100)
RandomBlock(0,91,6,minecraft:wool:7,10,quark:quilted_wool:7,100)
RandomBlock(0,91,7,minecraft:wool:7,10,quark:quilted_wool:7,100)
RandomBlock(0,91,8,minecraft:wool:7,10,quark:quilted_wool:7,100)
RandomBlock(0,92,2,minecraft:wool:7,10,quark:quilted_wool:7,100)
RandomBlock(0,92,3,minecraft:wool:7,10,quark:quilted_wool:7,100)
RandomBlock(0,92,4,minecraft:wool:7,10,quark:quilted_wool:7,100)
RandomBlock(0,92,5,minecraft:wool:7,10,quark:quilted_wool:7,100)
RandomBlock(0,92,6,minecraft:wool:7,10,quark:quilted_wool:7,100)
RandomBlock(0,92,7,minecraft:wool:7,10,quark:quilted_wool:7,100)
RandomBlock(0,92,8,minecraft:wool:7,10,quark:quilted_wool:7,100)
RandomBlock(0,93,2,minecraft:wool:7,10,quark:quilted_wool:7,100)
RandomBlock(0,93,3,minecraft:wool:7,10,quark:quilted_wool:7,100)
RandomBlock(0,93,4,minecraft:wool:7,10,quark:quilted_wool:7,100)
RandomBlock(0,93,5,minecraft:wool:7,10,quark:quilted_wool:7,100)
RandomBlock(0,93,6,minecraft:wool:7,10,quark:quilted_wool:7,100)
RandomBlock(0,93,7,minecraft:wool:7,10,quark:quilted_wool:7,100)
RandomBlock(0,93,8,minecraft:wool:7,10,quark:quilted_wool:7,100)
RandomBlock(0,94,4,minecraft:wool:7,10,quark:quilted_wool:7,100)
RandomBlock(0,94,5,minecraft:wool:7,10,quark:quilted_wool:7,100)
RandomBlock(0,94,6,minecraft:wool:7,10,quark:quilted_wool:7,100)
Block(1,3,8,LEAVES:0)
Block(1,4,7,LEAVES:0)
Block(1,4,8,LEAVES:0)
Block(1,5,6,LOG:12)
Block(1,5,7,LOG:12)
Block(1,5,8,LEAVES:0)
Block(1,6,-6,LOG:12)
Block(1,6,-5,LOG:12)
Block(1,6,-4,LOG:12)
Block(1,6,6,LOG:12)
Block(1,6,7,LEAVES:0)
Block(1,6,8,LEAVES:0)
Block(1,7,-6,LOG:12)
Block(1,7,-5,LOG:12)
Block(1,7,-4,LOG:12)
Block(1,7,6,quark:leaf_carpet)
Block(1,8,-6,LOG:12)
Block(1,8,-5,LOG:12)
Block(1,8,-4,LOG:12)
Block(1,9,-7,LEAVES:0)
Block(1,9,-6,quark:leaf_carpet)
Block(1,9,-5,LOG:12)
Block(1,10,-5,quark:leaf_carpet)
Block(1,10,8,LOG:12)
Block(1,11,7,LOG:12)
Block(1,11,8,LOG:12)
Block(1,12,7,LOG:12)
Block(1,12,8,LOG:12)
Block(1,13,7,LOG:12)
Block(1,13,8,LOG:12)
Block(1,14,7,LOG:12)
Block(1,14,8,LOG:12)
Block(1,15,-5,LOG:12)
Block(1,15,6,LOG:12)
Block(1,15,7,LOG:12)
Block(1,15,8,LOG:12)
Block(1,16,-6,LOG:12)
Block(1,16,-5,LOG:12)
Block(1,16,-4,LOG:12)
Block(1,16,5,LOG:12)
Block(1,16,6,LOG:12)
Block(1,16,7,LOG:12)
Block(1,16,8,quark:leaf_carpet)
Block(1,17,-5,LOG:12)
Block(1,17,-4,LOG:12)
Block(1,17,-3,LOG:12)
Block(1,17,-2,LOG:12)
Block(1,17,-1,LOG:12)
Block(1,17,6,LOG:12)
Block(1,17,7,LEAVES:0)
Block(1,18,-4,LOG:12)
Block(1,18,-3,LOG:12)
Block(1,18,-2,LOG:12)
Block(1,18,-1,LOG:12)
Block(1,18,5,LOG:12)
Block(1,18,6,LOG:12)
Block(1,18,7,LOG:12)
Block(1,19,-4,LOG:12)
Block(1,19,-3,LOG:12)
Block(1,19,-2,LOG:12)
Block(1,19,-1,LOG:12)
Block(1,19,5,LEAVES:0)
Block(1,19,6,LOG:12)
Block(1,19,7,quark:leaf_carpet)
Block(1,20,-4,quark:leaf_carpet)
Block(1,20,-3,LOG:12)
Block(1,20,-2,LOG:12)
Block(1,20,-1,LOG:12)
Block(1,20,5,LEAVES:0)
Block(1,20,6,inspirations:rope:1)
Block(1,21,-3,LOG:12)
Block(1,21,-2,LOG:12)
Block(1,21,-1,LOG:12)
Block(1,21,6,inspirations:rope:1)
Block(1,22,-3,LOG:12)
Block(1,22,-2,LOG:12)
Block(1,22,-1,LOG:12)
Block(1,22,6,inspirations:rope:1)
Block(1,23,-3,quark:leaf_carpet)
Block(1,23,-2,LOG:12)
Block(1,23,6,inspirations:rope:1)
Block(1,24,6,inspirations:rope:1)
Block(1,25,6,inspirations:rope:1)
RandomBlock(1,26,-7,minecraft:wool:7,10,quark:quilted_wool:7,100)
RandomBlock(1,26,-6,minecraft:wool:7,10,quark:quilted_wool:7,100)
RandomBlock(1,26,-5,minecraft:wool:7,10,quark:quilted_wool:7,100)
RandomBlock(1,26,-4,minecraft:wool:7,10,quark:quilted_wool:7,100)
RandomBlock(1,26,-3,minecraft:wool:7,10,quark:quilted_wool:7,100)
Block(1,26,6,inspirations:rope:1)
RandomBlock(1,27,-7,minecraft:wool:7,10,quark:quilted_wool:7,100)
RandomBlock(1,27,-6,minecraft:wool:7,10,quark:quilted_wool:7,100)
RandomBlock(1,27,-5,minecraft:wool:7,10,quark:quilted_wool:7,100)
RandomBlock(1,27,-4,minecraft:wool:7,10,quark:quilted_wool:7,100)
RandomBlock(1,27,-3,minecraft:wool:7,10,quark:quilted_wool:7,100)
Block(1,27,6,inspirations:rope:1)
RandomBlock(1,28,-7,minecraft:wool:7,10,quark:quilted_wool:7,100)
RandomBlock(1,28,-6,minecraft:wool:7,10,quark:quilted_wool:7,100)
RandomBlock(1,28,-5,minecraft:wool:7,10,quark:quilted_wool:7,100)
RandomBlock(1,28,-4,minecraft:wool:7,10,quark:quilted_wool:7,100)
RandomBlock(1,28,-3,minecraft:wool:7,10,quark:quilted_wool:7,100)
RandomBlock(1,28,-2,minecraft:wool:7,10,quark:quilted_wool:7,100)
Block(1,28,6,inspirations:rope:1)
RandomBlock(1,29,-7,minecraft:wool:7,10,quark:quilted_wool:7,100)
RandomBlock(1,29,-6,minecraft:wool:7,10,quark:quilted_wool:7,100)
RandomBlock(1,29,-5,minecraft:wool:7,10,quark:quilted_wool:7,100)
RandomBlock(1,29,-4,minecraft:wool:7,10,quark:quilted_wool:7,100)
RandomBlock(1,29,-3,minecraft:wool:7,10,quark:quilted_wool:7,100)
RandomBlock(1,29,-2,minecraft:wool:7,10,quark:quilted_wool:7,100)
Block(1,29,6,inspirations:rope:1)
RandomBlock(1,30,-7,minecraft:wool:7,10,quark:quilted_wool:7,100)
RandomBlock(1,30,-6,minecraft:wool:7,10,quark:quilted_wool:7,100)
RandomBlock(1,30,-5,minecraft:wool:7,10,quark:quilted_wool:7,100)
RandomBlock(1,30,-4,minecraft:wool:7,10,quark:quilted_wool:7,100)
RandomBlock(1,30,-3,minecraft:wool:7,10,quark:quilted_wool:7,100)
RandomBlock(1,30,-2,minecraft:wool:7,10,quark:quilted_wool:7,100)
Block(1,30,6,inspirations:rope:1)
RandomBlock(1,31,-7,minecraft:wool:7,10,quark:quilted_wool:7,100)
RandomBlock(1,31,-6,minecraft:wool:7,10,quark:quilted_wool:7,100)
RandomBlock(1,31,-5,minecraft:wool:7,10,quark:quilted_wool:7,100)
RandomBlock(1,31,-4,minecraft:wool:7,10,quark:quilted_wool:7,100)
RandomBlock(1,31,-3,minecraft:wool:7,10,quark:quilted_wool:7,100)
RandomBlock(1,31,-2,minecraft:wool:7,10,quark:quilted_wool:7,100)
RandomBlock(1,31,-1,minecraft:wool:7,10,quark:quilted_wool:7,100)
Block(1,31,6,inspirations:rope:1)
RandomBlock(1,32,-7,minecraft:wool:7,10,quark:quilted_wool:7,100)
RandomBlock(1,32,-6,minecraft:wool:7,10,quark:quilted_wool:7,100)
RandomBlock(1,32,-5,minecraft:wool:7,10,quark:quilted_wool:7,100)
RandomBlock(1,32,-4,minecraft:wool:7,10,quark:quilted_wool:7,100)
RandomBlock(1,32,-3,minecraft:wool:7,10,quark:quilted_wool:7,100)
RandomBlock(1,32,-2,minecraft:wool:7,10,quark:quilted_wool:7,100)
Block(1,32,6,inspirations:rope:1)
RandomBlock(1,33,-7,minecraft:wool:7,10,quark:quilted_wool:7,100)
RandomBlock(1,33,-6,minecraft:wool:7,10,quark:quilted_wool:7,100)
RandomBlock(1,33,-5,minecraft:wool:7,10,quark:quilted_wool:7,100)
RandomBlock(1,33,-4,minecraft:wool:7,10,quark:quilted_wool:7,100)
RandomBlock(1,33,-3,minecraft:wool:7,10,quark:quilted_wool:7,100)
RandomBlock(1,33,-2,minecraft:wool:7,10,quark:quilted_wool:7,100)
RandomBlock(1,33,5,minecraft:wool:0,10,quark:quilted_wool:0,100)
RandomBlock(1,33,6,minecraft:wool:0,10,quark:quilted_wool:0,100)
RandomBlock(1,33,7,minecraft:wool:0,10,quark:quilted_wool:0,100)
RandomBlock(1,34,-7,minecraft:wool:7,10,quark:quilted_wool:7,100)
RandomBlock(1,34,-6,minecraft:wool:7,10,quark:quilted_wool:7,100)
RandomBlock(1,34,-5,minecraft:wool:7,10,quark:quilted_wool:7,100)
RandomBlock(1,34,-4,minecraft:wool:7,10,quark:quilted_wool:7,100)
RandomBlock(1,34,-3,minecraft:wool:7,10,quark:quilted_wool:7,100)
RandomBlock(1,34,-2,minecraft:wool:7,10,quark:quilted_wool:7,100)
RandomBlock(1,34,4,minecraft:wool:0,10,quark:quilted_wool:0,100)
RandomBlock(1,34,5,minecraft:wool:0,10,quark:quilted_wool:0,100)
RandomBlock(1,34,6,minecraft:wool:0,10,quark:quilted_wool:0,100)
RandomBlock(1,34,7,minecraft:wool:0,10,quark:quilted_wool:0,100)
RandomBlock(1,34,8,minecraft:wool:0,10,quark:quilted_wool:0,100)
RandomBlock(1,35,-7,minecraft:wool:7,10,quark:quilted_wool:7,100)
RandomBlock(1,35,-6,minecraft:wool:7,10,quark:quilted_wool:7,100)
RandomBlock(1,35,-5,minecraft:wool:7,10,quark:quilted_wool:7,100)
RandomBlock(1,35,-4,minecraft:wool:7,10,quark:quilted_wool:7,100)
RandomBlock(1,35,-3,minecraft:wool:7,10,quark:quilted_wool:7,100)
RandomBlock(1,35,3,minecraft:wool:0,10,quark:quilted_wool:0,100)
RandomBlock(1,35,4,minecraft:wool:0,10,quark:quilted_wool:0,100)
RandomBlock(1,35,5,minecraft:wool:0,10,quark:quilted_wool:0,100)
RandomBlock(1,35,6,minecraft:wool:0,10,quark:quilted_wool:0,100)
RandomBlock(1,35,7,minecraft:wool:0,10,quark:quilted_wool:0,100)
RandomBlock(1,35,8,minecraft:wool:0,10,quark:quilted_wool:0,100)
RandomBlock(1,36,-7,minecraft:wool:7,10,quark:quilted_wool:7,100)
RandomBlock(1,36,-6,minecraft:wool:7,10,quark:quilted_wool:7,100)
RandomBlock(1,36,-5,minecraft:wool:7,10,quark:quilted_wool:7,100)
RandomBlock(1,36,-4,minecraft:wool:7,10,quark:quilted_wool:7,100)
RandomBlock(1,36,-3,minecraft:wool:7,10,quark:quilted_wool:7,100)
RandomBlock(1,36,3,minecraft:wool:0,10,quark:quilted_wool:0,100)
RandomBlock(1,36,4,minecraft:wool:0,10,quark:quilted_wool:0,100)
RandomBlock(1,36,5,minecraft:wool:0,10,quark:quilted_wool:0,100)
RandomBlock(1,36,6,minecraft:wool:0,10,quark:quilted_wool:0,100)
RandomBlock(1,36,7,minecraft:wool:0,10,quark:quilted_wool:0,100)
RandomBlock(1,36,8,minecraft:wool:0,10,quark:quilted_wool:0,100)
RandomBlock(1,37,3,minecraft:wool:0,10,quark:quilted_wool:0,100)
RandomBlock(1,37,4,minecraft:wool:0,10,quark:quilted_wool:0,100)
RandomBlock(1,37,5,minecraft:wool:0,10,quark:quilted_wool:0,100)
RandomBlock(1,37,6,minecraft:wool:0,10,quark:quilted_wool:0,100)
RandomBlock(1,37,7,minecraft:wool:0,10,quark:quilted_wool:0,100)
RandomBlock(1,37,8,minecraft:wool:0,10,quark:quilted_wool:0,100)
RandomBlock(1,38,3,minecraft:wool:0,10,quark:quilted_wool:0,100)
RandomBlock(1,38,4,minecraft:wool:0,10,quark:quilted_wool:0,100)
RandomBlock(1,38,5,minecraft:wool:0,10,quark:quilted_wool:0,100)
RandomBlock(1,38,6,minecraft:wool:0,10,quark:quilted_wool:0,100)
RandomBlock(1,38,7,minecraft:wool:0,10,quark:quilted_wool:0,100)
RandomBlock(1,38,8,minecraft:wool:0,10,quark:quilted_wool:0,100)
RandomBlock(1,39,3,minecraft:wool:0,10,quark:quilted_wool:0,100)
RandomBlock(1,39,4,minecraft:wool:0,10,quark:quilted_wool:0,100)
RandomBlock(1,39,5,minecraft:wool:0,10,quark:quilted_wool:0,100)
RandomBlock(1,39,6,minecraft:wool:0,10,quark:quilted_wool:0,100)
RandomBlock(1,39,7,minecraft:wool:0,10,quark:quilted_wool:0,100)
RandomBlock(1,39,8,minecraft:wool:0,10,quark:quilted_wool:0,100)
RandomBlock(1,40,4,minecraft:wool:0,10,quark:quilted_wool:0,100)
RandomBlock(1,40,5,minecraft:wool:0,10,quark:quilted_wool:0,100)
RandomBlock(1,40,6,minecraft:wool:0,10,quark:quilted_wool:0,100)
RandomBlock(1,40,7,minecraft:wool:0,10,quark:quilted_wool:0,100)
RandomBlock(1,40,8,minecraft:wool:0,10,quark:quilted_wool:0,100)
RandomBlock(1,41,5,minecraft:wool:0,10,quark:quilted_wool:0,100)
RandomBlock(1,41,6,minecraft:wool:0,10,quark:quilted_wool:0,100)
RandomBlock(1,41,7,minecraft:wool:0,10,quark:quilted_wool:0,100)
Block(1,51,4,rustic:iron_lantern:0)
Block(1,52,4,FENCE:0)
Block(1,53,-1,LOG:12)
Block(1,53,0,LOG:12)
Block(1,53,1,LOG:12)
Block(1,53,2,LOG:12)
Block(1,53,3,LOG:12)
Block(1,53,4,LOG:12)
Block(1,53,5,LOG:12)
Block(1,53,6,LOG:12)
Block(1,53,7,LOG:12)
Block(1,53,8,LOG:12)
Block(1,54,5,LOG:12)
Block(1,54,6,FENCE:0)
Block(1,54,7,FENCE:0)
Block(1,54,8,FENCE:0)
Block(1,55,5,LOG:12)
Block(1,55,6,FENCE:0)
Block(1,55,7,FENCE:0)
Block(1,55,8,FENCE:0)
Block(1,56,-1,LOG:12)
Block(1,56,0,LOG:12)
Block(1,56,1,LOG:12)
Block(1,56,2,LOG:12)
Block(1,56,3,LOG:12)
Block(1,56,4,LOG:12)
Block(1,56,5,LOG:12)
Block(1,56,6,LOG:12)
Block(1,56,7,LOG:12)
Block(1,56,8,FENCE:0)
Block(1,57,-3,LEAVES:0)
Block(1,57,-2,LEAVES:0)
Block(1,57,-1,LOG:12)
Block(1,57,0,LOG:12)
Block(1,57,1,LOG:12)
Block(1,57,7,LOG:12)
Block(1,57,8,LOG:12)
Block(1,58,-3,LEAVES:0)
Block(1,58,-2,LEAVES:0)
Block(1,58,-1,LOG:12)
Block(1,58,0,LOG:12)
Block(1,58,1,LOG:12)
Block(1,58,2,LEAVES:0)
Block(1,58,3,LEAVES:0)
Block(1,58,5,LEAVES:0)
Block(1,58,6,LEAVES:0)
Block(1,58,7,LOG:12)
Block(1,58,8,LOG:12)
Block(1,59,-2,LEAVES:0)
Block(1,59,-1,LOG:12)
Block(1,59,0,LOG:12)
Block(1,59,1,LOG:12)
Block(1,59,2,LEAVES:0)
Block(1,59,3,LEAVES:0)
Block(1,59,5,LEAVES:0)
Block(1,59,6,LEAVES:0)
Block(1,59,7,LOG:12)
Block(1,59,8,LOG:12)
Block(1,60,-2,LEAVES:0)
Block(1,60,-1,LEAVES:0)
Block(1,60,0,LOG:12)
Block(1,60,1,LOG:12)
Block(1,60,2,LEAVES:0)
Block(1,60,3,LEAVES:0)
Block(1,60,6,LEAVES:0)
Block(1,60,7,LOG:12)
Block(1,60,8,LOG:12)
Block(1,61,-1,LEAVES:0)
Block(1,61,0,LEAVES:0)
Block(1,61,1,LEAVES:0)
Block(1,61,2,LEAVES:0)
Block(1,61,6,LEAVES:0)
Block(1,61,7,LEAVES:0)
Block(1,61,8,LOG:12)
Block(1,62,0,LEAVES:0)
Block(1,62,1,LEAVES:0)
Block(1,62,7,LEAVES:0)
Block(1,62,8,LEAVES:0)
Block(1,63,3,LOG:12)
Block(1,63,4,LOG:12)
Block(1,64,4,LOG:12)
Block(1,65,4,LOG:12)
Block(1,66,2,LEAVES:0)
Block(1,66,3,LEAVES:0)
Block(1,66,4,LOG:12)
Block(1,66,5,LEAVES:0)
Block(1,66,6,LEAVES:0)
Block(1,67,2,LEAVES:0)
Block(1,67,3,LEAVES:0)
Block(1,67,4,LOG:12)
Block(1,67,5,LEAVES:0)
Block(1,67,6,LEAVES:0)
Block(1,68,-3,VINE:1)
Block(1,68,1,LEAVES:0)
Block(1,68,2,LEAVES:0)
Block(1,68,3,LEAVES:0)
Block(1,68,4,LOG:12)
Block(1,68,5,LEAVES:0)
Block(1,69,-3,VINE:1)
Block(1,69,-1,LEAVES:0)
Block(1,69,0,LEAVES:0)
Block(1,69,1,LEAVES:0)
Block(1,69,2,LEAVES:0)
Block(1,69,3,LEAVES:0)
Block(1,69,4,LEAVES:0)
Block(1,69,5,LEAVES:0)
Block(1,69,6,LEAVES:0)
Block(1,69,7,LEAVES:0)
Block(1,69,8,LEAVES:0)
Block(1,70,-3,VINE:1)
Block(1,70,-2,LEAVES:0)
Block(1,70,-1,LEAVES:0)
Block(1,70,0,LEAVES:0)
Block(1,70,1,LEAVES:0)
Block(1,70,2,LEAVES:0)
Block(1,70,3,LEAVES:0)
Block(1,70,4,LEAVES:0)
Block(1,70,5,LEAVES:0)
Block(1,70,6,LEAVES:0)
Block(1,70,7,LEAVES:0)
Block(1,70,8,LEAVES:0)
Block(1,71,-4,LEAVES:0)
Block(1,71,-3,LOG:12)
Block(1,71,-2,LEAVES:0)
Block(1,71,-1,LEAVES:0)
Block(1,71,0,LEAVES:0)
Block(1,71,1,LEAVES:0)
Block(1,71,2,LOG:12)
Block(1,71,3,LEAVES:0)
Block(1,71,4,LEAVES:0)
Block(1,71,5,LEAVES:0)
Block(1,71,6,LEAVES:0)
Block(1,71,7,LEAVES:0)
Block(1,71,8,LEAVES:0)
Block(1,72,-5,LEAVES:0)
Block(1,72,-4,LEAVES:0)
Block(1,72,-3,LEAVES:0)
Block(1,72,-2,LEAVES:0)
Block(1,72,-1,LEAVES:0)
Block(1,72,0,LEAVES:0)
Block(1,72,1,LEAVES:0)
Block(1,72,2,LEAVES:0)
Block(1,72,3,LOG:12)
Block(1,72,4,LEAVES:0)
Block(1,72,5,LEAVES:0)
Block(1,72,6,LOG:12)
Block(1,72,7,LEAVES:0)
Block(1,72,8,LEAVES:0)
Block(1,73,-5,LEAVES:0)
Block(1,73,-4,LEAVES:0)
Block(1,73,-3,LEAVES:0)
Block(1,73,-2,LEAVES:0)
Block(1,73,-1,LEAVES:0)
Block(1,73,0,LEAVES:0)
Block(1,73,1,LEAVES:0)
Block(1,73,2,LEAVES:0)
Block(1,73,3,LEAVES:0)
Block(1,73,4,LEAVES:0)
Block(1,73,5,LEAVES:0)
Block(1,73,6,LEAVES:0)
Block(1,73,7,LEAVES:0)
Block(1,74,-4,LEAVES:0)
Block(1,74,-3,LEAVES:0)
Block(1,74,-2,LEAVES:0)
Block(1,74,-1,LEAVES:0)
Block(1,74,0,LEAVES:0)
Block(1,74,1,LEAVES:0)
Block(1,74,2,LEAVES:0)
Block(1,74,3,LEAVES:0)
Block(1,74,4,LEAVES:0)
Block(1,74,5,LEAVES:0)
Block(1,74,6,LEAVES:0)
Block(1,74,7,LEAVES:0)
Block(1,74,8,LEAVES:0)
Block(1,75,-2,LEAVES:0)
Block(1,75,-1,LEAVES:0)
Block(1,75,0,LEAVES:0)
Block(1,75,1,LOG:12)
Block(1,75,2,LEAVES:0)
Block(1,75,3,LEAVES:0)
Block(1,75,4,LEAVES:0)
Block(1,75,5,LEAVES:0)
Block(1,75,7,LEAVES:0)
Block(1,75,8,LEAVES:0)
Block(1,76,-1,LEAVES:0)
Block(1,76,0,LEAVES:0)
Block(1,76,1,LEAVES:0)
Block(1,76,2,LEAVES:0)
Block(1,76,3,LEAVES:0)
Block(1,76,4,LEAVES:0)
Block(1,76,5,LEAVES:0)
Block(1,76,6,LEAVES:0)
Block(1,76,7,LEAVES:0)
Block(1,76,8,LEAVES:0)
Block(1,77,-1,LEAVES:0)
Block(1,77,0,LEAVES:0)
Block(1,77,1,LEAVES:0)
Block(1,77,2,LEAVES:0)
Block(1,77,3,LEAVES:0)
Block(1,77,4,LEAVES:12)
Block(1,77,5,LEAVES:0)
Block(1,77,6,LEAVES:0)
Block(1,77,7,LEAVES:0)
Block(1,77,8,LEAVES:0)
Block(1,78,-1,LEAVES:0)
Block(1,78,0,LEAVES:0)
Block(1,78,1,LEAVES:0)
Block(1,78,2,LEAVES:0)
Block(1,78,3,LEAVES:0)
Block(1,78,4,LEAVES:12)
Block(1,78,5,LEAVES:0)
Block(1,78,6,LEAVES:0)
Block(1,78,7,LEAVES:0)
Block(1,79,2,LEAVES:0)
Block(1,79,3,LEAVES:0)
Block(1,79,4,LEAVES:0)
Block(1,79,5,LEAVES:0)
Block(1,79,6,LEAVES:0)
Block(1,80,-6,WOOL:14)
Block(1,80,-5,WOOL:14)
Block(1,80,-4,WOOL:14)
Block(1,80,3,LEAVES:0)
Block(1,80,4,LEAVES:0)
Block(1,80,5,LEAVES:0)
Block(1,80,6,LEAVES:0)
Block(1,81,-7,WOOL:14)
Block(1,81,-6,WOOL:14)
Block(1,81,-5,WOOL:14)
Block(1,81,-4,WOOL:14)
Block(1,81,-3,WOOL:14)
Block(1,81,4,LEAVES:0)
Block(1,82,-7,WOOL:14)
Block(1,82,-6,WOOL:14)
Block(1,82,-5,WOOL:14)
Block(1,82,-4,WOOL:14)
Block(1,82,-3,WOOL:14)
Block(1,83,-7,WOOL:14)
Block(1,83,-6,WOOL:14)
Block(1,83,-5,WOOL:14)
Block(1,83,-4,WOOL:14)
Block(1,83,-3,WOOL:14)
Block(1,83,-2,WOOL:14)
Block(1,84,-7,WOOL:14)
Block(1,84,-6,WOOL:14)
Block(1,84,-5,WOOL:14)
Block(1,84,-4,WOOL:14)
Block(1,84,-3,WOOL:14)
Block(1,84,-2,WOOL:14)
RandomBlock(1,84,4,minecraft:wool:7,10,quark:quilted_wool:7,100)
RandomBlock(1,84,5,minecraft:wool:7,10,quark:quilted_wool:7,100)
RandomBlock(1,84,6,minecraft:wool:7,10,quark:quilted_wool:7,100)
Block(1,85,-7,WOOL:14)
Block(1,85,-6,WOOL:14)
Block(1,85,-5,WOOL:14)
Block(1,85,-4,WOOL:14)
Block(1,85,-3,WOOL:14)
Block(1,85,-2,WOOL:14)
RandomBlock(1,85,3,minecraft:wool:7,10,quark:quilted_wool:7,100)
RandomBlock(1,85,4,minecraft:wool:7,10,quark:quilted_wool:7,100)
RandomBlock(1,85,5,minecraft:wool:7,10,quark:quilted_wool:7,100)
RandomBlock(1,85,6,minecraft:wool:7,10,quark:quilted_wool:7,100)
RandomBlock(1,85,7,minecraft:wool:7,10,quark:quilted_wool:7,100)
Block(1,86,-7,WOOL:14)
Block(1,86,-6,WOOL:14)
Block(1,86,-5,WOOL:14)
Block(1,86,-4,WOOL:14)
Block(1,86,-3,WOOL:14)
RandomBlock(1,86,2,minecraft:wool:7,10,quark:quilted_wool:7,100)
RandomBlock(1,86,3,minecraft:wool:7,10,quark:quilted_wool:7,100)
RandomBlock(1,86,4,minecraft:wool:7,10,quark:quilted_wool:7,100)
RandomBlock(1,86,5,minecraft:wool:7,10,quark:quilted_wool:7,100)
RandomBlock(1,86,6,minecraft:wool:7,10,quark:quilted_wool:7,100)
RandomBlock(1,86,7,minecraft:wool:7,10,quark:quilted_wool:7,100)
RandomBlock(1,86,8,minecraft:wool:7,10,quark:quilted_wool:7,100)
Block(1,87,-7,WOOL:14)
Block(1,87,-6,WOOL:14)
Block(1,87,-5,WOOL:14)
Block(1,87,-4,WOOL:14)
Block(1,87,-3,WOOL:14)
RandomBlock(1,87,1,minecraft:wool:7,10,quark:quilted_wool:7,100)
RandomBlock(1,87,2,minecraft:wool:7,10,quark:quilted_wool:7,100)
RandomBlock(1,87,3,minecraft:wool:7,10,quark:quilted_wool:7,100)
RandomBlock(1,87,4,minecraft:wool:7,10,quark:quilted_wool:7,100)
RandomBlock(1,87,5,minecraft:wool:7,10,quark:quilted_wool:7,100)
RandomBlock(1,87,6,minecraft:wool:7,10,quark:quilted_wool:7,100)
RandomBlock(1,87,7,minecraft:wool:7,10,quark:quilted_wool:7,100)
RandomBlock(1,87,8,minecraft:wool:7,10,quark:quilted_wool:7,100)
Block(1,88,-6,WOOL:14)
Block(1,88,-5,WOOL:14)
Block(1,88,-4,WOOL:14)
RandomBlock(1,88,1,minecraft:wool:7,10,quark:quilted_wool:7,100)
RandomBlock(1,88,2,minecraft:wool:7,10,quark:quilted_wool:7,100)
RandomBlock(1,88,3,minecraft:wool:7,10,quark:quilted_wool:7,100)
RandomBlock(1,88,4,minecraft:wool:7,10,quark:quilted_wool:7,100)
RandomBlock(1,88,5,minecraft:wool:7,10,quark:quilted_wool:7,100)
RandomBlock(1,88,6,minecraft:wool:7,10,quark:quilted_wool:7,100)
RandomBlock(1,88,7,minecraft:wool:7,10,quark:quilted_wool:7,100)
RandomBlock(1,88,8,minecraft:wool:7,10,quark:quilted_wool:7,100)
RandomBlock(1,89,1,minecraft:wool:7,10,quark:quilted_wool:7,100)
RandomBlock(1,89,2,minecraft:wool:7,10,quark:quilted_wool:7,100)
RandomBlock(1,89,3,minecraft:wool:7,10,quark:quilted_wool:7,100)
RandomBlock(1,89,4,minecraft:wool:7,10,quark:quilted_wool:7,100)
RandomBlock(1,89,5,minecraft:wool:7,10,quark:quilted_wool:7,100)
RandomBlock(1,89,6,minecraft:wool:7,10,quark:quilted_wool:7,100)
RandomBlock(1,89,7,minecraft:wool:7,10,quark:quilted_wool:7,100)
RandomBlock(1,89,8,minecraft:wool:7,10,quark:quilted_wool:7,100)
RandomBlock(1,90,1,minecraft:wool:7,10,quark:quilted_wool:7,100)
RandomBlock(1,90,2,minecraft:wool:7,10,quark:quilted_wool:7,100)
RandomBlock(1,90,3,minecraft:wool:7,10,quark:quilted_wool:7,100)
RandomBlock(1,90,4,minecraft:wool:7,10,quark:quilted_wool:7,100)
RandomBlock(1,90,5,minecraft:wool:7,10,quark:quilted_wool:7,100)
RandomBlock(1,90,6,minecraft:wool:7,10,quark:quilted_wool:7,100)
RandomBlock(1,90,7,minecraft:wool:7,10,quark:quilted_wool:7,100)
RandomBlock(1,90,8,minecraft:wool:7,10,quark:quilted_wool:7,100)
RandomBlock(1,91,1,minecraft:wool:7,10,quark:quilted_wool:7,100)
RandomBlock(1,91,2,minecraft:wool:7,10,quark:quilted_wool:7,100)
RandomBlock(1,91,3,minecraft:wool:7,10,quark:quilted_wool:7,100)
RandomBlock(1,91,4,minecraft:wool:7,10,quark:quilted_wool:7,100)
RandomBlock(1,91,5,minecraft:wool:7,10,quark:quilted_wool:7,100)
RandomBlock(1,91,6,minecraft:wool:7,10,quark:quilted_wool:7,100)
RandomBlock(1,91,7,minecraft:wool:7,10,quark:quilted_wool:7,100)
RandomBlock(1,91,8,minecraft:wool:7,10,quark:quilted_wool:7,100)
RandomBlock(1,92,2,minecraft:wool:7,10,quark:quilted_wool:7,100)
RandomBlock(1,92,3,minecraft:wool:7,10,quark:quilted_wool:7,100)
RandomBlock(1,92,4,minecraft:wool:7,10,quark:quilted_wool:7,100)
RandomBlock(1,92,5,minecraft:wool:7,10,quark:quilted_wool:7,100)
RandomBlock(1,92,6,minecraft:wool:7,10,quark:quilted_wool:7,100)
RandomBlock(1,92,7,minecraft:wool:7,10,quark:quilted_wool:7,100)
RandomBlock(1,92,8,minecraft:wool:7,10,quark:quilted_wool:7,100)
RandomBlock(1,93,3,minecraft:wool:7,10,quark:quilted_wool:7,100)
RandomBlock(1,93,4,minecraft:wool:7,10,quark:quilted_wool:7,100)
RandomBlock(1,93,5,minecraft:wool:7,10,quark:quilted_wool:7,100)
RandomBlock(1,93,6,minecraft:wool:7,10,quark:quilted_wool:7,100)
RandomBlock(1,93,7,minecraft:wool:7,10,quark:quilted_wool:7,100)
RandomBlock(1,94,4,minecraft:wool:7,10,quark:quilted_wool:7,100)
RandomBlock(1,94,5,minecraft:wool:7,10,quark:quilted_wool:7,100)
RandomBlock(1,94,6,minecraft:wool:7,10,quark:quilted_wool:7,100)
Block(2,4,8,LEAVES:0)
Block(2,5,6,LEAVES:0)
Block(2,5,7,LEAVES:0)
Block(2,5,8,LEAVES:0)
Block(2,6,-5,LOG:12)
Block(2,6,4,LOG:12)
Block(2,6,5,LOG:12)
Block(2,6,6,LOG:12)
Block(2,6,7,LEAVES:0)
Block(2,7,-6,LOG:12)
Block(2,7,-5,LOG:12)
Block(2,7,-4,LOG:12)
Block(2,7,4,LOG:12)
Block(2,7,5,LOG:12)
Block(2,7,6,LEAVES:0)
Block(2,8,-7,LEAVES:0)
Block(2,8,-6,LOG:12)
Block(2,8,-5,LOG:12)
Block(2,8,-4,LOG:12)
Block(2,8,5,quark:leaf_carpet)
Block(2,8,6,LEAVES:0)
Block(2,9,-7,LEAVES:0)
Block(2,9,-6,LOG:12)
Block(2,9,-5,LOG:12)
Block(2,9,-4,LOG:12)
Block(2,9,5,LEAVES:0)
Block(2,10,-7,LEAVES:0)
Block(2,10,-6,LEAVES:0)
Block(2,10,-5,LOG:12)
Block(2,11,8,LOG:12)
Block(2,12,7,LOG:12)
Block(2,12,8,LOG:12)
Block(2,13,7,LOG:12)
Block(2,13,8,LOG:12)
Block(2,14,6,LOG:12)
Block(2,14,7,LOG:12)
Block(2,14,8,LOG:12)
Block(2,15,5,LOG:12)
Block(2,15,6,LOG:12)
Block(2,15,7,LOG:12)
Block(2,15,8,LOG:12)
Block(2,16,5,LOG:12)
Block(2,16,6,LOG:12)
Block(2,16,7,LOG:12)
Block(2,16,8,LOG:12)
Block(2,17,-2,LOG:12)
Block(2,17,5,LOG:12)
Block(2,17,6,LOG:12)
Block(2,17,7,LOG:12)
Block(2,17,8,quark:leaf_carpet)
Block(2,18,-4,LOG:12)
Block(2,18,-3,LOG:12)
